Workbook

Sheet 기업리스트
B2: 실적 기업 정보
B3: Ticker | C3: Company | D3: Date | E3: Time | F3: Quarter Ending | G3: Market Cap (mil$)
B4: AMZN | C4: Amazon.com, Inc. | D4: 05-Feb-26 | E4: After Hours | F4: Dec-25 | G4: 2558170
B5: SHEL | C5: Shell plc | D5: 05-Feb-26 | F5: Dec-25 | G5: 218501
B6: LIN | C6: Linde plc | D6: 05-Feb-26 | E6: Pre Market | F6: Dec-25 | G6: 213382
B7: BBVA | C7: Banco Bilbao Vizcaya Argentaria, S.A. | D7: 05-Feb-26 | F7: Dec-25 | G7: 145037
B8: 6758 | C8: Sony Group Corporation | D8: 05-Feb-26 | E8: Pre Market | F8: Dec-25 | G8: 133941
B9: COP | C9: ConocoPhillips | D9: 05-Feb-26 | E9: Pre Market | F9: Dec-25 | G9: 128799
B10: BNP | C10: BNP Paribas SA | D10: 05-Feb-26 | F10: Dec-25 | G10: 119716
B11: BMY | C11: Bristol-Myers Squibb Company | D11: 05-Feb-26 | E11: Pre Market | F11: Dec-25 | G11: 112068
B12: KKR | C12: KKR & Co. Inc. | D12: 05-Feb-26 | E12: Pre Market | F12: Dec-25 | G12: 101846
B13: ICE | C13: Intercontinental Exchange, Inc. | D13: 05-Feb-26 | F13: Dec-25 | G13: 99085.63
B14: 8058 | C14: Mitsubishi Corporation | D14: 05-Feb-26 | F14: Dec-25 | G14: 98651.89
B15: 8001 | C15: ITOCHU Corporation | D15: 05-Feb-26 | F15: Dec-25 | G15: 89964.99
B16: DG | C16: Vinci SA | D16: 05-Feb-26 | F16: Dec-25 | G16: 80084.42
B17: CMI | C17: Cummins Inc. | D17: 05-Feb-26 | E17: Pre Market | F17: Dec-25 | G17: 79898.14
B18: ABX | C18: Barrick Mining Corporation | D18: 05-Feb-26 | E18: Pre Market | F18: Dec-25 | G18: 77132.47
B19: CI | C19: The Cigna Group | D19: 05-Feb-26 | E19: Pre Market | F19: Dec-25 | G19: 73221.86
B20: FTNT | C20: Fortinet, Inc. | D20: 05-Feb-26 | E20: After Hours | F20: Dec-25 | G20: 60428.84
B21: DLR | C21: Digital Realty Trust, Inc. | D21: 05-Feb-26 | E21: After Hours | F21: Dec-25 | G21: 57004.08
B22: LICI | C22: Life Insurance Corporation of India | D22: 05-Feb-26 | F22: Dec-25 | G22: 56784.9
B23: SHL | C23: Siemens Healthineers AG | D23: 05-Feb-26 | F23: Dec-25 | G23: 56067.39
B24: MPWR | C24: Monolithic Power Systems, Inc. | D24: 05-Feb-26 | E24: After Hours | F24: Dec-25 | G24: 53854.65
B25: CAH | C25: Cardinal Health, Inc. | D25: 05-Feb-26 | E25: Pre Market | F25: Dec-25 | G25: 51054.42
B26: CARR | C26: Carrier Global Corporation | D26: 05-Feb-26 | E26: Pre Market | F26: Dec-25 | G26: 50178.86
B27: TRI | C27: Thomson Reuters Corporation | D27: 05-Feb-26 | F27: Dec-25 | G27: 49352.43
B28: MSTR | C28: Strategy Inc | D28: 05-Feb-26 | E28: After Hours | F28: Dec-25 | G28: 48394.89
B29: ROK | C29: Rockwell Automation, Inc. | D29: 05-Feb-26 | E29: Pre Market | F29: Dec-25 | G29: 47407.45
B30: RBLX | C30: Roblox Corporation | D30: 05-Feb-26 | E30: After Hours | F30: Dec-25 | G30: 46158.62
B31: ASSA B | C31: ASSA ABLOY AB (publ) | D31: 05-Feb-26 | F31: Dec-25 | G31: 45396.5
B32: XEL | C32: Xcel Energy Inc. | D32: 05-Feb-26 | E32: Pre Market | F32: Dec-25 | G32: 44992.52
B33: RDDT | C33: Reddit, Inc. | D33: 05-Feb-26 | E33: After Hours | F33: Dec-25 | G33: 43775.42
B34: 3711 | C34: ASE Technology Holding Co., Ltd. | D34: 05-Feb-26 | E34: Pre Market | F34: Dec-25 | G34: 41944.43
B35: EL | C35: The Estée Lauder Companies Inc. | D35: 05-Feb-26 | F35: Dec-25 | G35: 41459.45
B36: SAAB B | C36: Saab AB (publ) | D36: 05-Feb-26 | F36: Dec-25 | G36: 41191.6
B37: DANSKE | C37: Danske Bank A/S | D37: 05-Feb-26 | F37: Dec-25 | G37: 41185.25
B38: IQV | C38: IQVIA Holdings Inc. | D38: 05-Feb-26 | F38: Dec-25 | G38: 40476.9
B39: MCHP | C39: Microchip Technology Incorporated | D39: 05-Feb-26 | E39: After Hours | F39: Dec-25 | G39: 40371.38
B40: HSY | C40: The Hershey Company | D40: 05-Feb-26 | F40: Dec-25 | G40: 40102.79
B41: ARES | C41: Ares Management Corporation | D41: 05-Feb-26 | E41: Pre Market | F41: Dec-25 | G41: 37389.88
...

Sheet Revenue
B2: Ticker | C2: Country | D2: Industry | E2: Latest_Date | F2: Growth_Rate | G2: 4Q21 | H2: 1Q22 | I2: 2Q22 | J2: 3Q22 | K2: 4Q22 | L2: 1Q23 | M2: 2Q23 | N2: 3Q23 | O2: 4Q23 | P2: 1Q24 | Q2: 2Q24 | R2: 3Q24 | S2: 4Q24 | T2: 1Q25 | U2: 2Q25 | V2: 3Q25 | W2: 4Q25 | X2: 1Q25 | Y2: 2Q25 | Z2: 3Q25 | AA2: 4Q25
B3: MOFG | C3: United States | D3: Banks - Regional | E3: Sep'25 | F3: 224.8 | G3: 50.6 | H3: 49.43 | I3: 48.98 | J3: 50.05 | K3: 57.68 | L3: 52.68 | M3: 35.1 | N3: 44.11 | O3: 42.89 | P3: 34.65 | Q3: 39.79 | R3: 56.63 | S3: -94.4 | T3: 58.48 | U3: 55.89 | V3: 48.34 | W3: 59.13 | X3: 0.64985001 | Y3: 0.2661157 | Z3: -0.10822454 | AA3: 2.2475479
B4: ARWR | C4: United States | D4: Biotechnology | E4: Mar'26 | F4: 31.5 | G4: 27.44 | H4: 151.81 | I4: 32.41 | J4: 31.58 | K4: 62.55 | L4: 146.27 | M4: 15.83 | N4: 16.1 | O4: 3.55 | P4: 0 | Q4: 0 | R4: 0 | S4: 2.5 | T4: 542.71 | U4: 27.77 | V4: 256.47 | W4: 264.03 | X4: 217.084 | Y4: 0.050934502 | Z4: 0.44760725 | AA4: 0.31530532
B5: GOLD | C5: United States | D5: Capital Markets | E5: Jun'26 | F5: 31.3 | G5: 1946 | H5: 2109 | I5: 2090 | J5: 1900 | K5: 1950 | L5: 2317 | M5: 3119 | N5: 2485 | O5: 2079 | P5: 2611 | Q5: 2525 | R5: 2715 | S5: 2742 | T5: 3009 | U5: 2512 | V5: 3681 | W5: 6477 | X5: 0.037571981 | Y5: -0.0011827859 | Z5: 0.08799417 | AA5: 0.31270931
B6: ABX | C6: United States | D6: Insurance - Life | E6: Sep'25 | F6: 21.5 | G6: 0.32 | H6: 0.2 | I6: 9.88 | J6: 8.4 | K6: 11.51 | L6: 14.93 | M6: 10.27 | N6: 11.38 | O6: 21.12 | P6: 23.7 | Q6: 21.49 | R6: 29.08 | S6: 28.15 | T6: 33.21 | U6: 44.14 | V6: 56.22 | W6: 62.98 | X6: 0.092852958 | Y6: 0.20235862 | Z6: 0.20166444 | AA6: 0.21537225
B7: BLSH | C7: United States | D7: Software - Infrastructure | E7: Dec'25 | F7: 19.3 | L7: 0.26 | M7: 0.26 | N7: -0.11 | O7: -0.11 | P7: 38.37 | Q7: 47.99 | R7: 32.86 | S7: 39.27 | T7: 46.82 | U7: 47.66 | V7: 65.05 | W7: 77.71 | X7: 0.053315667 | Y7: -0.0019767581 | Z7: 0.19320569 | AA7: 0.19336016
B8: STEP | C8: United States | D8: Asset Management | E8: Sep'26 | F8: 16.1 | G8: 410.47 | H8: 364.69 | I8: -77.22 | J8: -158.5 | K8: -4.24 | L8: 172.37 | M8: 178.01 | N8: 191.42 | O8: -14.61 | P8: 356.81 | Q8: 186.4 | R8: 271.68 | S8: 339.02 | T8: 377.73 | U8: 364.29 | V8: 454.23 | W8: 586.51 | X8: 0.018129663 | Y8: 0.15141765 | Z8: 0.13495032 | AA8: 0.16120292
B9: RDDT | C9: United States | D9: Internet Content & Information | E9: Dec'25 | F9: 15.6 | G9: 176.67 | H9: 146.18 | I9: 148.56 | J9: 171.54 | K9: 200.43 | L9: 163.74 | M9: 183.03 | N9: 207.51 | O9: 249.75 | P9: 242.96 | Q9: 281.18 | R9: 348.35 | S9: 427.71 | T9: 392.36 | U9: 499.63 | V9: 584.91 | W9: 725.61 | X9: 0.1149054 | Y9: 0.15069674 | Z9: 0.14181829 | AA9: 0.15640997
B10: KKR | C10: United States | D10: Asset Management | E10: Dec'25 | F10: 15.6 | G10: 4103 | H10: 2592 | I10: -1396 | J10: 1844 | K10: 2476 | L10: 3213 | M10: 4517 | N10: 5074 | O10: 5860 | P10: 10613 | Q10: 5064 | R10: 6279 | S10: 4466 | T10: 4500 | U10: 6175 | V10: 7105 | W10: 7928 | X10: -0.23136023 | Y10: 0.054704811 | Z10: 0.038562092 | AA10: 0.15562348
B11: ARX | C11: United States | D11: Insurance Brokers | E11: Sep'25 | F11: 11.5 | O11: 68.6 | P11: 111 | Q11: 119.8 | R11: 121.4 | S11: 138.6 | T11: 181.2 | U11: 163.5 | V11: 204.7 | W11: 217.8 | X11: 0.14303178 | Y11: 0.077896613 | Z11: 0.13775426 | AA11: 0.11511628
B12: BE | C12: United States | D12: Electrical Equipment & Parts | E12: Dec'25 | F12: 11.3 | G12: 342.47 | H12: 201.04 | I12: 243.24 | J12: 292.27 | K12: 462.58 | L12: 275.19 | M12: 301.1 | N12: 400.27 | O12: 356.92 | P12: 235.3 | Q12: 335.77 | R12: 330.4 | S12: 572.39 | T12: 326.02 | U12: 401.24 | V12: 519.05 | W12: 777.68 | X12: 0.061552658 | Y12: 0.041845096 | Z12: 0.11573265 | AA12: 0.11287733
B13: TPG | C13: United States | D13: Asset Management | E13: Dec'25 | F13: 9.8 | G13: 1079 | H13: 1111 | I13: -108.28 | J13: 561.12 | K13: 439.34 | L13: 643.15 | M13: 603.27 | N13: 160.36 | O13: 983.14 | P13: 824.07 | Q13: 744.19 | R13: 855.4 | S13: 1076 | T13: 1035 | U13: 920.54 | V13: 1224 | W13: 1491 | X13: 0.060271569 | Y13: 0.047526135 | Z13: 0.094830381 | AA13: 0.097519939
B14: IREN | C14: United States | D14: Capital Markets | E14: Jun'26 | F14: 9.7 | G14: 20.15 | H14: 15.18 | I14: 16.21 | J14: 14.98 | K14: 13.76 | L14: 11.33 | M14: 34.22 | N14: 34.4 | O14: 42.57 | P14: 54.35 | Q14: 55.87 | R14: 52.76 | S14: 117.9 | T14: 148.1 | U14: 180.64 | V14: 240.3 | W14: 184.69 | X14: 0.33377243 | Y14: 0.33304861 | Z14: 0.37553064 | AA14: 0.097228288
B15: ADPT | C15: United States | D15: Biotechnology | E15: Dec'25 | F15: 9.6 | G15: 37.93 | H15: 38.62 | I15: 43.66 | J15: 47.83 | K15: 55.2 | L15: 37.65 | M15: 48.93 | N15: 37.92 | O15: 45.78 | P15: 41.87 | Q15: 43.19 | R15: 46.44 | S15: 47.46 | T15: 52.44 | U15: 58.88 | V15: 93.97 | W15: 71.68 | X15: 0.059063478 | Y15: 0.082783728 | Z15: 0.23160511 | AA15: 0.095825915
B16: RBLX | C16: United States | D16: Electronic Gaming & Multimedia | E16: Dec'25 | F16: 9.6 | G16: 568.77 | H16: 537.13 | I16: 591.21 | J16: 517.71 | K16: 579 | L16: 655.34 | M16: 680.77 | N16: 713.23 | O16: 749.94 | P16: 801.3 | Q16: 893.54 | R16: 918.95 | S16: 988.18 | T16: 1035 | U16: 1081 | V16: 1360 | W16: 1415 | X16: 0.064881162 | Y16: 0.048872818 | Z16: 0.10962857 | AA16: 0.095609944
B17: ROAD | C17: United States | D17: Engineering & Construction | E17: Mar'26 | F17: 8.8 | G17: 284.96 | H17: 243.39 | I17: 380.27 | J17: 393.05 | K17: 341.78 | L17: 324.85 | M17: 421.89 | N17: 475.03 | O17: 396.51 | P17: 371.43 | Q17: 517.79 | R17: 538.16 | S17: 561.58 | T17: 571.65 | U17: 779.28 | V17: 899.85 | W17: 809.47 | X17: 0.10066567 | Y17: 0.11944655 | Z17: 0.14758821 | AA17: 0.088143054
B18: AFRM | C18: United States | D18: Credit Services | E18: Jun'26 | F18: 7.4 | G18: 361.01 | H18: 354.76 | I18: 364.13 | J18: 361.62 | K18: 399.56 | L18: 380.98 | M18: 445.83 | N18: 496.55 | O18: 591.11 | P18: 576.16 | Q18: 659.19 | R18: 698.48 | S18: 866.38 | T18: 783.14 | U18: 876.42 | V18: 933.34 | W18: 1123 | X18: 0.073915885 | Y18: 0.072236872 | Z18: 0.072837906 | AA18: 0.074183067
B19: GOOS | C19: United States | D19: Apparel Manufacturing | E19: Sep'26 | F19: 6.3 | G19: 586.1 | H19: 223.1 | I19: 69.9 | J19: 277.2 | K19: 576.7 | L19: 293.2 | M19: 84.8 | N19: 281.1 | O19: 609.9 | P19: 358 | Q19: 88.1 | R19: 267.8 | S19: 607.9 | T19: 384.6 | U19: 107.8 | V19: 272.6 | W19: 694.5 | X19: 0.020124073 | Y19: 0.014609908 | Z19: 0.0035085155 | AA19: 0.063078156
B20: RGA | C20: United States | D20: Insurance - Reinsurance | E20: Dec'25 | F20: 6.2 | G20: 4359 | H20: 3917 | I20: 3903 | J20: 4050 | K20: 4357 | L20: 4251 | M20: 4156 | N20: 5153 | O20: 5007 | P20: 6337 | Q20: 4878 | R20: 5651 | S20: 5241 | T20: 5260 | U20: 5599 | V20: 6204 | W20: 6635 | X20: -0.048717601 | Y20: 0.034284356 | Z20: 0.025424118 | AA20: 0.0625
B21: GEN | C21: United States | D21: Software - Infrastructure | E21: Sep'26 | F21: 5.7 | G21: 702 | H21: 716 | I21: 707 | J21: 748 | K21: 936 | L21: 947 | M21: 943 | N21: 945 | O21: 948 | P21: 964 | Q21: 965 | R21: 974 | S21: 986 | T21: 1010 | U21: 1257 | V21: 1220 | W21: 1240 | X21: 0.011828233 | Y21: 0.074205845 | Z21: 0.058197303 | AA21: 0.056785155
B22: MTSI | C22: United States | D22: Semiconductors | E22: Mar'26 | F22: 5.5 | G22: 159.62 | H22: 165.15 | I22: 172.26 | J22: 178.14 | K22: 180.1 | L22: 169.41 | M22: 148.52 | N22: 150.38 | O22: 157.15 | P22: 181.23 | Q22: 190.49 | R22: 200.71 | S22: 218.12 | T22: 235.89 | U22: 252.08 | V22: 261.17 | W22: 271.61 | X22: 0.069141737 | Y22: 0.072869464 | Z22: 0.066674019 | AA22: 0.05530054
B23: TEAM | C23: United States | D23: Software - Application | E23: Jun'26 | F23: 5.5 | G23: 688.53 | H23: 740.49 | I23: 759.84 | J23: 807.39 | K23: 872.7 | L23: 915.45 | M23: 939.1 | N23: 977.78 | O23: 1060 | P23: 1189 | Q23: 1132 | R23: 1188 | S23: 1286 | T23: 1357 | U23: 1384 | V23: 1433 | W23: 1586 | X23: 0.035036496 | Y23: 0.05077574 | Z23: 0.046979866 | AA23: 0.054945055
... B53: TW | C53: United States | D53: Capital Markets | E53: Dec'25 | F53: 2.9 | G53: 276.47 | H53: 311.04 | I53: 297.14 | J53: 287.12 | K53: 293.04 | L53: 328.8 | M53: 310.15 | N53: 327.89 | O53: 369.33 | P53: 407.02 | Q53: 404.41 | R53: 447.47 | S53: 462.77 | T53: 509.09 | U53: 512.54 | V53: 508.08 | W53: 520.78 | X53: 0.059285461 | Y53: 0.05929025 | Z53: 0.031373747 | AA53: 0.02911447
B54: MAGN | C54: United States | D54: Household & Personal Products | E54: Mar'26 | F54: 2.8 | N54: 542 | O54: 519 | P54: 558 | Q54: 556 | R54: 554 | S54: 702 | T54: 824 | U54: 839 | V54: 839 | W54: 792 | X54: 0.11223629 | Y54: 0.10735964 | Z54: 0.097636177 | AA54: 0.028089888
B55: LSPD | C55: United States | D55: Software - Application | E55: Sep'26 | F55: 2.8 | G55: 152.68 | H55: 146.56 | I55: 173.88 | J55: 183.7 | K55: 188.7 | L55: 184.23 | M55: 209.09 | N55: 230.27 | O55: 239.7 | P55: 230.22 | Q55: 266.09 | R55: 277.18 | S55: 280.13 | T55: 253.42 | U55: 304.94 | V55: 318.96 | W55: 312.35 | X55: 0.022019324 | Y55: 0.036078453 | Z55: 0.037448349 | AA55: 0.027837056
B56: OMF | C56: United States | D56: Credit Services | E56: Dec'25 | F56: 2.8 | G56: 813 | H56: 794 | I56: 704 | J56: 642 | K56: 657 | L56: 647 | M56: 579 | N56: 675 | O56: 659 | P56: 647 | Q56: 533 | R56: 652 | S56: 665 | T56: 733 | U56: 708 | V56: 786 | W56: 745 | X56: 0.03444133 | Y56: 0.067750678 | Z56: 0.048585932 | AA56: 0.027662517
B57: ROK | C57: United States | D57: Specialty Industrial Machinery | E57: Mar'26 | F57: 2.7 | G57: 1857 | H57: 1808 | I57: 1969 | J57: 2126 | K57: 1981 | L57: 2275 | M57: 2239 | N57: 2563 | O57: 2052 | P57: 2126 | Q57: 2051 | R57: 2035 | S57: 1881 | T57: 2001 | U57: 2144 | V57: 2316 | W57: 2105 | X57: -0.015445447 | Y57: 0.011671687 | Z57: 0.034859199 | AA57: 0.026852074
B58: WEC | C58: United States | D58: Utilities - Regulated Electric | E58: Dec'25 | F58: 2.6 | G58: 2202 | H58: 2908 | I58: 2128 | J58: 2003 | K58: 2558 | L58: 2888 | M58: 1830 | N58: 1957 | O58: 2218 | P58: 2680 | Q58: 1772 | R58: 1864 | S58: 2284 | T58: 3150 | U58: 2010 | V58: 2104 | W58: 2537 | X58: 0.054651163 | Y58: 0.026240353 | Z58: 0.025784272 | AA58: 0.026497696
B59: DOCS | C59: United States | D59: Health Information Services | E59: Sep'26 | F59: 2.6 | G59: 97.88 | H59: 93.65 | I59: 90.64 | J59: 102.19 | K59: 115.26 | L59: 110.97 | M59: 108.47 | N59: 113.61 | O59: 135.28 | P59: 118.06 | Q59: 126.68 | R59: 136.83 | S59: 168.6 | T59: 138.29 | U59: 145.91 | V59: 168.53 | W59: 185.05 | X59: 0.036770453 | Y59: 0.033713184 | Z59: 0.053762529 | AA59: 0.026475464
B60: WMG | C60: United States | D60: Entertainment | E60: Mar'26 | F60: 2.6 | G60: 1614 | H60: 1376 | I60: 1432 | J60: 1497 | K60: 1488 | L60: 1399 | M60: 1564 | N60: 1586 | O60: 1748 | P60: 1494 | Q60: 1554 | R60: 1630 | S60: 1666 | T60: 1484 | U60: 1689 | V60: 1868 | W60: 1840 | X60: -0.0015762926 | Y60: 0.021313546 | Z60: 0.036790849 | AA60: 0.025943045
B61: IQV | C61: United States | D61: Diagnostics & Research | E61: Dec'25 | F61: 2.6 | G61: 3636 | H61: 3568 | I61: 3541 | J61: 3562 | K61: 3739 | L61: 3652 | M61: 3728 | N61: 3736 | O61: 3868 | P61: 3737 | Q61: 3814 | R61: 3896 | S61: 3958 | T61: 3829 | U61: 4017 | V61: 4100 | W61: 4364 | X61: 0.005972087 | Y61: 0.01309931 | Z61: 0.012993631 | AA61: 0.025528169
B62: CLSK | C62: United States | D62: Capital Markets | E62: Mar'26 | F62: 2.5 | G62: 37.13 | H62: 37.2 | I62: 31.03 | J62: 26.17 | K62: 27.82 | L62: 42.55 | M62: 45.52 | N62: 52.52 | O62: 73.79 | P62: 111.8 | Q62: 104.11 | R62: 89.28 | S62: 162.31 | T62: 181.71 | U62: 198.64 | V62: 223.65 | W62: 181.18 | X62: 0.14954011 | Y62: 0.17589922 | Z62: 0.21263095 | AA62: 0.024624499
B63: THR | C63: United States | D63: Specialty Industrial Machinery | E63: Sep'26 | F63: 2.5 | G63: 100.61 | H63: 102.58 | I63: 95.44 | J63: 100.56 | K63: 122.11 | L63: 122.48 | M63: 106.89 | N63: 123.66 | O63: 136.43 | P63: 127.65 | Q63: 115.13 | R63: 114.65 | S63: 134.35 | T63: 134.08 | U63: 108.9 | V63: 131.72 | W63: 147.31 | X63: 0.013074952 | Y63: -0.012504767 | Z63: 0.034696532 | AA63: 0.025459189
B64: CI | C64: United States | D64: Healthcare Plans | E64: Dec'25 | F64: 2.5 | G64: 45688 | H64: 44006 | I64: 45478 | J64: 45281 | K64: 45753 | L64: 46517 | M64: 48586 | N64: 49048 | O64: 51114 | P64: 57255 | Q64: 60523 | R64: 63694 | S64: 65649 | T64: 65502 | U64: 67178 | V64: 69748 | W64: 72472 | X64: 0.033372316 | Y64: 0.02606043 | Z64: 0.023104842 | AA64: 0.025451643
B65: QLYS | C65: United States | D65: Software - Infrastructure | E65: Dec'25 | F65: 2.5 | G65: 109.78 | H65: 113.42 | I65: 119.89 | J65: 125.56 | K65: 130.85 | L65: 130.68 | M65: 137.21 | N65: 142 | O65: 144.57 | P65: 145.81 | Q65: 148.71 | R65: 153.87 | S65: 159.19 | T65: 159.9 | U65: 164.06 | V65: 169.88 | W65: 175.28 | X65: 0.023190362 | Y65: 0.024691557 | Z65: 0.025132649 | AA65: 0.024638991
B66: POST | C66: United States | D66: Packaged Foods | E66: Mar'26 | F66: 2.5 | G66: 1338 | H66: 1410 | I66: 1525 | J66: 1579 | K66: 1566 | L66: 1620 | M66: 1859 | N66: 1945 | O66: 1966 | P66: 1999 | Q66: 1948 | R66: 2010 | S66: 1975 | T66: 1952 | U66: 1984 | V66: 2247 | W66: 2175 | X66: -0.0059253656 | Y66: 0.0045656309 | Z66: 0.029920465 | AA66: 0.024515813
... B152: AB | C152: United States | D152: Asset Management | E152: Dec'25 | F152: -164.8 | G152: 0 | H152: 0 | I152: 0 | J152: 0 | K152: 0 | L152: 0 | M152: 0 | N152: 65.76 | O152: -211.26 | P152: 0 | Q152: 0 | R152: 136.37 | S152: -345.36 | T152: 0 | U152: 0 | V152: 81.41 | W152: 89.76 | X152: 0 | Y152: 0 | Z152: 0.26297909 | AA152: -1.648494
B153: FABG | C153: Sweden | D153: =VLOOKUP(B153,기업리스트!$B:$G,2,FALSE) -> Fabege AB (publ) | E153: Dec'25 | F153: 6.3 | G153: 830 | H153: 766 | I153: 724 | J153: 884 | K153: 920 | L153: 1006 | M153: 960 | N153: 1101 | O153: 897 | P153: 997 | Q153: 837 | R153: 916 | S153: 830 | T153: 841 | U153: 966 | V153: 852 | W153: 1051 | X153: -0.043575419 | Y153: 0.037675234 | Z153: -0.018012947 | AA153: 0.063341932
B154: EAST | C154: Sweden | D154: =VLOOKUP(B154,기업리스트!$B:$G,2,FALSE) -> Eastnine AB (publ) | E154: Dec'25 | F154: 5.1 | G154: 5.45 | H154: 6.23 | I154: 7.35 | J154: 8.23 | K154: 8.5 | L154: 9.05 | M154: 9.09 | N154: 9.06 | O154: 8.97 | P154: 9.06 | Q154: 9.35 | R154: 10.7 | S154: 12.41 | T154: 15.61 | U154: 15.16 | V154: 15.53 | W154: 15.43 | X154: 0.1577553 | Y154: 0.1208654 | Z154: 0.089643653 | AA154: 0.051439278
B155: HTRO | C155: Sweden | D155: =VLOOKUP(B155,기업리스트!$B:$G,2,FALSE) -> Hexatronic Group AB (publ) | E155: Dec'25 | F155: 0.3 | G155: 1170 | H155: 1388 | I155: 1662 | J155: 1729 | K155: 1795 | L155: 2115 | M155: 2258 | N155: 1916 | O155: 1860 | P155: 1781 | Q155: 2024 | R155: 1951 | S155: 1824 | T155: 1881 | U155: 1906 | V155: 1883 | W155: 1848 | X155: 0.013192612 | Y155: -0.015364583 | Z155: -0.0089923301 | AA155: 0.003202562
...

Sheet Operating Income
B2: Ticker | C2: Country | D2: Industry | E2: Latest_Date | F2: Growth_Rate | G2: 4Q21 | H2: 1Q22 | I2: 2Q22 | J2: 3Q22 | K2: 4Q22 | L2: 1Q23 | M2: 2Q23 | N2: 3Q23 | O2: 4Q23 | P2: 1Q24 | Q2: 2Q24 | R2: 3Q24 | S2: 4Q24 | T2: 1Q25 | U2: 2Q25 | V2: 3Q25 | W2: 4Q25 | X2: 1Q25 | Y2: 2Q25 | Z2: 3Q25 | AA2: 4Q25
B3: IREN | C3: United States | D3: Capital Markets | E3: Jun'26 | F3: 22815.6 | G3: 5.56 | H3: 1.18 | I3: -8.63 | J3: -14.34 | K3: -17.74 | L3: -10.12 | M3: -9.65 | N3: -10.45 | O3: -2.44 | P3: 7.02 | Q3: -13.6 | R3: -39.28 | S3: 18.01 | T3: 27.9 | U3: 13.78 | V3: -60.14 | W3: -84.66 | X3: -0.7497307 | Y3: -3.928264 | Z3: -1.022048 | AA3: 228.15556
B4: CLSK | C4: United States | D4: Capital Markets | E4: Mar'26 | F4: 543.5 | G4: 15.59 | H4: 1.88 | I4: -15.32 | J4: -28.36 | K4: -28.88 | L4: -14.78 | M4: -15.59 | N4: -67.16 | O4: 29.19 | P4: 139.17 | Q4: -59.89 | R4: -167.71 | S4: 209.58 | T4: -140.25 | U4: 246.32 | V4: -411.66 | W4: -312.22 | X4: -2.306397 | Y4: -1.9347318 | Z4: -1.6489793 | AA4: 5.4348505
B5: IIIV | C5: United States | D5: Software - Infrastructure | E5: Mar'26 | F5: 430.3 | G5: 4.17 | H5: 5.33 | I5: 5.52 | J5: 7.03 | K5: 7.28 | L5: 0 | M5: 1.61 | N5: 4.11 | O5: 1.25 | P5: 0 | Q5: -1.31 | R5: 3.56 | S5: 4.08 | T5: 0 | U5: -4.77 | V5: 0.03 | W5: 1.24 | X5: 0 | Y5: -0.54660348 | Z5: -1.2299652 | AA5: 4.3030303
B6: ARWR | C6: United States | D6: Biotechnology | E6: Mar'26 | F6: 205.6 | G6: -63.32 | H6: 41.55 | I6: -72.91 | J6: -83.83 | K6: -42.13 | L6: 48.17 | M6: -102.7 | N6: -108.33 | O6: -136.55 | P6: -126.19 | Q6: -176.14 | R6: -162.2 | S6: -161.41 | T6: 381.2 | U6: -165.55 | V6: 44.11 | W6: 40.81 | X6: -0.81060485 | Y6: -0.089329397 | Z6: -1.9109856 | AA6: 2.0561261
B7: AFRM | C7: United States | D7: Credit Services | E7: Jun'26 | F7: 112.6 | G7: -196.1 | H7: -226.55 | I7: -276.83 | J7: -287.47 | K7: -359.53 | L7: -275.1 | M7: -241.55 | N7: -207.03 | O7: -171.1 | P7: -155.59 | Q7: -71.86 | R7: -132.88 | S7: -4.26 | T7: -8.38 | U7: 57.26 | V7: 63.66 | W7: 117.63 | X7: -0.40376862 | Y7: -0.59398289 | Z7: -2.2268298 | AA7: 1.1256926
B8: POWI | C8: United States | D8: Semiconductors | E8: Dec'25 | F8: 90.8 | G8: 44.3 | H8: 51.05 | I8: 61.3 | J8: 48.37 | K8: 20.89 | L8: 5.76 | M8: 12.64 | N8: 17.71 | O8: -1.05 | P8: 0.47 | Q8: 1.96 | R8: 11.58 | S8: 3.92 | T8: 6.72 | U8: -1.35 | V8: -3.95 | W8: 8.77 | X8: 0.3485778 | Y8: -0.13688999 | Z8: -0.74413033 | AA8: 0.9082397
B9: MCHP | C9: United States | D9: Semiconductors | E9: Sep'26 | F9: 78.7 | G9: 514.1 | H9: 560.4 | I9: 684.4 | J9: 759.4 | K9: 818.1 | L9: 850.1 | M9: 904.8 | N9: 886.8 | O9: 530.5 | P9: 236.6 | Q9: 221.7 | R9: 148.1 | S9: 34.4 | T9: -28.7 | U9: 54.3 | V9: 95.2 | W9: 156.5 | X9: -0.41401373 | Y9: -0.44580559 | Z9: -0.25420471 | AA9: 0.7867268
B10: TPG | C10: United States | D10: Asset Management | E10: Dec'25 | F10: 71.5 | G10: 780.55 | H10: 174.34 | I10: -157.26 | J10: 48.82 | K10: 17.12 | L10: 30.97 | M10: 47.52 | N10: -87.98 | O10: 75.19 | P10: 8.8 | Q10: -10.85 | R10: 10.06 | S10: 1.27 | T10: 111.08 | U10: 76.11 | V10: 224.52 | W10: 296.61 | X10: 11.021552 | Y10: 0.77949086 | Z10: 1.0802942 | AA10: 0.71514359
B11: RDDT | C11: United States | D11: Internet Content & Information | E11: Dec'25 | F11: 68 | G11: 7.19 | H11: -35.2 | I11: -53.07 | J11: -50.95 | K11: -29.68 | L11: -70.6 | M11: -52.99 | N11: -19.59 | O11: 3.02 | P11: -589.26 | Q11: -31.04 | R11: 6.85 | S11: 52.87 | T11: 3.9 | U11: 67.71 | V11: 138.54 | W11: 231.83 | X11: -1.0581184 | Y11: 3.0310006 | Z11: 1.0027412 | AA11: 0.68040453
B12: RAMP | C12: United States | D12: Software - Infrastructure | E12: Sep'26 | F12: 62.3 | G12: -13.79 | H12: -27.99 | I12: -24.86 | J12: -14.69 | K12: -12.21 | L12: -28.43 | M12: 2.39 | N12: 14.78 | O12: 17.7 | P12: -9.87 | Q12: -5.04 | R12: 7.88 | S12: 14.82 | T12: -4.27 | U12: 7.64 | V12: 21.43 | W12: 39.52 | X12: 0.71887035 | Y12: 0.94697535 | Z12: 0.51975451 | AA12: 0.62342251
B13: USAR | C13: United States | D13: Other Industrial Metals & Mining | E13: Sep'25 | F13: 54.7 | M13: -7.01 | N13: -7.01 | O13: -4.83 | P13: -5.95 | Q13: -4.7 | R13: -3.01 | S13: -1.96 | T13: -5.92 | U13: -8.72 | V13: -8.8 | W13: -15.86 | X13: -0.0019206146 | Y13: 0.2578576 | Z13: 0.29525752 | AA13: 0.54724409
B14: ILMN | C14: United States | D14: Diagnostics & Research | E14: Dec'25 | F14: 44.8 | G14: -37 | H14: 135 | I14: 30 | J14: 27 | K14: -81 | L14: -65 | M14: -26 | N14: 124 | O14: -98 | P14: -59 | Q14: -18 | R14: 210 | S14: -53 | T14: 184 | U14: 224 | V14: 232 | W14: 210 | X14: 3.0375 | Y14: 0.74922601 | Z14: 0.038938053 | AA14: 0.44804089
B15: ABX | C15: United States | D15: Insurance - Life | E15: Sep'25 | F15: 40.5 | G15: 0.1 | H15: -0.04 | I15: 7.19 | J15: 6.71 | K15: 9.68 | L15: 11.23 | M15: 8.36 | N15: 9.14 | O15: 4.52 | P15: 3.16 | Q15: 3.8 | R15: 7.48 | S15: 6.56 | T15: -7.59 | U15: 17.39 | V15: 22.79 | W15: 22.41 | X15: -0.51190476 | Y15: 1.3258537 | Z15: 0.64219799 | AA15: 0.40485313
B16: PTON | C16: United States | D16: Leisure | E16: Jun'26 | F16: 39 | G16: -390.9 | H16: -326.7 | I16: -474.3 | J16: -197.4 | K16: -231.6 | L16: -129.9 | M16: -175.8 | N16: -87 | O16: -167 | P16: -87.4 | Q16: -55 | R16: 43.9 | S16: -25.9 | T16: 0.5 | U16: 66.7 | V16: 54 | W16: 11.3 | X16: -0.70659164 | Y16: -3.3342466 | Z16: 0.1185446 | AA16: 0.39034627
B17: GOLD | C17: United States | D17: Capital Markets | E17: Jun'26 | F17: 24.4 | G17: 38.96 | H17: 44.88 | I17: 44.19 | J17: 55.71 | K17: 39.96 | L17: 48.36 | M17: 53.13 | N17: 24.82 | O17: 21.32 | P17: 11.26 | Q17: 17.78 | R17: 12.02 | S17: 15.06 | T17: 7.27 | U17: 19.17 | V17: 3.09 | W17: 25.95 | X17: -0.071097648 | Y17: 0.026664109 | Z17: -0.16685351 | AA17: 0.24422516
B18: AOSL | C18: United States | D18: Semiconductors | E18: Jun'26 | F18: 23.4 | G18: 27.72 | H18: 31.23 | I18: 18.14 | J18: 25.53 | K18: 8.79 | L18: -14.4 | M18: 2.61 | N18: 9.38 | O18: -1.13 | P18: -10.5 | Q18: -1.5 | R18: -0.25 | S18: -5.91 | T18: -10.66 | U18: -11.62 | V18: -4.58 | W18: -13.57 | X18: 0.0088105727 | Y18: 0.55240175 | Z18: 0.15225035 | AA18: 0.23375038
B19: MTSI | C19: United States | D19: Semiconductors | E19: Mar'26 | F19: 20.1 | G19: 27.07 | H19: 32.57 | I19: 36 | J19: 37.53 | K19: 39.38 | L19: 38.7 | M19: 19.51 | N19: 20.61 | O19: 18.11 | P19: 15.71 | Q19: 19.72 | R19: 27.83 | S19: 17.53 | T19: 34.87 | U19: 37.66 | V19: 39.7 | W19: 43.58 | X19: 0.23715806 | Y19: 0.17948974 | Z19: 0.10068708 | AA19: 0.20075524
B20: CTLP | C20: United States | D20: Software - Infrastructure | E20: Mar'26 | F20: 19.4 | G20: -1.14 | H20: -0.32 | I20: 0.88 | J20: -2.08 | K20: -8.22 | L20: 1.87 | M20: 6.74 | N20: 3.81 | O20: 2.83 | P20: 3.68 | Q20: 5.2 | R20: 2.16 | S20: 4.3 | T20: 6.21 | U20: 6.37 | V20: 6.47 | W20: 8.83 | X20: 0.16492829 | Y20: 0.06547286 | Z20: 0.22636555 | AA20: 0.19400428
B21: MAGN | C21: United States | D21: Household & Personal Products | E21: Mar'26 | F21: 19.3 | N21: 17 | O21: -2 | P21: 25 | Q21: 17 | R21: 35 | S21: 10 | T21: 27 | U21: 13 | V21: 85 | W21: 36 | X21: 0.022988506 | Y21: -0.04494382 | Z21: 0.58823529 | AA21: 0.19259259
B22: RGA | C22: United States | D22: Insurance - Reinsurance | E22: Dec'25 | F22: 18.5 | G22: 59 | H22: 310 | I22: 191 | J22: -28 | K22: 436 | L22: 404 | M22: 328 | N22: 452 | O22: 233 | P22: 340 | Q22: 341 | R22: 292 | S22: 311 | T22: 449 | U22: 431 | V22: 418 | W22: 608 | X22: 0.084890966 | Y22: 0.064608758 | Z22: 0.084962913 | AA22: 0.1845867
B23: COUR | C23: United States | D23: Education & Training Services | E23: Dec'25 | F23: 16 | G23: -47.49 | H23: -35.28 | I23: -42.14 | J23: -33.65 | K23: -45.88 | L23: -44.74 | M23: -38.52 | N23: -39.58 | O23: -25.5 | P23: -27.7 | Q23: -31.2 | R23: -21.7 | S23: -21.48 | T23: -15.3 | U23: -15.1 | V23: -15.6 | W23: -32.3 | X23: -0.12147335 | Y23: -0.17952721 | Z23: -0.082902963 | AA23: 0.16034381
B24: KKR | C24: United States | D24: Asset Management | E24: Dec'25 | F24: 15.6 | G24: 1027 | H24: 1289 | I24: -1917 | J24: 206.19 | K24: 129.15 | L24: 408.44 | M24: 1451 | N24: 2819 | O24: 1876 | P24: 1363 | Q24: 1210 | R24: 1645 | S24: 1643 | T24: 771.07 | U24: 1529 | V24: 2200 | W24: 2600 | X24: -0.10099471 | Y24: 0.060541993 | Z24: 0.099318727 | AA24: 0.1557853
B25: PI | C25: United States | D25: Semiconductors | E25: Dec'25 | F25: 13.8 | G25: -7.23 | H25: -9.32 | I25: -8.48 | J25: -1.74 | K25: -0.05 | L25: -4.44 | M25: -8.37 | N25: -15.83 | O25: -11.57 | P25: -9.01 | Q25: 9.05 | R25: -0.77 | S25: -2.61 | T25: -9.57 | U25: 10.87 | V25: 0.66 | W25: -2.7 | X25: 0.16766467 | Y25: -0.46666667 | Z25: -0.6875 | AA25: 0.13846154
B26: EVO | C26: United States | D26: Drug Manufacturers - Specialty & Generic | E26: Sep'25 | F26: 13.6 | G26: 17.74 | H26: 12.49 | I26: 0.46 | J26: -3.77 | K26: -13.53 | L26: 37.69 | M26: 12.52 | N26: -31.17 | O26: -12.18 | P26: 19.94 | Q26: -18.21 | R26: -36.15 | S26: -32.69 | T26: 1.17 | U26: -19.82 | V26: -28.6 | W26: -43.59 | X26: 0.27969006 | Y26: 0.018747089 | Z26: -0.086295577 | AA26: 0.13635226
B27: MMS | C27: United States | D27: Specialty Business Services | E27: Mar'26 | F27: 12.2 | G27: 81.53 | H27: 75.29 | I27: 54.56 | J27: 103.81 | K27: 74.78 | L27: 62.51 | M27: 58.39 | N27: 128.42 | O27: 107.51 | P27: 127.49 | Q27: 141.74 | R27: 110.74 | S27: 86.79 | T27: 152.97 | U27: 165.67 | V27: 83.52 | W27: 146.21 | X27: 0.054589082 | Y27: 0.048614497 | Z27: -0.052734564 | AA27: 0.12152572
B28: RBLX | C28: United States | D28: Electronic Gaming & Multimedia | E28: Dec'25 | F28: 12 | G28: -139.65 | H28: -151.61 | I28: -170.27 | J28: -300.01 | K28: -301.9 | L28: -289.84 | M28: -313.99 | N28: -300.04 | O28: -355.18 | P28: -302.33 | Q28: -237.95 | R28: -261.03 | S28: -226.21 | T28: -254.71 | U28: -322.46 | V28: -296.54 | W28: -358.64 | X28: -0.046344597 | Y28: 0.086243494 | Z28: 0.033361205 | AA28: 0.12039967
B29: EL | C29: United States | D29: Household & Personal Products | E29: Jun'26 | F29: 11.7 | G29: 1434 | H29: 978 | I29: 117 | J29: 661 | K29: 773 | L29: 316 | M29: 31 | N29: 101 | O29: 584 | P29: 553 | Q29: 340 | R29: 133 | S29: 461 | T29: 399 | U29: 109 | V29: 253 | W29: 604 | X29: -0.10356422 | Y29: -0.17329332 | Z29: 0.10889292 | AA29: 0.11702128
B30: TPR | C30: United States | D30: Luxury Goods | E30: Jun'26 | F30: 11.6 | G30: 476.1 | H30: 175.8 | I30: 259.6 | J30: 254.3 | K30: 418.2 | L30: 226.3 | M30: 280.8 | N30: 272.8 | O30: 475.9 | P30: 239.3 | Q30: 268.3 | R30: 285.4 | S30: 548.2 | T30: 272.3 | U30: 302.4 | V30: 361.6 | W30: 719.8 | X30: 0.024604831 | Y30: 0.024814437 | Z30: 0.05410779 | AA30: 0.11559448
B31: ARX | C31: United States | D31: Insurance Brokers | E31: Sep'25 | F31: 10.9 | O31: 2.1 | P31: 7.2 | Q31: 5.7 | R31: -10.8 | S31: -5.3 | T31: 18.3 | U31: 8.3 | V31: 29 | W31: 0.2 | X31: -3.46875 | Y31: 0.32911392 | Z31: 3.7904762 | AA31: 0.10934394
B32: LSPD | C32: United States | D32: Software - Application | E32: Sep'26 | F32: 10.5 | G32: -58.32 | H32: -91.39 | I32: -83.05 | J32: -72.39 | K32: -68.68 | L32: -48.73 | M32: -53.94 | N32: -50.19 | O32: -47.21 | P32: -30.81 | Q32: -27.71 | R32: -31.41 | S32: -22.2 | T32: -22.56 | U32: -35.6 | V32: -33.76 | W32: -34.2 | X32: -0.073575314 | Y32: 0.075953023 | Z32: 0.02102532 | AA32: 0.10515247
B33: AGCO | C33: United States | D33: Farm & Heavy Construction Machinery | E33: Dec'25 | F33: 10.3 | G33: 270.3 | H33: 241 | I33: 262 | J33: 331.4 | K33: 465.8 | L33: 386 | M33: 499.7 | N33: 421.5 | O33: 413.5 | P33: 272.3 | Q33: 286 | R33: 126.3 | S33: 212.5 | T33: 60.2 | U33: 195.5 | V33: 156.2 | W33: 276.8 | X33: -0.23642849 | Y33: -0.13211679 | Z33: 0.050294365 | AA33: 0.10297886
B34: ROAD | C34: United States | D34: Engineering & Construction | E34: Mar'26 | F34: 10.2 | G34: 8.02 | H34: -11.53 | I34: 18.12 | J34: 18.85 | K34: 0.77 | L34: -3.26 | M34: 32.3 | N34: 49.78 | O34: 16.43 | P34: 5.47 | Q34: 45.51 | R34: 58.03 | S34: 32.31 | T34: 26.55 | U34: 80.78 | V34: 132.35 | W34: 60 | X34: 0.14916502 | Y34: 0.2171798 | Z34: 0.37598017 | AA34: 0.10180521
B35: KN | C35: United States | D35: Electronic Components | E35: Sep'25 | F35: 9.5 | G35: 38.4 | H35: 42.5 | I35: 27.7 | J35: 25.6 | K35: 16 | L35: 30.1 | M35: -0.1 | N35: 0 | O35: 13 | P35: 0 | Q35: 10.7 | R35: 14 | S35: 20.2 | T35: 18.4 | U35: 7.7 | V35: 18 | W35: 26.3 | X35: 0.40979955 | Y35: -0.047393365 | Z35: 0.066334992 | AA35: 0.094867807
B36: FLS | C36: United States | D36: Specialty Industrial Machinery | E36: Dec'25 | F36: 9.2 | G36: 79.53 | H36: 5.81 | I36: 58.45 | J36: 28.94 | K36: 129.02 | L36: 76.44 | M36: 111.83 | N36: 102.02 | O36: 110.85 | P36: 116.12 | Q36: 138.42 | R36: 123.3 | S36: 125.95 | T36: 134.77 | U36: 137.29 | V36: 159.69 | W36: 177.37 | X36: 0.037019393 | Y36: -0.0021629278 | Z36: 0.069804915 | AA36: 0.092200108
B37: CAH | C37: United States | D37: Medical Distribution | E37: Jun'26 | F37: 9 | G37: 386 | H37: 466 | I37: 363 | J37: 346 | K37: 401 | L37: 532 | M37: 510 | N37: 493 | O37: 523 | P37: 586 | Q37: 548 | R37: 551 | S37: 566 | T37: 731 | U37: 629 | V37: 771 | W37: 809 | X37: 0.064415815 | Y37: 0.033806344 | Z37: 0.088817117 | AA37: 0.090100111
B38: XEL | C38: United States | D38: Utilities - Regulated Electric | E38: Dec'25 | F38: 9 | G38: 434 | H38: 518 | I38: 478 | J38: 931 | K38: 533 | L38: 578 | M38: 423 | N38: 954 | O38: 655 | P38: 684 | Q38: 455 | R38: 917 | S38: 351 | T38: 681 | U38: 581 | V38: 1042 | W38: 589 | X38: -0.0012463648 | Y38: 0.052412646 | Z38: 0.049407115 | AA38: 0.089642185
B39: HII | C39: United States | D39: Aerospace & Defense | E39: Dec'25 | F39: 8.8 | G39: 155 | H39: 202 | I39: 231 | J39: 189 | K39: 171 | L39: 166 | M39: 189 | N39: 200 | O39: 217 | P39: 186 | Q39: 224 | R39: 114 | S39: 141 | T39: 196 | U39: 202 | V39: 197 | W39: 206 | X39: 0.015037594 | Y39: -0.032592593 | Z39: 0.12710567 | AA39: 0.088315217
B40: WMG | C40: United States | D40: Entertainment | E40: Mar'26 | F40: 8.7 | G40: 239 | H40: 169 | I40: 146 | J40: 166 | K40: 224 | L40: 179 | M40: 203 | N40: 254 | O40: 337 | P40: 219 | Q40: 225 | R40: 244 | S40: 241 | T40: 199 | U40: 261 | V40: 288 | W40: 327 | X40: -0.021528525 | Y40: 0.03960396 | Z40: 0.046560847 | AA40: 0.086956522
B41: ROK | C41: United States | D41: Specialty Industrial Machinery | E41: Mar'26 | F41: 8.4 | G41: 306.1 | H41: 214.3 | I41: 372.6 | J41: 438.5 | K41: 356.8 | L41: 325.5 | M41: 419.5 | N41: 508.8 | O41: 286 | P41: 337 | Q41: 368 | R41: 318 | S41: 246 | T41: 341 | U41: 378 | V41: 457 | W41: 366 | X41: 0.0031520883 | Y41: 0.0078554595 | Z41: 0.10833983 | AA41: 0.084388186
...

Sheet 빨간줄
B2: (단위: mil $)
Y3: IIIV | Z3: 6723 | AA3: Renesas Electronics Corporation
B4: 3110 | C4: 6 | D4: 7 | E4: 8 | F4: 9 | G4: 10 | H4: 11 | I4: 12 | J4: 13 | K4: 14 | L4: 15 | M4: 16 | N4: 17 | O4: 18 | P4: 19 | Q4: 20 | R4: 21 | S4: 22 | Y4: ARWR | Z4: 7287 | AA4: Nippon Seiki Co., Ltd.
Y5: AFRM | Z5: 7752 | AA5: Ricoh Company, Ltd.
C6: 4Q21 | D6: 1Q22 | E6: 2Q22 | F6: 3Q22 | G6: 4Q22 | H6: 1Q23 | I6: 2Q23 | J6: 3Q23 | K6: 4Q23 | L6: 1Q24 | M6: 2Q24 | N6: 3Q24 | O6: 4Q24 | P6: 1Q25 | Q6: 2Q25 | R6: 3Q25 | S6: 4Q25 | T6: 1Q26 | U6: 2Q26 | V6: 3Q26 | W6: 4Q26 | Y6: POWI | Z6: 3636 | AA6: Mitsubishi Research Institute, Inc.
B7: Revenue | C7: =VLOOKUP($B$4,Revenue!$B:$W,C4,FALSE) -> 20568 | D7: =VLOOKUP($B$4,Revenue!$B:$W,D4,FALSE) -> 21034 | E7: =VLOOKUP($B$4,Revenue!$B:$W,E4,FALSE) -> 21931 | F7: =VLOOKUP($B$4,Revenue!$B:$W,F4,FALSE) -> 23827 | G7: =VLOOKUP($B$4,Revenue!$B:$W,G4,FALSE) -> 23210 | H7: =VLOOKUP($B$4,Revenue!$B:$W,H4,FALSE) -> 21725 | I7: =VLOOKUP($B$4,Revenue!$B:$W,I4,FALSE) -> 18767 | J7: =VLOOKUP($B$4,Revenue!$B:$W,J4,FALSE) -> 20297 | ... S7: =VLOOKUP($B$4,Revenue!$B:$W,S4,FALSE) -> 29181 | Y7: MCHP | Z7: 8934 | AA7: Sun Frontier Fudousan Co., Ltd.
B8: OP | C8: =VLOOKUP($B$4,'Operating Income'!$B:$W,C4,FALSE) -> 2238 | D8: =VLOOKUP($B$4,'Operating Income'!$B:$W,D4,FALSE) -> 1724 | E8: =VLOOKUP($B$4,'Operating Income'!$B:$W,E4,FALSE) -> 1612 | F8: =VLOOKUP($B$4,'Operating Income'!$B:$W,F4,FALSE) -> 2614 | G8: =VLOOKUP($B$4,'Operating Income'!$B:$W,G4,FALSE) -> 1983 | H8: =VLOOKUP($B$4,'Operating Income'!$B:$W,H4,FALSE) -> 1250 | I8: =VLOOKUP($B$4,'Operating Income'!$B:$W,I4,FALSE) -> -967 | J8: =VLOOKUP($B$4,'Operating Income'!$B:$W,J4,FALSE) -> 886 | ... S8: =VLOOKUP($B$4,'Operating Income'!$B:$W,S4,FALSE) -> 5157 | Y8: TPG | Z8: 7250 | AA8: Pacific Industrial Co., Ltd.
B9: Trailing 4Q OP avg. | C9: =AVERAGE(C8:C8) -> 2238 | D9: =AVERAGE(C8:D8) -> 1981 | E9: =AVERAGE(C8:E8) -> 1858 | F9: =AVERAGE(C8:F8) -> 2047 | G9: =AVERAGE(D8:G8) -> 1983.25 | H9: =AVERAGE(E8:H8) -> 1864.75 | I9: =AVERAGE(F8:I8) -> 1220 | J9: =AVERAGE(G8:J8) -> 788 | K9: =AVERAGE(H8:K8) -> 850.75 | L9: =AVERAGE(I8:L8) -> 1184.5 | M9: =AVERAGE(J8:M8) -> 2097.25 | ... S9: =AVERAGE(P8:S8) -> 4638.75 | Y9: RDDT | Z9: 7186 | AA9: Yokohama Financial Group, Inc.
B10: Trailing 4Q OP sum. | C10: =SUM(C8:C8) -> 2238 | D10: =SUM(C8:D8) -> 3962 | E10: =SUM(C8:E8) -> 5574 | F10: =SUM(C8:F8) -> 8188 | G10: =SUM(D8:G8) -> 7933 | H10: =SUM(E8:H8) -> 7459 | I10: =SUM(F8:I8) -> 4880 | J10: =SUM(G8:J8) -> 3152 | K10: =SUM(H8:K8) -> 3403 | L10: =SUM(I8:L8) -> 4738 | M10: =SUM(J8:M8) -> 8389 | ... S10: =SUM(P8:S8) -> 18555 | Y10: RAMP | Z10: 6486 | AA10: Eagle Industry Co.,Ltd.
B11: Trailing OP Delta | D11: =D9/C9-1 -> -0.11483467 | E11: =E9/D9-1 -> -0.062089854 | F11: =F9/E9-1 -> 0.10172228 | G11: =G9/F9-1 -> -0.031143136 | H11: =H9/G9-1 -> -0.05975041 | I11: =I9/H9-1 -> -0.3457568 | J11: =J9/I9-1 -> -0.35409836 | K11: =K9/J9-1 -> 0.07963198 | ... S11: =S9/R9-1 -> 0.10210264 | Z11: 3110 | AA11: Nitto Boseki Co., Ltd.
B12: opm | C12: =IFERROR(C8/C7,"-") -> 0.1088098 | D12: =IFERROR(D8/D7,"-") -> 0.081962537 | E12: =IFERROR(E8/E7,"-") -> 0.07350326 | F12: =IFERROR(F8/F7,"-") -> 0.10970747 | G12: =IFERROR(G8/G7,"-") -> 0.085437312 | H12: =IFERROR(H8/H7,"-") -> 0.057537399 | I12: =IFERROR(I8/I7,"-") -> -0.051526616 | J12: =IFERROR(J8/J7,"-") -> 0.043651771 | ... S12: =IFERROR(S8/S7,"-") -> 0.17672458 | Y12: ILMN
B13: op yoy | G13: =G8/C8-1 -> -0.11394102 | H13: =H8/D8-1 -> -0.274942 | I13: =I8/E8-1 -> -1.5998759 | J13: =J8/F8-1 -> -0.66105585 | K13: =K8/G8-1 -> 0.1265759 | L13: =L8/H8-1 -> 1.068 | M13: =M8/I8-1 -> -3.7755946 | N13: =N8/J8-1 -> 3.4108352 | ... S13: =S8/O8-1 -> 0.5 | Y13: ABX
B14: rv yoy | G14: =G7/C7-1 -> 0.12845196 | H14: =H7/D7-1 -> 0.032851574 | I14: =I7/E7-1 -> -0.14427067 | J14: =J7/F7-1 -> -0.14815126 | K14: =K7/G7-1 -> -0.03330461 | L14: =L7/H7-1 -> 0.16487917 | M14: =M7/I7-1 -> 0.34342196 | N14: =N7/J7-1 -> 0.28664335 | ... S14: =S7/O7-1 -> 0.083345708 | Y14: PTON
Y15: GOLD
Y17: MTSI
Y18: CTLP
Y19: MAGN
Y20: RGA
Y22: KKR
Y23: MMS
Y25: EL
Y26: TPR
Y27: ARX
Y29: AGCO
Y30: ROAD
