Workbook

Sheet 기업리스트
B2: 실적 기업 정보
B3: Ticker | C3: Company | D3: Date | E3: Time | F3: Quarter Ending | G3: Market Cap (mil$)
B4: UCG | C4: UniCredit S.p.A. | D4: 09-Feb-26 | F4: Dec-25 | G4: 136156
B5: APO | C5: Apollo Global Management, Inc. | D5: 09-Feb-26 | E5: Pre Market | F5: Dec-25 | G5: 77213.61
B6: 9434 | C6: SoftBank Corp. | D6: 09-Feb-26 | F6: Dec-25 | G6: 65196.52
B7: 6098 | C7: Recruit Holdings Co., Ltd. | D7: 09-Feb-26 | F7: Dec-25 | G7: 62479.11
B8: BDX | C8: Becton, Dickinson and Company | D8: 09-Feb-26 | E8: Pre Market | F8: Dec-25 | G8: 59836.4
B9: BPAC11 | C9: Banco BTG Pactual S.A. | D9: 09-Feb-26 | F9: Dec-25 | G9: 56319.04
B10: DEWA | C10: Dubai Electricity and Water Authority (PJSC) | D10: 09-Feb-26 | F10: Dec-25 | G10: 42340.58
B11: A012450 | C11: Hanwha Aerospace Co., Ltd. | D11: 09-Feb-26 | F11: Dec-25 | G11: 41418.55
B12: ACGL | C12: Arch Capital Group Ltd. | D12: 09-Feb-26 | E12: After Hours | F12: Dec-25 | G12: 36452.78
B13: 8591 | C13: ORIX Corporation | D13: 09-Feb-26 | E13: Pre Market | F13: Dec-25 | G13: 34611.12
B14: 5803 | C14: Fujikura Ltd. | D14: 09-Feb-26 | F14: Dec-25 | G14: 30913.09
B15: 8802 | C15: Mitsubishi Estate Co., Ltd. | D15: 09-Feb-26 | F15: Dec-25 | G15: 30521.73
B16: CINF | C16: Cincinnati Financial Corporation | D16: 09-Feb-26 | E16: After Hours | F16: Dec-25 | G16: 25303.08
B17: BAMI | C17: Banco BPM S.p.A. | D17: 09-Feb-26 | F17: Dec-25 | G17: 22230.52
B18: L | C18: Loews Corporation | D18: 09-Feb-26 | F18: Dec-25 | G18: 21180.54
B19: ON | C19: ON Semiconductor Corporation | D19: 09-Feb-26 | E19: After Hours | F19: Dec-25 | G19: 20150.15
B20: PFG | C20: Principal Financial Group, Inc. | D20: 09-Feb-26 | F20: Dec-25 | G20: 18766.01
B21: CRBG | C21: Corebridge Financial, Inc. | D21: 09-Feb-26 | F21: Dec-25 | G21: 17608.31
B22: ACM | C22: AECOM | D22: 09-Feb-26 | E22: After Hours | F22: Dec-25 | G22: 17073.63
B23: GCARSO A1 | C23: Grupo Carso, S.A.B. de C.V. | D23: 09-Feb-26 | F23: Dec-25 | G23: 15821.76
B24: MB | C24: Mediobanca Banca di Credito Finanziario S.p.A. | D24: 09-Feb-26 | F24: Dec-25 | G24: 15721.18
B25: MEDP | C25: Medpace Holdings, Inc. | D25: 09-Feb-26 | E25: After Hours | F25: Dec-25 | G25: 14959.26
B26: DT | C26: Dynatrace, Inc. | D26: 09-Feb-26 | E26: Pre Market | F26: Dec-25 | G26: 14945.66
B27: PTTEP | C27: PTT Exploration and Production Public Company Limited | D27: 09-Feb-26 | F27: Dec-25 | G27: 14000.88
B28: CNA | C28: CNA Financial Corporation | D28: 09-Feb-26 | E28: Pre Market | F28: Dec-25 | G28: 12556.17
B29: BBSE3 | C29: BB Seguridade Participações S.A. | D29: 09-Feb-26 | F29: Dec-25 | G29: 12258.72
B30: UDR | C30: UDR, Inc. | D30: 09-Feb-26 | E30: After Hours | F30: Dec-25 | G30: 12054.41
B31: 6823 | C31: HKT Trust and HKT Limited | D31: 09-Feb-26 | F31: Dec-25 | G31: 11484.2
B32: DU | C32: Emirates Integrated Telecommunications Company PJSC | D32: 09-Feb-26 | F32: Dec-25 | G32: 11367.44
B33: ZYDUSLIFE | C33: Zydus Lifesciences Limited | D33: 09-Feb-26 | F33: Dec-25 | G33: 11201.5
B34: 5838 | C34: Rakuten Bank, Ltd. | D34: 09-Feb-26 | F34: Dec-25 | G34: 9905.89
B35: A259960 | C35: KRAFTON, Inc. | D35: 09-Feb-26 | F35: Dec-25 | G35: 9495.09
B36: MNDY | C36: monday.com Ltd. | D36: 09-Feb-26 | E36: Pre Market | F36: Dec-25 | G36: 9463.3
B37: 4523 | C37: Eisai Co., Ltd. | D37: 09-Feb-26 | F37: Dec-25 | G37: 9163.78
B38: 5713 | C38: Sumitomo Metal Mining Co., Ltd. | D38: 09-Feb-26 | F38: Dec-25 | G38: 9002.73
B39: AMKR | C39: Amkor Technology, Inc. | D39: 09-Feb-26 | E39: After Hours | F39: Dec-25 | G39: 8520.76
B40: CLF | C40: Cleveland-Cliffs Inc. | D40: 09-Feb-26 | E40: Pre Market | F40: Dec-25 | G40: 8510.14
B41: 4151 | C41: Kyowa Kirin Co., Ltd. | D41: 09-Feb-26 | F41: Dec-25 | G41: 8461.03
...

Sheet Revenue
B2: Ticker | C2: Country | D2: Industry | E2: Latest_Date | F2: Growth_Rate | G2: 4Q21 | H2: 1Q22 | I2: 2Q22 | J2: 3Q22 | K2: 4Q22 | L2: 1Q23 | M2: 2Q23 | N2: 3Q23 | O2: 4Q23 | P2: 1Q24 | Q2: 2Q24 | R2: 3Q24 | S2: 4Q24 | T2: 1Q25 | U2: 2Q25 | V2: 3Q25 | W2: 4Q25 | X2: 1Q25 | Y2: 2Q25 | Z2: 3Q25 | AA2: 4Q25
B3: APO | C3: United States | D3: Asset Management | E3: Dec'25 | F3: 16.8 | G3: 1162 | H3: 830 | I3: 2255 | J3: 2948 | K3: 4811 | L3: 5270 | M3: 13671 | N3: 2004 | O3: 10999 | P3: 6989 | Q3: 5965 | R3: 7718 | S3: 5216 | T3: 5488 | U3: 6754 | V3: 9759 | W3: 9792 | X3: -0.057980532 | Y3: 0.032353303 | Z3: 0.081069272 | AA3: 0.16813021
B4: AMTM | C4: United States | D4: Specialty Business Services | E4: Dec'25 | F4: 13.5 | L4: 1843 | M4: 1928 | N4: 1956 | O4: 2137 | P4: 1983 | Q4: 2051 | R4: 2142 | S4: 2212 | T4: 3416 | U4: 3491 | V4: 3561 | W4: 3925 | X4: 0.17083929 | Y4: 0.14662458 | Z4: 0.12601012 | AA4: 0.13509464
B5: CURB | C5: United States | D5: REIT - Retail | E5: Dec'25 | F5: 11.7 | L5: 21.98 | M5: 21.98 | N5: 24.24 | O5: 25.47 | P5: 28.04 | Q5: 28.16 | R5: 29.76 | S5: 34.92 | T5: 38.7 | U5: 41.4 | V5: 48.65 | W5: 54.15 | X5: 0.088186631 | Y5: 0.10065379 | Z5: 0.13047382 | AA5: 0.11749252
B6: MNDY | C6: United States | D6: Software - Application | E6: Dec'25 | F6: 5.7 | G6: 95.55 | H6: 108.5 | I6: 123.72 | J6: 136.89 | K6: 149.92 | L6: 162.26 | M6: 175.68 | N6: 189.19 | O6: 202.57 | P6: 216.91 | Q6: 236.11 | R6: 251 | S6: 267.98 | T6: 282.25 | U6: 299.01 | V6: 316.86 | W6: 333.88 | X6: 0.067222222 | Y6: 0.060635857 | Z6: 0.059859667 | AA6: 0.056513164
B7: SVM | C7: United States | D7: Silver | E7: Jun'26 | F7: 5 | G7: 58.44 | H7: 59.08 | I7: 41.59 | J7: 63.59 | K7: 51.74 | L7: 58.65 | M7: 34.15 | N7: 60.01 | O7: 53.99 | P7: 58.51 | Q7: 42.68 | R7: 72.17 | S7: 68 | T7: 83.61 | U7: 75.11 | V7: 81.33 | W7: 83.33 | X7: 0.10399403 | Y7: 0.12170682 | Z7: 0.030646726 | AA7: 0.049764649
B8: DT | C8: United States | D8: Software - Application | E8: Sep'26 | F8: 4.3 | G8: 240.77 | H8: 252.59 | I8: 267.27 | J8: 279.33 | K8: 297.46 | L8: 314.48 | M8: 332.89 | N8: 351.7 | O8: 365.1 | P8: 380.85 | Q8: 399.22 | R8: 418.13 | S8: 436.17 | T8: 445.17 | U8: 477.35 | V8: 493.85 | W8: 515.47 | X8: 0.039354614 | Y8: 0.045994266 | Z8: 0.042615459 | AA8: 0.042806093
B9: CMCO | C9: United States | D9: Farm & Heavy Construction Machinery | E9: Jun'26 | F9: 2 | G9: 223.64 | H9: 216.09 | I9: 253.37 | J9: 220.29 | K9: 231.74 | L9: 230.37 | M9: 253.84 | N9: 235.49 | O9: 258.4 | P9: 254.14 | Q9: 265.5 | R9: 239.73 | S9: 242.27 | T9: 234.14 | U9: 246.89 | V9: 235.92 | W9: 261.05 | X9: -0.019967254 | Y9: -0.01895807 | Z9: -0.003956263 | AA9: 0.019578407
B10: AIOT | C10: United States | D10: Software - Infrastructure | E10: Sep'26 | F10: 1.7 | G10: 34.42 | H10: 33.16 | I10: 34.59 | J10: 34.29 | K10: 33.87 | L10: 32.84 | M10: 32.09 | N10: 34.24 | O10: 34.55 | P10: 33.74 | Q10: 75.43 | R10: 77.02 | S10: 106.43 | T10: 103.64 | U10: 104.12 | V10: 111.68 | W10: 113.49 | X10: 0.23887636 | Y10: 0.079140461 | Z10: 0.088596917 | AA10: 0.016577829
B11: SOHU | C11: United States | D11: Electronic Gaming & Multimedia | E11: Dec'25 | F11: 1.3 | G11: 192.99 | H11: 193.42 | I11: 194.78 | J11: 185.27 | K11: 160.4 | L11: 161.79 | M11: 152.09 | N11: 145.43 | O11: 141.36 | P11: 139.39 | Q11: 172.33 | R11: 151.99 | S11: 134.68 | T11: 135.65 | U11: 126.27 | V11: 180.16 | W11: 142.26 | X11: -0.0062501044 | Y11: -0.077457328 | Z11: 0.051349824 | AA11: 0.013142382
B12: L | C12: United States | D12: Insurance - Property & Casualty | E12: Dec'25 | F12: 1 | G12: 3661 | H12: 3402 | I12: 3388 | J12: 3461 | K12: 3793 | L12: 3783 | M12: 3934 | N12: 3926 | O12: 4258 | P12: 4231 | Q12: 4267 | R12: 4466 | S12: 4546 | T12: 4494 | U12: 4555 | V12: 4671 | W12: 4734 | X12: 0.015019989 | Y12: 0.016204355 | Z12: 0.011350424 | AA12: 0.010292346
B13: KD | C13: United States | D13: Information Technology Services | E13: Sep'26 | F13: 0.8 | G13: 4556 | H13: 4431 | I13: 4288 | J13: 4179 | K13: 4303 | L13: 4255 | M13: 4193 | N13: 4073 | O13: 3936 | P13: 3850 | Q13: 3739 | R13: 3774 | S13: 3744 | T13: 3800 | U13: 3743 | V13: 3721 | W13: 3859 | X13: -0.003309724 | Y13: 0.00026565717 | Z13: -0.0035190226 | AA13: 0.00766258
B14: ACM | C14: United States | D14: Engineering & Construction | E14: Dec'25 | F14: 0.4 | G14: 3354 | H14: 3267 | I14: 3214 | J14: 3242 | K14: 3426 | L14: 3382 | M14: 3490 | N14: 3664 | O14: 3842 | P14: 3900 | Q14: 3944 | R14: 4151 | S14: 4110 | T14: 4014 | U14: 3772 | V14: 4178 | W14: 4175 | X14: 0.007078547 | Y14: -0.010604846 | Z14: 0.0016825575 | AA14: 0.0040437974
B15: BDX | C15: United States | D15: Medical Instruments & Supplies | E15: Mar'26 | F15: 0.4 | G15: 4718 | H15: 4750 | I15: 4641 | J15: 4761 | K15: 4586 | L15: 4821 | M15: 4878 | N15: 0 | O15: 4706 | P15: 5045 | Q15: 4990 | R15: 5437 | S15: 5168 | T15: 5272 | U15: 5509 | V15: 5891 | W15: 5252 | X15: 0.010998062 | Y15: 0.024871807 | Z15: 0.021228841 | AA15: 0.0038461538
B16: EPC | C16: United States | D16: Household & Personal Products | E16: Mar'26 | F16: 0.4 | G16: 463.3 | H16: 547.7 | I16: 623.8 | J16: 536.9 | K16: 469.1 | L16: 598.4 | M16: 650 | N16: 534.1 | O16: 488.9 | P16: 599.4 | Q16: 647.8 | R16: 517.6 | S16: 415.1 | T16: 580.7 | U16: 627.2 | V16: 537.2 | W16: 422.8 | X16: -0.0085783752 | Y16: -0.0095317416 | Z16: 0.0091563113 | AA16: 0.0035644848
B17: SBH | C17: United States | D17: Specialty Retail | E17: Mar'26 | F17: 0.1 | G17: 980.25 | H17: 911.39 | I17: 961.47 | J17: 962.46 | K17: 957.06 | L17: 918.71 | M17: 931.01 | N17: 921.36 | O17: 931.3 | P17: 908.36 | Q17: 942.34 | R17: 935.03 | S17: 937.9 | T17: 883.15 | U17: 933.31 | V17: 947.08 | W17: 943.17 | X17: -0.0067702752 | Y17: -0.0024415832 | Z17: 0.0032661226 | AA17: 0.0014237702
... B21: UVV | C21: United States | D21: Tobacco | E21: Sep'26 | F21: -2.5 | G21: 652.64 | H21: 646.97 | I21: 429.82 | J21: 650.98 | K21: 795.04 | L21: 693.98 | M21: 517.72 | N21: 638.48 | O21: 821.51 | P21: 770.86 | Q21: 597.05 | R21: 710.76 | S21: 937.19 | T21: 702.28 | U21: 593.76 | V21: 754.18 | W21: 861.29 | X21: -0.022739782 | Y21: -0.0011162835 | Z21: 0.014748691 | AA21: -0.025406623
B22: 7189 | C22: Japan | D22: =VLOOKUP(Revenue!B22,기업리스트!B:G,2,FALSE) -> Nishi-Nippon Financial Holdings, Inc. | E22: Sep'26 | F22: 11.2 | G22: 30767 | H22: 31284 | I22: 35575 | J22: 33178 | K22: 42795 | L22: 32801 | M22: 39082 | N22: 37174 | O22: 39934 | P22: 37257 | Q22: 44537 | R22: 35711 | S22: 41196 | T22: 38467 | U22: 43229 | V22: 45028 | W22: 59942 | X22: 0.0076244006 | Y22: -0.0081795499 | Z22: 0.05874416 | AA22: 0.11163649
B23: 5838 | C23: Japan | D23: =VLOOKUP(Revenue!B23,기업리스트!B:G,2,FALSE) -> Rakuten Bank, Ltd. | E23: Sep'26 | F23: 8.2 | I23: 27644 | J23: 27664 | K23: 29060 | L23: 28010 | M23: 29969 | N23: 30066 | O23: 31717 | P23: 32525 | Q23: 36729 | R23: 35589 | S23: 39565 | T23: 39664 | U23: 46438 | V23: 45684 | W23: 53600 | X23: 0.049436319 | Y23: 0.064065933 | Z23: 0.062602322 | AA23: 0.081907897
B24: 8081 | C24: Japan | D24: =VLOOKUP(Revenue!B24,기업리스트!B:G,2,FALSE) -> Global Mixed-Mode Technology Inc. | E24: Sep'26 | F24: 6.6 | G24: 23234 | H24: 32599 | I24: 19355 | J24: 26199 | K24: 24763 | L24: 36102 | M24: 24703 | N24: 28944 | O24: 26716 | P24: 35908 | Q24: 22441 | R24: 29371 | S24: 27588 | T24: 46265 | U24: 29609 | V24: 32048 | W24: 36577 | X24: 0.089820307 | Y24: 0.057040544 | Z24: 0.020153125 | AA24: 0.066334588
B25: 3097 | C25: Japan | D25: =VLOOKUP(Revenue!B25,기업리스트!B:G,2,FALSE) -> The Monogatari Corporation | E25: Jun'26 | F25: 5 | G25: 19813 | H25: 18446 | I25: 19288 | J25: 21910 | K25: 22268 | L25: 24177 | M25: 23919 | N25: 25909 | O25: 26096 | P25: 28583 | Q25: 26568 | R25: 29752 | S25: 30153 | T25: 32674 | U25: 31342 | V25: 35599 | W25: 36700 | X25: 0.035556599 | Y25: 0.040068151 | Z25: 0.047183286 | AA25: 0.050451575
B26: 5805 | C26: Japan | D26: =VLOOKUP(Revenue!B26,기업리스트!B:G,2,FALSE) -> SWCC Corporation | E26: Sep'26 | F26: 5 | G26: 52506 | H26: 51947 | I26: 50026 | J26: 52259 | K26: 55763 | L26: 51063 | M26: 48415 | N26: 50014 | O26: 60076 | P26: 55399 | Q26: 56943 | R26: 60435 | S26: 60856 | T26: 59628 | U26: 62157 | V26: 66703 | W26: 73226 | X26: 0.018101039 | Y26: 0.021920273 | Z26: 0.025786174 | AA26: 0.049610177
B27: 5713 | C27: Japan | D27: =VLOOKUP(Revenue!B27,기업리스트!B:G,2,FALSE) -> Sumitomo Metal Mining Co., Ltd. | E27: Sep'26 | F27: 4.7 | G27: 324543 | H27: 336618 | I27: 357659 | J27: 352968 | K27: 365057 | L27: 347305 | M27: 369190 | N27: 347955 | O27: 367894 | P27: 360349 | Q27: 410297 | R27: 389828 | S27: 392676 | T27: 400547 | U27: 379600 | V27: 403761 | W27: 467360 | X27: 0.025881595 | Y27: -0.019265722 | Z27: 0.0089162583 | AA27: 0.047370771
B28: 9887 | C28: Japan | D28: =VLOOKUP(Revenue!B28,기업리스트!B:G,2,FALSE) -> Matsuya Foods Holdings Co., Ltd. | E28: Sep'26 | F28: 4.5 | G28: 25172 | H28: 24127 | I28: 24967 | J28: 26146 | K28: 27827 | L28: 27658 | M28: 28100 | N28: 30931 | O28: 34087 | P28: 34493 | Q28: 34263 | R28: 38124 | S28: 41027 | T28: 40809 | U28: 43165 | V28: 44781 | W28: 48742 | X28: 0.042702509 | Y28: 0.057721611 | Z28: 0.040809195 | AA28: 0.045440624
B29: 4186 | C29: Japan | D29: =VLOOKUP(Revenue!B29,기업리스트!B:G,2,FALSE) -> Tokyo Ohka Kogyo Co., Ltd. | E29: Dec'25 | F29: 4.3 | G29: 39529 | H29: 39599 | I29: 45112 | J29: 45752 | K29: 44971 | L29: 38463 | M29: 39211 | N29: 40946 | O29: 43650 | P29: 45017 | Q29: 49719 | R29: 51811 | S29: 54419 | T29: 54272 | U29: 57351 | V29: 61156 | W29: 64250 | X29: 0.046052566 | Y29: 0.036304651 | Z29: 0.042895898 | AA29: 0.043270627
B30: 4385 | C30: Japan | D30: =VLOOKUP(Revenue!B30,기업리스트!B:G,2,FALSE) -> Mercari, Inc. | E30: Jun'26 | F30: 3.8 | G30: 37557 | H30: 38510 | I30: 37348 | J30: 40029 | K30: 44256 | L30: 43628 | M30: 44151 | N30: 44271 | O30: 48115 | P30: 48492 | Q30: 46529 | R30: 44924 | S30: 49237 | T30: 49906 | U30: 48566 | V30: 49440 | W30: 56815 | X30: 0.007474284 | Y30: 0.010687528 | Z30: 0.023443543 | AA30: 0.038437933
B31: 8802 | C31: Japan | D31: =VLOOKUP(Revenue!B31,기업리스트!B:G,2,FALSE) -> Mitsubishi Estate Co., Ltd. | E31: Sep'26 | F31: 3.6 | G31: 325547 | H31: 444919 | I31: 305367 | J31: 289198 | K31: 311759 | L31: 471503 | M31: 292465 | N31: 295468 | O31: 338515 | P31: 578239 | Q31: 328239 | R31: 312826 | S31: 406854 | T31: 531893 | U31: 356954 | V31: 386250 | W31: 466869 | X31: -0.028500306 | Y31: 0.018176213 | Z31: 0.045646731 | AA31: 0.035681777
B32: 8361 | C32: Japan | D32: =VLOOKUP(Revenue!B32,기업리스트!B:G,2,FALSE) -> The Ogaki Kyoritsu Bank, Ltd. | E32: Jun'26 | F32: 3.4 | G32: 28853 | H32: 27572 | I32: 27903 | J32: 31210 | K32: 26998 | L32: 26992 | M32: 27449 | N32: 29072 | O32: 30013 | P32: 35761 | Q32: 30447 | R32: 30455 | S32: 28495 | T32: 29017 | U32: 33318 | V32: 30256 | W32: 32565 | X32: -0.053883891 | Y32: 0.024245444 | Z32: -0.0016407635 | AA32: 0.033612474
B33: 4021 | C33: Japan | D33: =VLOOKUP(Revenue!B33,기업리스트!B:G,2,FALSE) -> Nissan Chemical Corporation | E33: Sep'26 | F33: 3.3 | G33: 49530 | H33: 66635 | I33: 58290 | J33: 51241 | K33: 49703 | L33: 68831 | M33: 54939 | N33: 50736 | O33: 49659 | P33: 71371 | Q33: 58688 | R33: 59497 | S33: 56647 | T33: 76533 | U33: 69871 | V33: 60223 | W33: 65341 | X33: 0.020966438 | Y33: 0.04448909 | Z33: 0.0027652086 | AA33: 0.03302263
B34: 8591 | C34: Japan | D34: =VLOOKUP(Revenue!B34,기업리스트!B:G,2,FALSE) -> ORIX Corporation | E34: Sep'26 | F34: 3.1 | G34: 626579 | H34: 652252 | I34: 657813 | J34: 707003 | K34: 630028 | L34: 668815 | M34: 676974 | N34: 682982 | O34: 678125 | P34: 776501 | Q34: 708139 | R34: 695494 | S34: 750851 | T34: 720337 | U34: 768641 | V34: 795856 | W34: 844413 | X34: -0.019162159 | Y34: 0.021045484 | Z34: 0.034191126 | AA34: 0.030820721
B35: 4151 | C35: Japan | D35: =VLOOKUP(Revenue!B35,기업리스트!B:G,2,FALSE) -> Kyowa Kirin Co., Ltd. | E35: Dec'25 | F35: 3 | G35: 98277 | H35: 87751 | I35: 97520 | J35: 98504 | K35: 114596 | L35: 93535 | M35: 105675 | N35: 106844 | O35: 136180 | P35: 105569 | Q35: 127404 | R35: 129824 | S35: 132760 | T35: 104725 | U35: 125929 | V35: 118797 | W35: 147375 | X35: -0.001703134 | Y35: -0.0029815267 | Z35: -0.022356347 | AA35: 0.030308309
... B70: 6707 | C70: Japan | D70: =VLOOKUP(Revenue!B70,기업리스트!B:G,2,FALSE) -> Sanken Electric Co., Ltd. | E70: Sep'26 | F70: -5.7 | G70: 42496 | H70: 46743 | I70: 49632 | J70: 56333 | K70: 57308 | L70: 62114 | M70: 59906 | N70: 61644 | O70: 58278 | P70: 55393 | Q70: 49828 | R70: 22964 | S70: 23299 | T70: 25528 | U70: 22238 | V70: 18773 | W70: 18146 | X70: -0.19714953 | Y70: -0.226856 | Z70: -0.044571356 | AA70: -0.057358801
B71: TECHNOE | C71: India | D71: =VLOOKUP(Revenue!B71,기업리스트!B:G,2,FALSE) -> Techno Electric & Engineering Company Limited | E71: Jun'26 | F71: 16.6 | G71: 2735 | H71: 3034 | I71: 0 | J71: 1730 | K71: 2280 | L71: 1853 | M71: 3130 | N71: 2739 | O71: 4623 | P71: 3265 | Q71: 4396 | R71: 3754 | S71: 4414 | T71: 6361 | U71: 8158 | V71: 5260 | W71: 8434 | X71: 0.19559037 | Y71: 0.19878468 | Z71: 0.066381628 | AA71: 0.16616377
B72: PFOCUS | C72: India | D72: =VLOOKUP(Revenue!B72,기업리스트!B:G,2,FALSE) -> Prime Focus Limited | E72: Sep'26 | F72: 7.3 | G72: 8575 | H72: 10734 | I72: 10281 | J72: 10821 | K72: 11059 | L72: 14497 | M72: 12290 | N72: 10381 | O72: 8569 | P72: 8265 | Q72: 8236 | R72: 9072 | S72: 9198 | T72: 9483 | U72: 10313 | V72: 10609 | W72: 12072 | X72: 0.035029191 | Y72: 0.057712079 | Z72: 0.04037724 | AA72: 0.07257026
B73: ENGINERSIN | C73: India | D73: =VLOOKUP(Revenue!B73,기업리스트!B:G,2,FALSE) -> Engineers India Limited | E73: Jun'26 | F73: 7 | G73: 6568 | H73: 6921 | I73: 8178 | J73: 8148 | K73: 7931 | L73: 8422 | M73: 8801 | N73: 8183 | O73: 7898 | P73: 8676 | Q73: 8051 | R73: 6238 | S73: 6889 | T73: 7646 | U73: 10102 | V73: 8704 | W73: 9213 | X73: -0.034501239 | Y73: 0.071155981 | Z73: 0.079870445 | AA73: 0.069703968
B74: KIRLOSENG | C74: India | D74: =VLOOKUP(Revenue!B74,기업리스트!B:G,2,FALSE) -> Kirloskar Oil Engines Limited | E74: Jun'26 | F74: 6.9 | G74: 10014 | H74: 10178 | I74: 11820 | J74: 11914 | K74: 12281 | L74: 12204 | M74: 13838 | N74: 15434 | O74: 13048 | P74: 13901 | Q74: 16600 | R74: 16356 | S74: 15003 | T74: 14537 | U74: 17529 | V74: 17638 | W74: 19484 | X74: 0.01028128 | Y74: 0.014864951 | Z74: 0.02021285 | AA74: 0.069250622
B75: EIDPARRY | C75: India | D75: =VLOOKUP(Revenue!B75,기업리스트!B:G,2,FALSE) -> E.I.D.- Parry (India) Limited | E75: Jun'26 | F75: 6.8 | G75: 69784 | H75: 65287 | I75: 56595 | J75: 71465 | K75: 113276 | L75: 99166 | M75: 68531 | N75: 70265 | O75: 90595 | P75: 77701 | Q75: 55570 | R75: 67468 | S75: 93304 | T75: 87204 | U75: 68111 | V75: 87237 | W75: 116244 | X75: 0.032318402 | Y75: 0.04131499 | Z75: 0.062542907 | AA75: 0.068303082
B76: ZYDUSLIFE | C76: India | D76: =VLOOKUP(Revenue!B76,기업리스트!B:G,2,FALSE) -> Zydus Lifesciences Limited | E76: Sep'26 | F76: 6.5 | G76: 36550 | H76: 36447 | I76: 40727 | J76: 41347 | K76: 43623 | L76: 46677 | M76: 51396 | N76: 43688 | O76: 45052 | P76: 55338 | Q76: 62075 | R76: 52370 | S76: 52691 | T76: 65279 | U76: 65737 | V76: 61232 | W76: 68645 | X76: 0.044683873 | Y76: 0.015756298 | Z76: 0.0375386 | AA76: 0.065134585
B77: GALAXYSURF | C77: India | D77: =VLOOKUP(Revenue!B77,기업리스트!B:G,2,FALSE) -> Galaxy Surfactants Limited | E77: Jun'26 | F77: 5.8 | G77: 8773 | H77: 9291 | I77: 10529 | J77: 11589 | K77: 12316 | L77: 10803 | M77: 9933 | N77: 9418 | O77: 9831 | P77: 9405 | Q77: 9290 | R77: 9741 | S77: 10630 | T77: 10417 | U77: 11449 | V77: 12779 | W77: 13262 | X77: 0.025904879 | Y77: 0.053869954 | Z77: 0.071927457 | AA77: 0.058133628
B78: PFIZER | C78: India | D78: =VLOOKUP(Revenue!B78,기업리스트!B:G,2,FALSE) -> Pfizer Limited | E78: Sep'26 | F78: 4.5 | G78: 6759 | H78: 5497 | I78: 5929 | J78: 6375 | K78: 6218 | L78: 5726 | M78: 5314 | N78: 5752 | O78: 5400 | P78: 5466 | Q78: 5629 | R78: 5886 | S78: 5380 | T78: 5919 | U78: 6031 | V78: 6423 | W78: 6450 | X78: 0.020258486 | Y78: 0.017620759 | Z78: 0.0231306 | AA78: 0.045046941
...

Sheet Operating Income
B2: Ticker | C2: Country | D2: Industry | E2: Latest_Date | F2: Growth_Rate | G2: 4Q21 | H2: 1Q22 | I2: 2Q22 | J2: 3Q22 | K2: 4Q22 | L2: 1Q23 | M2: 2Q23 | N2: 3Q23 | O2: 4Q23 | P2: 1Q24 | Q2: 2Q24 | R2: 3Q24 | S2: 4Q24 | T2: 1Q25 | U2: 2Q25 | V2: 3Q25 | W2: 4Q25 | X2: 1Q25 | Y2: 2Q25 | Z2: 3Q25 | AA2: 4Q25
B3: AMTM | C3: United States | D3: Specialty Business Services | E3: Dec'25 | F3: 29 | L3: 41.21 | M3: 46.57 | N3: 42.17 | O3: 69.6 | P3: 71 | Q3: 74 | R3: 81 | S3: 32 | T3: 111 | U3: 123 | V3: 117 | W3: 143 | X3: 0.15503876 | Y3: 0.16442953 | Z3: 0.1037464 | AA3: 0.28981723
B4: CURB | C4: United States | D4: REIT - Retail | E4: Dec'25 | F4: 25.2 | L4: 8.03 | M4: 8.03 | N4: 9.17 | O4: 9.7 | P4: 11.33 | Q4: 10.55 | R4: 8.22 | S4: 3.83 | T4: 5.08 | U4: 6.57 | V4: 8.97 | W4: 10 | X4: -0.18420277 | Y4: -0.14378613 | Z4: 0.03164557 | AA4: 0.25235174
B5: CMCO | C5: United States | D5: Farm & Heavy Construction Machinery | E5: Jun'26 | F5: 24.1 | G5: 25.6 | H5: 16.65 | I5: 23.53 | J5: 22.45 | K5: 27.05 | L5: 21.08 | M5: 27.25 | N5: 23.68 | O5: 32.69 | P5: 21.77 | Q5: 32.02 | R5: 20.31 | S5: -5.34 | T5: 25.59 | U5: 42.91 | V5: 8.01 | W5: 11.81 | X5: 0.055555556 | Y5: 0.15004133 | Z5: -0.14735833 | AA5: 0.24097232
B6: L | C6: United States | D6: Insurance - Property & Casualty | E6: Dec'25 | F6: 15.9 | G6: 533 | H6: 510 | I6: 280 | J6: 32 | K6: 556 | L6: 586 | M6: 560 | N6: 428 | O6: 690 | P6: 706 | Q6: 594 | R6: 673 | S6: 188 | T6: 620 | U6: 628 | V6: 779 | W6: 541 | X6: -0.039796391 | Y6: 0.016385542 | Z6: 0.050260787 | AA6: 0.15936795
B7: AIOT | C7: United States | D7: Software - Infrastructure | E7: Sep'26 | F7: 15 | G7: -3.51 | H7: -3.74 | I7: -1.59 | J7: -1.22 | K7: -0.42 | L7: -1.89 | M7: -2.98 | N7: -2.96 | O7: -0.14 | P7: -2.7 | Q7: -2.54 | R7: 4.46 | S7: 5.42 | T7: 7.71 | U7: 2.21 | V7: 6.32 | W7: 8.67 | X7: 2.2435345 | Y7: 0.31561462 | Z7: 0.093939394 | AA7: 0.15004617
B8: DT | C8: United States | D8: Software - Application | E8: Sep'26 | F8: 11.2 | G8: 21.22 | H8: 17.63 | I8: 19.08 | J8: 20.4 | K8: 33.88 | L8: 19.45 | M8: 34.29 | N8: 35.27 | O8: 35.72 | P8: 23.12 | Q8: 42.03 | R8: 47.03 | S8: 47.46 | T8: 42.91 | U8: 62.34 | V8: 72.97 | W8: 72.74 | X8: 0.12396642 | Y8: 0.11319177 | Z8: 0.12986883 | AA8: 0.11201702
B9: SVM | C9: United States | D9: Silver | E9: Jun'26 | F9: 9.9 | G9: 19.39 | H9: 16.65 | I9: 10.5 | J9: 21.32 | K9: -9.4 | L9: 15.84 | M9: 6.68 | N9: 19.72 | O9: 16.21 | P9: 17.82 | Q9: 8.89 | R9: 30.39 | S9: 25.35 | T9: 27.31 | U9: 20.08 | V9: 30.79 | W9: 35.58 | X9: 0.11510006 | Y9: 0.12170981 | Z9: 0.0038785998 | AA9: 0.098811939
B10: APO | C10: United States | D10: Asset Management | E10: Dec'25 | F10: 9.6 | G10: 448 | H10: -2544 | I10: -3743 | J10: -1463 | K10: 1249 | L10: 2102 | M10: 828 | N10: -111 | O10: 2473 | P10: 2025 | Q10: 1449 | R10: 2685 | S10: 1110 | T10: 1621 | U10: 1017 | V10: 2920 | W10: 1752 | X10: -0.055578484 | Y10: -0.062927895 | Z10: 0.03653039 | AA10: 0.096280744
B11: KD | C11: United States | D11: Information Technology Services | E11: Sep'26 | F11: 7.6 | G11: -101 | H11: -139 | I11: -87 | J11: -152 | K11: -43 | L11: -59 | M11: -34 | N11: -22 | O11: 59 | P11: 7 | Q11: 146 | R11: 110 | S11: 125 | T11: 194 | U11: 149 | V11: 140 | W11: 171 | X11: 0.48195876 | Y11: 0.0052173913 | Z11: 0.051903114 | AA11: 0.075657895
B12: SOHU | C12: United States | D12: Electronic Gaming & Multimedia | E12: Dec'25 | F12: 7.4 | G12: -2.89 | H12: 12.67 | I12: 10.09 | J12: -18.06 | K12: -5.58 | L12: -18.45 | M12: -22.95 | N12: -20.63 | O12: -25.28 | P12: -26.88 | Q12: -44.29 | R12: -13.04 | S12: -25.19 | T12: -19.03 | U12: -22.32 | V12: 13.58 | W12: -29.09 | X12: -0.071755027 | Y12: -0.21634663 | Z12: -0.33450616 | AA12: 0.073640483
B13: ACM | C13: United States | D13: Engineering & Construction | E13: Dec'25 | F13: 3.9 | G13: 174.69 | H13: 165.2 | I13: 174.25 | J13: 189.08 | K13: 177.22 | L13: 180.78 | M13: 195.55 | N13: 208.4 | O13: 213.17 | P13: 210.45 | Q13: 218.59 | R13: 250.94 | S13: 252.77 | T13: 229.45 | U13: 252.21 | V13: 290.49 | W13: 293.13 | X13: 0.020369874 | Y13: 0.035324402 | Z13: 0.040137207 | AA13: 0.039378683
B14: SBH | C14: United States | D14: Specialty Retail | E14: Mar'26 | F14: 1.4 | G14: 113.48 | H14: 86.66 | I14: 104.25 | J14: 88.65 | K14: 94.71 | L14: 77.82 | M14: 91.28 | N14: 75.64 | O14: 70.34 | P14: 59.94 | Q14: 72.15 | R14: 82.93 | S14: 72.12 | T14: 71.85 | U14: 78.17 | V14: 56.14 | W14: 75.94 | X14: 0.041478025 | Y14: 0.020130413 | Z14: -0.087815911 | AA14: 0.013727181
B15: MMT | C15: United States | D15: Asset Management | E15: Dec'25 | F15: -0.4 | G15: 4.27 | H15: 3.97 | I15: 3.97 | J15: 4.32 | K15: 4.32 | L15: 5.28 | M15: 5.28 | N15: 4.98 | O15: 4.98 | P15: 5.04 | Q15: 5.04 | R15: 4.91 | S15: 4.91 | T15: 4.82 | U15: 4.82 | V15: 4.83 | W15: 4.83 | X15: -0.011055276 | Y15: -0.011178862 | Z15: -0.0041109969 | AA15: -0.004127967
B16: BDX | C16: United States | D16: Medical Instruments & Supplies | E16: Mar'26 | F16: -2.3 | G16: 736 | H16: 663 | I16: 633 | J16: 575 | K16: 624 | L16: 681 | M16: 709 | N16: 0 | O16: 503 | P16: 829 | Q16: 795 | R16: 799 | S16: 789 | T16: 844 | U16: 981 | V16: 1052 | W16: 703 | X16: 0.0046699875 | Y16: 0.057638674 | Z16: 0.074128333 | AA16: -0.023458811
... B21: MNDY | C21: United States | D21: Software - Application | E21: Dec'25 | F21: -131.8 | G21: -31.6 | H21: -67.5 | I21: -46.18 | J21: -28.24 | K21: -10.1 | L21: -22.75 | M21: -12.17 | N21: -2.52 | O21: -1.15 | P21: -5.02 | Q21: 1.79 | R21: -27.4 | S21: 9.6 | T21: 9.8 | U21: -11.55 | V21: -2.38 | W21: 2.39 | X21: -0.70470756 | Y21: 2.1481481 | Z21: -1.2797954 | AA21: -1.3180987
B22: 1893 | C22: Japan | D22: =VLOOKUP(B22,기업리스트!B:G,2,FALSE) -> Penta-Ocean Construction Co., Ltd. | E22: Sep'26 | F22: 58 | G22: 1133 | H22: 2718 | I22: 3532 | J22: 2747 | K22: -13601 | L22: 11442 | M22: 6446 | N22: 6507 | O22: 7770 | P22: 8003 | Q22: 6972 | R22: 8130 | S22: -334 | T22: 6930 | U22: 10278 | V22: 15560 | W22: 18472 | X22: -0.047121339 | Y22: 0.15236427 | Z22: 0.29715246 | AA22: 0.57982364
B23: 9887 | C23: Japan | D23: =VLOOKUP(B23,기업리스트!B:G,2,FALSE) -> Matsuya Foods Holdings Co., Ltd. | E23: Sep'26 | F23: 23.8 | G23: -365 | H23: -1698 | I23: -268 | J23: 500 | K23: 1226 | L23: 10 | M23: -39 | N23: 1646 | O23: 2567 | P23: 1149 | Q23: 135 | R23: 1750 | S23: 2297 | T23: 225 | U23: 914.97 | V23: 1915 | W23: 3571 | X23: -0.17332583 | Y23: 0.17698434 | Z23: 0.031810479 | AA23: 0.23804319
B24: 5195 | C24: Japan | D24: =VLOOKUP(B24,기업리스트!B:G,2,FALSE) -> Bando Chemical Industries, Ltd. | E24: Sep'26 | F24: 22.7 | G24: 1940 | H24: -445 | I24: 1904 | J24: 1807 | K24: 2126 | L24: 1026 | M24: 1796 | N24: 2088 | O24: 2193 | P24: 1624 | Q24: 1905 | R24: 2344 | S24: 655 | T24: 2720 | U24: 3536 | V24: 2389 | W24: 2767 | X24: 0.16789216 | Y24: 0.2139297 | Z24: 0.0048622366 | AA24: 0.22709677
B25: 5463 | C25: Japan | D25: =VLOOKUP(B25,기업리스트!B:G,2,FALSE) -> Maruichi Steel Tube Ltd. | E25: Jun'26 | F25: 19.2 | G25: 9563 | H25: 10960 | I25: 8019 | J25: 8790 | K25: 9623 | L25: 5757 | M25: 5850 | N25: 9333 | O25: 9936 | P25: 8431 | Q25: 7112 | R25: 8287 | S25: 4714 | T25: 672 | U25: 9246 | V25: 6627 | W25: 8796 | X25: -0.27182595 | Y25: 0.10267019 | Z25: -0.072428989 | AA25: 0.19201279
B26: 5805 | C26: Japan | D26: =VLOOKUP(B26,기업리스트!B:G,2,FALSE) -> SWCC Corporation | E26: Sep'26 | F26: 17.9 | G26: 3218 | H26: 1806 | I26: 2157 | J26: 2154 | K26: 2774 | L26: 3390 | M26: 1605 | N26: 2858 | O26: 4887 | P26: 3475 | Q26: 4868 | R26: 5550 | S26: 3869 | T26: 5392 | U26: 5138 | V26: 6768 | W26: 7657 | X26: 0.10792704 | Y26: 0.013720209 | Z26: 0.061055692 | AA26: 0.17895781
B27: 8361 | C27: Japan | D27: =VLOOKUP(B27,기업리스트!B:G,2,FALSE) -> The Ogaki Kyoritsu Bank, Ltd. | E27: Jun'26 | F27: 16.1 | G27: 5473 | H27: 4075 | I27: 2445 | J27: 6593 | K27: 2125 | L27: 1517 | M27: -1561 | N27: 5071 | O27: -257 | P27: 5253 | Q27: 3525 | R27: 4196 | S27: 1668 | T27: 5431 | U27: 8716 | V27: 5667 | W27: 5127 | X27: 0.012156809 | Y27: 0.35026991 | Z27: 0.07350957 | AA27: 0.16101853
B28: 6588 | C28: Japan | D28: =VLOOKUP(B28,기업리스트!B:G,2,FALSE) -> Toshiba Tec Corporation | E28: Sep'26 | F28: 13.6 | G28: 4332 | H28: 2902 | I28: 204 | J28: 5752 | K28: 5849 | L28: 4275 | M28: 1288 | N28: 4623 | O28: 3553 | P28: 6391 | Q28: 4277 | R28: 5196 | S28: 2295 | T28: 8484 | U28: -2118 | V28: 1043 | W28: 3616 | X28: 0.11525965 | Y28: -0.31577128 | Z28: -0.29970412 | AA28: 0.13612943
B29: 4186 | C29: Japan | D29: =VLOOKUP(B29,기업리스트!B:G,2,FALSE) -> Tokyo Ohka Kogyo Co., Ltd. | E29: Dec'25 | F29: 13.5 | G29: 5621 | H29: 6945 | I29: 7867 | J29: 7853 | K29: 7516 | L29: 5393 | M29: 5512 | N29: 4542 | O29: 7261 | P29: 5794 | Q29: 7650 | R29: 9800 | S29: 9848 | T29: 9802 | U29: 10045 | V29: 12048 | W29: 15492 | X29: 0.12111689 | Y29: 0.064555256 | Z29: 0.056918597 | AA29: 0.1352083
B30: 7189 | C30: Japan | D30: =VLOOKUP(B30,기업리스트!B:G,2,FALSE) -> Nishi-Nippon Financial Holdings, Inc. | E30: Sep'26 | F30: 12.9 | G30: 7467 | H30: 6658 | I30: 12127 | J30: 6786 | K30: 14308 | L30: 889 | M30: 12618 | N30: 9498 | O30: 6777 | P30: 5961 | Q30: 15164 | R30: 8253 | S30: 11302 | T30: 10297 | U30: 12403 | V30: 18289 | W30: 18042 | X30: 0.106588 | Y30: -0.061333748 | Z30: 0.23751035 | AA30: 0.12889407
B31: 1870 | C31: Japan | D31: =VLOOKUP(B31,기업리스트!B:G,2,FALSE) -> Yahagi Construction Co.,Ltd. | E31: Sep'26 | F31: 12.6 | G31: 930 | H31: 3055 | I31: 645 | J31: 1093 | K31: 1644 | L31: 3831 | M31: 139 | N31: 1349 | O31: 7553 | P31: 474 | Q31: 729 | R31: 558 | S31: 2032 | T31: 5336 | U31: 3648 | V31: 4343 | W31: 3974 | X31: 1.281835 | Y31: 0.3372617 | Z31: 0.32702609 | AA31: 0.12644052
B32: 4385 | C32: Japan | D32: =VLOOKUP(B32,기업리스트!B:G,2,FALSE) -> Mercari, Inc. | E32: Jun'26 | F32: 11.7 | G32: -2624 | H32: -2911 | I32: 970 | J32: 3120 | K32: 2714 | L32: 5696 | M32: 5494 | N32: 4478 | O32: 3345 | P32: 4980 | Q32: 5551 | R32: 4347 | S32: 7067 | T32: 8924 | U32: 7751 | V32: 8895 | W32: 10884 | X32: 0.17972203 | Y32: 0.084978176 | Z32: 0.16191392 | AA32: 0.11695315
B33: 8392 | C33: Japan | D33: =VLOOKUP(B33,기업리스트!B:G,2,FALSE) -> The Oita Bank, Ltd. | E33: Jun'26 | F33: 11.2 | G33: 794 | H33: 2483 | I33: -164 | J33: 3334 | K33: 943 | L33: 2771 | M33: 370 | N33: 3026 | O33: 1344 | P33: 2223 | Q33: 2185 | R33: 4934 | S33: 420 | T33: 4465 | U33: 1236 | V33: 4897 | W33: 1659 | X33: 0.22966605 | Y33: -0.079056981 | Z33: -0.0033469019 | AA33: 0.11245235
B34: 4023 | C34: Japan | D34: =VLOOKUP(B34,기업리스트!B:G,2,FALSE) -> Kureha Corporation | E34: Sep'26 | F34: 11.2 | G34: 6568 | H34: 6483 | I34: 7774 | J34: 8253 | K34: 7306 | L34: -272 | M34: 5004 | N34: 4618 | O34: 6465 | P34: 2297 | Q34: 2774 | R34: 3597 | S34: 3658 | T34: 5 | U34: 1928 | V34: 5235 | W34: 4874 | X34: -0.1859484 | Y34: -0.084313335 | Z34: 0.17827601 | AA34: 0.11232219
B35: 5838 | C35: Japan | D35: =VLOOKUP(B35,기업리스트!B:G,2,FALSE) -> Rakuten Bank, Ltd. | E35: Sep'26 | F35: 9.5 | I35: 9218 | J35: 8748 | K35: 10577 | L35: 10203 | M35: 11368 | N35: 11176 | O35: 12670 | P35: 13073 | Q35: 15262 | R35: 15826 | S35: 18409 | T35: 22024 | U35: 23944 | V35: 24345 | W35: 26818 | X35: 0.14305578 | Y35: 0.12139092 | Z35: 0.10621797 | AA35: 0.094779198
B36: 8086 | C36: Japan | D36: =VLOOKUP(B36,기업리스트!B:G,2,FALSE) -> Nipro Corporation | E36: Sep'26 | F36: 9.4 | G36: 6871 | H36: 4149 | I36: 2955 | J36: 3417 | K36: 6808 | L36: 4550 | M36: 7338 | N36: 6150 | O36: 8875 | P36: -28 | Q36: 5808 | R36: 7651 | S36: 8746 | T36: 4394 | U36: 8041 | V36: 7297 | W36: 11410 | X36: 0.19939577 | Y36: 0.083950524 | Z36: -0.012278024 | AA36: 0.093545895
B37: 4046 | C37: Japan | D37: =VLOOKUP(B37,기업리스트!B:G,2,FALSE) -> Osaka Soda Co., Ltd. | E37: Sep'26 | F37: 8 | G37: 4146 | H37: 2562 | I37: 5150 | J37: 4573 | K37: 4228 | L37: 1607 | M37: 2808 | N37: 2110 | O37: 2682 | P37: 2893 | Q37: 3310 | R37: 3658 | S37: 3672 | T37: 2607 | U37: 3941 | V37: 4171 | W37: 4826 | X37: -0.021133525 | Y37: 0.047633426 | Z37: 0.036964981 | AA37: 0.080189007
B38: 3097 | C38: Japan | D38: =VLOOKUP(B38,기업리스트!B:G,2,FALSE) -> The Monogatari Corporation | E38: Jun'26 | F38: 8 | G38: 1542 | H38: 456 | I38: 908 | J38: 1856 | K38: 1628 | L38: 2149 | M38: 1570 | N38: 2190 | O38: 2021 | P38: 2663 | Q38: 1292 | R38: 2363 | S38: 1972 | T38: 2605 | U38: 2303 | V38: 2734 | W38: 2738 | X38: -0.0069963812 | Y38: 0.12281341 | Z38: 0.040138483 | AA38: 0.079675473
B39: 8802 | C39: Japan | D39: =VLOOKUP(B39,기업리스트!B:G,2,FALSE) -> Mitsubishi Estate Co., Ltd. | E39: Sep'26 | F39: 7.9 | G39: 60683 | H39: 106636 | I39: 83518 | J39: 58562 | K39: 57933 | L39: 96690 | M39: 48402 | N39: 41913 | O39: 56506 | P39: 131806 | Q39: 51799 | R39: 48080 | S39: 94601 | T39: 114753 | U39: 62406 | V39: 45185 | W39: 119784 | X39: -0.052263965 | Y39: 0.034300996 | Z39: -0.0090514007 | AA39: 0.079455426
B40: 6651 | C40: Japan | D40: =VLOOKUP(B40,기업리스트!B:G,2,FALSE) -> Nitto Kogyo Corporation | E40: Sep'26 | F40: 7.6 | G40: 2884 | H40: 1851 | I40: 336 | J40: 1836 | K40: 3154 | L40: 2847 | M40: 1772 | N40: 3000 | O40: 4225 | P40: 2955 | Q40: 2032 | R40: 2470 | S40: 4566 | T40: 4288 | U40: 2647 | V40: 3438 | W40: 5706 | X40: 0.11087083 | Y40: 0.046046721 | Z40: 0.069286379 | AA40: 0.076310329
B41: 6098 | C41: Japan | D41: =VLOOKUP(B41,기업리스트!B:G,2,FALSE) -> Recruit Holdings Co., Ltd. | E41: Sep'26 | F41: 7.5 | G41: 110658 | H41: 64080 | I41: 119373 | J41: 108583 | K41: 96886 | L41: 71064 | M41: 121656 | N41: 116178 | O41: 108971 | P41: 101716 | Q41: 127820 | R41: 141890 | S41: 139650 | T41: 115825 | U41: 153735 | V41: 159792 | W41: 182153 | X41: 0.027606462 | Y41: 0.049344517 | Z41: 0.032484123 | AA41: 0.074697453
B42: 4151 | C42: Japan | D42: =VLOOKUP(B42,기업리스트!B:G,2,FALSE) -> Kyowa Kirin Co., Ltd. | E42: Dec'25 | F42: 7.4 | G42: 19881 | H42: 16104 | I42: 20775 | J42: 17293 | K42: 24160 | L42: 13821 | M42: 8590 | N42: 36132 | O42: 37254 | P42: 16364 | Q42: 24400 | R42: 30117 | S42: 19329 | T42: 9534 | U42: 11626 | V42: 27546 | W42: 24360 | X42: -0.075712227 | Y42: -0.15320221 | Z42: -0.036413336 | AA42: 0.073947233
B43: 8081 | C43: Japan | D43: =VLOOKUP(B43,기업리스트!B:G,2,FALSE) -> Global Mixed-Mode Technology Inc. | E43: Sep'26 | F43: 7.3 | G43: 396 | H43: 1614 | I43: 139 | J43: 1186 | K43: 803 | L43: 1840 | M43: 522 | N43: 1324 | O43: 754 | P43: 1945 | Q43: 338 | R43: 1180 | S43: 507 | T43: 2476 | U43: 470 | V43: 1206 | W43: 848 | X43: 0.13375315 | Y43: 0.029326816 | Z43: 0.0056119145 | AA43: 0.073191672
B44: 5803 | C44: Japan | D44: =VLOOKUP(B44,기업리스트!B:G,2,FALSE) -> Fujikura Ltd. | E44: Sep'26 | F44: 6.4 | G44: 9351 | H44: 10340 | I44: 11286 | J44: 23966 | K44: 21257 | L44: 13654 | M44: 12572 | N44: 18206 | O44: 20666 | P44: 18040 | Q44: 24452 | R44: 30688 | S44: 41134 | T44: 39245 | U44: 41086 | V44: 49085 | W44: 52025 | X44: 0.18549784 | Y44: 0.12274294 | Z44: 0.12091119 | AA44: 0.063858106
B45: 6490 | C45: Japan | D45: =VLOOKUP(B45,기업리스트!B:G,2,FALSE) -> PILLAR Corporation | E45: Sep'26 | F45: 4.8 | G45: 3015 | H45: 3106 | I45: 2977 | J45: 3837 | K45: 3483 | L45: 3546 | M45: 3076 | N45: 3821 | O45: 3709 | P45: 3601 | Q45: 2496 | R45: 3330 | S45: 2512 | T45: 2998 | U45: 2706 | V45: 2900 | W45: 3051 | X45: -0.050506743 | Y45: 0.018525053 | Z45: -0.037242335 | AA45: 0.048488665
...

Sheet 빨간줄
B2: (단위: mil $)
B4: 4023 | C4: 6 | D4: 7 | E4: 8 | F4: 9 | G4: 10 | H4: 11 | I4: 12 | J4: 13 | K4: 14 | L4: 15 | M4: 16 | N4: 17 | O4: 18 | P4: 19 | Q4: 20 | R4: 21 | S4: 22 | Y4: AMTM | Z4: 1893 | AA4: Penta-Ocean Construction Co., Ltd.
Y5: CURB
C6: 4Q21 | D6: 1Q22 | E6: 2Q22 | F6: 3Q22 | G6: 4Q22 | H6: 1Q23 | I6: 2Q23 | J6: 3Q23 | K6: 4Q23 | L6: 1Q24 | M6: 2Q24 | N6: 3Q24 | O6: 4Q24 | P6: 1Q25 | Q6: 2Q25 | R6: 3Q25 | S6: 4Q25 | T6: 1Q26 | U6: 2Q26 | V6: 3Q26 | W6: 4Q26 | Y6: CMCO | Z6: 9887 | AA6: Matsuya Foods Holdings Co., Ltd.
B7: Revenue | C7: =VLOOKUP($B$4,Revenue!$B:$W,C4,FALSE) -> 44042 | D7: =VLOOKUP($B$4,Revenue!$B:$W,D4,FALSE) -> 45230 | E7: =VLOOKUP($B$4,Revenue!$B:$W,E4,FALSE) -> 49280 | F7: =VLOOKUP($B$4,Revenue!$B:$W,F4,FALSE) -> 52475 | G7: =VLOOKUP($B$4,Revenue!$B:$W,G4,FALSE) -> 47225 | H7: =VLOOKUP($B$4,Revenue!$B:$W,H4,FALSE) -> 42297 | I7: =VLOOKUP($B$4,Revenue!$B:$W,I4,FALSE) -> 43759 | J7: =VLOOKUP($B$4,Revenue!$B:$W,J4,FALSE) -> 44730 | ... S7: =VLOOKUP($B$4,Revenue!$B:$W,S4,FALSE) -> 40376 | Y7: L | Z7: 5195 | AA7: Bando Chemical Industries, Ltd.
B8: OP | C8: =VLOOKUP($B$4,'Operating Income'!$B:$W,C4,FALSE) -> 6568 | D8: =VLOOKUP($B$4,'Operating Income'!$B:$W,D4,FALSE) -> 6483 | E8: =VLOOKUP($B$4,'Operating Income'!$B:$W,E4,FALSE) -> 7774 | F8: =VLOOKUP($B$4,'Operating Income'!$B:$W,F4,FALSE) -> 8253 | G8: =VLOOKUP($B$4,'Operating Income'!$B:$W,G4,FALSE) -> 7306 | H8: =VLOOKUP($B$4,'Operating Income'!$B:$W,H4,FALSE) -> -272 | I8: =VLOOKUP($B$4,'Operating Income'!$B:$W,I4,FALSE) -> 5004 | J8: =VLOOKUP($B$4,'Operating Income'!$B:$W,J4,FALSE) -> 4618 | ... S8: =VLOOKUP($B$4,'Operating Income'!$B:$W,S4,FALSE) -> 4874 | Y8: AIOT | Z8: 5463 | AA8: Maruichi Steel Tube Ltd.
B9: Trailing 4Q OP avg. | C9: =AVERAGE(C8:C8) -> 6568 | D9: =AVERAGE(C8:D8) -> 6525.5 | E9: =AVERAGE(C8:E8) -> 6941.6667 | F9: =AVERAGE(C8:F8) -> 7269.5 | G9: =AVERAGE(D8:G8) -> 7454 | H9: =AVERAGE(E8:H8) -> 5765.25 | I9: =AVERAGE(F8:I8) -> 5072.75 | J9: =AVERAGE(G8:J8) -> 4164 | K9: =AVERAGE(H8:K8) -> 3953.75 | L9: =AVERAGE(I8:L8) -> 4596 | M9: =AVERAGE(J8:M8) -> 4038.5 | ... S9: =AVERAGE(P8:S8) -> 3010.5 | Y9: DT | Z9: 5805 | AA9: SWCC Corporation
B10: Trailing 4Q OP sum. | C10: =SUM(C8:C8) -> 6568 | D10: =SUM(C8:D8) -> 13051 | E10: =SUM(C8:E8) -> 20825 | F10: =SUM(C8:F8) -> 29078 | G10: =SUM(D8:G8) -> 29816 | H10: =SUM(E8:H8) -> 23061 | I10: =SUM(F8:I8) -> 20291 | J10: =SUM(G8:J8) -> 16656 | K10: =SUM(H8:K8) -> 15815 | L10: =SUM(I8:L8) -> 18384 | M10: =SUM(J8:M8) -> 16154 | ... S10: =SUM(P8:S8) -> 12042 | Z10: 8361 | AA10: The Ogaki Kyoritsu Bank, Ltd.
B11: Trailing OP Delta | D11: =D9/C9-1 -> -0.0064707674 | E11: =E9/D9-1 -> 0.063775445 | F11: =F9/E9-1 -> 0.047226891 | G11: =G9/F9-1 -> 0.025380012 | H11: =H9/G9-1 -> -0.22655621 | I11: =I9/H9-1 -> -0.12011621 | J11: =J9/I9-1 -> -0.17914346 | K11: =K9/J9-1 -> -0.050492315 | ... S11: =S9/R9-1 -> 0.11232219 | Z11: 6588 | AA11: Toshiba Tec Corporation
B12: opm | C12: =IFERROR(C8/C7,"-") -> 0.14913038 | D12: =IFERROR(D8/D7,"-") -> 0.14333407 | E12: =IFERROR(E8/E7,"-") -> 0.15775162 | F12: =IFERROR(F8/F7,"-") -> 0.15727489 | G12: =IFERROR(G8/G7,"-") -> 0.15470619 | H12: =IFERROR(H8/H7,"-") -> -0.0064307161 | I12: =IFERROR(I8/I7,"-") -> 0.11435362 | J12: =IFERROR(J8/J7,"-") -> 0.10324167 | ... S12: =IFERROR(S8/S7,"-") -> 0.12071528 | Z12: 4186 | AA12: Tokyo Ohka Kogyo Co., Ltd.
B13: op yoy | C13: =C8/#REF!-1 -> #REF! | D13: =D8/#REF!-1 -> #REF! | E13: =E8/#REF!-1 -> #REF! | F13: =F8/#REF!-1 -> #REF! | G13: =G8/C8-1 -> 0.11236297 | H13: =H8/D8-1 -> -1.0419559 | I13: =I8/E8-1 -> -0.35631592 | J13: =J8/F8-1 -> -0.4404459 | K13: =K8/G8-1 -> -0.11511087 | L13: =L8/H8-1 -> -9.4448529 | M13: =M8/I8-1 -> -0.44564349 | N13: =N8/J8-1 -> -0.22109138 | ... S13: =S8/O8-1 -> 0.33242209 | Z13: 7189 | AA13: Nishi-Nippon Financial Holdings, Inc.
B14: rv yoy | G14: =G7/C7-1 -> 0.072271922 | H14: =H7/D7-1 -> -0.064846341 | I14: =I7/E7-1 -> -0.11203328 | J14: =J7/F7-1 -> -0.14759409 | K14: =K7/G7-1 -> -0.060603494 | L14: =L7/H7-1 -> 0.06671868 | M14: =M7/I7-1 -> -0.041705706 | N14: =N7/J7-1 -> -0.112296 | ... S14: =S7/O7-1 -> 0.00012385128 | Z14: 1870 | AA14: Yahagi Construction Co.,Ltd.
Z15: 4385 | AA15: Mercari, Inc.
Z16: 8392 | AA16: The Oita Bank, Ltd.
Z17: 4023 | AA17: Kureha Corporation
