Workbook

Sheet 기업리스트
B2: 실적 기업 정보
B3: Ticker | C3: Company | D3: Date | E3: Time | F3: Quarter Ending | G3: Market Cap (mil$)
B4: AMAT | C4: Applied Materials, Inc. | D4: 12-Feb-26 | E4: After Hours | F4: Jan-26 | G4: 255983
B5: RMS | C5: Hermès International Société en commandite par actions | D5: 12-Feb-26 | F5: Dec-25 | G5: 254688
B6: OR | C6: L'Oréal S.A. | D6: 12-Feb-26 | F6: Dec-25 | G6: 248655
B7: SIE | C7: Siemens Aktiengesellschaft | D7: 12-Feb-26 | F7: Dec-25 | G7: 229885
B8: ANET | C8: Arista Networks, Inc. | D8: 12-Feb-26 | E8: After Hours | F8: Dec-25 | G8: 173139
B9: ULVR | C9: Unilever PLC | D9: 12-Feb-26 | F9: Dec-25 | G9: 158619
B10: ABI | C10: Anheuser-Busch InBev SA/NV | D10: 12-Feb-26 | F10: Dec-25 | G10: 148335
B11: 9984 | C11: SoftBank Group Corp. | D11: 12-Feb-26 | F11: Dec-25 | G11: 145052
B12: BATS | C12: British American Tobacco p.l.c. | D12: 12-Feb-26 | F12: Dec-25 | G12: 136225
B13: VRTX | C13: Vertex Pharmaceuticals Incorporated | D13: 12-Feb-26 | E13: After Hours | F13: Dec-25 | G13: 121257
B14: BN | C14: Brookfield Corporation | D14: 12-Feb-26 | E14: Pre Market | F14: Dec-25 | G14: 101439
B15: AEM | C15: Agnico Eagle Mines Limited | D15: 12-Feb-26 | E15: After Hours | F15: Dec-25 | G15: 98702.35
B16: HWM | C16: Howmet Aerospace Inc. | D16: 12-Feb-26 | E16: Pre Market | F16: Dec-25 | G16: 89724.21
B17: ABNB | C17: Airbnb, Inc. | D17: 12-Feb-26 | E17: After Hours | F17: Dec-25 | G17: 74083.81
B18: VALE3 | C18: Vale S.A. | D18: 12-Feb-26 | F18: Dec-25 | G18: 70068.94
B19: MBG | C19: Mercedes-Benz Group AG | D19: 12-Feb-26 | F19: Dec-25 | G19: 66248.67
B20: 285A | C20: Kioxia Holdings Corporation | D20: 12-Feb-26 | F20: Dec-25 | G20: 66176.67
B21: AEP | C21: American Electric Power Company, Inc. | D21: 12-Feb-26 | E21: Pre Market | F21: Dec-25 | G21: 64518.62
B22: KBC | C22: KBC Group NV | D22: 12-Feb-26 | F22: Dec-25 | G22: 56390.83
B23: ZTS | C23: Zoetis Inc. | D23: 12-Feb-26 | E23: Pre Market | F23: Dec-25 | G23: 56153.13
B24: REL | C24: RELX PLC | D24: 12-Feb-26 | E24: Pre Market | F24: Dec-25 | G24: 52874.83
B25: PSA | C25: Public Storage | D25: 12-Feb-26 | E25: After Hours | F25: Dec-25 | G25: 50357.89
B26: CBRE | C26: CBRE Group, Inc. | D26: 12-Feb-26 | E26: Pre Market | F26: Dec-25 | G26: 49736.33
B27: EXC | C27: Exelon Corporation | D27: 12-Feb-26 | E27: Pre Market | F27: Dec-25 | G27: 44786.17
B28: COIN | C28: Coinbase Global, Inc. | D28: 12-Feb-26 | E28: After Hours | F28: Dec-25 | G28: 44525.87
B29: ETR | C29: Entergy Corporation | D29: 12-Feb-26 | E29: Pre Market | F29: Dec-25 | G29: 44306.28
B30: SCMN | C30: Swisscom AG | D30: 12-Feb-26 | F30: Dec-25 | G30: 44228.91
B31: ALNY | C31: Alnylam Pharmaceuticals, Inc. | D31: 12-Feb-26 | E31: Pre Market | F31: Dec-25 | G31: 43354.47
B32: ADYEN | C32: Adyen N.V. | D32: 12-Feb-26 | F32: Dec-25 | G32: 42269.11
B33: IR | C33: Ingersoll Rand Inc. | D33: 12-Feb-26 | E33: After Hours | F33: Dec-25 | G33: 38918.37
B34: EMAAR | C34: Emaar Properties PJSC | D34: 12-Feb-26 | F34: Dec-25 | G34: 38386.62
B35: ONGC | C35: Oil and Natural Gas Corporation Limited | D35: 12-Feb-26 | F35: Dec-25 | G35: 37351.94
B36: PCG | C36: PG&E Corporation | D36: 12-Feb-26 | F36: Dec-25 | G36: 36045.73
B37: COALINDIA | C37: Coal India Limited | D37: 12-Feb-26 | F37: Dec-25 | G37: 31410.13
B38: HAL | C38: Hindustan Aeronautics Limited | D38: 12-Feb-26 | F38: Dec-25 | G38: 30030.25
B39: EXPE | C39: Expedia Group, Inc. | D39: 12-Feb-26 | E39: After Hours | F39: Dec-25 | G39: 29021.83
B40: IRM | C40: Iron Mountain Incorporated | D40: 12-Feb-26 | E40: Pre Market | F40: Dec-25 | G40: 28311.56
B41: NBIS | C41: Nebius Group N.V. | D41: 12-Feb-26 | F41: Dec-25 | G41: 27379
...

Sheet Revenue
B2: Ticker | C2: Country | D2: Industry | E2: Latest_Date | F2: Growth_Rate | G2: 4Q21 | H2: 1Q22 | I2: 2Q22 | J2: 3Q22 | K2: 4Q22 | L2: 1Q23 | M2: 2Q23 | N2: 3Q23 | O2: 4Q23 | P2: 1Q24 | Q2: 2Q24 | R2: 3Q24 | S2: 4Q24 | T2: 1Q25 | U2: 2Q25 | V2: 3Q25 | W2: 4Q25 | X2: 1Q25 | Y2: 2Q25 | Z2: 3Q25 | AA2: 4Q25
B3: 1347 | C3: Hong Kong | D3: N/A | E3: Sep'25 | F3: 5 | G3: 451.48 | H3: 528.32 | I3: 594.65 | J3: 620.82 | K3: 629.91 | L3: 630.11 | M3: 630.84 | N3: 631.38 | O3: 568.53 | P3: 455.36 | Q3: 459.99 | R3: 478.52 | S3: 526.31 | T3: 539.18 | U3: 540.94 | V3: 566.07 | W3: 635.18 | X3: 0.043652158 | Y3: 0.040394212 | Z3: 0.041991415 | AA3: 0.050112773
B4: NBIS | C4: United States | D4: Internet Content & Information | E4: Dec'25 | F4: 55.1 | G4: 1470 | H4: 1288 | I4: 2161 | J4: 2201 | K4: 2261 | L4: 2107 | M4: 2039 | N4: 2095 | O4: 0 | P4: 11.3 | Q4: 12.08 | R4: 32.1 | S4: 37.9 | T4: 55.3 | U4: 105.1 | V4: 146.1 | W4: 227.7 | X4: 0.47119297 | Y4: 0.67710001 | Z4: 0.49479167 | AA4: 0.55110337
B5: BTDR | C5: United States | D5: Software - Application | E5: Dec'25 | F5: 33.6 | G5: 87.49 | H5: 90.44 | I5: 89.18 | J5: 76.58 | K5: 77.14 | L5: 72.59 | M5: 93.82 | N5: 87.3 | O5: 114.85 | P5: 119.51 | Q5: 99.23 | R5: 62.03 | S5: 69.02 | T5: 70.13 | U5: 155.58 | V5: 169.71 | W5: 224.84 | X5: -0.14117042 | Y5: 0.18757698 | Z5: 0.30182756 | AA5: 0.33550082
B6: H | C6: United States | D6: Lodging | E6: Dec'25 | F6: 30.8 | G6: 575 | H6: 739 | I6: 843 | J6: 836 | K6: 853 | L6: 951 | M6: 921 | N6: 868 | O6: 869 | P6: 912 | Q6: 861 | R6: 762 | S6: 761 | T6: 832 | U6: 863 | V6: 883 | W6: 1789 | X6: -0.024271845 | Y6: 0.00062189055 | Z6: 0.037600994 | AA6: 0.30787661
B7: FWDI | C7: United States | D7: Footwear & Accessories | E7: Dec'25 | F7: 21.4 | G7: 10.94 | H7: 11.61 | I7: 10.31 | J7: 10.59 | K7: 0 | L7: 9.75 | M7: 9.74 | N7: 8.71 | O7: 8.49 | P7: 5.14 | Q7: 5.07 | R7: 5.04 | S7: 4.74 | T7: 4.62 | U7: 3.12 | V7: 2.49 | W7: 7.95 | X7: -0.026013007 | Y7: -0.10015408 | Z7: -0.14554795 | AA7: 0.21442886
B8: AGIO | C8: United States | D8: Biotechnology | E8: Dec'25 | F8: 20.6 | G8: 0 | H8: 0.83 | I8: 5.58 | J8: 3.52 | K8: 4.31 | L8: 5.61 | M8: 6.71 | N8: 7.4 | O8: 7.1 | P8: 8.19 | Q8: 8.62 | R8: 8.96 | S8: 10.73 | T8: 8.73 | U8: 12.46 | V8: 12.88 | W8: 19.97 | X8: 0.014794521 | Y8: 0.10367171 | Z8: 0.095890411 | AA8: 0.20625
B9: KEY | C9: United States | D9: Banks - Regional | E9: Dec'25 | F9: 18.1 | G9: 1938 | H9: 1607 | I9: 1740 | J9: 1770 | K9: 1626 | L9: 1568 | M9: 1420 | N9: 1477 | O9: 1429 | P9: 1421 | Q9: 1414 | R9: 588 | S9: 816 | T9: 1646 | U9: 1693 | V9: 1779 | W9: 1889 | X9: 0.053078556 | Y9: 0.0625 | Z9: 0.25110689 | AA9: 0.18082238
B10: ELVA | C10: United States | D10: Electrical Equipment & Parts | E10: Dec'25 | F10: 16.3 | G10: 4.16 | H10: 1.25 | I10: 4.29 | J10: 4.31 | K10: 6.43 | L10: 8.56 | M10: 8.47 | N10: 10.6 | O10: 16.43 | P10: 12.09 | Q10: 10.7 | R10: 10.27 | S10: 11.56 | T10: 11.17 | U10: 15.02 | V10: 17.13 | W10: 20.51 | X10: -0.020618557 | Y10: 0.098855835 | Z10: 0.14285714 | AA10: 0.16308309
B11: ALNY | C11: United States | D11: Biotechnology | E11: Dec'25 | F11: 15.7 | G11: 258.54 | H11: 213.26 | I11: 224.82 | J11: 264.31 | K11: 335.04 | L11: 319.29 | M11: 318.75 | N11: 750.53 | O11: 439.72 | P11: 494.33 | Q11: 659.83 | R11: 500.92 | S11: 593.17 | T11: 594.19 | U11: 773.69 | V11: 1249 | W11: 1097 | X11: 0.044416769 | Y11: 0.048490062 | Z11: 0.30385423 | AA11: 0.15695394
B12: AEM | C12: United States | D12: Gold | E12: Dec'25 | F12: 12.7 | G12: 951.53 | H12: 1326 | I12: 1581 | J12: 1450 | K12: 1385 | L12: 1510 | M12: 1718 | N12: 1642 | O12: 1757 | P12: 1830 | Q12: 2077 | R12: 2156 | S12: 2224 | T12: 2468 | U12: 2816 | V12: 3060 | W12: 3564 | X12: 0.076988054 | Y12: 0.08280112 | Z12: 0.093543046 | AA12: 0.12679788
B13: 2212 | C13: Japan | D13: N/A | E13: Sep'25 | F13: 1.2 | G13: 249845 | H13: 290917 | I13: 259727 | J13: 268525 | K13: 263876 | L13: 284881 | M13: 276839 | N13: 287105 | O13: 282281 | P13: 329337 | Q13: 306658 | R13: 311089 | S13: 301846 | T13: 324895 | U13: 318735 | V13: 331898 | W13: 317467 | X13: -0.0035566445 | Y13: 0.0097043925 | Z13: 0.016560226 | AA13: 0.012228995
B14: CNR | C14: United States | D14: Thermal Coal | E14: Dec'25 | F14: 12.7 | G14: 340.19 | H14: 539.5 | I14: 611.61 | J14: 533.61 | K14: 612.15 | L14: 680.88 | M14: 657.96 | N14: 564.52 | O14: 624.46 | P14: 546.69 | Q14: 490.72 | R14: 553.43 | S14: 573.17 | T14: 1017 | U14: 1102 | V14: 1003 | W14: 1042 | X14: 0.21733264 | Y14: 0.2320447 | Z14: 0.13851676 | AA14: 0.12687644
B15: CTRE | C15: United States | D15: REIT - Healthcare Facilities | E15: Dec'25 | F15: 11.2 | G15: 49.74 | H15: 46.48 | I15: 47.55 | J15: 50.29 | K15: 51.81 | L15: 50.61 | M15: 51.55 | N15: 55.88 | O15: 59.73 | P15: 63.07 | Q15: 68.89 | R15: 77.38 | S15: 86.94 | T15: 96.62 | U15: 112.47 | V15: 132.44 | W15: 134.86 | X15: 0.11323748 | Y15: 0.13212867 | Z15: 0.14745186 | AA15: 0.1118398
B16: DKNG | C16: United States | D16: Gambling | E16: Dec'25 | F16: 10.9 | G16: 473.33 | H16: 417.21 | I16: 466.19 | J16: 501.94 | K16: 855.13 | L16: 769.65 | M16: 874.93 | N16: 789.96 | O16: 1231 | P16: 1175 | Q16: 1104 | R16: 1095 | S16: 1393 | T16: 1409 | U16: 1513 | V16: 1144 | W16: 1989 | X16: 0.049087476 | Y16: 0.081783643 | Z16: 0.0090573013 | AA16: 0.10917751
B17: 2502 | C17: Japan | D17: N/A | E17: Jun'25 | F17: -1.1 | G17: 576926 | H17: 586708 | I17: 615773 | J17: 496863 | K17: 654476 | L17: 698604 | M17: 661164 | N17: 556335 | O17: 696664 | P17: 770004 | Q17: 746087 | R17: 616614 | S17: 762352 | T17: 788986 | U17: 771470 | V17: 679776 | W17: 729128 | X17: 0.006556693 | Y17: 0.0087105904 | Z17: 0.021487898 | AA17: -0.011065136
B18: SPHR | C18: United States | D18: Entertainment | E18: Dec'25 | F18: 7.6 | G18: 0 | H18: 352.53 | I18: -318.39 | J18: 123.13 | K18: 159.54 | L18: 162.06 | M18: 0 | N18: 118.01 | O18: 314.16 | P18: 321.33 | Q18: 273.4 | R18: 227.91 | S18: 308.29 | T18: 280.57 | U18: 282.68 | V18: 262.51 | W18: 394.28 | X18: -0.036041134 | Y18: 0.0085124338 | Z18: 0.031470281 | AA18: 0.075825581
B19: AIP | C19: United States | D19: Semiconductors | E19: Dec'25 | F19: 7.1 | G19: 11.43 | H19: 11.76 | I19: 14.82 | J19: 12.6 | K19: 11.2 | L19: 13.15 | M19: 14.73 | N19: 13.27 | O19: 12.5 | P19: 12.95 | Q19: 14.58 | R19: 14.71 | S19: 15.49 | T19: 16.53 | U19: 16.5 | V19: 17.41 | W19: 20.14 | X19: 0.062012818 | Y19: 0.031316262 | Z19: 0.042701249 | AA19: 0.070529349
B20: HCC | C20: United States | D20: Coking Coal | E20: Dec'25 | F20: 7 | G20: 415.55 | H20: 378.67 | I20: 625.17 | J20: 390.18 | K20: 344.75 | L20: 509.67 | M20: 379.16 | N20: 423.49 | O20: 365 | P20: 503.51 | Q20: 396.52 | R20: 327.72 | S20: 297.47 | T20: 302.64 | U20: 296.12 | V20: 328.09 | W20: 383.19 | X20: -0.13169903 | Y20: -0.075810775 | Z20: 0.00030229993 | AA20: 0.070014375
B21: RARE | C21: United States | D21: Biotechnology | E21: Dec'25 | F21: 6.7 | G21: 83.39 | H21: 79.94 | I21: 89.34 | J21: 90.7 | K21: 103.35 | L21: 100.5 | M21: 108.31 | N21: 98.05 | O21: 127.39 | P21: 108.83 | Q21: 147.03 | R21: 139.49 | S21: 164.88 | T21: 139.29 | U21: 166.5 | V21: 159.93 | W21: 207 | X21: 0.054370526 | Y21: 0.032961452 | Z21: 0.03349941 | AA21: 0.06679353
B22: ANET | C22: United States | D22: Computer Hardware | E22: Dec'25 | F22: 6.6 | G22: 824.46 | H22: 877.07 | I22: 1052 | J22: 1177 | K22: 1276 | L22: 1351 | M22: 1459 | N22: 1509 | O22: 1540 | P22: 1571 | Q22: 1690 | R22: 1811 | S22: 1930 | T22: 2005 | U22: 2205 | V22: 2308 | W22: 2488 | X22: 0.061982291 | Y22: 0.069257665 | Z22: 0.062507861 | AA22: 0.066051136
B23: 3659 | C23: Japan | D23: N/A | E23: Sep'25 | F23: -3.8 | G23: 75890 | H23: 54250 | I23: 87578 | J23: 84122 | K23: 97463 | L23: 81095 | M23: 124087 | N23: 94436 | O23: 120256 | P23: 84577 | Q23: 108418 | R23: 122474 | S23: 135593 | T23: 79726 | U23: 113934 | V23: 118850 | W23: 118719 | X23: -0.010754619 | Y23: 0.012361865 | Z23: -0.0080225446 | AA23: -0.037656521
B24: BGC | C24: United States | D24: Capital Markets | E24: Dec'25 | F24: 6.6 | G24: 445.53 | H24: 492.16 | I24: 421.41 | J24: 402.07 | K24: 421.73 | L24: 517.13 | M24: 473.17 | N24: 461.91 | O24: 495.97 | P24: 558.48 | Q24: 529.21 | R24: 535.99 | S24: 548.07 | T24: 639.59 | U24: 750.2 | V24: 703.03 | W24: 723.33 | X24: 0.037347761 | Y24: 0.098093091 | Z24: 0.067522283 | AA24: 0.066363991
B25: 3964 | C25: Japan | D25: N/A | E25: Sep'25 | F25: 1.7 | G25: 8652 | H25: 9447 | I25: 10501 | J25: 10102 | K25: 9882 | L25: 9970 | M25: 10728 | N25: 11203 | O25: 10311 | P25: 11061 | Q25: 10988 | R25: 15583 | S25: 13872 | T25: 15467 | U25: 15978 | V25: 16554 | W25: 14949 | X25: 0.085546754 | Y25: 0.089250581 | Z25: 0.015944171 | AA25: 0.017407186
B26: BROS | C26: United States | D26: Restaurants | E26: Dec'25 | F26: 6.6 | G26: 140.08 | H26: 152.16 | I26: 186.38 | J26: 198.65 | K26: 201.83 | L26: 197.27 | M26: 249.88 | N26: 264.51 | O26: 254.12 | P26: 275.1 | Q26: 324.92 | R26: 338.21 | S26: 342.79 | T26: 355.15 | U26: 415.81 | V26: 423.58 | W26: 443.61 | X26: 0.062489266 | Y26: 0.066778344 | Z26: 0.058796386 | AA26: 0.065581235
B27: COHU | C27: United States | D27: Semiconductor Equipment & Materials | E27: Dec'25 | F27: 6.6 | G27: 191.86 | H27: 197.76 | I27: 217.23 | J27: 206.69 | K27: 191.11 | L27: 179.37 | M27: 168.92 | N27: 150.8 | O27: 137.23 | P27: 107.61 | Q27: 104.7 | R27: 95.34 | S27: 94.12 | T27: 96.8 | U27: 107.68 | V27: 126.25 | W27: 122.23 | X27: -0.026905941 | Y27: 0.0076222631 | Z27: 0.078463725 | AA27: 0.066164529
B28: 4045 | C28: Japan | D28: N/A | E28: Sep'25 | F28: -1.4 | G28: 39231 | H28: 42918 | I28: 37750 | J28: 40227 | K28: 40740 | L28: 42108 | M28: 38198 | N28: 38749 | O28: 39202 | P28: 43222 | Q28: 39014 | R28: 42557 | S28: 41792 | T28: 44231 | U28: 39822 | V28: 40522 | W28: 39519 | X28: 0.0060569679 | Y28: 0.004821175 | Z28: -0.01208418 | AA28: -0.013662565
B29: 4293 | C29: Japan | D29: N/A | E29: Sep'25 | F29: 0.6 | G29: 5473 | H29: 6572 | I29: 7885 | J29: 7109 | K29: 7252 | L29: 6973 | M29: 7566 | N29: 7097 | O29: 7470 | P29: 0 | Q29: 7291 | R29: 6697 | S29: 6898 | T29: 7397 | U29: 8206 | V29: 7001 | W29: 7081 | X29: 0.35416068 | Y29: 0.032351589 | Z29: 0.010411672 | AA29: 0.0062029693
B30: STNG | C30: United States | D30: Oil & Gas Midstream | E30: Dec'25 | F30: 5.5 | G30: 147.91 | H30: 174.05 | I30: 405.07 | J30: 490 | K30: 493.76 | L30: 384.43 | M30: 329.3 | N30: 291.18 | O30: 336.31 | P30: 391.34 | Q30: 380.66 | R30: 267.99 | S30: 203.97 | T30: 213.98 | U30: 230.23 | V30: 241.36 | W30: 252.65 | X30: -0.14257693 | Y30: -0.14103694 | Z30: -0.029066658 | AA30: 0.054724914
B31: TOST | C31: United States | D31: Software - Infrastructure | E31: Dec'25 | F31: 5 | G31: 512 | H31: 535 | I31: 675 | J31: 752 | K31: 768 | L31: 819 | M31: 978 | N31: 1032 | O31: 1036 | P31: 1075 | Q31: 1242 | R31: 1305 | S31: 1338 | T31: 1337 | U31: 1550 | V31: 1633 | W31: 1633 | X31: 0.052822581 | Y31: 0.058981233 | Z31: 0.059312839 | AA31: 0.050358484
B32: 4755 | C32: Japan | D32: N/A | E32: Sep'25 | F32: 2.6 | G32: 406903 | H32: 481183 | I32: 437127 | J32: 456471 | K32: 471110 | L32: 563170 | M32: 475635 | N32: 497165 | O32: 518439 | P32: 580076 | Q32: 513624 | R32: 537284 | S32: 566713 | T32: 661612 | U32: 562704 | V32: 596369 | W32: 628562 | X32: 0.037100656 | Y32: 0.02153356 | Z32: 0.025376743 | AA32: 0.025906447
B33: 4776 | C33: Japan | D33: N/A | E33: Sep'25 | F33: 6.4 | G33: 4637 | H33: 4879 | I33: 5184 | J33: 5379 | K33: 5630 | L33: 5874 | M33: 6059 | N33: 6229 | O33: 6448 | P33: 6696 | Q33: 6907 | R33: 7180 | S33: 7381 | T33: 8207 | U33: 8759 | V33: 9140 | W33: 9514 | X33: 0.05365005 | Y33: 0.062409436 | Z33: 0.062168935 | AA33: 0.06369636
B34: 4784 | C34: Japan | D34: N/A | E34: Sep'25 | F34: 37.3 | G34: 7747 | H34: 8770 | I34: 3986 | J34: 4400 | K34: 4240 | L34: 4003 | M34: 4269 | N34: 3876 | O34: 3461 | P34: 3297 | Q34: 3454 | R34: 3083 | S34: 3084 | T34: 3376 | U34: 19080 | V34: 19426 | W34: 19839 | X34: 0.0061154978 | Y34: 1.2022774 | Z34: 0.57097439 | AA34: 0.37261486
B35: 4812 | C35: Japan | D35: N/A | E35: Sep'25 | F35: 1.8 | G35: 25591 | H35: 32201 | I35: 29982 | J35: 31476 | K35: 32350 | L35: 35246 | M35: 34779 | N35: 35070 | O35: 35418 | P35: 37341 | Q35: 37099 | R35: 37136 | S35: 37996 | T35: 40411 | U35: 40244 | V35: 39995 | W35: 40912 | X35: 0.020525232 | Y35: 0.020603766 | Z35: 0.018351981 | AA35: 0.018380545
B36: 4912 | C36: Japan | D36: N/A | E36: Sep'25 | F36: 0.7 | G36: 94368 | H36: 98642 | I36: 87030 | J36: 98165 | K36: 100946 | L36: 103728 | M36: 90849 | N36: 102037 | O36: 103210 | P36: 106670 | Q36: 92965 | R36: 105668 | S36: 102525 | T36: 111784 | U36: 94237 | V36: 105222 | W36: 105486 | X36: 0.0125396 | Y36: 0.0030803357 | Z36: -0.0010767381 | AA36: 0.0071561841
B37: 4922 | C37: Japan | D37: N/A | E37: Sep'25 | F37: 0.1 | G37: 64163 | H37: 102050 | I37: 59013 | J37: 71591 | K37: 70283 | L37: 88249 | M37: 68158 | N37: 76137 | O37: 74666 | P37: 81445 | Q37: 77583 | R37: 81550 | S37: 79592 | T37: 84033 | U37: 78998 | V37: 81526 | W37: 79986 | X37: 0.0080832058 | Y37: 0.0043840896 | Z37: -7.4034543e-05 | AA37: 0.0012154904
B38: 4971 | C38: Japan | D38: N/A | E38: Sep'25 | F38: 4.3 | G38: 4133 | H38: 3881 | I38: 3955 | J38: 4172 | K38: 4237 | L38: 3965 | M38: 2765 | N38: 3433 | O38: 3783 | P38: 4039 | Q38: 4354 | R38: 4528 | S38: 4800 | T38: 4552 | U38: 4424 | V38: 4963 | W38: 5601 | X38: 0.028948705 | Y38: 0.0038389821 | Z38: 0.023765297 | AA38: 0.042745077
B39: ECX | C39: United States | D39: Auto Parts | E39: Dec'25 | F39: 4.8 | G39: 133.35 | H39: 103.46 | I39: 98.23 | J39: 101.18 | K39: 221.57 | L39: 111.38 | M39: 133.96 | N39: 149.19 | O39: 264.35 | P39: 129.88 | Q39: 174.45 | R39: 198.2 | S39: 265.88 | T39: 168.46 | U39: 152.66 | V39: 219.9 | W39: 304.7 | X39: 0.050207571 | Y39: -0.027001574 | Z39: 0.027636271 | AA39: 0.048110051
B40: CNCK | C40: United States | D40: Capital Markets | E40: Sep'26 | F40: 4.5 | G40: 335265 | H40: 335265 | I40: 59294 | J40: 59294 | K40: 29169 | L40: 29169 | M40: 26114 | N40: 37419 | O40: 59116 | P40: 101400 | Q40: 75300 | R40: 70348 | S40: 123104 | T40: 114579 | U40: 83989 | V40: 133105 | W40: 143455 | X40: 0.035604292 | Y40: 0.022667094 | Z40: 0.16008622 | AA40: 0.044749405
B41: 5301 | C41: Japan | D41: N/A | E41: Sep'25 | F41: -2.5 | G41: 67715 | H41: 73779 | I41: 69512 | J41: 87558 | K41: 89262 | L41: 94039 | M41: 86530 | N41: 91898 | O41: 89247 | P41: 96271 | Q41: 82161 | R41: 88761 | S41: 87737 | T41: 91455 | U41: 80346 | V41: 77730 | W41: 79260 | X41: -0.013568873 | Y41: -0.0051840258 | Z41: -0.031671064 | AA41: -0.025134315
...

Sheet Operating Income
B2: Ticker | C2: Country | D2: Industry | E2: Latest_Date | F2: Growth_Rate | G2: 4Q21 | H2: 1Q22 | I2: 2Q22 | J2: 3Q22 | K2: 4Q22 | L2: 1Q23 | M2: 2Q23 | N2: 3Q23 | O2: 4Q23 | P2: 1Q24 | Q2: 2Q24 | R2: 3Q24 | S2: 4Q24 | T2: 1Q25 | U2: 2Q25 | V2: 3Q25 | W2: 4Q25 | X2: 1Q25 | Y2: 2Q25 | Z2: 3Q25 | AA2: 4Q25
B3: WYFI | C3: United States | D3: Software - Application | E3: Sep'25 | F3: 143.4 | Q3: 0.93 | R3: 2.41 | S3: -0.85 | T3: -1.55 | U3: 2.04 | V3: -9.16 | W3: -14.5 | Y3: 1.1808511 | Z3: -5.6439024 | AA3: 1.4338235
B4: HCC | C4: United States | D4: Coking Coal | E4: Dec'25 | F4: 520.5 | G4: 191.74 | H4: 193.54 | I4: 378.82 | J4: 131.54 | K4: 120.98 | L4: 213.88 | M4: 93.98 | N4: 108.1 | O4: 133.75 | P4: 149.08 | Q4: 70.9 | R4: 39.12 | S4: -3.69 | T4: -17.38 | U4: 7.72 | V4: 20.72 | W4: 34.67 | X4: -0.65173642 | Y4: -0.71028668 | Z4: -0.71400854 | AA4: 5.2048847
B5: ALNY | C5: United States | D5: Biotechnology | E5: Dec'25 | F5: 89.5 | G5: -194.56 | H5: -146.73 | I5: -191.69 | J5: -258.04 | K5: -188.61 | L5: -149.81 | M5: -229.83 | N5: 213.87 | O5: -116.4 | P5: -43.44 | Q5: 48.61 | R5: -76.91 | S5: -105.16 | T5: 18.08 | U5: -16.2 | V5: 367.98 | W5: 131.72 | X5: -0.3477671 | Y5: 0.56170914 | Z5: -2.4690049 | AA5: 0.89489989
B6: KEY | C6: United States | D6: Banks - Regional | E6: Dec'25 | F6: 85.4 | G6: 768 | H6: 537 | I6: 662 | J6: 664 | K6: 470 | L6: 392 | M6: 344 | N6: 367 | O6: 57 | P6: 278 | Q6: 335 | R6: -506 | S6: -413 | T6: 515 | U6: 539 | V6: 602 | W6: 648 | X6: -0.7745098 | Y6: -2.9565217 | Z6: 8.2074074 | AA6: 0.85358005
B7: HR | C7: United States | D7: REIT - Healthcare Facilities | E7: Dec'25 | F7: 58.9 | G7: 20.75 | H7: 18.71 | I7: 20.39 | J7: 18.42 | K7: 21.36 | L7: 10.4 | M7: 13.41 | N7: 13.01 | O7: 13.69 | P7: 12 | Q7: 10.55 | R7: 11.33 | S7: -0.54 | T7: 18.51 | U7: 15.91 | V7: 24.86 | W7: 34.08 | X7: 0.19526095 | Y7: 0.13450439 | Z7: 0.29927007 | AA7: 0.58937692
B8: NN | C8: United States | D8: Software - Infrastructure | E8: Sep'25 | F8: 6.1 | G8: -7.03 | H8: -14.16 | I8: -16.05 | J8: -17.02 | K8: -17.94 | L8: -13.64 | M8: -13.95 | N8: -15.03 | O8: -14.62 | P8: -19.93 | Q8: -16.15 | R8: -15.33 | S8: -13.85 | T8: -14.77 | U8: -17 | V8: -17.24 | W8: -17.67 | X8: -0.079068342 | Y8: 0.014143095 | Z8: 0.031337162 | AA8: 0.060769965
B9: ELVA | C9: United States | D9: Electrical Equipment & Parts | E9: Dec'25 | F9: 42.8 | G9: -1.36 | H9: -1.57 | I9: -1.36 | J9: -1.09 | K9: -3.24 | L9: -0.8 | M9: -0.68 | N9: 0.9 | O9: 1.8 | P9: -0.1 | Q9: 0.7 | R9: -0.58 | S9: 0.71 | T9: -0.19 | U9: 1.4 | V9: 1.96 | W9: 2.37 | X9: -0.12328767 | Y9: 1.09375 | Z9: 1.8955224 | AA9: 0.42783505
B10: TWLO | C10: United States | D10: Software - Infrastructure | E10: Dec'25 | F10: 42 | G10: -276.18 | H10: -217.15 | I10: -310.1 | J10: -286.7 | K10: -211.76 | L10: -118.12 | M10: -114.5 | N10: -102.12 | O10: -50.01 | P10: -43.5 | Q10: -19.04 | R10: -4.89 | S10: 13.67 | T10: 23.08 | U10: 36.99 | V10: 40.95 | W10: 61.83 | X10: -1.2384673 | Y10: 4.3705148 | Z10: 0.66579521 | AA10: 0.41991455
B11: DRUG | C11: United States | D11: Biotechnology | E11: Mar'26 | F11: 38 | G11: -4.72 | H11: -4.38 | I11: -2.65 | J11: -2.97 | K11: -2.26 | L11: -1.96 | M11: -1.43 | N11: -1.55 | O11: -1.62 | P11: -0.47 | Q11: 0.25 | R11: -0.77 | S11: -1.58 | T11: -3.24 | U11: -3.03 | V11: -5.76 | W11: -6.75 | X11: 1.077821 | Y11: 0.61423221 | Z11: 0.57888631 | AA11: 0.37986774
B12: PINS | C12: United States | D12: Internet Content & Information | E12: Dec'25 | F12: 30.2 | G12: 179.45 | H12: -3.67 | I12: -34.51 | J12: -69.38 | K12: 15.27 | L12: -243.69 | M12: -73.24 | N12: -5 | O12: 196.25 | P12: -54.42 | Q12: -21.44 | R12: 28.73 | S12: 226.94 | T12: -35.48 | U12: -4.33 | V12: 58.52 | W12: 301.17 | X12: 0.10533341 | Y12: 0.08608805 | Z12: 0.13800612 | AA12: 0.3021779
B13: AEM | C13: United States | D13: Gold | E13: Dec'25 | F13: 24.8 | G13: 263.1 | H13: 406.78 | I13: 523.08 | J13: 225.88 | K13: 472.8 | L13: 445.88 | M13: 526.74 | N13: 315.01 | O13: 164.03 | P13: 532.71 | Q13: 792.35 | R13: 876.22 | S13: 804.98 | T13: 1236 | U13: 1650 | V13: 1625 | W13: 2123 | X13: 0.23394184 | Y13: 0.23120055 | Z13: 0.16394728 | AA13: 0.24793547
B14: TRUP | C14: United States | D14: Insurance - Property & Casualty | E14: Dec'25 | F14: 20.7 | G14: -5.74 | H14: -9.05 | I14: -12.73 | J14: -11.66 | K14: -8.94 | L14: -20.31 | M14: -12.95 | N14: -3.49 | O14: 0.49 | P14: -6.03 | Q14: -5.42 | R14: 1.78 | S14: 5.65 | T14: -1.17 | U14: 2.31 | V14: 5.86 | W14: 8.27 | X14: -1.2089552 | Y14: 9.202381 | Z14: 0.47607935 | AA14: 0.20711462
B15: TOST | C15: United States | D15: Software - Infrastructure | E15: Dec'25 | F15: 20.6 | G15: -111 | H15: -101 | I15: -99 | J15: -85 | K15: -99 | L15: -92 | M15: -80 | N15: -59 | O15: -42 | P15: -15 | Q15: 9 | R15: 34 | S15: 37 | T15: 50 | U15: 81 | V15: 84 | W15: 89 | X15: 1 | Y15: 0.55384615 | Z15: 0.24752475 | AA15: 0.20634921
... B68: BN | C68: United States | D68: Asset Management | E68: Dec'25 | F68: 0.7 | G68: 4020 | H68: 3997 | I68: 3953 | J68: 4553 | K68: 4246 | L68: 3892 | M68: 4140 | N68: 4146 | O68: 4336 | P68: 4530 | Q68: 4704 | R68: 5443 | S68: 6046 | T68: 4995 | U68: 4615 | V68: 4810 | W68: 6186 | X68: 0.022438836 | Y68: -0.0042004908 | Z68: -0.030001422 | AA68: 0.0068406137
B69: PHIN | C69: United States | D69: Auto Parts | E69: Dec'25 | F69: 0.6 | H69: 82 | I69: 77 | J69: 127 | K69: 101 | L69: 80 | M69: 100 | N69: 75 | O69: 79 | P69: 90 | Q69: 76 | R69: 80 | S69: 72 | T69: 79 | U69: 97 | V69: 92 | W69: 74 | X69: -0.034591195 | Y69: 0.068403909 | Z69: 0.036585366 | AA69: 0.0058823529
B70: BLX | C70: United States | D70: Banks - Regional | E70: Sep'25 | F70: 0.9 | G70: 15.73 | H70: 20.07 | I70: 11.12 | J70: 23.02 | K70: 26.87 | L70: 31.03 | M70: 36.95 | N70: 37.07 | O70: 45.75 | P70: 46.39 | Q70: 51.27 | R70: 50.12 | S70: 52.99 | T70: 51.49 | U70: 51.73 | V70: 64.18 | W70: 54.97 | X70: 0.025402202 | Y70: 0.0022344198 | Z70: 0.068143266 | AA70: 0.0089840737
B71: BIO | C71: United States | D71: Medical Devices | E71: Sep'25 | F71: 0.8 | G71: 155.8 | H71: 185.19 | I71: 146.41 | J71: 122.79 | K71: 94.55 | L71: 123.07 | M71: 61.91 | N71: 89.92 | O71: 91.15 | P71: 94.92 | Q71: 51.7 | R71: 100.5 | S71: 66 | T71: 57.93 | U71: 56.9 | V71: 79.6 | W71: 68 | X71: -0.11813362 | Y71: 0.01883171 | Z71: -0.07428998 | AA71: 0.0076796068
B72: IR | C72: United States | D72: Specialty Industrial Machinery | E72: Dec'25 | F72: 0.5 | G72: 159.3 | H72: 175.8 | I72: 211.6 | J72: 203.6 | K72: 288.4 | L72: 263.3 | M72: 293.6 | N72: 331.4 | O72: 361.6 | P72: 317.9 | Q72: 360.8 | R72: 385.2 | S72: 390.8 | T72: 326.2 | U72: 365.3 | V72: 400.3 | W72: 397.8 | X72: 0.0057056438 | Y72: 0.0030758715 | Z72: 0.010289608 | AA72: 0.0047214353
B73: BDC | C73: United States | D73: Communication Equipment | E73: Dec'25 | F73: 0.4 | G73: 85.84 | H73: 77.7 | I73: 84.17 | J73: 96.42 | K73: 81.78 | L73: 86.03 | M73: 93.24 | N73: 83.7 | O73: 63.01 | P73: 53.25 | Q73: 69.14 | R73: 75.64 | S73: 85.04 | T73: 72.19 | U73: 78.87 | V73: 75.89 | W73: 86.35 | X73: 0.066909245 | Y73: 0.032217476 | Z73: 0.00080195034 | AA73: 0.0041988525
B74: PSA | C74: United States | D74: REIT - Industrial | E74: Dec'25 | F74: 0.3 | G74: 481.93 | H74: 487.06 | I74: 552.33 | J74: 569 | K74: 597.18 | L74: 567.85 | M74: 604.41 | N74: 597.56 | O74: 562.39 | P74: 528.57 | Q74: 565.82 | R74: 559.87 | S74: 551.23 | T74: 543.47 | U74: 570.39 | V74: 576.38 | W74: 557.23 | X74: 0.0067558683 | Y74: 0.002058197 | Z74: 0.0074203581 | AA74: 0.0026768148
B75: LECO | C75: United States | D75: Tools & Accessories | E75: Dec'25 | F75: 0.1 | G75: 118.35 | H75: 161.31 | I75: 169.56 | J75: 156.53 | K75: 134.68 | L75: 162.41 | M75: 179.15 | N75: 190.07 | O75: 171.19 | P75: 173.03 | Q75: 182.78 | R75: 166.65 | S75: 189.83 | T75: 161.11 | U75: 181.49 | V75: 184.45 | W75: 190.3 | X75: -0.016734757 | Y75: -0.0018418836 | Z75: 0.025462036 | AA75: 0.00065561879
B76: FTS | C76: United States | D76: Utilities - Regulated Electric | E76: Dec'25 | F76: 0 | G76: 654 | H76: 700 | I76: 639 | J76: 716 | K76: 777 | L76: 846 | M76: 670 | N76: 836 | O76: 794 | P76: 894 | Q76: 756 | R76: 833 | S76: 809 | T76: 972 | U76: 820 | V76: 890 | W76: 810 | X76: 0.023693803 | Y76: 0.018991098 | Z76: 0.016598719 | AA76: 0.00028645087
B77: FLO | C77: United States | D77: Packaged Foods | E77: Dec'25 | F77: -0.1 | G77: 59.53 | H77: 122.27 | I77: 87.25 | J77: 87.69 | K77: 69.73 | L77: 107.49 | M77: 98.19 | N77: 85.27 | O77: 59.35 | P77: 111.33 | Q77: 106.75 | R77: 96.1 | S77: 65.41 | T77: 112.86 | U77: 97.94 | V77: 78.33 | W77: 64.99 | X77: 0.0040306647 | Y77: -0.023116079 | Z77: -0.047729043 | AA77: -0.0011846336
B78: ETR | C78: United States | D78: Utilities - Regulated Electric | E78: Sep'25 | F78: 0.1 | G78: 828.85 | H78: 276.17 | I78: 568.05 | J78: -79.61 | K78: 924 | L78: 503.22 | M78: 469.31 | N78: 763.46 | O78: 1191 | P78: 272.88 | Q78: 386.43 | R78: 635.52 | S78: 1141 | T78: 659.92 | U78: 708.63 | V78: 849.83 | W78: 1146 | X78: 0.1588945 | Y78: 0.11413916 | Z78: 0.068141568 | AA78: 0.0014883699
B79: TOP | C79: United States | D79: Capital Markets | E79: H1 2026 | F79: -0.11490126 | G79: 0.91 | I79: 2.67 | K79: 1.84 | M79: 1.59 | O79: 3.59 | Q79: -2.6 | S79: -0.45 | U79: -5.12 | W79: 0.19 | X79: -0.80888031 | Y79: -4.0808081 | Z79: 0.82622951 | AA79: -0.11490126
B80: GTES | C80: United States | D80: Specialty Industrial Machinery | E80: Dec'25 | F80: -0.5 | G80: 77.4 | H80: 71.6 | I80: 119 | J80: 111.3 | K80: 88 | L80: 105.5 | M80: 133.7 | N80: 130.6 | O80: 122.6 | P80: 119.2 | Q80: 136.7 | R80: 121.3 | S80: 118.3 | T80: 129.6 | U80: 132.8 | V80: 127.8 | W80: 115.8 | X80: 0.0209889 | Y80: -0.0077090334 | Z80: 0.012948207 | AA80: -0.0049164208
B81: AGIO | C81: United States | D81: Biotechnology | E81: Dec'25 | F81: -0.7 | G81: -104.83 | H81: -101.15 | I81: -97.64 | J81: -91.09 | K81: -99.17 | L81: -90.61 | M81: -93.7 | N81: -100.9 | O81: -106.28 | P81: -92.07 | Q81: -105.82 | R81: -102.81 | S81: -125.04 | T81: -106.63 | U81: -127.06 | V81: -116.87 | W81: -121.58 | X81: 0.034199277 | Y81: 0.048239836 | Z81: 0.030463232 | AA81: -0.007275021
B82: ZBRA | C82: United States | D82: Communication Equipment | E82: Dec'25 | F82: -0.7 | G82: 244 | H82: 216 | I82: 243 | J82: 205 | K82: 272 | L82: 235 | M82: 210 | N82: 48 | O82: 92 | P82: 170 | Q82: 171 | R82: 196 | S82: 228 | T82: 198 | U82: 187 | V82: 193 | W82: 222 | X82: 0.036601307 | Y82: 0.020176545 | Z82: -0.0037082818 | AA82: -0.0074441687
B83: AMAT | C83: United States | D83: Semiconductor Equipment & Materials | E83: Mar'26 | F83: -0.9 | G83: 1972 | H83: 1894 | I83: 1924 | J83: 1994 | K83: 1970 | L83: 1911 | M83: 1802 | N83: 1971 | O83: 1967 | P83: 1912 | Q83: 1942 | R83: 2046 | S83: 2175 | T83: 2169 | U83: 2233 | V83: 1934 | W83: 2096 | X83: 0.031826625 | Y83: 0.034925588 | Z83: -0.012988519 | AA83: -0.0092821055
B84: RARE | C84: United States | D84: Biotechnology | E84: Dec'25 | F84: -1.5 | G84: -102.56 | H84: -136.63 | I84: -141.59 | J84: -225.07 | K84: -145.63 | L84: -154.11 | M84: -147.96 | N84: -145.1 | O84: -122.05 | P84: -165.35 | Q84: -116.36 | R84: -131.99 | S84: -122.28 | T84: -142.94 | U84: -107.89 | V84: -170.89 | W84: -114 | X84: -0.041811262 | Y84: -0.016492396 | Z84: 0.077014453 | AA84: -0.015220588
B85: TRN | C85: United States | D85: Railroads | E85: Dec'25 | F85: -1.8 | G85: 53.4 | H85: 29.3 | I85: 46.1 | J85: 53.1 | K85: 53.1 | L85: 53.3 | M85: 66.9 | N85: 92.7 | O85: 111.6 | P85: 112.4 | Q85: 117.7 | R85: 109 | S85: 92.7 | T85: 92.2 | U85: 84 | V85: 96.2 | W85: 86 | X85: -0.046780917 | Y85: -0.081875607 | Z85: -0.033871395 | AA85: -0.018351137
B86: VNT | C86: United States | D86: Scientific & Technical Instruments | E86: Dec'25 | F86: -1.8 | G86: 174 | H86: 134.8 | I86: 136.5 | J86: 150.2 | K86: 167.9 | L86: 133.8 | M86: 120.6 | N86: 142.6 | O86: 171.6 | P86: 146.8 | Q86: 114.1 | R86: 131.5 | S86: 162.8 | T86: 134.4 | U86: 136.4 | V86: 142.4 | W86: 152.7 | X86: -0.022334294 | Y86: 0.041083272 | Z86: 0.019288621 | AA86: -0.017534722
B87: DBD | C87: United States | D87: Software - Application | E87: Dec'25 | F87: -2.3 | G87: 68.2 | H87: -29 | I87: -7.2 | J87: 26.7 | K87: 28.8 | L87: 14.4 | M87: 15.8 | N87: 50 | O87: 69.8 | P87: 60.5 | Q87: 81.3 | R87: 80.3 | S87: 89.1 | T87: 49.6 | U87: 72.5 | V87: 86.4 | W87: 82.4 | X87: -0.035025707 | Y87: -0.029304029 | Z87: 0.020926244 | AA87: -0.022513441
B88: RYAN | C88: United States | D88: Insurance - Specialty | E88: Dec'25 | F88: -2.3 | G88: 68.47 | H88: 53.5 | I88: 115.53 | J88: 65.46 | K88: 74.54 | L88: 68.04 | M88: 135.25 | N88: 81.43 | O88: 97.04 | P88: 103.48 | Q88: 177.45 | R88: 107.49 | S88: 120.19 | T88: 104.27 | U88: 200.48 | V88: 134.54 | W88: 107.52 | X88: 0.001553253 | Y88: 0.045210051 | Z88: 0.050804801 | AA88: -0.022646028
B89: CALY | C89: United States | D89: Leisure | E89: Sep'25 | F89: -1.9 | G89: 76 | H89: -67.1 | I89: 94.3 | J89: 129 | K89: 68.2 | L89: -29.2 | M89: 80.5 | N89: 116 | O89: 73.8 | P89: -18.6 | Q89: 66.9 | R89: 109.3 | S89: 33.7 | T89: -8.4 | U89: 81.2 | V89: 116.4 | W89: 29.5 | X89: 0.053319394 | Y89: 0.070967742 | Z89: 0.032900834 | AA89: -0.01884253
B90: CHKP | C90: United States | D90: Software - Infrastructure | E90: Dec'25 | F90: -2.5 | G90: 245.9 | H90: 200.2 | I90: 208.8 | J90: 221.3 | K90: 254 | L90: 199.8 | M90: 221.4 | N90: 226.1 | O90: 251.8 | P90: 193.9 | Q90: 209.3 | R90: 218.5 | S90: 254.3 | T90: 195.5 | U90: 203.6 | V90: 199.1 | W90: 232.9 | X90: 0.001826484 | Y90: -0.0064949863 | Z90: -0.022250258 | AA90: -0.025102639
B91: BNT | C91: United States | D91: Insurance - Diversified | E91: Dec'25 | F91: -2.9 | G91: -41 | H91: 154 | I91: -15 | J91: 164 | K91: 206 | L91: 31 | M91: 389 | N91: 185 | O91: 251 | P91: 421 | Q91: 348 | R91: 480 | S91: 326 | T91: 265 | U91: 774 | V91: 994 | W91: 257 | X91: -0.099047619 | Y91: 0.30021142 | Z91: 0.27859079 | AA91: -0.029249682
... B93: YELP | C93: United States | D93: Internet Content & Information | E93: Dec'25 | F93: -3 | G93: 19.59 | H93: -4.46 | I93: 16 | J93: 23.89 | K93: 33.38 | L93: -3.03 | M93: 29.74 | N93: 41.87 | O93: 45.02 | P93: 11.22 | Q93: 39.75 | R93: 52.57 | S93: 54.7 | T93: 30 | U93: 53.35 | V93: 52.66 | W93: 48.89 | X93: 0.11868049 | Y93: 0.076827477 | Z93: 0.00047214353 | AA93: -0.030465104
B94: FMCC | C94: United States | D94: Mortgage Finance | E94: FY 2025 | F94: -3.4 | S94: 15199 | T94: 11604 | U94: 13199 | V94: 14778 | W94: 13361 | AA94: -0.033552391
...

Sheet 빨간줄
B2: (단위: mil $)
Y3: HCC | Z3: 5711 | AA3: Mitsubishi Materials Corporation
B4: 8136 | C4: 6 | D4: 7 | E4: 8 | F4: 9 | G4: 10 | H4: 11 | I4: 12 | J4: 13 | K4: 14 | L4: 15 | M4: 16 | N4: 17 | O4: 18 | P4: 19 | Q4: 20 | R4: 21 | S4: 22 | Y4: ALNY | Z4: 7222 | AA4: Nissan Shatai Co., Ltd.
Y5: KEY | Z5: 1762 | AA5: Takamatsu Construction Group Co., Ltd.
C6: 4Q21 | D6: 1Q22 | E6: 2Q22 | F6: 3Q22 | G6: 4Q22 | H6: 1Q23 | I6: 2Q23 | J6: 3Q23 | K6: 4Q23 | L6: 1Q24 | M6: 2Q24 | N6: 3Q24 | O6: 4Q24 | P6: 1Q25 | Q6: 2Q25 | R6: 3Q25 | S6: 4Q25 | T6: 1Q26 | U6: 2Q26 | V6: 3Q26 | W6: 4Q26 | Y6: HR | Z6: 9409 | AA6: TV Asahi Holdings Corporation
B7: Revenue | C7: =VLOOKUP($B$4,Revenue!$B:$W,C4,FALSE) -> 12991 | D7: =VLOOKUP($B$4,Revenue!$B:$W,D4,FALSE) -> 14769 | E7: =VLOOKUP($B$4,Revenue!$B:$W,E4,FALSE) -> 14201 | F7: =VLOOKUP($B$4,Revenue!$B:$W,F4,FALSE) -> 13829 | G7: =VLOOKUP($B$4,Revenue!$B:$W,G4,FALSE) -> 16801 | H7: =VLOOKUP($B$4,Revenue!$B:$W,H4,FALSE) -> 20995 | I7: =VLOOKUP($B$4,Revenue!$B:$W,I4,FALSE) -> 20999 | J7: =VLOOKUP($B$4,Revenue!$B:$W,J4,FALSE) -> 20315 | ... S7: =VLOOKUP($B$4,Revenue!$B:$W,S4,FALSE) -> 44579 | Y7: ELVA | Z7: 5831 | AA7: Shizuoka Financial Group,Inc.
B8: OP | C8: =VLOOKUP($B$4,'Operating Income'!$B:$W,C4,FALSE) -> 347 | D8: =VLOOKUP($B$4,'Operating Income'!$B:$W,D4,FALSE) -> 1747 | E8: =VLOOKUP($B$4,'Operating Income'!$B:$W,E4,FALSE) -> 502 | F8: =VLOOKUP($B$4,'Operating Income'!$B:$W,F4,FALSE) -> 2384 | G8: =VLOOKUP($B$4,'Operating Income'!$B:$W,G4,FALSE) -> 2963 | H8: =VLOOKUP($B$4,'Operating Income'!$B:$W,H4,FALSE) -> 5256 | I8: =VLOOKUP($B$4,'Operating Income'!$B:$W,I4,FALSE) -> 2645 | J8: =VLOOKUP($B$4,'Operating Income'!$B:$W,J4,FALSE) -> 5965 | ... S8: =VLOOKUP($B$4,'Operating Income'!$B:$W,S4,FALSE) -> 18985 | Y8: TWLO | Z8: 3465 | AA8: Ki-Star Real Estate Co.,Ltd
B9: Trailing 4Q OP avg. | C9: =AVERAGE(C8:C8) -> 347 | D9: =AVERAGE(C8:D8) -> 1047 | E9: =AVERAGE(C8:E8) -> 865.33333 | F9: =AVERAGE(C8:F8) -> 1245 | G9: =AVERAGE(D8:G8) -> 1899 | H9: =AVERAGE(E8:H8) -> 2776.25 | I9: =AVERAGE(F8:I8) -> 3312 | J9: =AVERAGE(G8:J8) -> 4207.25 | K9: =AVERAGE(H8:K8) -> 5302.25 | L9: =AVERAGE(I8:L8) -> 6009 | M9: =AVERAGE(J8:M8) -> 6738.5 | ... S9: =AVERAGE(P8:S8) -> 16849.5 | Y9: DRUG | Z9: 2264 | AA9: Morinaga Milk Industry Co., Ltd.
B10: Trailing 4Q OP sum. | C10: =SUM(C8:C8) -> 347 | D10: =SUM(C8:D8) -> 2094 | E10: =SUM(C8:E8) -> 2596 | F10: =SUM(C8:F8) -> 4980 | G10: =SUM(D8:G8) -> 7596 | H10: =SUM(E8:H8) -> 11105 | I10: =SUM(F8:I8) -> 13248 | J10: =SUM(G8:J8) -> 16829 | K10: =SUM(H8:K8) -> 21209 | L10: =SUM(I8:L8) -> 24036 | M10: =SUM(J8:M8) -> 26954 | ... S10: =SUM(P8:S8) -> 67398 | Y10: PINS | Z10: 8795 | AA10: T&D Holdings, Inc.
B11: Trailing OP Delta | D11: =D9/C9-1 -> 2.0172911 | E11: =E9/D9-1 -> -0.17351162 | F11: =F9/E9-1 -> 0.43875193 | G11: =G9/F9-1 -> 0.5253012 | H11: =H9/G9-1 -> 0.46195366 | I11: =I9/H9-1 -> 0.19297614 | J11: =J9/I9-1 -> 0.27030495 | K11: =K9/J9-1 -> 0.26026502 | ... S11: =S9/R9-1 -> 0.10023181 | Y11: AEM | Z11: 8136 | AA11: Sanrio Company, Ltd.
B12: opm | C12: =IFERROR(C8/C7,"-") -> 0.0267108 | D12: =IFERROR(D8/D7,"-") -> 0.11828831 | E12: =IFERROR(E8/E7,"-") -> 0.035349623 | F12: =IFERROR(F8/F7,"-") -> 0.17239135 | G12: =IFERROR(G8/G7,"-") -> 0.17635855 | H12: =IFERROR(H8/H7,"-") -> 0.25034532 | I12: =IFERROR(I8/I7,"-") -> 0.12595838 | J12: =IFERROR(J8/J7,"-") -> 0.2936254 | ... S12: =IFERROR(S8/S7,"-") -> 0.42587317 | Y12: TRUP
B13: op yoy | C13: =C8/#REF!-1 -> #REF! | D13: =D8/#REF!-1 -> #REF! | E13: =E8/#REF!-1 -> #REF! | F13: =F8/#REF!-1 -> #REF! | G13: =G8/C8-1 -> 7.5389049 | H13: =H8/D8-1 -> 2.0085861 | I13: =I8/E8-1 -> 4.2689243 | J13: =J8/F8-1 -> 1.5020973 | K13: =K8/G8-1 -> 1.4782315 | L13: =L8/H8-1 -> 0.53786149 | M13: =M8/I8-1 -> 1.1032136 | N13: =N8/J8-1 -> 0.80167645 | ... S13: =S8/O8-1 -> 0.47800701 | Y13: TOST
B14: rv yoy | G14: =G7/C7-1 -> 0.29327996 | H14: =H7/D7-1 -> 0.42155867 | I14: =I7/E7-1 -> 0.47869868 | J14: =J7/F7-1 -> 0.46901439 | K14: =K7/G7-1 -> 0.4055711 | L14: =L7/H7-1 -> 0.35722791 | M14: =M7/I7-1 -> 0.31225296 | N14: =N7/J7-1 -> 0.42313561 | ... S14: =S7/O7-1 -> 0.31516993 | Y14: DXCM
Y15: STNG
Y16: NBIS
Y17: FWDI
Y18: AORT
Y19: CTRE
Y20: HASI
