Workbook

Sheet 기업리스트
B2: 실적 기업 정보
B3: Ticker | C3: Company | D3: Date | E3: Time | F3: Quarter Ending | G3: Market Cap (mil$)
B4: PLTR | C4: Palantir Technologies Inc. | D4: Feb 2, 2026 | E4: After Hours | F4: Dec/2025 | G4: 349387.93
B5: DIS | C5: The Walt Disney Company | D5: Feb 2, 2026 | F5: Dec/2025 | G5: 201380.58
B6: ISP | C6: Intesa Sanpaolo S.p.A. | D6: Feb 2, 2026 | F6: Dec/2025 | G6: 123582.78
B7: 8411 | C7: Mizuho Financial Group, Inc. | D7: Feb 2, 2026 | F7: Dec/2025 | G7: 108869.48
B8: ITUB4 | C8: Itaú Unibanco Holding S.A. | D8: Feb 2, 2026 | F8: Dec/2025 | G8: 91584.13
B9: SPG | C9: Simon Property Group, Inc. | D9: Feb 2, 2026 | E9: After Hours | F9: Dec/2025 | G9: 62220.11
B10: NXPI | C10: NXP Semiconductors N.V. | D10: Feb 2, 2026 | E10: After Hours | F10: Dec/2025 | G10: 56913.66
B11: IDXX | C11: IDEXX Laboratories, Inc. | D11: Feb 2, 2026 | E11: Pre Market | F11: Dec/2025 | G11: 53537.12
B12: 6981 | C12: Murata Manufacturing Co., Ltd. | D12: Feb 2, 2026 | F12: Dec/2025 | G12: 39312.39
B13: TER | C13: Teradyne, Inc. | D13: Feb 2, 2026 | E13: After Hours | F13: Dec/2025 | G13: 35729.4
B14: 9020 | C14: East Japan Railway Company | D14: Feb 2, 2026 | F14: Dec/2025 | G14: 28273.48
B15: 9022 | C15: Central Japan Railway Company | D15: Feb 2, 2026 | F15: Dec/2025 | G15: 25620.45
B16: 6762 | C16: TDK Corporation | D16: Feb 2, 2026 | F16: Dec/2025 | G16: 25069.09
B17: 1010 | C17: Riyad Bank | D17: Feb 2, 2026 | F17: Dec/2025 | G17: 21317.66
B18: 6971 | C18: Kyocera Corporation | D18: Feb 2, 2026 | F18: Dec/2025 | G18: 18668.24
B19: TSN | C19: Tyson Foods, Inc. | D19: Feb 2, 2026 | E19: Pre Market | F19: Dec/2025 | G19: 18514.24
B20: 1150 | C20: Alinma Bank | D20: Feb 2, 2026 | F20: Dec/2025 | G20: 17890.95
B21: 1060 | C21: Saudi Awwal Bank | D21: Feb 2, 2026 | F21: Dec/2025 | G21: 17805.85
B22: APTV | C22: Aptiv PLC | D22: Feb 2, 2026 | E22: Pre Market | F22: Dec/2025 | G22: 16986
B23: WWD | C23: Woodward, Inc. | D23: Feb 2, 2026 | E23: After Hours | F23: Dec/2025 | G23: 15454.49
B24: BAER | C24: Julius Bär Gruppe AG | D24: Feb 2, 2026 | F24: Dec/2025 | G24: 14222.32
B25: DOC | C25: Healthpeak Properties, Inc. | D25: Feb 2, 2026 | E25: After Hours | F25: Dec/2025 | G25: 13460.67
B26: A000810 | C26: Samsung Fire & Marine Insurance Co., Ltd. | D26: Feb 2, 2026 | F26: Dec/2025 | G26: 13406.95
B27: FN | C27: Fabrinet | D27: Feb 2, 2026 | E27: After Hours | F27: Dec/2025 | G27: 13077.03
B28: 1140 | C28: Bank Albilad | D28: Feb 2, 2026 | F28: Dec/2025 | G28: 11582.46
B29: 9532 | C29: Osaka Gas Co., Ltd. | D29: Feb 2, 2026 | F29: Dec/2025 | G29: 11248.27
B30: 8601 | C30: Daiwa Securities Group Inc. | D30: Feb 2, 2026 | F30: Dec/2025 | G30: 11033.39
B31: RVTY | C31: Revvity, Inc. | D31: Feb 2, 2026 | E31: Pre Market | F31: Dec/2025 | G31: 10916.63
B32: RMBS | C32: Rambus Inc. | D32: Feb 2, 2026 | F32: Dec/2025 | G32: 10758.31
B33: INDUSTOWER | C33: Indus Towers Limited | D33: Feb 2, 2026 | F33: Dec/2025 | G33: 10489.07
B34: 9502 | C34: Chubu Electric Power Company, Incorporated | D34: Feb 2, 2026 | F34: Dec/2025 | G34: 10469.58
B35: 3008 | C35: LARGAN Precision Co.,Ltd | D35: Feb 2, 2026 | F35: Dec/2025 | G35: 10468.01
B36: DVA | C36: DaVita Inc. | D36: Feb 2, 2026 | E36: After Hours | F36: Dec/2025 | G36: 9377.94
B37: POLICYBZR | C37: PB Fintech Limited | D37: Feb 2, 2026 | F37: Dec/2025 | G37: 8797.68
B38: CHMF | C38: Public Joint Stock Company Severstal | D38: Feb 2, 2026 | F38: Dec/2025 | G38: 8355.87
B39: 4768 | C39: Otsuka Corporation | D39: Feb 2, 2026 | F39: Dec/2025 | G39: 7822.9
B40: GICRE | C40: General Insurance Corporation of India | D40: Feb 2, 2026 | F40: Dec/2025 | G40: 7374.71
B41: AKBNK | C41: Akbank T.A.S. | D41: Feb 2, 2026 | F41: Dec/2025 | G41: 7252.37
...

Sheet Revenue
B2: Ticker | C2: Country | D2: Industry | E2: Latest_Date | F2: Growth_Rate | G2: 4Q21 | H2: 1Q22 | I2: 2Q22 | J2: 3Q22 | K2: 4Q22 | L2: 1Q23 | M2: 2Q23 | N2: 3Q23 | O2: 4Q23 | P2: 1Q24 | Q2: 2Q24 | R2: 3Q24 | S2: 4Q24 | T2: 1Q25 | U2: 2Q25 | V2: 3Q25 | W2: 4Q25 | X2: 1Q25 롤링 | Y2: 2Q25 롤링 | Z2: 3Q25 롤링 | AA2: 4Q25 롤링
B3: PLTR | C3: United States | D3: Software - Infrastructure | E3: Dec'25 | F3: 14.9 | G3: 432.87 | H3: 446.36 | I3: 473.01 | J3: 477.88 | K3: 508.62 | L3: 525.19 | M3: 533.32 | N3: 558.16 | O3: 608.35 | P3: 634.34 | Q3: 678.13 | R3: 725.52 | S3: 827.52 | T3: 883.86 | U3: 1004 | V3: 1181 | W3: 1407 | X3: 0.087076995 | Y3: 0.10461215 | Z3: 0.13237234 | AA3: 0.14872266
B4: TER | C4: United States | D4: Semiconductor Equipment & Materials | E4: Dec'25 | F4: 11.5 | G4: 885.05 | H4: 755.37 | I4: 840.77 | J4: 827.07 | K4: 731.84 | L4: 617.53 | M4: 684.44 | N4: 703.73 | O4: 670.6 | P4: 599.82 | Q4: 729.88 | R4: 737.3 | S4: 752.88 | T4: 685.68 | U4: 651.8 | V4: 769.21 | W4: 1083 | X4: 0.030448104 | Y4: -0.026870952 | Z4: 0.011284949 | AA4: 0.11544393
B5: FN | C5: United States | D5: Electronic Components | E5: Jun'26 | F5: 8.3 | G5: 566.63 | H5: 564.4 | I5: 587.87 | J5: 655.43 | K5: 668.66 | L5: 665.28 | M5: 655.87 | N5: 685.48 | O5: 712.69 | P5: 731.54 | Q5: 753.26 | R5: 804.23 | S5: 833.61 | T5: 871.8 | U5: 909.69 | V5: 978.13 | W5: 1133 | X5: 0.044917121 | Y5: 0.047942015 | Z5: 0.050857917 | AA5: 0.083320578
B6: WWD | C6: United States | D6: Aerospace & Defense | E6: Mar'26 | F6: 6.3 | G6: 541.59 | H6: 586.84 | I6: 614.33 | J6: 640.03 | K6: 618.62 | L6: 718.21 | M6: 800.66 | N6: 777.07 | O6: 786.73 | P6: 835.34 | Q6: 847.69 | R6: 854.49 | S6: 772.73 | T6: 883.63 | U6: 915.45 | V6: 995.26 | W6: 996.45 | X6: 0.014588022 | Y6: 0.020175433 | Z6: 0.041085136 | AA6: 0.062718141
B7: CSWC | C7: United States | D7: Asset Management | E7: Sep'26 | F7: 4.4 | G7: 22.31 | H7: 21.03 | I7: 22.54 | J7: 26.8 | K7: 32.77 | L7: 37.19 | M7: 40.36 | N7: 42.78 | O7: 48.57 | P7: 46.43 | Q7: 51.35 | R7: 48.71 | S7: 51.97 | T7: 52.41 | U7: 55.95 | V7: 56.95 | W7: 61.45 | X7: 0.030132017 | Y7: 0.022500489 | Z7: 0.039418293 | AA7: 0.043630339
B8: RMBS | C8: United States | D8: Semiconductors | E8: Dec'25 | F8: 4.3 | G8: 91.78 | H8: 99.05 | I8: 121.13 | J8: 112.24 | K8: 122.37 | L8: 113.76 | M8: 119.83 | N8: 105.3 | O8: 122.23 | P8: 117.87 | Q8: 132.14 | R8: 145.51 | S8: 161.1 | T8: 166.66 | U8: 172.21 | V8: 178.51 | W8: 190.24 | X8: 0.087654055 | Y8: 0.066186551 | Z8: 0.051124744 | AA8: 0.042948945
B9: TWST | C9: United States | D9: Diagnostics & Research | E9: Mar'26 | F9: 4 | G9: 42.02 | H9: 48.13 | I9: 56.11 | J9: 57.31 | K9: 54.24 | L9: 60.18 | M9: 63.74 | N9: 66.95 | O9: 71.5 | P9: 75.3 | Q9: 81.46 | R9: 84.71 | S9: 88.71 | T9: 92.79 | U9: 96.06 | V9: 99.01 | W9: 103.7 | X9: 0.052971107 | Y9: 0.041993845 | Z9: 0.039473321 | AA9: 0.039806676
B10: SPG | C10: United States | D10: REIT - Retail | E10: Dec'25 | F10: 3.4 | G10: 1324 | H10: 1296 | I10: 1280 | J10: 1316 | K10: 1400 | L10: 1351 | M10: 1370 | N10: 1411 | O10: 1527 | P10: 1443 | Q10: 1458 | R10: 1481 | S10: 1582 | T10: 1473 | U10: 1498 | V10: 1602 | W10: 1791 | X10: 0.0050301811 | Y10: 0.00667334 | Z10: 0.020053033 | AA10: 0.033956133
B11: IDXX | C11: United States | D11: Diagnostics & Research | E11: Dec'25 | F11: 3.3 | G11: 801.09 | H11: 836.55 | I11: 860.55 | J11: 841.66 | K11: 828.57 | L11: 900.2 | M11: 943.63 | N11: 915.53 | O11: 901.6 | P11: 964.1 | Q11: 1004 | R11: 975.54 | S11: 954.29 | T11: 998.43 | U11: 1109 | V11: 1105 | W11: 1091 | X11: 0.0088072387 | Y11: 0.026702202 | Z11: 0.032066302 | AA11: 0.03280998
B12: BSRR | C12: United States | D12: Banks - Regional | E12: Dec'25 | F12: 3.2 | G12: 34.87 | H12: 30.31 | I12: 34.61 | J12: 34.26 | K12: 30.54 | L12: 34.45 | M12: 36.4 | N12: 35.88 | O12: 32.39 | P12: 37.18 | Q12: 36.9 | R12: 37.22 | S12: 35.46 | T12: 34.68 | U12: 38.01 | V12: 36.34 | W12: 40.15 | X12: -0.017034614 | Y12: 0.0076944406 | Z12: -0.0060535186 | AA12: 0.032458994
B13: NSSC | C13: United States | D13: Security & Protection Services | E13: Jun'26 | F13: 2.8 | G13: 33.41 | H13: 35.91 | I13: 43.23 | J13: 39.49 | K13: 42.31 | L13: 43.53 | M13: 44.66 | N13: 41.68 | O13: 47.55 | P13: 49.27 | Q13: 50.33 | R13: 44 | S13: 42.93 | T13: 43.96 | U13: 50.72 | V13: 49.17 | W13: 48.17 | X13: -0.028467271 | Y13: 0.0021520803 | Z13: 0.028467595 | AA13: 0.028054396
B14: DVA | C14: United States | D14: Medical Care Facilities | E14: Dec'25 | F14: 2.4 | G14: 2944 | H14: 2818 | I14: 2927 | J14: 2949 | K14: 0 | L14: 2873 | M14: 3000 | N14: 3121 | O14: 3146 | P14: 3071 | Q14: 3187 | R14: 3264 | S14: 3295 | T14: 3224 | U14: 3380 | V14: 3420 | W14: 3620 | X14: 0.011937271 | Y14: 0.014880493 | Z14: 0.011851402 | AA14: 0.024401231
... B29: TWO | C29: United States | D29: REIT - Mortgage | E29: Dec'25 | F29: -39.5 | G29: 166.7 | H29: -33.03 | I29: -88.9 | J29: 346.8 | K29: -146.17 | L29: -100.54 | M29: 239.29 | N29: 349.87 | O29: -233.74 | P29: 259.25 | Q29: 136.57 | R29: -73.11 | S29: 271.04 | T29: 7.89 | U29: 23.61 | V29: 201.36 | W29: 71.94 | X29: -0.42334316 | Y29: -0.32991618 | Z29: 1.1963126 | AA29: -0.39511808
B30: 8331 | C30: Japan | D30: N/A | E30: Sep'26 | F30: 7 | G30: 52659 | H30: 49973 | I30: 61244 | J30: 63020 | K30: 60603 | L30: 55498 | M30: 60170 | N30: 60590 | O30: 61776 | P30: 55515 | Q30: 67905 | R30: 66474 | S30: 64252 | T30: 65179 | U30: 75955 | V30: 81359 | W30: 84291 | X30: 0.038025387 | Y30: 0.030514385 | Z30: 0.054752446 | AA30: 0.069884392
B31: 7337 | C31: Japan | D31: N/A | E31: Sep'26 | F31: 6.9 | G31: 35473 | H31: 31052 | I31: 36024 | J31: 28051 | K31: 34042 | L31: 33564 | M31: 36058 | N31: 36180 | O31: 35605 | P31: 27550 | Q31: 38834 | R31: 38922 | S31: 42895 | T31: 37223 | U31: 42154 | V31: 39847 | W31: 54153 | X31: 0.065269465 | Y31: 0.021029429 | Z31: 0.005738427 | AA31: 0.069442817
B32: 8386 | C32: Japan | D32: N/A | E32: Jun'26 | F32: 6 | G32: 17037 | H32: 18567 | I32: 15023 | J32: 21178 | K32: 20437 | L32: 19040 | M32: 14645 | N32: 16940 | O32: 14494 | P32: 17039 | Q32: 17520 | R32: 17247 | S32: 14292 | T32: 19913 | U32: 18479 | V32: 20602 | W32: 18703 | X32: 0.043480892 | Y32: 0.013904193 | Z32: 0.047975862 | AA32: 0.060188849
B33: 1814 | C33: Japan | D33: N/A | E33: Jun'26 | F33: 4.9 | G33: 16376 | H33: 18292 | I33: 18640 | J33: 18790 | K33: 20028 | L33: 16361 | M33: 16655 | N33: 17353 | O33: 18899 | P33: 20503 | Q33: 21060 | R33: 19901 | S33: 21156 | T33: 23529 | U33: 24442 | V33: 21464 | W33: 25558 | X33: 0.036625514 | Y33: 0.039488126 | Z33: 0.017556274 | AA33: 0.048592023
B34: 6762 | C34: Japan | D34: N/A | E34: Jun'26 | F34: 3.5 | G34: 474127 | H34: 499670 | I34: 508269 | J34: 510504 | K34: 611489 | L34: 586972 | M34: 471852 | N34: 503399 | O34: 556312 | P34: 559250 | Q34: 484915 | R34: 518809 | S34: 570692 | T34: 581043 | U34: 534262 | V34: 535753 | W34: 647610 | X34: 0.010213876 | Y34: 0.022893964 | Z34: 0.0076850299 | AA34: 0.034620457
B35: 8346 | C35: Japan | D35: N/A | E35: Jun'26 | F35: 3.2 | G35: 14750 | H35: 14288 | I35: 14091 | J35: 14536 | K35: 13215 | L35: 13962 | M35: 13006 | N35: 14421 | O35: 13647 | P35: 15023 | Q35: 13888 | R35: 15806 | S35: 15618 | T35: 16217 | U35: 16230 | V35: 18249 | W35: 17757 | X35: 0.019789509 | Y35: 0.038063352 | Z35: 0.038248971 | AA35: 0.032255632
B36: 3132 | C36: Japan | D36: N/A | E36: Jun'26 | F36: 2.9 | G36: 184279 | H36: 194802 | I36: 204678 | J36: 241320 | K36: 251242 | L36: 275442 | M36: 261259 | N36: 278562 | O36: 268399 | P36: 253342 | Q36: 228415 | R36: 256330 | S36: 262630 | T36: 262829 | U36: 252391 | V36: 281613 | W36: 293822 | X36: 0.0094802027 | Y36: 0.02373382 | Z36: 0.024447388 | AA36: 0.02944133
B37: 8841 | C37: Japan | D37: N/A | E37: Jun'26 | F37: 2.8 | G37: 4012 | H37: 4018 | I37: 4257 | J37: 4001 | K37: 4053 | L37: 3956 | M37: 3676 | N37: 3477 | O37: 3347 | P37: 3486 | Q37: 3405 | R37: 2993 | S37: 3282 | T37: 3382 | U37: 3495 | V37: 3465 | W37: 3666 | X37: -0.0078991341 | Y37: 0.0068902159 | Z37: 0.035888078 | AA37: 0.028185555
B38: 8601 | C38: Japan | D38: N/A | E38: Jun'26 | F38: 2.5 | G38: 154678 | H38: 166602 | I38: 148323 | J38: 146604 | K38: 192551 | L38: 233022 | M38: 293864 | N38: 266255 | O38: 303827 | P38: 335377 | Q38: 372008 | R38: 176188 | S38: 159958 | T38: 160018 | U38: 876860 | V38: 160993 | W38: 194358 | X38: -0.16804388 | Y38: 0.5815115 | Z38: -0.011066813 | AA38: 0.02533456
B39: 3467 | C39: Japan | D39: N/A | E39: Jun'26 | F39: 2.5 | Q39: 13370 | R39: 4971 | S39: 8508 | T39: 6124 | U39: 11140 | V39: 6930 | W39: 9318 | Y39: -0.067631092 | Z39: 0.063721823 | AA39: 0.024769127
B40: 4768 | C40: Japan | D40: N/A | E40: Dec'25 | F40: 2.5 | G40: 192635 | H40: 210069 | I40: 235267 | J40: 207843 | K40: 207843 | L40: 242609 | M40: 278447 | N40: 219002 | O40: 237312 | P40: 266664 | Q40: 303058 | R40: 252540 | S40: 285406 | T40: 315541 | U40: 379591 | V40: 310587 | W40: 317072 | X40: 0.044126038 | Y40: 0.066173819 | Z40: 0.047074881 | AA40: 0.024525898
B41: 2222 | C41: Japan | D41: N/A | E41: Sep'26 | F41: 2.4 | G41: 10963 | H41: 9270 | I41: 9515 | J41: 10584 | K41: 15271 | L41: 14785 | M41: 13853 | N41: 15038 | O41: 18145 | P41: 16999 | Q41: 15526 | R41: 17380 | S41: 20901 | T41: 18542 | U41: 16976 | V41: 18811 | W41: 22698 | X41: 0.021791939 | Y41: 0.020041742 | Z41: 0.019390507 | AA41: 0.023886747
B42: 8081 | C42: Japan | D42: N/A | E42: Jun'26 | F42: 2 | G42: 23819 | H42: 23234 | I42: 32599 | J42: 19355 | K42: 26199 | L42: 24763 | M42: 36102 | N42: 24703 | O42: 28944 | P42: 26716 | Q42: 35908 | R42: 22441 | S42: 29371 | T42: 27588 | U42: 46265 | V42: 29609 | W42: 32048 | X42: 0.0076199797 | Y42: 0.089820307 | Z42: 0.057040544 | AA42: 0.020153125
B43: 6908 | C43: Japan | D43: N/A | E43: Jun'26 | F43: 2 | G43: 10792 | H43: 10446 | I43: 11439 | J43: 11929 | K43: 13614 | L43: 13976 | M43: 13384 | N43: 12496 | O43: 15644 | P43: 13000 | Q43: 14131 | R43: 12534 | S43: 14625 | T43: 15009 | U43: 14164 | V43: 15163 | W43: 15811 | X43: 0.037004973 | Y43: 0.00058615606 | Z43: 0.046669744 | AA43: 0.020114991
B44: 9022 | C44: Japan | D44: N/A | E44: Sep'26 | F44: 1.9 | G44: 299440 | H44: 248750 | I44: 309342 | J44: 324797 | K44: 385012 | L44: 381134 | M44: 395091 | N44: 422454 | O44: 455472 | P44: 437390 | Q44: 435290 | R44: 438575 | S44: 494172 | T44: 463810 | U44: 478283 | V44: 503919 | W44: 531950 | X44: 0.014633657 | Y44: 0.023469755 | Z44: 0.034853107 | AA44: 0.019471349
B45: 6971 | C45: Japan | D45: N/A | E45: Sep'26 | F45: 1.9 | G45: 479328 | H45: 483273 | I45: 491954 | J45: 520218 | K45: 514325 | L45: 498835 | M45: 479420 | N45: 505870 | O45: 507382 | P45: 511549 | Q45: 498868 | R45: 499720 | S45: 493467 | T45: 522399 | U45: 478038 | V45: 513347 | W45: 530611 | X45: 0.0054152417 | Y45: -0.010340271 | Z45: 0.0068352909 | AA45: 0.01850491
B46: 2676 | C46: Japan | D46: N/A | E46: Jun'26 | F46: 1.8 | G46: 5181 | H46: 5200 | I46: 6001 | J46: 4974 | K46: 6144 | L46: 5816 | M46: 6426 | N46: 6080 | O46: 6649 | P46: 6231 | Q46: 6264 | R46: 6421 | S46: 6893 | T46: 6334 | U46: 8450 | V46: 6068 | W46: 7404 | X46: 0.0039908559 | Y46: 0.084362458 | Z46: -0.012563172 | AA46: 0.018417733
B47: 2282 | C47: Japan | D47: N/A | E47: Jun'26 | F47: 1.6 | G47: 308418 | H47: 349874 | I47: 0 | J47: 311512 | K47: 322512 | L47: 352079 | M47: 273689 | N47: 322175 | O47: 329947 | P47: 345835 | Q47: 305475 | R47: 338050 | S47: 345814 | T47: 371154 | U47: 315535 | V47: 354141 | W47: 368458 | X47: 0.018963071 | Y47: 0.0073943784 | Z47: 0.011740516 | AA47: 0.016330075
B48: 9020 | C48: Japan | D48: N/A | E48: Sep'26 | F48: 1.6 | G48: 604954 | H48: 496173 | I48: 557618 | J48: 557455 | K48: 612011 | L48: 678454 | M48: 629472 | N48: 670357 | O48: 701193 | P48: 729096 | Q48: 686670 | R48: 708447 | S48: 730953 | T48: 761483 | U48: 715349 | V48: 747747 | W48: 776926 | X48: 0.011343298 | Y48: 0.0099319389 | Z48: 0.013476294 | AA48: 0.015554898
B49: 9064 | C49: Japan | D49: N/A | E49: Sep'26 | F49: 1.5 | G49: 506916 | H49: 421232 | I49: 424159 | J49: 459596 | K49: 512212 | L49: 404701 | M49: 420212 | N49: 446370 | O49: 500245 | P49: 391799 | Q49: 405632 | R49: 434781 | S49: 504118 | T49: 418165 | U49: 437352 | V49: 469422 | W49: 531982 | X49: 0.015184901 | Y49: 0.017995162 | Z49: 0.019304888 | AA49: 0.01523408
B50: 4272 | C50: Japan | D50: N/A | E50: Jun'26 | F50: 1.5 | G50: 42393 | H50: 49255 | I50: 46710 | J50: 48296 | K50: 54432 | L50: 50899 | M50: 44753 | N50: 48584 | O50: 49324 | P50: 51845 | Q50: 52038 | R50: 53645 | S50: 55464 | T50: 58846 | U50: 54629 | V50: 54758 | W50: 58817 | X50: 0.032869779 | Y50: 0.011777647 | Z50: 0.0050003594 | AA50: 0.014989025
B51: 8411 | C51: Japan | D51: N/A | E51: Sep'26 | F51: 1.5 | G51: 681625 | H51: 802755 | I51: 689784 | J51: 451997 | K51: 995900 | L51: 641535 | M51: 771638 | N51: 788870 | O51: 807972 | P51: 753625 | Q51: 950408 | R51: 1071722 | S51: 1058632 | T51: 818078 | U51: 957553 | V51: 1139963 | W51: 1117111 | X51: 0.016809206 | Y51: 0.0018325964 | Z51: 0.017470881 | AA51: 0.014714563
... B65: 7480 | C65: Japan | D65: N/A | E65: Jun'26 | F65: -1.1 | G65: 13633 | H65: 15441 | I65: 17523 | J65: 15847 | K65: 17287 | L65: 17783 | M65: 16522 | N65: 14281 | O65: 13030 | P65: 12619 | Q65: 10999 | R65: 11021 | S65: 11315 | T65: 12378 | U65: 11917 | V65: 10288 | W65: 10812 | X65: -0.0052443748 | Y65: 0.020081815 | Z65: -0.015719157 | AA65: -0.010959083
B66: SOUTHWEST | C66: India | D66: N/A | E66: Jun'26 | F66: 18.4 | G66: 279.55 | H66: 308.89 | I66: 351.02 | J66: 258.34 | K66: 248.47 | L66: 352.8 | M66: 383.03 | N66: 229.85 | O66: 232.72 | P66: 421.54 | Q66: 450.13 | R66: 294.29 | S66: 273.6 | T66: 485.42 | U66: 749.63 | V66: 402.16 | W66: 624.45 | X66: 0.04437467 | Y66: 0.19920981 | Z66: 0.059830055 | AA66: 0.18361323
B67: CLEDUCATE | C67: India | D67: N/A | E67: Jun'26 | F67: 16 | G67: 532.07 | H67: 501.62 | I67: 539.28 | J67: 692.53 | K67: 891.22 | L67: 631.34 | M67: 698.04 | N67: 900.19 | O67: 890.44 | P67: 664.23 | Q67: 669.54 | R67: 939.86 | S67: 986.82 | T67: 705.36 | U67: 948.81 | V67: 1457 | W67: 1643 | X67: 0.012614823 | Y67: 0.084586774 | Z67: 0.14441822 | AA67: 0.1601224
B68: NILASPACES | C68: India | D68: N/A | E68: Sep'26 | F68: 12.3 | G68: 8.81 | H68: 9.98 | I68: 10.11 | J68: 0 | K68: 0 | L68: 0 | M68: 0 | N68: 0 | O68: 584.23 | P68: 322.9 | Q68: 311.06 | R68: 319.07 | S68: 330.25 | T68: 397.61 | U68: 408.33 | V68: 421.84 | W68: 522 | X68: 0.058218004 | Y68: 0.071627921 | Z68: 0.070619683 | AA68: 0.12307208
...

Sheet Operating Income
B2: Ticker | C2: Country | D2: Industry | E2: Latest_Date | F2: Growth_Rate | G2: 4Q21 | H2: 1Q22 | I2: 2Q22 | J2: 3Q22 | K2: 4Q22 | L2: 1Q23 | M2: 2Q23 | N2: 3Q23 | O2: 4Q23 | P2: 1Q24 | Q2: 2Q24 | R2: 3Q24 | S2: 4Q24 | T2: 1Q25 | U2: 2Q25 | V2: 3Q25 | W2: 4Q25 | X2: 1Q25 롤링 | Y2: 2Q25 롤링 | Z2: 3Q25 롤링 | AA2: 4Q25 롤링
B3: PLTR | C3: United States | D3: Software - Infrastructure | E3: Dec'25 | F3: 66.4 | G3: -58.94 | H3: -39.44 | I3: -41.75 | J3: -62.19 | K3: -17.83 | L3: 4.12 | M3: 10.07 | N3: 39.98 | O3: 65.79 | P3: 80.88 | Q3: 105.34 | R3: 113.14 | S3: 11.04 | T3: 176.05 | U3: 269.32 | V3: 393.26 | W3: 575.39 | X3: 0.30660438 | Y3: 0.40431985 | Z3: 0.49182688 | AA3: 0.66419904
B4: TER | C4: United States | D4: Semiconductor Equipment & Materials | E4: Dec'25 | F4: 26.2 | G4: 270.83 | H4: 200.56 | I4: 247.99 | J4: 232.71 | K4: 215.44 | L4: 94.9 | M4: 145.01 | N4: 147.96 | O4: 130.26 | P4: 81.97 | Q4: 154.88 | R4: 154.54 | S4: 154.55 | T4: 135.3 | U4: 93.04 | V4: 145.32 | W4: 293.2 | X4: 0.097684727 | Y4: -0.10319222 | Z4: -0.017155723 | AA4: 0.2624903
B5: ARLP | C5: United States | D5: Thermal Coal | E5: Dec'25 | F5: 16.2 | G5: 59.22 | H5: 88.46 | I5: 176.51 | J5: 180.36 | K5: 212.17 | L5: 205.83 | M5: 182.35 | N5: 163.9 | O5: 114.16 | P5: 158.32 | Q5: 115.4 | R5: 98.95 | S5: 44.36 | T5: 92.78 | U5: 87.2 | V5: 103.46 | W5: 97.34 | X5: -0.15715896 | Y5: -0.080229879 | Z5: 0.013950323 | AA5: 0.16162294
B6: WWD | C6: United States | D6: Aerospace & Defense | E6: Mar'26 | F6: 13.2 | G6: 35.75 | H6: 56.66 | I6: 56.24 | J6: 59.66 | K6: 33.82 | L6: 45.56 | M6: 104.06 | N6: 91.57 | O6: 103.28 | P6: 120.83 | Q6: 117.46 | R6: 99.73 | S6: 93.94 | T6: 123.53 | U6: 120.07 | V6: 158.01 | W6: 159.42 | X6: 0.0062505788 | Y6: 0.0060046933 | Z6: 0.1332815 | AA6: 0.13213601
B7: FN | C7: United States | D7: Electronic Components | E7: Jun'26 | F7: 10 | G7: 51.58 | H7: 53.66 | I7: 56.71 | J7: 62.19 | K7: 66.29 | L7: 67.7 | M7: 62.76 | N7: 63.98 | O7: 68.82 | P7: 71.31 | Q7: 73.7 | R7: 76.89 | S7: 80.09 | T7: 80.12 | U7: 89 | V7: 94.29 | W7: 114.4 | X7: 0.029173151 | Y7: 0.049227799 | Z7: 0.053357866 | AA7: 0.099883552
B8: BSRR | C8: United States | D8: Banks - Regional | E8: Dec'25 | F8: 8.8 | G8: 12.69 | H8: 10.14 | I8: 12.49 | J8: 13.27 | K8: 9.01 | L8: 11.46 | M8: 13.43 | N8: 13.32 | O8: 8.25 | P8: 12.65 | Q8: 14.21 | R8: 14.41 | S8: 12.6 | T8: 12.27 | U8: 14.24 | V8: 12.7 | W8: 17.14 | X8: -0.0070540189 | Y8: 0.0005608525 | Z8: -0.031950673 | AA8: 0.087627871
B9: NSSC | C9: United States | D9: Security & Protection Services | E9: Jun'26 | F9: 7.4 | G9: 1.27 | H9: 4.58 | I9: 9.38 | J9: 3.65 | K9: 4.33 | L9: 10.54 | M9: 11.36 | N9: 11.56 | O9: 13.81 | P9: 14.49 | Q9: 15.66 | R9: 11.86 | S9: 11.17 | T9: 11.15 | U9: 12.73 | V9: 13.64 | W9: 14.75 | X9: -0.062805566 | Y9: -0.058788122 | Z9: 0.037945001 | AA9: 0.073526391
B10: FLXS | C10: United States | D10: Furnishings, Fixtures & Appliances | E10: Jun'26 | F10: 6.8 | G10: -8.01 | H10: 5.76 | I10: 3.58 | J10: 0.43 | K10: 0.97 | L10: 2.12 | M10: 4.24 | N10: 1.92 | O10: 4.58 | P10: 5.61 | Q10: 4.69 | R10: 6.05 | S10: 6.66 | T10: 8.27 | U10: 10.27 | V10: 8.99 | W10: 9 | X10: 0.11560191 | Y10: 0.21737437 | Z10: 0.09408 | AA10: 0.068441065
B11: DVA | C11: United States | D11: Medical Care Facilities | E11: Dec'25 | F11: 6.2 | G11: 386.26 | H11: 331.26 | I11: 423.57 | J11: 303.28 | K11: 0 | L11: 304.83 | M11: 396.84 | N11: 488.71 | O11: 315.33 | P11: 442.02 | Q11: 500.92 | R11: 531.17 | S11: 432.53 | T11: 433.33 | U11: 530.48 | V11: 507.31 | W11: 551.21 | X11: -0.0045577561 | Y11: 0.015574699 | Z11: -0.012378665 | AA11: 0.062343393
B12: RMBS | C12: United States | D12: Semiconductors | E12: Dec'25 | F12: 5.2 | G12: 16.47 | H12: 9.52 | I12: 30.06 | J12: 19.33 | K12: 22.34 | L12: 8.84 | M12: 28.09 | N12: 18.31 | O12: 36.26 | P12: 30.83 | Q12: 40.19 | R12: 50.15 | S12: 57.86 | T12: 63.14 | U12: 62.99 | V12: 63.26 | W12: 70.83 | X12: 0.18047255 | Y12: 0.10788303 | Z12: 0.055992141 | AA12: 0.052457027
B13: IDXX | C13: United States | D13: Diagnostics & Research | E13: Dec'25 | F13: 4.1 | G13: 199.19 | H13: 248.34 | I13: 179.07 | J13: 244.83 | K13: 226.53 | L13: 280.4 | M13: 296.14 | N13: 275.28 | O13: 245.3 | P13: 298.96 | Q13: 325.3 | R13: 303.89 | S13: 261.69 | T13: 316.53 | U13: 373.05 | V13: 354.85 | W13: 315.61 | X13: 0.014766691 | Y13: 0.039547461 | Z13: 0.040600402 | AA13: 0.041282577
B14: CSWC | C14: United States | D14: Asset Management | E14: Sep'26 | F14: 3.9 | G14: 16.49 | H14: 16.9 | I14: 18.11 | J14: 21.61 | K14: 26.62 | L14: 31.58 | M14: 34.68 | N14: 36.89 | O14: 41.24 | P14: 41.22 | Q14: 43.73 | R14: 42.6 | S14: 45.4 | T14: 43.67 | U14: 47.98 | V14: 50.04 | W14: 52.68 | X14: 0.014165944 | Y14: 0.024230331 | Z14: 0.04141386 | AA14: 0.038911754
... B29: TWO | C29: United States | D29: REIT - Mortgage | E29: Dec'25 | F29: -129.4 | G29: 1.48 | H29: 334.76 | I29: -44.08 | J29: 303.66 | K29: -269.09 | L29: -175.3 | M29: 222.16 | N29: 354.05 | O29: -459.45 | P29: 216.76 | Q29: 69.71 | R29: -248.84 | S29: 308.94 | T29: -78.52 | U29: -57.45 | V29: 52.41 | W29: 17.29 | X29: -0.85200681 | Y29: -2.4792357 | Z29: -3.9706076 | AA29: -1.2940367
B30: 6971 | C30: Japan | D30: N/A | E30: Sep'26 | F30: 75.9 | G30: 42779 | H30: 30452 | I30: 41428 | J30: 35060 | K30: 37396 | L30: 14633 | M30: 25677 | N30: 28325 | O30: 25842 | P30: 13079 | Q30: 20956 | R30: 16920 | S30: -25601 | T30: 55172 | U30: 18550 | V30: 23395 | W30: 28676 | X30: 1.6602114 | Y30: -0.035672454 | Z30: 0.09955259 | AA30: 0.75894905
B31: 2282 | C31: Japan | D31: N/A | E31: Jun'26 | F31: 30.5 | G31: 11670 | H31: 20357 | I31: 0 | J31: 13202 | K31: 6423 | L31: 1760 | M31: -10848 | N31: 17632 | O31: 13023 | P31: 12269 | Q31: -11247 | R31: 19099 | S31: 9780 | T31: 14203 | U31: -6510 | V31: 18261 | W31: 20694 | X31: 0.064680111 | Y31: 0.14879849 | Z31: -0.022913704 | AA31: 0.30542341
B32: 1814 | C32: Japan | D32: N/A | E32: Jun'26 | F32: 26.5 | G32: 374 | H32: 840 | I32: 743 | J32: 229 | K32: 704 | L32: 471 | M32: 483 | N32: 275 | O32: -41 | P32: 263 | Q32: 1094 | R32: 520 | S32: 599 | T32: 799 | U32: 1778 | V32: 793 | W32: 1649 | X32: 0.21647819 | Y32: 0.22709163 | Z32: 0.073863636 | AA32: 0.26455026
B33: 8841 | C33: Japan | D33: N/A | E33: Jun'26 | F33: 17 | G33: 1378 | H33: 1328 | I33: 1483 | J33: 1358 | K33: 1277 | L33: 1024 | M33: 609 | N33: 787 | O33: 452 | P33: 677 | Q33: 370 | R33: 313 | S33: 369 | T33: 608 | U33: 129 | V33: 420 | W33: 629 | X33: -0.039907461 | Y33: -0.14518072 | Z33: 0.075405215 | AA33: 0.17038008
B34: 2676 | C34: Japan | D34: N/A | E34: Jun'26 | F34: 16.6 | G34: 365 | H34: 191 | I34: 402 | J34: 207 | K34: 377 | L34: 346 | M34: 446 | N34: 315 | O34: 399 | P34: 266 | Q34: 486 | R34: 464 | S34: 472 | T34: 427 | U34: 717 | V34: 184 | W34: 770 | X34: 0.095379147 | Y34: 0.1249324 | Z34: -0.13461538 | AA34: 0.16555556
B35: 7241 | C35: Japan | D35: N/A | E35: Jun'26 | F35: 16.4 | G35: -1909 | H35: 940 | I35: 3878 | J35: -2008 | K35: 1718 | L35: 2764 | M35: 5208 | N35: 4730 | O35: 4716 | P35: 6565 | Q35: 3202 | R35: 3615 | S35: 1832 | T35: 4466 | U35: 5265 | V35: 4192 | W35: 4417 | X35: -0.13796503 | Y35: 0.1573008 | Z35: 0.038015549 | AA35: 0.1640749
B36: 8386 | C36: Japan | D36: N/A | E36: Jun'26 | F36: 15.4 | G36: 4702 | H36: 4792 | I36: 479 | J36: 5110 | K36: 3616 | L36: 2197 | M36: 2285 | N36: 5688 | O36: 1616 | P36: 3488 | Q36: 3489 | R36: 4955 | S36: 3016 | T36: 5576 | U36: 4050 | V36: 6603 | W36: 5971 | X36: 0.13968424 | Y36: 0.032930265 | Z36: 0.093652327 | AA36: 0.15354638
B37: 7981 | C37: Japan | D37: N/A | E37: Jun'26 | F37: 9.9 | G37: 3990 | H37: 5837 | I37: 877 | J37: 3225 | K37: 2861 | L37: 3886 | M37: 969 | N37: 2684 | O37: 2624 | P37: 5411 | Q37: 1709 | R37: 3098 | S37: 2860 | T37: 6885 | U37: 2793 | V37: 4196 | W37: 4519 | X37: 0.11270837 | Y37: 0.074491479 | Z37: 0.070222563 | AA37: 0.099139477
B38: 9502 | C38: Japan | D38: N/A | E38: Jun'26 | F38: 9.2 | G38: 31762 | H38: -55866 | I38: -52029 | J38: 41486 | K38: 19776 | L38: -12994 | M38: 58821 | N38: 157186 | O38: 88472 | P38: 43953 | Q38: 53729 | R38: 85868 | S38: 56887 | T38: 41365 | U38: 57925 | V38: 67932 | W38: 77613 | X38: -0.010763734 | Y38: 0.017641445 | Z38: -0.074101923 | AA38: 0.092481783
B39: 8331 | C39: Japan | D39: N/A | E39: Sep'26 | F39: 8.9 | G39: 19452 | H39: 13461 | I39: 23942 | J39: 26698 | K39: 19092 | L39: 16937 | M39: 25921 | N39: 24001 | O39: 22592 | P39: 18153 | Q39: 28626 | R39: 25631 | S39: 25108 | T39: 27460 | U39: 30960 | V39: 31799 | W39: 35358 | X39: 0.095438791 | Y39: 0.021848818 | Z39: 0.056504732 | AA39: 0.088877713
B40: 8346 | C40: Japan | D40: N/A | E40: Jun'26 | F40: 8.5 | G40: 2851 | H40: 2876 | I40: 1558 | J40: 2478 | K40: 1533 | L40: 2341 | M40: 711 | N40: 2858 | O40: 2201 | P40: 3211 | Q40: -276 | R40: 3291 | S40: 3211 | T40: 2872 | U40: 1250 | V40: 4545 | W40: 4222 | X40: -0.035922433 | Y40: 0.16772917 | Z40: 0.11803464 | AA40: 0.085115339
B41: 6762 | C41: Japan | D41: N/A | E41: Jun'26 | F41: 8.5 | G41: 48962 | H41: 59492 | I41: 21407 | J41: 44414 | K41: 75390 | L41: 66228 | M41: -28306 | N41: 25342 | O41: 58605 | P41: 69027 | Q41: 17688 | R41: 57872 | S41: 72806 | T41: 75791 | U41: 11743 | V41: 56419 | W41: 91208 | X41: 0.031114157 | Y41: -0.02652159 | Z41: -0.0066586622 | AA41: 0.084896129
... B43: 9064 | C43: Japan | D43: N/A | E43: Sep'26 | F43: 4.3 | G43: 47482 | H43: -1973 | I43: 2418 | J43: 15631 | K43: 48352 | L43: -6315 | M43: 1598 | N43: 10761 | O43: 38004 | P43: -10303 | Q43: -14205 | R43: -797 | S43: 41267 | T43: -12058 | U43: -6494 | V43: 2712 | W43: 42368 | X43: -0.10994863 | Y43: 0.54276061 | Z43: 0.16009672 | AA43: 0.043300429
B44: 3467 | C44: Japan | D44: N/A | E44: Jun'26 | F44: 4.1 | Q44: 1293 | R44: 226 | S44: 855 | T44: 427 | U44: 1041 | V44: 508 | W44: 971 | Y44: -0.089967869 | Z44: 0.11063162 | AA44: 0.040974921
B45: 8411 | C45: Japan | D45: N/A | E45: Sep'26 | F45: 3.7 | G45: 108485 | H45: 48765 | I45: 207355 | J45: 237700 | K45: 244905 | L45: 89003 | M45: 313573 | N45: 282748 | O45: 325130 | P45: 33582 | Q45: 397385 | R45: 393772 | S45: 376077 | T45: 22849 | U45: 378595 | V45: 520119 | W45: 424507 | X45: -0.0089380888 | Y45: -0.015788815 | Z45: 0.10786968 | AA45: 0.037321599
B46: 4272 | C46: Japan | D46: N/A | E46: Jun'26 | F46: 3.4 | G46: 4964 | H46: 6438 | I46: 3711 | J46: 6381 | K46: 7179 | L46: 5503 | M46: 2443 | N46: 2335 | O46: 2433 | P46: -656 | Q46: 3225 | R46: 5570 | S46: 5591 | T46: 6955 | U46: 2286 | V46: 4369 | W46: 6250 | X46: 0.55433358 | Y46: -0.043999813 | Z46: -0.058866778 | AA46: 0.034321129
B47: 9022 | C47: Japan | D47: N/A | E47: Sep'26 | F47: 3 | G47: 71276 | H47: -35464 | I47: 83541 | J47: 88386 | K47: 134444 | L47: 68133 | M47: 146519 | N47: 165573 | O47: 190507 | P47: 104783 | Q47: 184329 | R47: 180881 | S47: 218719 | T47: 118866 | U47: 221226 | V47: 232826 | W47: 242711 | X47: 0.020448315 | Y47: 0.052500374 | Z47: 0.070225175 | AA47: 0.03030682
B48: 2222 | C48: Japan | D48: N/A | E48: Sep'26 | F48: 2.9 | G48: 2279 | H48: 539 | I48: 1151 | J48: 1679 | K48: 4027 | L48: 3093 | M48: 3059 | N48: 3564 | O48: 5112 | P48: 4044 | Q48: 3428 | R48: 4050 | S48: 6068 | T48: 4064 | U48: 3441 | V48: 3999 | W48: 6573 | X48: 0.0011370097 | Y48: 0.00073821692 | Z48: -0.0028939454 | AA48: 0.028738903
B49: 3024 | C49: Japan | D49: N/A | E49: Jun'26 | F49: 1.9 | G49: 13 | H49: 189 | I49: 118 | J49: 107 | K49: 188 | L49: 214 | M49: 171 | N49: -49 | O49: 140 | P49: 334 | Q49: -12 | R49: 75 | S49: 144 | T49: 328 | U49: 222 | V49: 134 | W49: 160 | X49: -0.011090573 | Y49: 0.43738318 | Z49: 0.076723017 | AA49: 0.019323671
B50: 4768 | C50: Japan | D50: N/A | E50: Dec'25 | F50: 1.5 | G50: 11293 | H50: 13787 | I50: 16992 | J50: 11997 | K50: 11997 | L50: 16876 | M50: 19837 | N50: 10678 | O50: 15574 | P50: 17243 | Q50: 21601 | R50: 13326 | S50: 22047 | T50: 21176 | U50: 27998 | V50: 17357 | W50: 23413 | X50: 0.05299325 | Y50: 0.081855406 | Z50: 0.047677623 | AA50: 0.015421436
B51: 8601 | C51: Japan | D51: N/A | E51: Jun'26 | F51: 0.9 | G51: 56158 | H51: 68276 | I51: 53515 | J51: 49366 | K51: 93611 | L51: 133122 | M51: 192039 | N51: 162882 | O51: 197335 | P51: 225544 | Q51: 254516 | R51: 34552 | S51: 41008 | T51: 37040 | U51: 781179 | V51: 35094 | W51: 48910 | X51: -0.33926784 | Y51: 1.4345956 | Z51: 0.00060641389 | AA51: 0.0088357536
B52: 8081 | C52: Japan | D52: N/A | E52: Jun'26 | F52: 0.6 | G52: 732 | H52: 396 | I52: 1614 | J52: 139 | K52: 1186 | L52: 803 | M52: 1840 | N52: 522 | O52: 1324 | P52: 754 | Q52: 1945 | R52: 338 | S52: 1180 | T52: 507 | U52: 2476 | V52: 470 | W52: 1206 | X52: -0.058572445 | Y52: 0.13375315 | Z52: 0.029326816 | AA52: 0.0056119145
B53: 9020 | C53: Japan | D53: N/A | E53: Sep'26 | F53: 0.3 | G53: 73356 | H53: -111402 | I53: 40298 | J53: 26413 | K53: 45297 | L53: 28622 | M53: 80176 | N53: 111622 | O53: 106713 | P53: 46651 | Q53: 120531 | R53: 115075 | S53: 116948 | T53: 24233 | U53: 114787 | V53: 116694 | W53: 118134 | X53: -0.056156611 | Y53: -0.015244687 | Z53: 0.0043633757 | AA53: 0.0031825085
B54: 3433 | C54: Japan | D54: N/A | E54: Jun'26 | F54: -0.1 | G54: 2351 | H54: 2443 | I54: 2702 | J54: 2724 | K54: 2858 | L54: 2642 | M54: 2335 | N54: 2270 | O54: 2027 | P54: 2108 | Q54: 2793 | R54: 2688 | S54: 2696 | T54: 3107 | U54: 3781 | V54: 3838 | W54: 2682 | X54: 0.097131745 | Y54: 0.087557604 | Z54: 0.093709257 | AA54: -0.0010430636
B55: 9532 | C55: Japan | D55: N/A | E55: Sep'26 | F55: -0.2 | G55: 2137 | H55: 52229 | I55: 7367 | J55: -53057 | K55: 30763 | L55: 74929 | M55: 73664 | N55: 23068 | O55: 43961 | P55: 31862 | Q55: 28750 | R55: 26191 | S55: 44567 | T55: 61224 | U55: 47680 | V55: 41990 | W55: 44079 | X55: 0.22350613 | Y55: 0.11777369 | Z55: 0.087937349 | AA55: -0.0024966617
B56: 3132 | C56: Japan | D56: N/A | E56: Jun'26 | F56: -2.8 | G56: 8130 | H56: 9939 | I56: 11435 | J56: 12266 | K56: 14536 | L56: 18493 | M56: 16353 | N56: 20654 | O56: 17346 | P56: 13311 | Q56: 12422 | R56: 12048 | S56: 10329 | T56: 10841 | U56: 6432 | V56: 8198 | W56: 9309 | X56: -0.051340678 | Y56: -0.13124452 | Z56: -0.097099622 | AA56: -0.02849162
...

Sheet 빨간줄
B2: (단위: mil $)
B4: PLTR | C4: 6 | D4: 7 | E4: 8 | F4: 9 | G4: 10 | H4: 11 | I4: 12 | J4: 13 | K4: 14 | L4: 15 | M4: 16 | N4: 17 | O4: 18 | P4: 19 | Q4: 20 | R4: 21 | S4: 22
C6: 4Q21 | D6: 1Q22 | E6: 2Q22 | F6: 3Q22 | G6: 4Q22 | H6: 1Q23 | I6: 2Q23 | J6: 3Q23 | K6: 4Q23 | L6: 1Q24 | M6: 2Q24 | N6: 3Q24 | O6: 4Q24 | P6: 1Q25 | Q6: 2Q25 | R6: 3Q25 | S6: 4Q25
B7: Revenue | C7: =IFERROR(VLOOKUP($B$4,Revenue!$B$2:$X$500,C$4,FALSE),"-") -> 432.87 | D7: =IFERROR(VLOOKUP($B$4,Revenue!$B$2:$X$500,D$4,FALSE),"-") -> 446.36 | E7: =IFERROR(VLOOKUP($B$4,Revenue!$B$2:$X$500,E$4,FALSE),"-") -> 473.01 | F7: =IFERROR(VLOOKUP($B$4,Revenue!$B$2:$X$500,F$4,FALSE),"-") -> 477.88 | G7: =IFERROR(VLOOKUP($B$4,Revenue!$B$2:$X$500,G$4,FALSE),"-") -> 508.62 | H7: =IFERROR(VLOOKUP($B$4,Revenue!$B$2:$X$500,H$4,FALSE),"-") -> 525.19 | I7: =IFERROR(VLOOKUP($B$4,Revenue!$B$2:$X$500,I$4,FALSE),"-") -> 533.32 | J7: =IFERROR(VLOOKUP($B$4,Revenue!$B$2:$X$500,J$4,FALSE),"-") -> 558.16 | ... S7: =IFERROR(VLOOKUP($B$4,Revenue!$B$2:$X$500,S$4,FALSE),"-") -> 1407
B8: OP | C8: =IFERROR(VLOOKUP($B$4,'Operating Income'!$B$2:$X$500,C$4,FALSE),"-") -> -58.94 | D8: =IFERROR(VLOOKUP($B$4,'Operating Income'!$B$2:$X$500,D$4,FALSE),"-") -> -39.44 | E8: =IFERROR(VLOOKUP($B$4,'Operating Income'!$B$2:$X$500,E$4,FALSE),"-") -> -41.75 | F8: =IFERROR(VLOOKUP($B$4,'Operating Income'!$B$2:$X$500,F$4,FALSE),"-") -> -62.19 | G8: =IFERROR(VLOOKUP($B$4,'Operating Income'!$B$2:$X$500,G$4,FALSE),"-") -> -17.83 | H8: =IFERROR(VLOOKUP($B$4,'Operating Income'!$B$2:$X$500,H$4,FALSE),"-") -> 4.12 | I8: =IFERROR(VLOOKUP($B$4,'Operating Income'!$B$2:$X$500,I$4,FALSE),"-") -> 10.07 | J8: =IFERROR(VLOOKUP($B$4,'Operating Income'!$B$2:$X$500,J$4,FALSE),"-") -> 39.98 | ... S8: =IFERROR(VLOOKUP($B$4,'Operating Income'!$B$2:$X$500,S$4,FALSE),"-") -> 575.39
B9: Trailing 4Q OP avg. | C9: =IFERROR(AVERAGE(C8:C8),"-") -> -58.94 | D9: =IFERROR(AVERAGE(C8:D8),"-") -> -49.19 | E9: =IFERROR(AVERAGE(C8:E8),"-") -> -46.71 | F9: =IFERROR(AVERAGE(C8:F8),"-") -> -50.58 | G9: =IFERROR(AVERAGE(D8:G8),"-") -> -40.3025 | H9: =IFERROR(AVERAGE(E8:H8),"-") -> -29.4125 | I9: =IFERROR(AVERAGE(F8:I8),"-") -> -16.4575 | J9: =IFERROR(AVERAGE(G8:J8),"-") -> 9.085 | K9: =IFERROR(AVERAGE(H8:K8),"-") -> 29.99 | L9: =IFERROR(AVERAGE(I8:L8),"-") -> 49.18 | M9: =IFERROR(AVERAGE(J8:M8),"-") -> 72.9975 | ... S9: =IFERROR(AVERAGE(P8:S8),"-") -> 353.505
B10: Trailing 4Q OP sum. | C10: =IFERROR(SUM(C8:C8),"-") -> -58.94 | D10: =IFERROR(SUM(C8:D8),"-") -> -98.38 | E10: =IFERROR(SUM(C8:E8),"-") -> -140.13 | F10: =IFERROR(SUM(C8:F8),"-") -> -202.32 | G10: =IFERROR(SUM(D8:G8),"-") -> -161.21 | H10: =IFERROR(SUM(E8:H8),"-") -> -117.65 | I10: =IFERROR(SUM(F8:I8),"-") -> -65.83 | J10: =IFERROR(SUM(G8:J8),"-") -> 36.34 | K10: =IFERROR(SUM(H8:K8),"-") -> 119.96 | L10: =IFERROR(SUM(I8:L8),"-") -> 196.72 | M10: =IFERROR(SUM(J8:M8),"-") -> 291.99 | ... S10: =IFERROR(SUM(P8:S8),"-") -> 1414.02
B11: Trailing OP Delta | D11: =IFERROR(D9/C9-1,"-") -> -0.16542246 | E11: =IFERROR(E9/D9-1,"-") -> -0.050416751 | F11: =IFERROR(F9/E9-1,"-") -> 0.082851638 | G11: =IFERROR(G9/F9-1,"-") -> -0.20319296 | H11: =IFERROR(H9/G9-1,"-") -> -0.27020656 | I11: =IFERROR(I9/H9-1,"-") -> -0.44045899 | J11: =IFERROR(J9/I9-1,"-") -> -1.552028 | K11: =IFERROR(K9/J9-1,"-") -> 2.3010457 | ... S11: =IFERROR(S9/R9-1,"-") -> 0.66419904
B12: opm | C12: =IFERROR(C8/C7,"-") -> -0.13616097 | D12: =IFERROR(D8/D7,"-") -> -0.088359172 | E12: =IFERROR(E8/E7,"-") -> -0.088264519 | F12: =IFERROR(F8/F7,"-") -> -0.13013727 | G12: =IFERROR(G8/G7,"-") -> -0.035055641 | H12: =IFERROR(H8/H7,"-") -> 0.00784478 | I12: =IFERROR(I8/I7,"-") -> 0.018881722 | J12: =IFERROR(J8/J7,"-") -> 0.071628207 | ... S12: =IFERROR(S8/S7,"-") -> 0.40894812
B13: op yoy | G13: =IFERROR(G8/C8-1,"-") -> -0.69748897 | H13: =IFERROR(H8/D8-1,"-") -> -1.1044625 | I13: =IFERROR(I8/E8-1,"-") -> -1.2411976 | J13: =IFERROR(J8/F8-1,"-") -> -1.6428686 | K13: =IFERROR(K8/G8-1,"-") -> -4.6898486 | L13: =IFERROR(L8/H8-1,"-") -> 18.631068 | M13: =IFERROR(M8/I8-1,"-") -> 9.4607746 | N13: =IFERROR(N8/J8-1,"-") -> 1.829915 | ... S13: =IFERROR(S8/O8-1,"-") -> 51.118659
B14: rv yoy | G14: =IFERROR(G7/C7-1,"-") -> 0.1749948 | H14: =IFERROR(H7/D7-1,"-") -> 0.17660633 | I14: =IFERROR(I7/E7-1,"-") -> 0.12750259 | J14: =IFERROR(J7/F7-1,"-") -> 0.16799196 | K14: =IFERROR(K7/G7-1,"-") -> 0.19607959 | L14: =IFERROR(L7/H7-1,"-") -> 0.20782955 | M14: =IFERROR(M7/I7-1,"-") -> 0.27152554 | N14: =IFERROR(N7/J7-1,"-") -> 0.29984234 | ... S14: =IFERROR(S7/O7-1,"-") -> 0.70026102
