Workbook

Sheet 기업리스트
B2: 실적 기업 정보
B3: Ticker | C3: Company | D3: Date | E3: Time | F3: Quarter Ending | G3: Market Cap (mil$)
B4: AMD | C4: Advanced Micro Devices, Inc. | D4: 03-Feb-26 | E4: After Hours | F4: Dec-25 | G4: 385406
B5: MRK | C5: Merck & Co., Inc. | D5: 03-Feb-26 | F5: Dec-25 | G5: 273693
B6: PEP | C6: PepsiCo, Inc. | D6: 03-Feb-26 | F6: Dec-25 | G6: 212497
B7: AMGN | C7: Amgen Inc. | D7: 03-Feb-26 | E7: After Hours | F7: Dec-25 | G7: 184096
B8: PFE | C8: Pfizer Inc. | D8: 03-Feb-26 | F8: Dec-25 | G8: 150330
B9: ETN | C9: Eaton Corporation plc | D9: 03-Feb-26 | F9: Dec-25 | G9: 136492
B10: CB | C10: Chubb Limited | D10: 03-Feb-26 | F10: Dec-25 | G10: 121828
B11: EMR | C11: Emerson Electric Co. | D11: 03-Feb-26 | F11: Dec-25 | G11: 82635.92
B12: TDG | C12: TransDigm Group Incorporated | D12: 03-Feb-26 | F12: Dec-25 | G12: 80587.97
B13: 7974 | C13: Nintendo Co., Ltd. | D13: 03-Feb-26 | F13: Dec-25 | G13: 76065.45
B14: ITW | C14: Illinois Tool Works Inc. | D14: 03-Feb-26 | E14: Pre Market | F14: Dec-25 | G14: 75791.53
B15: MDLZ | C15: Mondelez International, Inc. | D15: 03-Feb-26 | E15: After Hours | F15: Dec-25 | G15: 75447.26
B16: EPD | C16: Enterprise Products Partners L.P. | D16: 03-Feb-26 | E16: Pre Market | F16: Dec-25 | G16: 71800.63
B17: 6503 | C17: Mitsubishi Electric Corporation | D17: 03-Feb-26 | F17: Dec-25 | G17: 64221.8
B18: SU | C18: Suncor Energy Inc. | D18: 03-Feb-26 | F18: Dec-25 | G18: 63761.61
B19: BAJFINANCE | C19: Bajaj Finance Limited | D19: 03-Feb-26 | F19: Dec-25 | G19: 62857.21
B20: MPLX | C20: MPLX LP | D20: 03-Feb-26 | E20: Pre Market | F20: Dec-25 | G20: 56853.94
B21: MPC | C21: Marathon Petroleum Corporation | D21: 03-Feb-26 | E21: Pre Market | F21: Dec-25 | G21: 52963.15
B22: AME | C22: AMETEK, Inc. | D22: 03-Feb-26 | F22: Dec-25 | G22: 51561.06
B23: CMG | C23: Chipotle Mexican Grill, Inc. | D23: 03-Feb-26 | E23: After Hours | F23: Dec-25 | G23: 51396.95
B24: GWW | C24: W.W. Grainger, Inc. | D24: 03-Feb-26 | E24: Pre Market | F24: Dec-25 | G24: 51350.43
B25: EA | C25: Electronic Arts Inc. | D25: 03-Feb-26 | E25: After Hours | F25: Dec-25 | G25: 50858.58
B26: PYPL | C26: PayPal Holdings, Inc. | D26: 03-Feb-26 | E26: Pre Market | F26: Dec-25 | G26: 49299.5
B27: CTVA | C27: Corteva, Inc. | D27: 03-Feb-26 | E27: After Hours | F27: Dec-25 | G27: 49193.29
B28: TTWO | C28: Take-Two Interactive Software, Inc. | D28: 03-Feb-26 | E28: After Hours | F28: Dec-25 | G28: 44372.79
B29: 8015 | C29: Toyota Tsusho Corporation | D29: 03-Feb-26 | F29: Dec-25 | G29: 40700.3
B30: PRU | C30: Prudential Financial, Inc. | D30: 03-Feb-26 | E30: After Hours | F30: Dec-25 | G30: 39080.33
B31: ADANIPORTS | C31: Adani Ports and Special Economic Zone Limited | D31: 03-Feb-26 | F31: Dec-25 | G31: 36104.02
B32: 5802 | C32: Sumitomo Electric Industries, Ltd. | D32: 03-Feb-26 | F32: Dec-25 | G32: 33687.35
B33: 2412 | C33: Chunghwa Telecom Co., Ltd. | D33: 03-Feb-26 | E33: Pre Market | F33: Dec-25 | G33: 32675.86
B34: ADVANC | C34: Advanced Info Service Public Company Limited | D34: 03-Feb-26 | F34: Dec-25 | G34: 32414.91
B35: WTW | C35: Willis Towers Watson Public Limited Company | D35: 03-Feb-26 | E35: Pre Market | F35: Dec-25 | G35: 31540.55
B36: ADM | C36: Archer-Daniels-Midland Company | D36: 03-Feb-26 | E36: Pre Market | F36: Dec-25 | G36: 31323.54
B37: 512599 | C37: Adani Enterprises Limited | D37: 03-Feb-26 | F37: Dec-25 | G37: 30725.1
B38: ATO | C38: Atmos Energy Corporation | D38: 03-Feb-26 | E38: After Hours | F38: Dec-25 | G38: 27573.18
B39: HUBB | C39: Hubbell Incorporated | D39: 03-Feb-26 | F39: Dec-25 | G39: 26004.26
B40: BR | C40: Broadridge Financial Solutions, Inc. | D40: 03-Feb-26 | E40: Pre Market | F40: Dec-25 | G40: 25521.31
B41: VLTO | C41: Veralto Corporation | D41: 03-Feb-26 | F41: Jan-26 | G41: 25492.69
...

Sheet Revenue
B2: Ticker | C2: Country | D2: Industry | E2: Latest_Date | F2: Growth_Rate | G2: 4Q21 | H2: 1Q22 | I2: 2Q22 | J2: 3Q22 | K2: 4Q22 | L2: 1Q23 | M2: 2Q23 | N2: 3Q23 | O2: 4Q23 | P2: 1Q24 | Q2: 2Q24 | R2: 3Q24 | S2: 4Q24 | T2: 1Q25 | U2: 2Q25 | V2: 3Q25 | W2: 4Q25 | X2: 1Q25 | Y2: 2Q25 | Z2: 3Q25 | AA2: 4Q25
B3: SMCI | C3: United States | D3: Computer Hardware | E3: Jun'26 | F3: 33.3 | G3: 1172 | H3: 1355 | I3: 1635 | J3: 1852 | K3: 1803 | L3: 1283 | M3: 2185 | N3: 2120 | O3: 3665 | P3: 3850 | Q3: 5355 | R3: 5937 | S3: 5678 | T3: 4600 | U3: 5757 | V3: 5018 | W3: 12682 | X3: 0.036023055 | Y3: 0.018636996 | Z3: -0.04182596 | AA3: 0.33268418
B4: LITE | C4: United States | D4: Communication Equipment | E4: Jun'26 | F4: 14.3 | G4: 446.7 | H4: 395.4 | I4: 422.1 | J4: 506.8 | K4: 506 | L4: 383.4 | M4: 370.8 | N4: 317.6 | O4: 366.8 | P4: 366.5 | Q4: 308.3 | R4: 336.9 | S4: 402.2 | T4: 425.2 | U4: 480.7 | V4: 533.8 | W4: 665.5 | X4: 0.041516373 | Y4: 0.11707185 | Z4: 0.11969605 | AA4: 0.14295021
B5: AMCR | C5: United States | D5: Packaging & Containers | E5: Jun'26 | F5: 12.7 | G5: 3507 | H5: 3708 | I5: 3909 | J5: 3712 | K5: 3642 | L5: 3667 | M5: 3673 | N5: 3443 | O5: 3251 | P5: 3411 | Q5: 3535 | R5: 3353 | S5: 3241 | T5: 3333 | U5: 5082 | V5: 5745 | W5: 5449 | X5: -0.005760709 | Y5: 0.11491606 | Z5: 0.15937104 | AA5: 0.12688926
B6: BDN | C6: United States | D6: REIT - Office | E6: Dec'25 | F6: 11 | G6: 117.65 | H6: 120.49 | I6: 121.62 | J6: 119.48 | K6: 120.12 | L6: 123.1 | M6: 118.35 | N6: 119.24 | O6: 77.14 | P6: 112.67 | Q6: 111.27 | R6: 6.17 | S6: 77.38 | T6: 111.21 | U6: 105.34 | V6: 103.14 | W6: 120.95 | X6: -0.0047481219 | Y6: -0.019377185 | Z6: 0.32312562 | AA6: 0.10972876
B7: SIMO | C7: United States | D7: Semiconductors | E7: Dec'25 | F7: 10.9 | G7: 264.36 | H7: 241.98 | I7: 252.37 | J7: 250.81 | K7: 200.76 | L7: 124.07 | M7: 140.36 | N7: 172.33 | O7: 202.38 | P7: 189.31 | Q7: 210.67 | R7: 212.41 | S7: 191.16 | T7: 166.49 | U7: 198.68 | V7: 242 | W7: 278.46 | X7: -0.02839898 | Y7: -0.015357422 | Z7: 0.038491558 | AA7: 0.10935327
B8: AMD | C8: United States | D8: Semiconductors | E8: Dec'25 | F8: 8.2 | G8: 4826 | H8: 5887 | I8: 6550 | J8: 5565 | K8: 5599 | L8: 5353 | M8: 5359 | N8: 5800 | O8: 6168 | P8: 5473 | Q8: 5835 | R8: 6819 | S8: 7658 | T8: 7438 | U8: 7685 | V8: 9246 | W8: 10270 | X8: 0.076207097 | Y8: 0.066666667 | Z8: 0.081993243 | AA8: =SUM(T8:W8)/SUM(S8:V8)-1 -> 0.081556187
B9: RES | C9: United States | D9: Oil & Gas Equipment & Services | E9: Dec'25 | F9: 5.9 | G9: 268.25 | H9: 284.62 | I9: 375.51 | J9: 459.6 | K9: 482.03 | L9: 476.67 | M9: 415.86 | N9: 330.42 | O9: 394.53 | P9: 377.83 | Q9: 364.15 | R9: 337.65 | S9: 335.36 | T9: 332.88 | U9: 420.81 | V9: 447.1 | W9: 425.78 | X9: -0.031767009 | Y9: 0.041356457 | Z9: 0.076715497 | AA9: 0.058861439
B10: TRNS | C10: United States | D10: Specialty Business Services | E10: Sep'26 | F10: 5.7 | G10: 50.9 | H10: 55.88 | I10: 54.66 | J10: 56.44 | K10: 57.4 | L10: 62.07 | M10: 60.6 | N10: 62.8 | O10: 65.17 | P10: 70.91 | Q10: 66.71 | R10: 67.83 | S10: 66.75 | T10: 77.13 | U10: 76.42 | V10: 82.27 | W10: 83.86 | X10: 0.022850845 | Y10: 0.034875368 | Z10: 0.050116267 | AA10: 0.056548898
B11: MSGE | C11: United States | D11: Leisure | E11: Jun'26 | F11: 5.5 | G11: -13.35 | H11: 193.99 | I11: 178.34 | J11: 146.45 | K11: 355.88 | L11: 201.23 | M11: 147.94 | N11: 142.21 | O11: 402.67 | P11: 228.31 | Q11: 186.07 | R11: 138.71 | S11: 407.42 | T11: 242.47 | U11: 154.14 | V11: 158.26 | W11: 459.94 | X11: 0.014742168 | Y11: -0.032759806 | Z11: 0.020737425 | AA11: 0.054578142
B12: TTWO | C12: United States | D12: Electronic Gaming & Multimedia | E12: Sep'26 | F12: 5.4 | G12: 903.3 | H12: 930 | I12: 1102 | J12: 1394 | K12: 1408 | L12: 1446 | M12: 1285 | N12: 1299 | O12: 1366 | P12: 1399 | Q12: 1338 | R12: 1353 | S12: 1360 | T12: 1583 | U12: 1504 | V12: 1774 | W12: 1699 | X12: 0.033761468 | Y12: 0.029463969 | Z12: 0.072586207 | AA12: 0.054492847
B13: ATS | C13: United States | D13: Specialty Industrial Machinery | E13: Jun'26 | F13: 4.5 | G13: 522.13 | H13: 546.8 | I13: 603.16 | J13: 610.59 | K13: 588.95 | L13: 647.05 | M13: 730.79 | N13: 753.65 | O13: 735.72 | P13: 752.05 | Q13: 791.47 | R13: 694.27 | S13: 612.78 | T13: 651.99 | U13: 574.24 | V13: 736.72 | W13: 728.46 | X13: -0.035101752 | Y13: -0.07897808 | Z13: 0.016756932 | AA13: 0.04491154
B14: PGC | C14: United States | D14: Banks - Regional | E14: Dec'25 | F14: 4.3 | G14: 52.43 | H14: 51.96 | I14: 59.95 | J14: 61.31 | K14: 62.9 | L14: 60.52 | M14: 55.8 | N14: 50.01 | O14: 49.2 | P14: 52.45 | Q14: 52.69 | R14: 55.4 | S14: 59.86 | T14: 59.89 | U14: 63.16 | V14: 65.9 | W14: 70.53 | X14: 0.033756806 | Y14: 0.045953301 | Z14: 0.044060258 | AA14: 0.042884128
B15: HLNE | C15: United States | D15: Asset Management | E15: Sep'26 | F15: 4.1 | G15: 91.7 | H15: 100.9 | I15: 135.51 | J15: 153.38 | K15: 127.07 | L15: 112.79 | M15: 125.04 | N15: 126.88 | O15: 125.26 | P15: 176.67 | Q15: 196.73 | R15: 150 | S15: 168.26 | T15: 197.97 | U15: 175.96 | V15: 190.88 | W15: 198.59 | X15: 0.030795478 | Y15: -0.029132069 | Z15: 0.059058929 | AA15: 0.041373948
B16: SR | C16: United States | D16: Utilities - Regulated Gas | E16: Mar'26 | F16: 3.8 | G16: 555.4 | H16: 880.9 | I16: 448 | J16: 314.2 | K16: 814 | L16: 1123 | M16: 418.5 | N16: 310.4 | O16: 756.6 | P16: 1129 | Q16: 414.1 | R16: 293.8 | S16: 669.1 | T16: 1051 | U16: 421.9 | V16: 334.1 | W16: 762.2 | X16: -0.031125299 | Y16: 0.0032125206 | Z16: 0.016544872 | AA16: 0.037599451
B17: BALL | C17: United States | D17: Packaging & Containers | E17: Dec'25 | F17: 3.7 | G17: 3674 | H17: 3716 | I17: 4134 | J17: 3951 | K17: 3548 | L17: 2981 | M17: 3067 | N17: 3111 | O17: 2903 | P17: 2874 | Q17: 2959 | R17: 3082 | S17: 2880 | T17: 3097 | U17: 3338 | V17: 3379 | W17: 3347 | X17: 0.018906316 | Y17: 0.031536029 | Z17: 0.023957409 | AA17: 0.036789034
B18: INTA | C18: United States | D18: Software - Application | E18: Jun'26 | F18: 3.6 | G18: 64.7 | H18: 69.66 | I18: 75.52 | J18: 79.54 | K18: 84.69 | L18: 92.02 | M18: 94.62 | N18: 101.58 | O18: 103.93 | P18: 110.64 | Q18: 114.38 | R18: 118.81 | S18: 121.21 | T18: 129.07 | U18: 135.04 | V18: 139.03 | W18: 140.21 | X18: 0.039630999 | Y18: 0.042732745 | Z18: 0.040108702 | AA18: 0.036235339
B19: ATO | C19: United States | D19: Utilities - Regulated Gas | E19: Mar'26 | F19: 3.6 | G19: 1013 | H19: 1650 | I19: 816.43 | J19: 722.63 | K19: 1484 | L19: 1541 | M19: 662.73 | N19: 587.64 | O19: 1158 | P19: 1647 | Q19: 701.55 | R19: 657.94 | S19: 1176 | T19: 1951 | U19: 838.77 | V19: 737.48 | W19: 1343 | X19: 0.072683975 | Y19: 0.030585157 | Z19: 0.017202636 | AA19: 0.035507362
B20: INNV | C20: United States | D20: Medical Care Facilities | E20: Jun'26 | F20: 3.5 | G20: 175.35 | H20: 177.36 | I20: 172.86 | J20: 171.22 | K20: 167.46 | L20: 172.54 | M20: 176.87 | N20: 182.49 | O20: 188.9 | P20: 193.07 | Q20: 199.4 | R20: 205.14 | S20: 209 | T20: 218.14 | U20: 221.42 | V20: 236.11 | W20: 239.71 | X20: 0.031080696 | Y20: 0.026476529 | Z20: 0.036277381 | AA20: 0.034713509
... B23: AME | C23: United States | D23: Specialty Industrial Machinery | E23: Dec'25 | F23: 3.3 | G23: 1504 | H23: 1459 | I23: 1515 | J23: 1552 | K23: 1626 | L23: 1597 | M23: 1646 | N23: 1623 | O23: 1731 | P23: 1736 | Q23: 1735 | R23: 1709 | S23: 1762 | T23: 1732 | U23: 1778 | V23: 1893 | W23: 1998 | X23: -0.00057620282 | Y23: 0.0061977515 | Z23: 0.026357255 | AA23: 0.032937893
B24: APPS | C24: United States | D24: =VLOOKUP(B24,기업리스트!B:G,2,FALSE) -> Digital Turbine, Inc. | E24: Sep'26 | F24: 3.2 | G24: 216.82 | H24: 184.14 | I24: 188.63 | J24: 174.86 | K24: 162.31 | L24: 140.12 | M24: 146.37 | N24: 143.26 | O24: 142.63 | P24: 112.22 | Q24: 117.99 | R24: 118.73 | S24: 134.64 | T24: 119.15 | U24: 130.93 | V24: 140.38 | W24: 151.4 | X24: 0.014330617 | Y24: 0.026380706 | Z24: 0.043003277 | AA24: 0.03191773
B25: TDG | C25: United States | D25: Aerospace & Defense | E25: Mar'26 | F25: 3.2 | G25: 1194 | H25: 1327 | I25: 1398 | J25: 1510 | K25: 1397 | L25: 1592 | M25: 1744 | N25: 1852 | O25: 1789 | P25: 1919 | Q25: 2046 | R25: 2186 | S25: 2006 | T25: 2150 | U25: 2237 | V25: 2437 | W25: 2285 | X25: 0.028319235 | Y25: 0.022770625 | Z25: 0.029257489 | AA25: 0.031596829
B26: MPLX | C26: United States | D26: Oil & Gas Midstream | E26: Dec'25 | F26: 3.1 | G26: 2641 | H26: 2511 | I26: 2829 | J26: 3276 | K26: 2521 | L26: 2579 | M26: 2545 | N26: 2753 | O26: 2804 | P26: 2689 | Q26: 2707 | R26: 2823 | S26: 2892 | T26: 2938 | U26: 2833 | V26: 2949 | W26: 3252 | X26: 0.022410224 | Y26: 0.011091549 | Z26: 0.010969876 | AA26: 0.031002411
B27: ETN | C27: United States | D27: Specialty Industrial Machinery | E27: Dec'25 | F27: 3.1 | G27: 4798 | H27: 4843 | I27: 5212 | J27: 5313 | K27: 5384 | L27: 5483 | M27: 5866 | N27: 5880 | O27: 5967 | P27: 5943 | Q27: 6350 | R27: 6345 | S27: 6240 | T27: 6377 | U27: 7028 | V27: 6988 | W27: 7055 | X27: 0.017445132 | Y27: 0.026785714 | Z27: 0.024740285 | AA27: 0.030601134
B28: J | C28: United States | D28: Engineering & Construction | E28: Mar'26 | F28: 3 | G28: 3381 | H28: 3834 | I28: 3827 | J28: 3881 | K28: 3799 | L28: 4078 | M28: 4187 | N28: -1212 | O28: 2810 | P28: 2847 | Q28: 2883 | R28: 0 | S28: 2933 | T28: 2910 | U28: 3032 | V28: 3155 | W28: 3293 | X28: 0.0072723075 | Y28: 0.017075407 | Z28: 0.35549296 | AA28: 0.029925187
B29: PRU | C29: United States | D29: Insurance - Life | E29: Dec'25 | F29: 3 | G29: 16424 | H29: 11855 | I29: 11392 | J29: 20201 | K29: 11135 | L29: 17045 | M29: 13498 | N29: 8352 | O29: 15084 | P29: 23509 | Q29: 14883 | R29: 19490 | S29: 12523 | T29: 13470 | U29: 13726 | V29: 17879 | W29: 14229 | X29: -0.1425893 | Y29: -0.019166418 | Z29: -0.027208701 | AA29: 0.029619084
B30: HUBB | C30: United States | D30: Electrical Equipment & Parts | E30: Dec'25 | F30: 2.8 | G30: 1100 | H30: 1156 | I30: 1256 | J30: 1316 | K30: 1220 | L30: 1285 | M30: 1366 | N30: 1376 | O30: 1346 | P30: 1399 | Q30: 1453 | R30: 1443 | S30: 1334 | T30: 1365 | U30: 1484 | V30: 1502 | W30: 1493 | X30: -0.0060401492 | Y30: 0.0055406613 | Z30: 0.010487025 | AA30: 0.027968338
B31: VRNS | C31: United States | D31: Software - Infrastructure | E31: Dec'25 | F31: 2.4 | G31: 126.58 | H31: 96.26 | I31: 111.45 | J31: 123.31 | K31: 142.62 | L31: 107.34 | M31: 115.42 | N31: 122.31 | O31: 154.1 | P31: 114.02 | Q31: 130.35 | R31: 148.07 | S31: 158.51 | T31: 136.42 | U31: 152.16 | V31: 161.58 | W31: 173.37 | X31: 0.040657047 | Y31: 0.038039592 | Z31: 0.022699778 | AA31: 0.024413886
B32: BR | C32: United States | D32: Information Technology Services | E32: Mar'26 | F32: 2.4 | G32: 1193 | H32: 1260 | I32: 1534 | J32: 1723 | K32: 1283 | L32: 1293 | M32: 1646 | N32: 1839 | O32: 1431 | P32: 1405 | Q32: 1727 | R32: 1944 | S32: 1423 | T32: 1589 | U32: 1812 | V32: 2065 | W32: 1589 | X32: 0.028312048 | Y32: 0.012718839 | Z32: 0.017878251 | AA32: 0.024096386
B33: MDLZ | C33: United States | D33: Confectioners | E33: Dec'25 | F33: 2.4 | G33: 7658 | H33: 7764 | I33: 7274 | J33: 7763 | K33: 8695 | L33: 9166 | M33: 8507 | N33: 9029 | O33: 9314 | P33: 9290 | Q33: 8343 | R33: 9204 | S33: 9604 | T33: 9313 | U33: 8984 | V33: 9744 | W33: 10496 | X33: 0.00063115721 | Y33: 0.017578982 | Z33: 0.014553295 | AA33: 0.023695046
B34: ZWS | C34: United States | D34: Pollution & Treatment Controls | E34: Dec'25 | F34: 2.2 | G34: 232.3 | H34: 239.6 | I34: 284.2 | J34: 417.7 | K34: 340.3 | L34: 372.1 | M34: 403.2 | N34: 398.4 | O34: 356.8 | P34: 373.8 | Q34: 412 | R34: 410 | S34: 370.7 | T34: 388.8 | U34: 444.5 | V34: 455.4 | W34: 407.2 | X34: 0.0095754868 | Y34: 0.020550111 | Z34: 0.028128872 | AA34: 0.021995902
B35: AMGN | C35: United States | D35: Drug Manufacturers - General | E35: Dec'25 | F35: 2.2 | G35: 6846 | H35: 6238 | I35: 6594 | J35: 6652 | K35: 6839 | L35: 6105 | M35: 6986 | N35: 6903 | O35: 8196 | P35: 7447 | Q35: 8388 | R35: 8503 | S35: 9086 | T35: 8149 | U35: 9179 | V35: 9557 | W35: 9866 | X35: 0.021002872 | Y35: 0.023178808 | Z35: 0.030185869 | AA35: 0.021684134
B36: SWKS | C36: United States | D36: Semiconductors | E36: Dec'25 | F36: 1.9 | G36: 1311 | H36: 1510 | I36: 1336 | J36: 1233 | K36: 1407 | L36: 1329 | M36: 1153 | N36: 1071 | O36: 1219 | P36: 1202 | Q36: 1046 | R36: 905.5 | S36: 1025 | T36: 1069 | U36: 953.2 | V36: 965 | W36: 1100 | X36: -0.031829604 | Y36: -0.022939068 | Z36: 0.015053002 | AA36: 0.018692986
... B54: MLI | C54: United States | D54: Metal Fabrication | E54: Dec'25 | F54: 0.9 | G54: 956.36 | H54: 1010 | I54: 1150 | J54: 944.83 | K54: 877.58 | L54: 971.19 | M54: 896.98 | N54: 819.79 | O54: 732.38 | P54: 849.65 | Q54: 997.75 | R54: 997.83 | S54: 923.54 | T54: 1000 | U54: 1138 | V54: 1078 | W54: 962.39 | X54: 0.039893652 | Y54: 0.035786095 | Z54: 0.01974937 | AA54: 0.0093851008
B55: VLTO | C55: United States | D55: Pollution & Treatment Controls | E55: Dec'25 | F55: 0.9 | H55: 1172 | I55: 1231 | J55: 1219 | K55: 1248 | L55: 1225 | M55: 1253 | N55: 1255 | O55: 1288 | P55: 1246 | Q55: 1288 | R55: 1314 | S55: 1345 | T55: 1332 | U55: 1371 | V55: 1404 | W55: 1396 | X55: 0.016560755 | Y55: 0.015722675 | Z55: 0.016784782 | AA55: 0.0093543654
B56: POWL | C56: United States | D56: Electrical Equipment & Parts | E56: Mar'26 | F56: 0.9 | G56: 106.57 | H56: 127.85 | I56: 135.48 | J56: 162.68 | K56: 126.86 | L56: 171.44 | M56: 192.37 | N56: 208.64 | O56: 194.02 | P56: 255.11 | Q56: 288.17 | R56: 275.06 | S56: 241.43 | T56: 278.63 | U56: 286.27 | V56: 297.98 | W56: 251.18 | X56: 0.022193495 | Y56: -0.0017539163 | Z56: 0.021194944 | AA56: 0.0088290426
B57: CRVL | C57: United States | D57: Insurance Brokers | E57: Sep'26 | F57: 0.8 | G57: 164.51 | H57: 171.36 | I57: 176.31 | J57: 177.43 | K57: 179.39 | L57: 185.44 | M57: 190.25 | N57: 195.52 | O57: 202.3 | P57: 207.23 | Q57: 211.72 | R57: 224.38 | S57: 227.97 | T57: 231.51 | U57: 234.71 | V57: 239.64 | W57: 235.63 | X57: 0.027866407 | Y57: 0.025670515 | Z57: 0.016612779 | AA57: 0.0082027778
B58: FUBO | C58: United States | D58: Broadcasting | E58: Dec'25 | F58: 0.8 | P58: 1051 | Q58: 1076 | R58: 1058 | S58: 1058 | T58: 1116 | U58: 1125 | V58: 1091 | W58: 1091 | X58: 0.01531935 | Y58: 0.011374188 | Z58: 0.0075740188 | AA58: 0.0075170843
B59: IT | C59: United States | D59: Information Technology Services | E59: Dec'25 | F59: 0.6 | G59: 1306 | H59: 1263 | I59: 1377 | J59: 1332 | K59: 1505 | L59: 1409 | M59: 1503 | N59: 1409 | O59: 1586 | P59: 1473 | Q59: 1595 | R59: 1484 | S59: 1715 | T59: 1534 | U59: 1686 | V59: 1524 | W59: 1753 | X59: 0.0097335248 | Y59: 0.014380531 | Z59: 0.0062315002 | AA59: 0.0058832637
B60: BV | C60: United States | D60: Specialty Business Services | E60: Mar'26 | F60: 0.6 | G60: 591.8 | H60: 711.9 | I60: 747.4 | J60: 723.4 | K60: 655.9 | L60: 650.4 | M60: 766 | N60: 743.7 | O60: 626.7 | P60: 672.9 | Q60: 738.8 | R60: 728.7 | S60: 599.2 | T60: 662.5 | U60: 708.3 | V60: 702.8 | W60: 614.7 | X60: -0.0037961746 | Y60: -0.011175436 | Z60: -0.0095972135 | AA60: 0.0057991619
...

Sheet Operating Income
B2: Ticker | C2: Country | D2: Industry | E2: Latest_Date | F2: Growth_Rate | G2: 4Q21 | H2: 1Q22 | I2: 2Q22 | J2: 3Q22 | K2: 4Q22 | L2: 1Q23 | M2: 2Q23 | N2: 3Q23 | O2: 4Q23 | P2: 1Q24 | Q2: 2Q24 | R2: 3Q24 | S2: 4Q24 | T2: 1Q25 | U2: 2Q25 | V2: 3Q25 | W2: 4Q25 | X2: 1Q25 | Y2: 2Q25 | Z2: 3Q25 | AA2: 4Q25
B3: KREF | C3: United States | D3: REIT - Mortgage | E3: Dec'25 | F3: 1180.3 | G3: 35.67 | H3: 35.41 | I3: 25 | J3: -42.92 | K3: 18.86 | L3: -25.09 | M3: -19.95 | N3: 27 | O3: -12.91 | P3: -3.39 | Q3: 25.6 | R3: -7.24 | S3: 19.6 | T3: -5.75 | U3: -30.57 | V3: 12.77 | W3: -27.02 | X3: -0.068267284 | Y3: -1.7438684 | Z3: -0.8351419 | AA3: 11.802532
B4: INNV | C4: United States | D4: Medical Care Facilities | E4: Jun'26 | F4: 239.2 | G4: 2.95 | H4: -6.27 | I4: -12.35 | J4: -16.6 | K4: -13.68 | L4: -8.17 | M4: -10.94 | N4: -10.72 | O4: -1.79 | P4: -5.79 | Q4: -4.88 | R4: -4.9 | S4: -4.06 | T4: -10.16 | U4: 13.07 | V4: 8.39 | W4: 13.26 | X4: 0.22261844 | Y4: -0.74791667 | Z4: -2.1966942 | AA4: 2.3922652
B5: IAC | C5: United States | D5: Internet Content & Information | E5: Dec'25 | F5: 63.8 | G5: -4.52 | H5: -117.74 | I5: -106.37 | J5: -97.26 | K5: 0 | L5: -65.5 | M5: -51.8 | N5: -15.39 | O5: -105.06 | P5: -63.37 | Q5: -21.54 | R5: 8.15 | S5: 51.24 | T5: 35.67 | U5: 0.68 | V5: -20.4 | W5: 94.08 | X5: -3.8808777 | Y5: 0.30223069 | Z5: -0.29820347 | AA5: 0.63759488
B6: ATS | C6: United States | D6: Specialty Industrial Machinery | E6: Jun'26 | F6: 60.8 | G6: 43.65 | H6: 53.69 | I6: 66.61 | J6: 67.15 | K6: 58.72 | L6: 67.17 | M6: 69.13 | N6: 79.15 | O6: 84.22 | P6: 96.46 | Q6: 88.05 | R6: 69.89 | S6: 40.94 | T6: 39.54 | U6: -84.45 | V6: 60.58 | W6: 75.34 | X6: -0.19272703 | Y6: -0.72351313 | Z6: -0.1412318 | AA6: 0.60766649
B7: HTLD | C7: United States | D7: Trucking | E7: Dec'25 | F7: 59.2 | G7: 16.41 | H7: 18.14 | I7: 23.34 | J7: 27.91 | K7: 22.07 | L7: 16.1 | M7: 8.21 | N7: -8.51 | O7: -14.51 | P7: -14.29 | Q7: -0.86 | R7: -7.62 | S7: -4.98 | T7: -16.68 | U7: -15.2 | V7: -13.94 | W7: -35.04 | X7: 0.086126126 | Y7: 0.47577969 | Z7: 0.14208633 | AA7: 0.59173228
B8: PRU | C8: United States | D8: Insurance - Life | E8: Dec'25 | F8: 57.7 | G8: 2448 | H8: -657 | I8: -1061 | J8: -126 | K8: -1435 | L8: 1847 | M8: 621 | N8: -1058 | O8: 2069 | P8: 1390 | Q8: 1415 | R8: 553 | S8: -148 | T8: 920 | U8: 740 | V8: 1773 | W8: 1747 | X8: -0.14641745 | Y8: -0.24635036 | Z8: 0.59079903 | AA8: 0.57686454
B9: MPC | C9: United States | D9: Oil & Gas Refining & Marketing | E9: Dec'25 | F9: 28.4 | G9: 1610 | H9: 1613 | I9: 8110 | J9: 5462 | K9: 0 | L9: 3948 | M9: 3118 | N9: 4448 | O9: 2130 | P9: 1571 | Q9: 2161 | R9: 1140 | S9: 886 | T9: 452 | U9: 1973 | V9: 1733 | W9: 2321 | X9: -0.19433831 | Y9: -0.040525975 | Z9: 0.13322849 | AA9: 0.28449643
B10: AMD | C10: United States | D10: Semiconductors | E10: Dec'25 | F10: 22.899506 | G10: 1174 | H10: 951 | I10: 526 | J10: -64 | K10: -149 | L10: -145 | M10: -20 | N10: 224 | O10: 342 | P10: 36 | Q10: 269 | R10: 724 | S10: 1057 | T10: 806 | U10: -98 | V10: 1270 | W10: 1752 | X10: 0.36912752 | Y10: -0.1285014 | Z10: 0.21936521 | AA10: 0.22899506
B11: MSGE | C11: United States | D11: Leisure | E11: Jun'26 | F11: 19.8 | G11: 59.98 | H11: 21.19 | I11: -5.27 | J11: -11.31 | K11: 116.62 | L11: 27.42 | M11: -25.42 | N11: -20.48 | O11: 137.25 | P11: 18.31 | Q11: -6.9 | R11: -19.38 | S11: 138.11 | T11: 36.25 | U11: -23.19 | V11: -15.41 | W11: 164.94 | X11: 0.13785154 | Y11: -0.1100081 | Z11: 0.030123682 | AA11: 0.19762817
B12: SIMO | C12: United States | D12: Semiconductors | E12: Dec'25 | F12: 17.7 | G12: 68.87 | H12: 66.46 | I12: 67.85 | J12: 55.07 | K12: 24.93 | L12: 5.52 | M12: 5.04 | N12: 15.69 | O12: 14.94 | P12: 17.95 | Q12: 32.04 | R12: 24.46 | S12: 17.69 | T12: 9.77 | U12: 22.33 | V12: 29.23 | W12: 31.71 | X12: -0.088777947 | Y12: -0.11565031 | Z12: 0.064242424 | AA12: 0.17742344
B13: CPRI | C13: United States | D13: Luxury Goods | E13: Sep'26 | F13: 17.2 | G13: 343 | H13: 172 | I13: 233 | J13: 263 | K13: 237 | L13: 89 | M13: 78 | N13: 124 | O13: 141 | P13: 41 | Q13: 17 | R13: 25 | S13: 69 | T13: -39 | U13: 17 | V13: 11 | W13: 79 | X13: -0.52631579 | Y13: 0 | Z13: -0.19444444 | AA13: 0.17241379
B14: VRNS | C14: United States | D14: Software - Infrastructure | E14: Dec'25 | F14: 15.3 | G14: -17.83 | H14: -48.09 | I14: -37.57 | J14: -25.58 | K14: -9.99 | L14: -43.12 | M14: -39.72 | N14: -29.15 | O14: -5.24 | P14: -47.63 | Q14: -28.83 | R14: -23.64 | S14: -10.9 | T14: -43.16 | U14: -36.55 | V14: -35.93 | W14: -30.26 | X14: -0.04027027 | Y14: 0.072467849 | Z14: 0.10757112 | AA14: 0.1529951
... B34: RNR | C34: United States | D34: Insurance - Reinsurance | E34: Sep'25 | F34: -7.7 | G34: -645.83 | H34: 337.76 | I34: -406.75 | J34: -234.56 | K34: -1173 | L34: 700.34 | M34: 895.83 | N34: 420.4 | O34: 478.06 | P34: 1507 | Q34: 712.93 | R34: 757.5 | S34: 1742 | T34: -57.4 | U34: -34.97 | V34: 1366 | W34: 1510 | X34: -0.33148071 | Y34: -0.23705004 | Z34: 0.25279067 | AA34: -0.076932515
B35: SSII | C35: United States | D35: Medical Devices | E35: Sep'25 | F35: -12.5 | I35: -0.94 | J35: -0.71 | K35: -0.43 | L35: -4.53 | M35: -0.91 | N35: -5.36 | O35: -1.85 | P35: -12.16 | Q35: -9.83 | R35: -4.1 | S35: -3.2 | T35: -1.84 | U35: -5.92 | V35: 0.1 | W35: -1.84 | X35: -0.35233868 | Y35: -0.20611492 | Z35: -0.27888446 | AA35: -0.1252302
B36: SNT | C36: United States | D36: Security & Protection Services | E36: Sep'25 | F36: -12.6 | G36: 0.78 | H36: -1.24 | I36: -0.67 | J36: 0.11 | K36: 1.13 | L36: 0.92 | M36: -1.73 | N36: 0.08 | O36: 0.12 | P36: 0.26 | Q36: -0.07 | R36: 0.67 | S36: 1.82 | T36: 1.47 | U36: 1.05 | V36: 0.97 | W36: 1.15 | X36: 0.45149254 | Y36: 0.28791774 | Z36: 0.05988024 | AA36: -0.12617702
B37: APAM | C37: United States | D37: Asset Management | E37: Dec'25 | F37: 5.6 | G37: 137.82 | H37: 106.99 | I37: 88.41 | J37: 78.73 | K37: 71.39 | L37: 68.31 | M37: 76.7 | N37: 82.16 | O37: 76.43 | P37: 77.64 | Q37: 86.65 | R37: 93.18 | S37: 110.14 | T37: 86.54 | U37: 79.77 | V37: 101.82 | W37: 131.5 | X37: 0.02421044 | Y37: -0.018273087 | Z37: 0.023374726 | AA37: 0.056467603
B38: BHE | C38: United States | D38: Electronic Components | E38: Dec'25 | F38: 4.9 | G38: 22.73 | H38: 19.7 | I38: 21.32 | J38: 26.62 | K38: 31 | L38: 24.17 | M38: 27.77 | N38: 31.98 | O38: 34.15 | P38: 28.87 | Q38: 28.72 | R38: 28.9 | S38: 29.25 | T38: 23.18 | U38: 23 | V38: 25.22 | W38: 34.2 | X38: -0.049161915 | Y38: -0.051976374 | Z38: -0.035272692 | AA38: 0.049180328
B39: PFE | C39: United States | D39: Drug Manufacturers - General | E39: Dec'25 | F39: 4.9 | G39: 6745 | H39: 10349 | I39: 12286 | J39: 10148 | K39: 6216 | L39: 6865 | M39: 2788 | N39: -2386 | O39: 5234 | P39: 4706 | Q39: 2973 | R39: 5838 | S39: 2825 | T39: 4823 | U39: 4203 | V39: 5875 | W39: 3688 | X39: 0.0071594664 | Y39: 0.07473115 | Z39: 0.0020916954 | AA39: 0.048685547
B40: BR | C40: United States | D40: Information Technology Services | E40: Mar'26 | F40: 4.6 | G40: 103.3 | H40: 68.9 | I40: 246 | J40: 341.7 | K40: 87.6 | L40: 107.9 | M40: 286.8 | N40: 454.2 | O40: 148.5 | P40: 124.4 | Q40: 303 | R40: 441.4 | S40: 134.5 | T40: 210.6 | U40: 344.9 | V40: 498.7 | W40: 188.7 | X40: 0.085916476 | Y40: 0.038458008 | Z40: 0.050645218 | AA40: 0.045596029
B41: HUBB | C41: United States | D41: Electrical Equipment & Parts | E41: Dec'25 | F41: 4.4 | G41: 135.7 | H41: 143.7 | I41: 187.8 | J41: 208.6 | K41: 171.5 | L41: 244.8 | M41: 289.6 | N41: 277.4 | O41: 227.6 | P41: 223 | Q41: 309.3 | R41: 316.9 | S41: 259.9 | T41: 227.5 | U41: 335.2 | V41: 339.4 | W41: 311.3 | X41: 0.0040573438 | Y41: 0.023257902 | Z41: 0.019745502 | AA41: 0.044234079
B42: MTCH | C42: United States | D42: Internet Content & Information | E42: Dec'25 | F42: 4.3 | G42: 231.92 | H42: 207.82 | I42: 207.32 | J42: 210.64 | K42: 0 | L42: 198.29 | M42: 214.8 | N42: 243.56 | O42: 260.25 | P42: 184.74 | Q42: 204.53 | R42: 241.26 | S42: 253.99 | T42: 172.59 | U42: 208.22 | V42: 281.83 | W42: 293.33 | X42: -0.013736264 | Y42: 0.0042298566 | Z42: 0.046309613 | AA42: 0.04291808
B43: SR | C43: United States | D43: Utilities - Regulated Gas | E43: Mar'26 | F43: 3.9 | G43: 98.8 | H43: 248.9 | I43: 41.7 | J43: 33.2 | K43: 152.4 | L43: 262.5 | M43: 14.2 | N43: -2.2 | O43: 141 | P43: 300.5 | Q43: 32.7 | R43: 22.9 | S43: 152.7 | T43: 310.5 | U43: 73.2 | V43: 3.1 | W43: 173.5 | X43: 0.019654088 | Y43: 0.078064765 | Z43: -0.035401395 | AA43: 0.038554217
B44: MRK | C44: United States | D44: Drug Manufacturers - General | E44: Dec'25 | F44: 3.6 | G44: 3600 | H44: 5817 | I44: 5210 | J44: 5134 | K44: 4329 | L44: 5143 | M44: 5882 | N44: 6083 | O44: -654 | P44: 6699 | Q44: 6384 | R44: 4364 | S44: 5341 | T44: 6221 | U44: 5923 | V44: 7049 | W44: 6236 | X44: -0.020975952 | Y44: -0.02066338 | Z44: 0.12288892 | AA44: 0.036479987
B45: POWL | C45: United States | D45: Electrical Equipment & Parts | E45: Mar'26 | F45: 3.3 | G45: -4.29 | H45: 0.3 | I45: 0.85 | J45: 10.36 | K45: 1.09 | L45: 10.07 | M45: 21.55 | N45: 29.8 | O45: 25.88 | P45: 39.49 | Q45: 57.29 | R45: 56.12 | S45: 35.57 | T45: 58.92 | U45: 60.12 | V45: 63.25 | W45: 42.77 | X45: 0.10309333 | Y45: 0.013612314 | Z45: 0.033834765 | AA45: 0.033048747
B46: HLNE | C46: United States | D46: Asset Management | E46: Sep'26 | F46: 3.3 | G46: 41.05 | H46: 46.27 | I46: 62.53 | J46: 69.83 | K46: 58.37 | L46: 49.32 | M46: 54.94 | N46: 55.6 | O46: 51.39 | P46: 83.89 | Q46: 89.61 | R46: 67.19 | S46: 75.72 | T46: 84.03 | U46: 76.98 | V46: 79.72 | W46: 86.01 | X46: 0.00044246389 | Y46: -0.03989891 | Z46: 0.041227955 | AA46: 0.032516985
B47: ETN | C47: United States | D47: Specialty Industrial Machinery | E47: Dec'25 | F47: 3.2 | G47: 685 | H47: 651 | I47: 719 | J47: 792 | K47: 880 | L47: 811 | M47: 955 | N47: 1070 | O47: 1097 | P47: 1016 | Q47: 1201 | R47: 1221 | S47: 1238 | T47: 1207 | U47: 1305 | V47: 1383 | W47: 1402 | X47: 0.040846878 | Y47: 0.021368399 | Z47: 0.032589016 | AA47: 0.031950127
... B66: J | C66: United States | D66: Engineering & Construction | E66: Mar'26 | F66: 0.5 | G66: 256.02 | H66: 266.2 | I66: 245.75 | J66: 252.13 | K66: 264.46 | L66: 299.52 | M66: 299.9 | N66: -184.71 | O66: 182.92 | P66: 149.36 | Q66: 219.4 | R66: 0 | S66: 227.9 | T66: 194.86 | U66: 264.61 | V66: 331.76 | W66: 232.56 | X66: 0.076257835 | Y66: 0.070403015 | Z66: 0.48265126 | AA66: 0.0045725275
B67: VLTO | C67: United States | D67: Pollution & Treatment Controls | E67: Dec'25 | F67: 0.4 | H67: 231 | I67: 311 | J67: 285 | K67: 295 | L67: 292 | M67: 295 | N67: 273 | O67: 299 | P67: 293 | Q67: 299 | R67: 308 | S67: 311 | T67: 322 | U67: 313 | V67: 326 | W67: 316 | X67: 0.023947151 | Y67: 0.011290323 | Z67: 0.014354067 | AA67: 0.0039308176
B68: JJSF | C68: United States | D68: Packaged Foods | E68: Mar'26 | F68: 0.2 | G68: 14.85 | H68: 4.09 | I68: 21.26 | J68: 25.72 | K68: 9.33 | L68: 10.19 | M68: 48.29 | N68: 43.38 | O68: 11.88 | P68: 17.9 | Q68: 50.12 | R68: 44.84 | S68: 5.74 | T68: 5.72 | U68: 51.48 | V68: 33.7 | W68: 5.95 | X68: -0.10269815 | Y68: 0.012779553 | Z68: -0.10335869 | AA68: 0.0021730132
B69: CMG | C69: United States | D69: Restaurants | E69: Dec'25 | F69: 0.1 | G69: 163 | H69: 194.53 | I69: 342.28 | J69: 342.62 | K69: 302.12 | L69: 375.97 | M69: 448.05 | N69: 402.19 | O69: 369.98 | P69: 446.77 | Q69: 591.82 | R69: 488.43 | S69: 426.36 | T69: 497.3 | U69: 564.52 | V69: 484.58 | W69: 428.78 | X69: 0.025867983 | Y69: -0.013623366 | Z69: -0.0019477793 | AA69: 0.0012267078
B70: PNR | C70: United States | D70: Specialty Industrial Machinery | E70: Dec'25 | F70: 0 | G70: 158.6 | H70: 153.2 | I70: 196 | J70: 175.5 | K70: 197.8 | L70: 195.2 | M70: 215.3 | N70: 182.1 | O70: 171.6 | P70: 203.2 | Q70: 265.1 | R70: 229.3 | S70: 204.8 | T70: 227.1 | U70: 286.9 | V70: 245.1 | W70: 205 | X70: 0.026484929 | Y70: 0.023534492 | Z70: 0.016664909 | AA70: 0.0002074904
B71: VOYA | C71: United States | D71: Financial Conglomerates | E71: Dec'25 | F71: -0.1 | G71: 20 | H71: 171 | I71: 198 | J71: 114 | K71: 232 | L71: 191 | M71: 369 | N71: 248 | O71: 252 | P71: 344 | Q71: 374 | R71: 185 | S71: 198 | T71: 240 | U71: 251 | V71: 367 | W71: 197 | X71: -0.094459582 | Y71: -0.12337011 | Z71: 0.20823799 | AA71: -0.0009469697
B72: MZTI | C72: United States | D72: Packaged Foods | E72: Jun'26 | F72: -0.3 | G72: 45.06 | H72: 13.81 | I72: 44.24 | J72: 49.3 | K72: 51.33 | L72: 29.41 | M72: 36.44 | N72: 56.78 | O72: 65.94 | P72: 50.07 | Q72: 43.87 | R72: 55.86 | S72: 77.47 | T72: 51.59 | U72: 44.09 | V72: 60.4 | W72: 76.85 | X72: 0.0066880803 | Y72: 0.00096158049 | Z72: 0.019824462 | AA72: -0.0026546778
B73: WTW | C73: United States | D73: Insurance Brokers | E73: Dec'25 | F73: -0.5 | G73: 0 | H73: 276 | I73: 300 | J73: 277 | K73: 958 | L73: 375 | M73: 270 | N73: 318 | O73: 965 | P73: 445 | Q73: 333 | R73: 380 | S73: 1045 | T73: 357 | U73: 383 | V73: 432 | W73: 1035 | X73: -0.039945529 | Y73: 0.023640662 | Z73: 0.024018476 | AA73: -0.0045105999
B74: HRB | C74: United States | D74: Personal Services | E74: Jun'26 | F74: -0.7 | G74: -277.3 | H74: 885.37 | I74: 311.6 | J74: -209.11 | K74: -283.2 | L74: 864.5 | M74: 376.51 | N74: -206.33 | O74: -267.43 | P74: 928.2 | Q74: 350.83 | R74: -228.33 | S74: -293.29 | T74: 978.31 | U74: 371.28 | V74: -207.03 | W74: -298.88 | X74: 0.066159676 | Y74: 0.02532445 | Z74: 0.02572557 | AA74: -0.0065821235
B75: ATI | C75: United States | D75: Metal Fabrication | E75: Dec'25 | F75: -1 | G75: 58.1 | H75: 88.4 | I75: 96.4 | J75: 104.1 | K75: 266.2 | L75: 110.2 | M75: 121.2 | N75: 122.4 | O75: 62.7 | P75: 114.6 | Q75: 142.1 | R75: 140.8 | S75: 154.6 | T75: 150.9 | U75: 164.3 | V75: 170.1 | W75: 148 | X75: 0.065748959 | Y75: 0.037729436 | Z75: 0.047985588 | AA75: -0.010314112
B76: GWW | C76: United States | D76: Industrial Distribution | E76: Dec'25 | F76: -1.2 | G76: 588 | H76: 534 | I76: 534 | J76: 603 | K76: 546 | L76: 680 | M76: 661 | N76: 667 | O76: 601 | P76: 669 | Q76: 649 | R76: 686 | S76: 668 | T76: 672 | U76: 678 | V76: 707 | W76: 634 | X76: 0.0011227545 | Y76: 0.010841121 | Z76: 0.0077662722 | AA76: -0.012477064
B77: ADM | C77: United States | D77: Farm Products | E77: Dec'25 | F77: -1.4 | G77: 880 | H77: 1074 | I77: 1292 | J77: 1000 | K77: 805 | L77: 1203 | M77: 1047 | N77: 999 | O77: 751 | P77: 708 | Q77: 489 | R77: 460 | S77: 340 | T77: 248 | U77: 459 | V77: 397 | W77: 320 | X77: -0.23034552 | Y77: -0.019518543 | Z77: -0.04180491 | AA77: -0.013850416
B78: FUBO | C78: United States | D78: Broadcasting | E78: Dec'25 | F78: -1.5 | P78: -38.78 | Q78: -43.98 | R78: -40.75 | S78: -40.75 | T78: -39.75 | U78: -40.91 | V78: -38.39 | W78: -38.39 | X78: 0.0059052721 | Y78: -0.018580161 | Z78: -0.014553527 | AA78: -0.014768461
...

Sheet 빨간줄
B2: (단위: mil $)
B4: NAZARA | C4: 6 | D4: 7 | E4: 8 | F4: 9 | G4: 10 | H4: 11 | I4: 12 | J4: 13 | K4: 14 | L4: 15 | M4: 16 | N4: 17 | O4: 18 | P4: 19 | Q4: 20 | R4: 21 | S4: 22
C6: 4Q21 | D6: 1Q22 | E6: 2Q22 | F6: 3Q22 | G6: 4Q22 | H6: 1Q23 | I6: 2Q23 | J6: 3Q23 | K6: 4Q23 | L6: 1Q24 | M6: 2Q24 | N6: 3Q24 | O6: 4Q24 | P6: 1Q25 | Q6: 2Q25 | R6: 3Q25 | S6: 4Q25 | T6: 1Q26 | U6: 2Q26 | V6: 3Q26 | W6: 4Q26
B7: Revenue | C7: =IFERROR(VLOOKUP($B$4,Revenue!$B$2:$X$500,C$4,FALSE),"-") -> 1296 | D7: =IFERROR(VLOOKUP($B$4,Revenue!$B$2:$X$500,D$4,FALSE),"-") -> 1858 | E7: =IFERROR(VLOOKUP($B$4,Revenue!$B$2:$X$500,E$4,FALSE),"-") -> 1775 | F7: =IFERROR(VLOOKUP($B$4,Revenue!$B$2:$X$500,F$4,FALSE),"-") -> 2231 | G7: =IFERROR(VLOOKUP($B$4,Revenue!$B$2:$X$500,G$4,FALSE),"-") -> 2638 | H7: =IFERROR(VLOOKUP($B$4,Revenue!$B$2:$X$500,H$4,FALSE),"-") -> 3148 | I7: =IFERROR(VLOOKUP($B$4,Revenue!$B$2:$X$500,I$4,FALSE),"-") -> 2894 | J7: =IFERROR(VLOOKUP($B$4,Revenue!$B$2:$X$500,J$4,FALSE),"-") -> 2544 | ... S7: =IFERROR(VLOOKUP($B$4,Revenue!$B$2:$X$500,S$4,FALSE),"-") -> 5265
B8: OP | C8: =IFERROR(VLOOKUP($B$4,'Operating Income'!$B$2:$X$500,C$4,FALSE),"-") -> 99 | D8: =IFERROR(VLOOKUP($B$4,'Operating Income'!$B$2:$X$500,D$4,FALSE),"-") -> 168 | E8: =IFERROR(VLOOKUP($B$4,'Operating Income'!$B$2:$X$500,E$4,FALSE),"-") -> 80 | F8: =IFERROR(VLOOKUP($B$4,'Operating Income'!$B$2:$X$500,F$4,FALSE),"-") -> 165 | G8: =IFERROR(VLOOKUP($B$4,'Operating Income'!$B$2:$X$500,G$4,FALSE),"-") -> 110 | H8: =IFERROR(VLOOKUP($B$4,'Operating Income'!$B$2:$X$500,H$4,FALSE),"-") -> 180 | I8: =IFERROR(VLOOKUP($B$4,'Operating Income'!$B$2:$X$500,I$4,FALSE),"-") -> 77.2 | J8: =IFERROR(VLOOKUP($B$4,'Operating Income'!$B$2:$X$500,J$4,FALSE),"-") -> 178.8 | ... S8: =IFERROR(VLOOKUP($B$4,'Operating Income'!$B$2:$X$500,S$4,FALSE),"-") -> 11.8
B9: Trailing 4Q OP avg. | C9: =IFERROR(AVERAGE(C8:C8),"-") -> 99 | D9: =IFERROR(AVERAGE(C8:D8),"-") -> 133.5 | E9: =IFERROR(AVERAGE(C8:E8),"-") -> 115.66667 | F9: =IFERROR(AVERAGE(C8:F8),"-") -> 128 | G9: =IFERROR(AVERAGE(D8:G8),"-") -> 130.75 | H9: =IFERROR(AVERAGE(E8:H8),"-") -> 133.75 | I9: =IFERROR(AVERAGE(F8:I8),"-") -> 133.05 | J9: =IFERROR(AVERAGE(G8:J8),"-") -> 136.5 | K9: =IFERROR(AVERAGE(H8:K8),"-") -> 141 | L9: =IFERROR(AVERAGE(I8:L8),"-") -> 152.25 | M9: =IFERROR(AVERAGE(J8:M8),"-") -> 162.15 | ... S9: =IFERROR(AVERAGE(P8:S8),"-") -> 14
B10: Trailing 4Q OP sum. | C10: =IFERROR(SUM(C8:C8),"-") -> 99 | D10: =IFERROR(SUM(C8:D8),"-") -> 267 | E10: =IFERROR(SUM(C8:E8),"-") -> 347 | F10: =IFERROR(SUM(C8:F8),"-") -> 512 | G10: =IFERROR(SUM(D8:G8),"-") -> 523 | H10: =IFERROR(SUM(E8:H8),"-") -> 535 | I10: =IFERROR(SUM(F8:I8),"-") -> 532.2 | J10: =IFERROR(SUM(G8:J8),"-") -> 546 | K10: =IFERROR(SUM(H8:K8),"-") -> 564 | L10: =IFERROR(SUM(I8:L8),"-") -> 609 | M10: =IFERROR(SUM(J8:M8),"-") -> 648.6 | ... S10: =IFERROR(SUM(P8:S8),"-") -> 56
B11: Trailing OP Delta | D11: =IFERROR(D9/C9-1,"-") -> 0.34848485 | E11: =IFERROR(E9/D9-1,"-") -> -0.13358302 | F11: =IFERROR(F9/E9-1,"-") -> 0.10662824 | G11: =IFERROR(G9/F9-1,"-") -> 0.021484375 | H11: =IFERROR(H9/G9-1,"-") -> 0.022944551 | I11: =IFERROR(I9/H9-1,"-") -> -0.0052336449 | J11: =IFERROR(J9/I9-1,"-") -> 0.025930101 | K11: =IFERROR(K9/J9-1,"-") -> 0.032967033 | ... S11: =IFERROR(S9/R9-1,"-") -> 0.45833333
B12: opm | C12: =IFERROR(C8/C7,"-") -> 0.076388889 | D12: =IFERROR(D8/D7,"-") -> 0.090419806 | E12: =IFERROR(E8/E7,"-") -> 0.045070423 | F12: =IFERROR(F8/F7,"-") -> 0.073957866 | G12: =IFERROR(G8/G7,"-") -> 0.041698256 | H12: =IFERROR(H8/H7,"-") -> 0.057179161 | I12: =IFERROR(I8/I7,"-") -> 0.026675881 | J12: =IFERROR(J8/J7,"-") -> 0.070283019 | ... S12: =IFERROR(S8/S7,"-") -> 0.0022412156
B13: op yoy | G13: =IFERROR(G8/C8-1,"-") -> 0.11111111 | H13: =IFERROR(H8/D8-1,"-") -> 0.071428571 | I13: =IFERROR(I8/E8-1,"-") -> -0.035 | J13: =IFERROR(J8/F8-1,"-") -> 0.083636364 | K13: =IFERROR(K8/G8-1,"-") -> 0.16363636 | L13: =IFERROR(L8/H8-1,"-") -> 0.25 | M13: =IFERROR(M8/I8-1,"-") -> 0.51295337 | N13: =IFERROR(N8/J8-1,"-") -> -0.45637584 | ... S13: =IFERROR(S8/O8-1,"-") -> -3.0344828
B14: rv yoy | G14: =IFERROR(G7/C7-1,"-") -> 1.0354938 | H14: =IFERROR(H7/D7-1,"-") -> 0.69429494 | I14: =IFERROR(I7/E7-1,"-") -> 0.63042254 | J14: =IFERROR(J7/F7-1,"-") -> 0.14029583 | K14: =IFERROR(K7/G7-1,"-") -> 0.12661107 | L14: =IFERROR(L7/H7-1,"-") -> 0.017789072 | M14: =IFERROR(M7/I7-1,"-") -> -0.08016586 | N14: =IFERROR(N7/J7-1,"-") -> -0.016902516 | ... S14: =IFERROR(S7/O7-1,"-") -> 0.65098777
