Workbook

Sheet 기업 정보
B2: 260126 실적 기업 정보
B4: Ticker | C4: Company | D4: Date | E4: Time | F4: Quarter Ending | G4: Market Cap (mil$)
B5: KFH | C5: Kuwait Finance House K.S.C.P. | D5: 46048 | F5: 46381 | G5: 46335940000
B6: NUE | C6: Nucor Corporation | D6: 46048 | E6: After Hours | F6: 46381 | G6: 39910660000
B7: RYA | C7: Ryanair Holdings plc | D7: 46048 | E7: Pre Market | F7: 46381 | G7: 35084800000
B8: EPI A | C8: Epiroc AB (publ) | D8: 46048 | F8: 46381 | G8: 28793840000
B9: BRO | C9: Brown & Brown, Inc. | D9: 46048 | E9: After Hours | F9: 46381 | G9: 27317080000
B10: WRB | C10: W. R. Berkley Corporation | D10: 46048 | F10: 46381 | G10: 25795840000
B11: STLD | C11: Steel Dynamics, Inc. | D11: 46048 | E11: Pre Market | F11: 46381 | G11: 25348730000
B12: SRT3 | C12: Sartorius Aktiengesellschaft | D12: 46048 | F12: 46381 | G12: 16651880000
B13: ARE | C13: Alexandria Real Estate Equities, Inc. | D13: 46048 | E13: After Hours | F13: 46381 | G13: 14493960000
B14: GGG | C14: Graco Inc. | D14: 46048 | E14: After Hours | F14: 46381 | G14: 14044240000
B15: STR | C15: Strabag SE | D15: 46048 | F15: 46381 | G15: 10642690000
B16: AGNC | C16: AGNC Investment Corp. | D16: 46048 | E16: After Hours | F16: 46381 | G16: 10479830000
B17: CR | C17: Crane Company | D17: 46048 | E17: After Hours | F17: 46381 | G17: 10354400000
B18: WAL | C18: Western Alliance Bancorporation | D18: 46048 | E18: After Hours | F18: 46381 | G18: 9453040000
B19: SANM | C19: Sanmina Corporation | D19: 46048 | E19: After Hours | F19: 46381 | G19: 9047700000
B20: SAVE | C20: Nordnet AB (publ) | D20: 46048 | F20: 46381 | G20: 7445120000
B21: GETI B | C21: Getinge AB (publ) | D21: 46048 | F21: 46381 | G21: 6468100000
B22: MOTILALOFS | C22: Motilal Oswal Financial Services Limited | D22: 46048 | F22: 46381 | G22: 5714150000
B23: M44U | C23: Mapletree Logistics Trust | D23: 46048 | F23: 46381 | G23: 5127830000
B24: QIIK | C24: Qatar International Islamic Bank (Q.P.S.C) | D24: 46048 | F24: 46381 | G24: 4465600000
B25: APARINDS | C25: APAR Industries Limited | D25: 46048 | F25: 46381 | G25: 3938900000
B26: FINN | C26: First National of Nebraska, Inc. | D26: 46048 | F26: 46381 | G26: 3880010000
B27: PCH | C27: PotlatchDeltic Corporation | D27: 46048 | F27: 46381 | G27: 3159660000
B28: WSFS | C28: WSFS Financial Corporation | D28: 46048 | E28: After Hours | F28: 46381 | G28: 3113800000
B29: HPOL B | C29: HEXPOL AB (publ) | D29: 46048 | F29: 46381 | G29: 3058350000
B30: AGYS | C30: Agilysys, Inc. | D30: 46048 | E30: After Hours | F30: 46381 | G30: 2923030000
B31: TURSG | C31: Türkiye Sigorta A.S. | D31: 46048 | F31: 46381 | G31: 2921930000
B32: R A | C32: Regional S.A.B. de C.V. | D32: 46048 | F32: 46381 | G32: 2819540000
B33: BOH | C33: Bank of Hawaii Corporation | D33: 46048 | E33: Pre Market | F33: 46381 | G33: 2751140000
B34: PRK | C34: Park National Corporation | D34: 46048 | F34: 46381 | G34: 2640690000
B35: SUMICHEM | C35: Sumitomo Chemical India Limited | D35: 46048 | F35: 46381 | G35: 2537120000
B36: HMS | C36: HMS Networks AB (publ) | D36: 46048 | F36: 46381 | G36: 2378660000
B37: NBTB | C37: NBT Bancorp Inc. | D37: 46048 | E37: After Hours | F37: 46381 | G37: 2159570000
B38: DX | C38: Dynex Capital, Inc. | D38: 46048 | F38: 46381 | G38: 2146530000
B39: FRME | C39: First Merchants Corporation | D39: 46048 | E39: After Hours | F39: 46381 | G39: 2130850000
B40: EFSC | C40: Enterprise Financial Services Corp | D40: 46048 | F40: 46381 | G40: 2001180000
B41: NWBI | C41: Northwest Bancshares, Inc. | D41: 46048 | E41: After Hours | F41: 46381 | G41: 1719560000
B42: GABC | C42: German American Bancorp, Inc. | D42: 46048 | F42: 46381 | G42: 1509040000
...

Sheet 매출 DATA
B1: 1 | C1: 2 | D1: 3 | E1: 4 | F1: 5 | G1: 6 | H1: 7 | I1: 8 | J1: 9 | K1: 10 | L1: 11 | M1: 12 | N1: 13 | O1: 14 | P1: 15 | Q1: 16 | R1: 17 | S1: 18 | T1: 19 | U1: 20 | V1: 21 | W1: 22
B2: Ticker | C2: Industry | D2: Latest_Date | E2: Growth_Rate | F2: Recent_Avg | G2: 4Q21 | H2: 1Q22 | I2: 2Q22 | J2: 3Q22 | K2: 4Q22 | L2: 1Q23 | M2: 2Q23 | N2: 3Q23 | O2: 4Q23 | P2: 1Q24 | Q2: 2Q24 | R2: 3Q24 | S2: 4Q24 | T2: 1Q25 | U2: 2Q25 | V2: 3Q25 | W2: 4Q25 | X2: Highlight_Quarters
B3: NUE | C3: Steel | D3: ('Q4 2025', "Dec '25 Dec 31, 2025") | E3: 1.9163818 | F3: 8123.5 | G3: 10364 | H3: 10493 | I3: 11794 | J3: 10501 | K3: 8724 | L3: 8710 | M3: 9523 | N3: 8776 | O3: 7705 | P3: 8137 | Q3: 8077 | R3: 7444 | S3: 7076 | T3: 7830 | U3: 8456 | V3: 8521 | W3: 7687 | X3: set()
B4: FSBC | C4: Banks - Regional | D4: ('Q3 2025', "Sep '25 Sep 30, 2025") | E4: 6.7852063 | F4: 37.535 | G4: 21.94 | H4: 23.15 | I4: 24.05 | J4: 26.49 | K4: 28.96 | L4: 30.74 | M4: 30.52 | N4: 30.4 | O4: 28.86 | P4: 28.61 | Q4: 28.58 | R4: 30.67 | S4: 31.77 | T4: 35.16 | U4: 35.34 | V4: 38.33 | W4: 41.31 | X4: set()
B5: HBT | C5: Banks - Regional | D5: ('Q4 2025', "Dec '25 Dec 31, 2025") | E5: 0.59826884 | F5: 59.2725 | G5: 42.21 | H5: 41.97 | I5: 42.92 | J5: 45.62 | K5: 50.07 | L5: 54.27 | M5: 58.79 | N5: 57.77 | O5: 56.29 | P5: 52.31 | Q5: 56.64 | R5: 56.44 | S5: 59.03 | T5: 58.01 | U5: 58.8 | V5: 59.84 | W5: 60.44 | X5: set()
B6: NBN | C6: Banks - Regional | D6: ('Q1 2026', "Sep '25 Sep 30, 2025") | E6: 4.5858197 | F6: 55.6475 | G6: 27.2 | H6: 26.55 | I6: 26.36 | J6: 27.76 | K6: 25.31 | L6: 30.05 | M6: 33.43 | N6: 35.27 | O6: 37.9 | P6: 38.47 | Q6: 38.05 | R6: 40.03 | S6: 43.12 | T6: 54.44 | U6: 52.57 | V6: 62.7 | W6: 52.88 | X6: {'3Q25', '4Q23', '1Q25'}
B7: MAC | C7: REIT - Retail | D7: ('Q3 2025', "Sep '25 Sep 30, 2025") | E7: 3.635307 | F7: 240.75 | G7: 197.14 | H7: 213.89 | I7: 203.41 | J7: 188.59 | K7: 195.59 | L7: 212.95 | M7: 199.05 | N7: 192.65 | O7: 197.31 | P7: 220.02 | Q7: 191.65 | R7: 197.96 | S7: 203.45 | T7: 257.39 | U7: 235.65 | V7: 232.73 | W7: 237.23 | X7: set()
B8: MRTN | C8: Trucking | D8: ('Q3 2025', "Sep '25 Sep 30, 2025") | E8: -1.835221 | F8: 225.9925 | G8: 251.28 | H8: 266.88 | I8: 287.28 | J8: 329.57 | K8: 324.45 | L8: 322.58 | M8: 298.02 | N8: 285.67 | O8: 279.54 | P8: 268.22 | Q8: 249.67 | R8: 246.24 | S8: 237.37 | T8: 230.43 | U8: 223.15 | V8: 229.92 | W8: 220.47 | X8: set()
B9: FSUN | C9: Banks - Regional | D9: ('Q3 2025', "Sep '25 Sep 30, 2025") | E9: 2.2724422 | F9: 101.9375 | G9: 68.65 | H9: 69.85 | I9: 64.98 | J9: 80.89 | K9: 93.44 | L9: 91.89 | M9: 93.05 | N9: 98.13 | O9: 92.06 | P9: 89.29 | Q9: 93.61 | R9: 96.17 | S9: 98.23 | T9: 98.68 | U9: 96.21 | V9: 105.57 | W9: 107.29 | X9: set()
B10: LKFN | C10: Banks - Regional | D10: ('Q4 2025', "Dec '25 Dec 31, 2025") | E10: 2.3709849 | F10: 67.2475 | G10: 54.72 | H10: 55.57 | I10: 59.17 | J10: 62.66 | K10: 67.36 | L10: 61.83 | M10: 60.03 | N10: 59.23 | O10: 65.81 | P10: 59.03 | Q10: 68.74 | R10: 61.19 | S10: 63.57 | T10: 63.8 | U10: 66.36 | V10: 69.03 | W10: 69.8 | X10: set()
B11: GABC | C11: Banks - Regional | D11: ('Q3 2025', "Sep '25 Sep 30, 2025") | E11: 10.624059 | F11: 82.65 | G11: 56.84 | H11: 55.7 | I11: 63.1 | J11: 64.78 | K11: 65.8 | L11: 66.05 | M11: 63.98 | N11: 63.15 | O11: 62.36 | P11: 61.2 | Q11: 60.82 | R11: 64.89 | S11: 62.4 | T11: 65.15 | U11: 81.41 | V11: 89.89 | W11: 94.15 | X11: {'4Q25'}
B12: NWBI | C12: Banks - Regional | D12: ('Q3 2025', "Sep '25 Sep 30, 2025") | E12: 4.8387366 | F12: 157.245 | G12: 127.61 | H12: 123.7 | I12: 116.36 | J12: 130.71 | K12: 139.55 | L12: 144.9 | M12: 136.43 | N12: 138.35 | O12: 139.26 | P12: 135.47 | Q12: 131.2 | R12: 97.99 | S12: 139.14 | T12: 154.26 | U12: 156.17 | V12: 150.38 | W12: 168.17 | X12: set()
B13: EFSC | C13: Banks - Regional | D13: ('Q3 2025', "Sep '25 Sep 30, 2025") | E13: 2.0481763 | F13: 167.6575 | G13: 111.57 | H13: 120.32 | I13: 117.2 | J13: 122.62 | K13: 137.37 | L13: 153.32 | M13: 154.61 | N13: 154.61 | O13: 156.4 | P13: 156.5 | Q13: 152.08 | R13: 154.15 | S13: 161.64 | T13: 160.98 | U13: 163.39 | V13: 171.16 | W13: 175.1 | X13: set()
B14: FRME | C14: Banks - Regional | D14: ('Q3 2025', "Sep '25 Sep 30, 2025") | E14: 1.5447068 | F14: 166.9725 | G14: 133.22 | H14: 127.12 | I14: 128.18 | J14: 156.94 | K14: 169.92 | L14: 173.11 | M14: 169.12 | N14: 164.15 | O14: 161.23 | P14: 156.51 | Q14: 153.7 | R14: 159.91 | S14: 155.98 | T14: 177.11 | U14: 160.32 | V14: 164.32 | W14: 166.14 | X14: set()
... B33: STM | C33: Semiconductors | D33: ('Q3 2025', "Sep '25 Sep 27, 2025") | E33: -0.52520119 | F33: 2935.75 | G33: 3192 | H33: 3542 | I33: 3540 | J33: 3830 | K33: 4305 | L33: 4408 | M33: 4241 | N33: 4320 | O33: 4416 | P33: 4262 | Q33: 3444 | R33: 3227 | S33: 3245 | T33: 3302 | U33: 2513 | V33: 2745 | W33: 3183 | X33: set()

Sheet 영업이익 DATA
B1: 1 | C1: 2 | D1: 3 | E1: 4 | F1: 5 | G1: 6 | H1: 7 | I1: 8 | J1: 9 | K1: 10 | L1: 11 | M1: 12 | N1: 13 | O1: 14 | P1: 15 | Q1: 16 | R1: 17 | S1: 18 | T1: 19 | U1: 20 | V1: 21 | W1: 22 | X1: 23
B2: Ticker | C2: Industry | D2: Latest_Date | E2: 최근 분기 빨간줄 | F2: Recent_Avg | G2: 4Q21 | H2: 1Q22 | I2: 2Q22 | J2: 3Q22 | K2: 4Q22 | L2: 1Q23 | M2: 2Q23 | N2: 3Q23 | O2: 4Q23 | P2: 1Q24 | Q2: 2Q24 | R2: 3Q24 | S2: 4Q24 | T2: 1Q25 | U2: 2Q25 | V2: 3Q25 | W2: 4Q25 | X2: Highlight_Quarters
B3: AGNC | C3: REIT - Mortgage | D3: ('Q4 2025', "Dec '25 Dec 31, 2025") | E3: 99.28401 | F3: 417.5 | G3: -27 | H3: -651 | I3: -434 | J3: -666 | K3: 561 | L3: -151 | M3: 286 | N3: -392 | O3: 412 | P3: 443 | Q3: -48 | R3: 346 | S3: 122 | T3: 50 | U3: -140 | V3: 806 | W3: 954 | X3: {'3Q25'}
B4: FSBC | C4: Banks - Regional | D4: ('Q3 2025', "Sep '25 Sep 30, 2025") | E4: 9.5622435 | F4: 20.0225 | G4: 13.3 | H4: 12.63 | I4: 13.52 | J4: 14.03 | K4: 16.53 | L4: 18.77 | M4: 18.5 | N4: 17.17 | O4: 15.8 | P4: 15.15 | Q4: 14.96 | R4: 15.15 | S4: 15.24 | T4: 19.37 | U4: 18.39 | V4: 20.1 | W4: 22.23 | X4: {'1Q23'}
B5: DX | C5: REIT - Mortgage | D5: ('Q4 2025', "Dec '25 Dec 31, 2025") | E5: 72.660858 | F5: 79.765 | G5: 14.06 | H5: 117.21 | I5: 29.34 | J5: -46.67 | K5: 43.29 | L5: -41.72 | M5: 54.34 | N5: -43.05 | O5: 24.31 | P5: 40.12 | Q5: -8.3 | R5: 31 | S5: 51.09 | T5: -3.08 | U5: -13.61 | V5: 150.39 | W5: 185.36 | X5: set()
B6: AGYS | C6: Software - Application | D6: ('Q3 2026', "Dec '25 Dec 31, 2025") | E6: 16.97318 | F6: 7.6325 | G6: 1.62 | H6: 2.64 | I6: 3.25 | J6: 2.99 | K6: 3.68 | L6: 3.51 | M6: 1.72 | N6: 3.56 | O6: 7.75 | P6: 3.51 | Q6: 6.01 | R6: 4.23 | S6: 7.24 | T6: 5.76 | U6: 4.54 | V6: 8.56 | W6: 11.67 | X6: {'3Q25', '4Q23', '1Q25'}
B7: MAC | C7: REIT - Retail | D7: ('Q3 2025', "Sep '25 Sep 30, 2025") | E7: 11.25822 | F7: 63.445 | G7: 35.84 | H7: 38.48 | I7: 9.85 | J7: 35.92 | K7: 37.56 | L7: 73.05 | M7: -24.43 | N7: 81.79 | O7: 40.07 | P7: 52.49 | Q7: -44.4 | R7: 34.23 | S7: 29.15 | T7: 127.18 | U7: 31.09 | V7: 40.68 | W7: 54.83 | X7: {'4Q25', '3Q23', '1Q25', '2Q25', '1Q23'}
B8: MRTN | C8: Trucking | D8: ('Q3 2025', "Sep '25 Sep 30, 2025") | E8: -13.806172 | F8: 3.98 | G8: 23.96 | H8: 26.24 | I8: 31.32 | J8: 36.13 | K8: 32.7 | L8: 29.83 | M8: 23.76 | N8: 24.66 | O8: 14.22 | P8: 13.86 | Q8: 11.08 | R8: 7.44 | S8: 3.39 | T8: 6.34 | U8: 4.19 | V8: 4.55 | W8: 0.84 | X8: set()
B9: FSUN | C9: Banks - Regional | D9: ('Q3 2025', "Sep '25 Sep 30, 2025") | E9: -0.25139163 | F9: 27.775 | G9: 10.58 | H9: 10.34 | I9: 8.81 | J9: 0.22 | K9: 34.14 | L9: 30.85 | M9: 33.42 | N9: 35.66 | O9: 31.99 | P9: 30.41 | Q9: 15.29 | R9: 31.1 | S9: 28.57 | T9: 20.16 | U9: 29.69 | V9: 32.96 | W9: 28.29 | X9: {'4Q22', '2Q23', '3Q23', '2Q25', '1Q23'}
B10: BOH | C10: Banks - Regional | D10: ('Q4 2025', "Dec '25 Dec 31, 2025") | E10: 11.059771 | F10: 65.4975 | G10: 76.98 | H10: 70.44 | I10: 74.62 | J10: 66.57 | K10: 79.01 | L10: 62.77 | M10: 61.07 | N10: 63.67 | O10: 39.61 | P10: 48.36 | Q10: 45.31 | R10: 52.64 | S10: 51.54 | T10: 56.16 | U10: 60.45 | V10: 67.75 | W10: 77.63 | X10: set()
B11: GABC | C11: Banks - Regional | D11: ('Q3 2025', "Sep '25 Sep 30, 2025") | E11: 16.953754 | F11: 31.2325 | G11: 26.4 | H11: 22.43 | I11: 9.74 | J11: 28.78 | K11: 30.73 | L11: 29.94 | M11: 25.26 | N11: 26.88 | O11: 26.04 | P11: 25.47 | Q11: 23.18 | R11: 26.6 | S11: 25.64 | T11: 28.68 | U11: 13.33 | V11: 39.17 | W11: 43.75 | X11: {'3Q25', '4Q25', '2Q23'}
B12: NWBI | C12: Banks - Regional | D12: ('Q3 2025', "Sep '25 Sep 30, 2025") | E12: -21.459596 | F12: 36.6175 | G12: 45.86 | H12: 39.32 | I12: 35.9 | J12: 43.28 | K12: 49.29 | L12: 45.23 | M12: 43.99 | N12: 43.56 | O12: 50.68 | P12: 36.85 | Q12: 37.74 | R12: 5.94 | S12: 43.49 | T12: 42.37 | U12: 56.53 | V12: 44.1 | W12: 3.47 | X12: {'3Q25', '2Q25'}
B13: EFSC | C13: Banks - Regional | D13: ('Q3 2025', "Sep '25 Sep 30, 2025") | E13: 10.412226 | F13: 68.635 | G13: 18.34 | H13: 64.66 | I13: 61.07 | J13: 57.73 | K13: 64.23 | L13: 76.44 | M13: 71.26 | N13: 62.69 | O13: 57.05 | P13: 55.53 | Q13: 50.63 | R13: 57.19 | S13: 62.78 | T13: 60.65 | U13: 61.03 | V13: 64.19 | W13: 88.67 | X13: {'4Q25', '4Q22'}
B14: FRME | C14: Banks - Regional | D14: ('Q3 2025', "Sep '25 Sep 30, 2025") | E14: 3.417397 | F14: 67.56 | G14: 61.83 | H14: 54.68 | I14: 55.85 | J14: 42.87 | K14: 73.55 | L14: 83.41 | M14: 75.4 | N14: 71.56 | O14: 65.37 | P14: 46.9 | Q14: 54.77 | R14: 43.99 | S14: 56.35 | T14: 76.62 | U14: 63.22 | V14: 65.12 | W14: 65.28 | X14: {'1Q23', '3Q23', '1Q25'}
... B33: STM | C33: Semiconductors | D33: ('Q3 2025', "Sep '25 Sep 27, 2025") | E33: -20.38961 | F33: 153.25 | G33: 606 | H33: 894 | I33: 880 | J33: 999 | K33: 1268 | L33: 1322 | M33: 1195 | N33: 1136 | O33: 1233 | P33: 1025 | Q33: 546 | R33: 372 | S33: 368 | T33: 364 | U33: -1 | V33: 39 | W33: 211 | X33: {'4Q22', '1Q23'}
B35: * 최근에 실적 안나온 기업은 제외, 비미국 기업 제외

Sheet 빨간줄
B2: (단위: mil $)
B4: agys | C4: 6 | D4: 7 | E4: 8 | F4: 9 | G4: 10 | H4: 11 | I4: 12 | J4: 13 | K4: 14 | L4: 15 | M4: 16 | N4: 17 | O4: 18 | P4: 19 | Q4: 20 | R4: 21 | S4: 22
C6: 4Q21 | D6: 1Q22 | E6: 2Q22 | F6: 3Q22 | G6: 4Q22 | H6: 1Q23 | I6: 2Q23 | J6: 3Q23 | K6: 4Q23 | L6: 1Q24 | M6: 2Q24 | N6: 3Q24 | O6: 4Q24 | P6: 1Q25 | Q6: 2Q25 | R6: 3Q25 | S6: 4Q25 | T6: 1Q26 | U6: 2Q26 | V6: 3Q26 | W6: 4Q26
B7: Revenue | C7: =VLOOKUP($B$4,'매출 DATA'!$B$1:$W$32,C4,FALSE) -> 39.46 | D7: =VLOOKUP($B$4,'매출 DATA'!$B$1:$W$32,D4,FALSE) -> 46.56 | E7: =VLOOKUP($B$4,'매출 DATA'!$B$1:$W$32,E4,FALSE) -> 47.51 | F7: =VLOOKUP($B$4,'매출 DATA'!$B$1:$W$32,F4,FALSE) -> 47.74 | G7: =VLOOKUP($B$4,'매출 DATA'!$B$1:$W$32,G4,FALSE) -> 49.92 | H7: =VLOOKUP($B$4,'매출 DATA'!$B$1:$W$32,H4,FALSE) -> 52.9 | I7: =VLOOKUP($B$4,'매출 DATA'!$B$1:$W$32,I4,FALSE) -> 56.06 | J7: =VLOOKUP($B$4,'매출 DATA'!$B$1:$W$32,J4,FALSE) -> 58.62 | ... S7: =VLOOKUP($B$4,'매출 DATA'!$B$1:$W$32,S4,FALSE) -> 80.39
B8: OP | C8: =VLOOKUP($B$4,'영업이익 DATA'!$B$1:$W$32,C4,FALSE) -> 1.62 | D8: =VLOOKUP($B$4,'영업이익 DATA'!$B$1:$W$32,D4,FALSE) -> 2.64 | E8: =VLOOKUP($B$4,'영업이익 DATA'!$B$1:$W$32,E4,FALSE) -> 3.25 | F8: =VLOOKUP($B$4,'영업이익 DATA'!$B$1:$W$32,F4,FALSE) -> 2.99 | G8: =VLOOKUP($B$4,'영업이익 DATA'!$B$1:$W$32,G4,FALSE) -> 3.68 | H8: =VLOOKUP($B$4,'영업이익 DATA'!$B$1:$W$32,H4,FALSE) -> 3.51 | I8: =VLOOKUP($B$4,'영업이익 DATA'!$B$1:$W$32,I4,FALSE) -> 1.72 | J8: =VLOOKUP($B$4,'영업이익 DATA'!$B$1:$W$32,J4,FALSE) -> 3.56 | ... S8: =VLOOKUP($B$4,'영업이익 DATA'!$B$1:$W$32,S4,FALSE) -> 11.67
B9: Trailing 4Q OP avg. | C9: =AVERAGE(C8:C8) -> 1.62 | D9: =AVERAGE(C8:D8) -> 2.13 | E9: =AVERAGE(C8:E8) -> 2.5033333 | F9: =AVERAGE(C8:F8) -> 2.625 | G9: =AVERAGE(D8:G8) -> 3.14 | H9: =AVERAGE(E8:H8) -> 3.3575 | I9: =AVERAGE(F8:I8) -> 2.975 | J9: =AVERAGE(G8:J8) -> 3.1175 | K9: =AVERAGE(H8:K8) -> 4.135 | L9: =AVERAGE(I8:L8) -> 4.135 | M9: =AVERAGE(J8:M8) -> 5.2075 | ... S9: =AVERAGE(P8:S8) -> 7.6325
B10: Trailing 4Q OP sum. | C10: =SUM(C8:C8) -> 1.62 | D10: =SUM(C8:D8) -> 4.26 | E10: =SUM(C8:E8) -> 7.51 | F10: =SUM(C8:F8) -> 10.5 | G10: =SUM(D8:G8) -> 12.56 | H10: =SUM(E8:H8) -> 13.43 | I10: =SUM(F8:I8) -> 11.9 | J10: =SUM(G8:J8) -> 12.47 | K10: =SUM(H8:K8) -> 16.54 | L10: =SUM(I8:L8) -> 16.54 | M10: =SUM(J8:M8) -> 20.83 | ... S10: =SUM(P8:S8) -> 30.53
B11: Trailing OP Delta | D11: =D9/C9-1 -> 0.31481481 | E11: =E9/D9-1 -> 0.17527387 | F11: =F9/E9-1 -> 0.048601864 | G11: =G9/F9-1 -> 0.19619048 | H11: =H9/G9-1 -> 0.069267516 | I11: =I9/H9-1 -> -0.11392405 | J11: =J9/I9-1 -> 0.04789916 | K11: =K9/J9-1 -> 0.32638332 | ... S11: =S9/R9-1 -> 0.1697318
B12: opm | C12: =IFERROR(C8/C7,"-") -> 0.041054232 | D12: =IFERROR(D8/D7,"-") -> 0.056701031 | E12: =IFERROR(E8/E7,"-") -> 0.068406651 | F12: =IFERROR(F8/F7,"-") -> 0.062630917 | G12: =IFERROR(G8/G7,"-") -> 0.073717949 | H12: =IFERROR(H8/H7,"-") -> 0.066351607 | I12: =IFERROR(I8/I7,"-") -> 0.030681413 | J12: =IFERROR(J8/J7,"-") -> 0.060730126 | ... S12: =IFERROR(S8/S7,"-") -> 0.14516731
B13: op yoy | C13: =C8/#REF!-1 -> #REF! | D13: =D8/#REF!-1 -> #REF! | E13: =E8/#REF!-1 -> #REF! | F13: =F8/#REF!-1 -> #REF! | G13: =G8/C8-1 -> 1.2716049 | H13: =H8/D8-1 -> 0.32954545 | I13: =I8/E8-1 -> -0.47076923 | J13: =J8/F8-1 -> 0.19063545 | K13: =K8/G8-1 -> 1.1059783 | L13: =L8/H8-1 -> 0 | M13: =M8/I8-1 -> 2.494186 | N13: =N8/J8-1 -> 0.18820225 | ... S13: =S8/O8-1 -> 0.61187845
B14: rv yoy | G14: =G7/C7-1 -> 0.26507856 | H14: =H9/D9-1 -> 0.57629108 | I14: =I9/E9-1 -> 0.18841545 | J14: =J9/F9-1 -> 0.18761905 | K14: =K9/G9-1 -> 0.31687898 | L14: =L9/H9-1 -> 0.23157111 | M14: =M9/I9-1 -> 0.75042017 | N14: =N9/J9-1 -> 0.72413793 | O14: =O9/K9-1 -> 0.26904474 | ... S14: =S9/O9-1 -> 0.45450214
