Workbook

Sheet 실적 기업 정보
B2: 실적 기업 정보
B4: Ticker | C4: Company | D4: Date | E4: Time | F4: Quarter Ending | G4: Market Cap (mil$)
B5: MSFT | C5: Microsoft Corporation | D5: 46050 | E5: After Hours | F5: 46381 | G5: 3417853.2
B6: META | C6: Meta Platforms, Inc. | D6: 46050 | E6: After Hours | F6: 46381 | G6: 1563357.2
B7: TSLA | C7: Tesla, Inc. | D7: 46050 | F7: 46381 | G7: 1455045.9
B8: XOM | C8: Exxon Mobil Corporation | D8: 30-Jan-26 | E8: Pre Market | F8: 25-Dec | G8: 590910.6
B9: ASML | C9: ASML Holding N.V. | D9: 46050 | E9: Pre Market | F9: 46381 | G9: 522992.7
B10: AMD | C10: Advanced Micro Devices, Inc. | D10: 03-Feb-26 | E10: After Hours | F10: Dec-25 | G10: 385406
B11: A000660 | C11: SK hynix Inc. | D11: 46050 | F11: 46381 | G11: 354526.93
B12: CVX | C12: Chevron Corporation | D12: 30-Jan-26 | E12: Pre Market | F12: 25-Dec | G12: 350262
B13: PLTR | C13: Palantir Technologies Inc. | D13: 02-Feb-26 | E13: After Hours | F13: Dec-25 | G13: 349387.93
B14: LRCX | C14: Lam Research Corporation | D14: 46050 | E14: After Hours | F14: 46381 | G14: 273739.18
B15: MRK | C15: Merck & Co., Inc. | D15: 03-Feb-26 | F15: Dec-25 | G15: 273693
B16: IBM | C16: International Business Machines Corporation | D16: 46050 | E16: After Hours | F16: 46381 | G16: 273353.96
B17: AXP | C17: American Express Company | D17: 30-Jan-26 | E17: Pre Market | F17: 25-Dec | G17: 241588.62
B18: PEP | C18: PepsiCo, Inc. | D18: 03-Feb-26 | F18: Dec-25 | G18: 212497
B19: DIS | C19: The Walt Disney Company | D19: 02-Feb-26 | F19: Dec-25 | G19: 201380.58
B20: VZ | C20: Verizon Communications Inc. | D20: 30-Jan-26 | E20: Pre Market | F20: 25-Dec | G20: 187740.84
B21: APH | C21: Amphenol Corporation | D21: 46050 | E21: Pre Market | F21: 46381 | G21: 184820.14
B22: AMGN | C22: Amgen Inc. | D22: 03-Feb-26 | E22: After Hours | F22: Dec-25 | G22: 184096
B23: GEV | C23: GE Vernova Inc. | D23: 46050 | E23: Pre Market | F23: 46381 | G23: 178469.17
B24: T | C24: AT&T Inc. | D24: 46050 | E24: Pre Market | F24: 46381 | G24: 167240.11
B25: DHR | C25: Danaher Corporation | D25: 46050 | E25: Pre Market | F25: 46381 | G25: 165999.21
B26: PFE | C26: Pfizer Inc. | D26: 03-Feb-26 | F26: Dec-25 | G26: 150330
B27: NOW | C27: ServiceNow, Inc. | D27: 46050 | E27: After Hours | F27: 46381 | G27: 138089.32
B28: ETN | C28: Eaton Corporation plc | D28: 03-Feb-26 | F28: Dec-25 | G28: 136492
B29: 8316 | C29: Sumitomo Mitsui Financial Group, Inc. | D29: 30-Jan-26 | F29: 25-Dec | G29: 136109.76
B30: ISP | C30: Intesa Sanpaolo S.p.A. | D30: 02-Feb-26 | F30: Dec-25 | G30: 123582.78
B31: CB | C31: Chubb Limited | D31: 03-Feb-26 | F31: Dec-25 | G31: 121828
B32: PGR | C32: The Progressive Corporation | D32: 46050 | F32: 46351 | G32: 120815.42
B33: SBUX | C33: Starbucks Corporation | D33: 46050 | E33: Pre Market | F33: 46381 | G33: 111003.7
B34: 6857 | C34: Advantest Corporation | D34: 46050 | F34: 46381 | G34: 109823.18
B35: 8411 | C35: Mizuho Financial Group, Inc. | D35: 02-Feb-26 | F35: Dec-25 | G35: 108869.48
B36: ADP | C36: Automatic Data Processing, Inc. | D36: 46050 | E36: Pre Market | F36: 46381 | G36: 104295.2
B37: GD | C37: General Dynamics Corporation | D37: 46050 | E37: Pre Market | F37: 46381 | G37: 97979.74
B38: CABK | C38: CaixaBank, S.A. | D38: 30-Jan-26 | F38: 25-Dec | G38: 93154.76
B39: WM | C39: Waste Management, Inc. | D39: 46050 | E39: After Hours | F39: 46381 | G39: 92349.21
B40: ITUB4 | C40: Itaú Unibanco Holding S.A. | D40: 02-Feb-26 | F40: Dec-25 | G40: 91584.13
B41: EMR | C41: Emerson Electric Co. | D41: 03-Feb-26 | F41: Dec-25 | G41: 82635.92
B42: ELV | C42: Elevance Health, Inc. | D42: 46050 | E42: Pre Market | F42: 46381 | G42: 82463.92
...

Sheet Revenue
B1: 1 | C1: 2 | D1: 3 | E1: 4 | F1: 5 | G1: 6 | H1: 7 | I1: 8 | J1: 9 | K1: 10 | L1: 11 | M1: 12 | N1: 13 | O1: 14 | P1: 15 | Q1: 16 | R1: 17 | S1: 18 | T1: 19 | U1: 20 | V1: 21 | W1: 22
B2: Ticker | C2: Country | D2: Industry | E2: Latest_Date | F2: Growth_Rate | G2: 4Q21 | H2: 1Q22 | I2: 2Q22 | J2: 3Q22 | K2: 4Q22 | L2: 1Q23 | M2: 2Q23 | N2: 3Q23 | O2: 4Q23 | P2: 1Q24 | Q2: 2Q24 | R2: 3Q24 | S2: 4Q24 | T2: 1Q25 | U2: 2Q25 | V2: 3Q25 | W2: 4Q25 | X2: 1Q25 | Y2: 2Q25 | Z2: 3Q25 | AA2: 4Q25
A3: 260203 | B3: SMCI | C3: United States | D3: Computer Hardware | E3: Jun'26 | F3: 33.3 | G3: 1172 | H3: 1355 | I3: 1635 | J3: 1852 | K3: 1803 | L3: 1283 | M3: 2185 | N3: 2120 | O3: 3665 | P3: 3850 | Q3: 5355 | R3: 5937 | S3: 5678 | T3: 4600 | U3: 5757 | V3: 5018 | W3: 12682 | X3: 0.036023055 | Y3: 0.018636996 | Z3: -0.04182596 | AA3: 0.33268418
A4: 260203 | B4: LITE | C4: United States | D4: Communication Equipment | E4: Jun'26 | F4: 14.3 | G4: 446.7 | H4: 395.4 | I4: 422.1 | J4: 506.8 | K4: 506 | L4: 383.4 | M4: 370.8 | N4: 317.6 | O4: 366.8 | P4: 366.5 | Q4: 308.3 | R4: 336.9 | S4: 402.2 | T4: 425.2 | U4: 480.7 | V4: 533.8 | W4: 665.5 | X4: 0.041516373 | Y4: 0.11707185 | Z4: 0.11969605 | AA4: 0.14295021
A5: 260203 | B5: AMCR | C5: United States | D5: Packaging & Containers | E5: Jun'26 | F5: 12.7 | G5: 3507 | H5: 3708 | I5: 3909 | J5: 3712 | K5: 3642 | L5: 3667 | M5: 3673 | N5: 3443 | O5: 3251 | P5: 3411 | Q5: 3535 | R5: 3353 | S5: 3241 | T5: 3333 | U5: 5082 | V5: 5745 | W5: 5449 | X5: -0.005760709 | Y5: 0.11491606 | Z5: 0.15937104 | AA5: 0.12688926
A6: 260203 | B6: BDN | C6: United States | D6: REIT - Office | E6: Dec'25 | F6: 11 | G6: 117.65 | H6: 120.49 | I6: 121.62 | J6: 119.48 | K6: 120.12 | L6: 123.1 | M6: 118.35 | N6: 119.24 | O6: 77.14 | P6: 112.67 | Q6: 111.27 | R6: 6.17 | S6: 77.38 | T6: 111.21 | U6: 105.34 | V6: 103.14 | W6: 120.95 | X6: -0.0047481219 | Y6: -0.019377185 | Z6: 0.32312562 | AA6: 0.10972876
A7: 260203 | B7: SIMO | C7: United States | D7: Semiconductors | E7: Dec'25 | F7: 10.9 | G7: 264.36 | H7: 241.98 | I7: 252.37 | J7: 250.81 | K7: 200.76 | L7: 124.07 | M7: 140.36 | N7: 172.33 | O7: 202.38 | P7: 189.31 | Q7: 210.67 | R7: 212.41 | S7: 191.16 | T7: 166.49 | U7: 198.68 | V7: 242 | W7: 278.46 | X7: -0.02839898 | Y7: -0.015357422 | Z7: 0.038491558 | AA7: 0.10935327
A8: 260203 | B8: AMD | C8: United States | D8: Semiconductors | E8: Dec'25 | F8: 8.2 | G8: 4826 | H8: 5887 | I8: 6550 | J8: 5565 | K8: 5599 | L8: 5353 | M8: 5359 | N8: 5800 | O8: 6168 | P8: 5473 | Q8: 5835 | R8: 6819 | S8: 7658 | T8: 7438 | U8: 7685 | V8: 9246 | W8: 10270 | X8: 0.076207097 | Y8: 0.066666667 | Z8: 0.081993243 | AA8: =SUM(T8:W8)/SUM(S8:V8)-1 -> 0.081556187
A9: 260203 | B9: RES | C9: United States | D9: Oil & Gas Equipment & Services | E9: Dec'25 | F9: 5.9 | G9: 268.25 | H9: 284.62 | I9: 375.51 | J9: 459.6 | K9: 482.03 | L9: 476.67 | M9: 415.86 | N9: 330.42 | O9: 394.53 | P9: 377.83 | Q9: 364.15 | R9: 337.65 | S9: 335.36 | T9: 332.88 | U9: 420.81 | V9: 447.1 | W9: 425.78 | X9: -0.031767009 | Y9: 0.041356457 | Z9: 0.076715497 | AA9: 0.058861439
A10: 260203 | B10: TRNS | C10: United States | D10: Specialty Business Services | E10: Sep'26 | F10: 5.7 | G10: 50.9 | H10: 55.88 | I10: 54.66 | J10: 56.44 | K10: 57.4 | L10: 62.07 | M10: 60.6 | N10: 62.8 | O10: 65.17 | P10: 70.91 | Q10: 66.71 | R10: 67.83 | S10: 66.75 | T10: 77.13 | U10: 76.42 | V10: 82.27 | W10: 83.86 | X10: 0.022850845 | Y10: 0.034875368 | Z10: 0.050116267 | AA10: 0.056548898
A11: 260203 | B11: MSGE | C11: United States | D11: Leisure | E11: Jun'26 | F11: 5.5 | G11: -13.35 | H11: 193.99 | I11: 178.34 | J11: 146.45 | K11: 355.88 | L11: 201.23 | M11: 147.94 | N11: 142.21 | O11: 402.67 | P11: 228.31 | Q11: 186.07 | R11: 138.71 | S11: 407.42 | T11: 242.47 | U11: 154.14 | V11: 158.26 | W11: 459.94 | X11: 0.014742168 | Y11: -0.032759806 | Z11: 0.020737425 | AA11: 0.054578142
A12: 260203 | B12: TTWO | C12: United States | D12: Electronic Gaming & Multimedia | E12: Sep'26 | F12: 5.4 | G12: 903.3 | H12: 930 | I12: 1102 | J12: 1394 | K12: 1408 | L12: 1446 | M12: 1285 | N12: 1299 | O12: 1366 | P12: 1399 | Q12: 1338 | R12: 1353 | S12: 1360 | T12: 1583 | U12: 1504 | V12: 1774 | W12: 1699 | X12: 0.033761468 | Y12: 0.029463969 | Z12: 0.072586207 | AA12: 0.054492847
A13: 260203 | B13: ATS | C13: United States | D13: Specialty Industrial Machinery | E13: Jun'26 | F13: 4.5 | G13: 522.13 | H13: 546.8 | I13: 603.16 | J13: 610.59 | K13: 588.95 | L13: 647.05 | M13: 730.79 | N13: 753.65 | O13: 735.72 | P13: 752.05 | Q13: 791.47 | R13: 694.27 | S13: 612.78 | T13: 651.99 | U13: 574.24 | V13: 736.72 | W13: 728.46 | X13: -0.035101752 | Y13: -0.07897808 | Z13: 0.016756932 | AA13: 0.04491154
A14: 260203 | B14: PGC | C14: United States | D14: Banks - Regional | E14: Dec'25 | F14: 4.3 | G14: 52.43 | H14: 51.96 | I14: 59.95 | J14: 61.31 | K14: 62.9 | L14: 60.52 | M14: 55.8 | N14: 50.01 | O14: 49.2 | P14: 52.45 | Q14: 52.69 | R14: 55.4 | S14: 59.86 | T14: 59.89 | U14: 63.16 | V14: 65.9 | W14: 70.53 | X14: 0.033756806 | Y14: 0.045953301 | Z14: 0.044060258 | AA14: 0.042884128
A15: 260203 | B15: HLNE | C15: United States | D15: Asset Management | E15: Sep'26 | F15: 4.1 | G15: 91.7 | H15: 100.9 | I15: 135.51 | J15: 153.38 | K15: 127.07 | L15: 112.79 | M15: 125.04 | N15: 126.88 | O15: 125.26 | P15: 176.67 | Q15: 196.73 | R15: 150 | S15: 168.26 | T15: 197.97 | U15: 175.96 | V15: 190.88 | W15: 198.59 | X15: 0.030795478 | Y15: -0.029132069 | Z15: 0.059058929 | AA15: 0.041373948
A16: 260203 | B16: SR | C16: United States | D16: Utilities - Regulated Gas | E16: Mar'26 | F16: 3.8 | G16: 555.4 | H16: 880.9 | I16: 448 | J16: 314.2 | K16: 814 | L16: 1123 | M16: 418.5 | N16: 310.4 | O16: 756.6 | P16: 1129 | Q16: 414.1 | R16: 293.8 | S16: 669.1 | T16: 1051 | U16: 421.9 | V16: 334.1 | W16: 762.2 | X16: -0.031125299 | Y16: 0.0032125206 | Z16: 0.016544872 | AA16: 0.037599451
A17: 260203 | B17: BALL | C17: United States | D17: Packaging & Containers | E17: Dec'25 | F17: 3.7 | G17: 3674 | H17: 3716 | I17: 4134 | J17: 3951 | K17: 3548 | L17: 2981 | M17: 3067 | N17: 3111 | O17: 2903 | P17: 2874 | Q17: 2959 | R17: 3082 | S17: 2880 | T17: 3097 | U17: 3338 | V17: 3379 | W17: 3347 | X17: 0.018906316 | Y17: 0.031536029 | Z17: 0.023957409 | AA17: 0.036789034
A18: 260203 | B18: INTA | C18: United States | D18: Software - Application | E18: Jun'26 | F18: 3.6 | G18: 64.7 | H18: 69.66 | I18: 75.52 | J18: 79.54 | K18: 84.69 | L18: 92.02 | M18: 94.62 | N18: 101.58 | O18: 103.93 | P18: 110.64 | Q18: 114.38 | R18: 118.81 | S18: 121.21 | T18: 129.07 | U18: 135.04 | V18: 139.03 | W18: 140.21 | X18: 0.039630999 | Y18: 0.042732745 | Z18: 0.040108702 | AA18: 0.036235339
A19: 260203 | B19: ATO | C19: United States | D19: Utilities - Regulated Gas | E19: Mar'26 | F19: 3.6 | G19: 1013 | H19: 1650 | I19: 816.43 | J19: 722.63 | K19: 1484 | L19: 1541 | M19: 662.73 | N19: 587.64 | O19: 1158 | P19: 1647 | Q19: 701.55 | R19: 657.94 | S19: 1176 | T19: 1951 | U19: 838.77 | V19: 737.48 | W19: 1343 | X19: 0.072683975 | Y19: 0.030585157 | Z19: 0.017202636 | AA19: 0.035507362
A20: 260203 | B20: INNV | C20: United States | D20: Medical Care Facilities | E20: Jun'26 | F20: 3.5 | G20: 175.35 | H20: 177.36 | I20: 172.86 | J20: 171.22 | K20: 167.46 | L20: 172.54 | M20: 176.87 | N20: 182.49 | O20: 188.9 | P20: 193.07 | Q20: 199.4 | R20: 205.14 | S20: 209 | T20: 218.14 | U20: 221.42 | V20: 236.11 | W20: 239.71 | X20: 0.031080696 | Y20: 0.026476529 | Z20: 0.036277381 | AA20: 0.034713509
... A23: 260203 | B23: AME | C23: United States | D23: Specialty Industrial Machinery | E23: Dec'25 | F23: 3.3 | G23: 1504 | H23: 1459 | I23: 1515 | J23: 1552 | K23: 1626 | L23: 1597 | M23: 1646 | N23: 1623 | O23: 1731 | P23: 1736 | Q23: 1735 | R23: 1709 | S23: 1762 | T23: 1732 | U23: 1778 | V23: 1893 | W23: 1998 | X23: -0.00057620282 | Y23: 0.0061977515 | Z23: 0.026357255 | AA23: 0.032937893
A24: 260203 | B24: APPS | C24: United States | D24: =VLOOKUP(B24,[1]기업리스트!B:G,2,FALSE) -> Digital Turbine, Inc. | E24: Sep'26 | F24: 3.2 | G24: 216.82 | H24: 184.14 | I24: 188.63 | J24: 174.86 | K24: 162.31 | L24: 140.12 | M24: 146.37 | N24: 143.26 | O24: 142.63 | P24: 112.22 | Q24: 117.99 | R24: 118.73 | S24: 134.64 | T24: 119.15 | U24: 130.93 | V24: 140.38 | W24: 151.4 | X24: 0.014330617 | Y24: 0.026380706 | Z24: 0.043003277 | AA24: 0.03191773
A25: 260203 | B25: TDG | C25: United States | D25: Aerospace & Defense | E25: Mar'26 | F25: 3.2 | G25: 1194 | H25: 1327 | I25: 1398 | J25: 1510 | K25: 1397 | L25: 1592 | M25: 1744 | N25: 1852 | O25: 1789 | P25: 1919 | Q25: 2046 | R25: 2186 | S25: 2006 | T25: 2150 | U25: 2237 | V25: 2437 | W25: 2285 | X25: 0.028319235 | Y25: 0.022770625 | Z25: 0.029257489 | AA25: 0.031596829
A26: 260203 | B26: MPLX | C26: United States | D26: Oil & Gas Midstream | E26: Dec'25 | F26: 3.1 | G26: 2641 | H26: 2511 | I26: 2829 | J26: 3276 | K26: 2521 | L26: 2579 | M26: 2545 | N26: 2753 | O26: 2804 | P26: 2689 | Q26: 2707 | R26: 2823 | S26: 2892 | T26: 2938 | U26: 2833 | V26: 2949 | W26: 3252 | X26: 0.022410224 | Y26: 0.011091549 | Z26: 0.010969876 | AA26: 0.031002411
A27: 260203 | B27: ETN | C27: United States | D27: Specialty Industrial Machinery | E27: Dec'25 | F27: 3.1 | G27: 4798 | H27: 4843 | I27: 5212 | J27: 5313 | K27: 5384 | L27: 5483 | M27: 5866 | N27: 5880 | O27: 5967 | P27: 5943 | Q27: 6350 | R27: 6345 | S27: 6240 | T27: 6377 | U27: 7028 | V27: 6988 | W27: 7055 | X27: 0.017445132 | Y27: 0.026785714 | Z27: 0.024740285 | AA27: 0.030601134
A28: 260203 | B28: J | C28: United States | D28: Engineering & Construction | E28: Mar'26 | F28: 3 | G28: 3381 | H28: 3834 | I28: 3827 | J28: 3881 | K28: 3799 | L28: 4078 | M28: 4187 | N28: -1212 | O28: 2810 | P28: 2847 | Q28: 2883 | R28: 0 | S28: 2933 | T28: 2910 | U28: 3032 | V28: 3155 | W28: 3293 | X28: 0.0072723075 | Y28: 0.017075407 | Z28: 0.35549296 | AA28: 0.029925187
A29: 260203 | B29: PRU | C29: United States | D29: Insurance - Life | E29: Dec'25 | F29: 3 | G29: 16424 | H29: 11855 | I29: 11392 | J29: 20201 | K29: 11135 | L29: 17045 | M29: 13498 | N29: 8352 | O29: 15084 | P29: 23509 | Q29: 14883 | R29: 19490 | S29: 12523 | T29: 13470 | U29: 13726 | V29: 17879 | W29: 14229 | X29: -0.1425893 | Y29: -0.019166418 | Z29: -0.027208701 | AA29: 0.029619084
A30: 260203 | B30: HUBB | C30: United States | D30: Electrical Equipment & Parts | E30: Dec'25 | F30: 2.8 | G30: 1100 | H30: 1156 | I30: 1256 | J30: 1316 | K30: 1220 | L30: 1285 | M30: 1366 | N30: 1376 | O30: 1346 | P30: 1399 | Q30: 1453 | R30: 1443 | S30: 1334 | T30: 1365 | U30: 1484 | V30: 1502 | W30: 1493 | X30: -0.0060401492 | Y30: 0.0055406613 | Z30: 0.010487025 | AA30: 0.027968338
A31: 260203 | B31: VRNS | C31: United States | D31: Software - Infrastructure | E31: Dec'25 | F31: 2.4 | G31: 126.58 | H31: 96.26 | I31: 111.45 | J31: 123.31 | K31: 142.62 | L31: 107.34 | M31: 115.42 | N31: 122.31 | O31: 154.1 | P31: 114.02 | Q31: 130.35 | R31: 148.07 | S31: 158.51 | T31: 136.42 | U31: 152.16 | V31: 161.58 | W31: 173.37 | X31: 0.040657047 | Y31: 0.038039592 | Z31: 0.022699778 | AA31: 0.024413886
A32: 260203 | B32: BR | C32: United States | D32: Information Technology Services | E32: Mar'26 | F32: 2.4 | G32: 1193 | H32: 1260 | I32: 1534 | J32: 1723 | K32: 1283 | L32: 1293 | M32: 1646 | N32: 1839 | O32: 1431 | P32: 1405 | Q32: 1727 | R32: 1944 | S32: 1423 | T32: 1589 | U32: 1812 | V32: 2065 | W32: 1589 | X32: 0.028312048 | Y32: 0.012718839 | Z32: 0.017878251 | AA32: 0.024096386
A33: 260203 | B33: MDLZ | C33: United States | D33: Confectioners | E33: Dec'25 | F33: 2.4 | G33: 7658 | H33: 7764 | I33: 7274 | J33: 7763 | K33: 8695 | L33: 9166 | M33: 8507 | N33: 9029 | O33: 9314 | P33: 9290 | Q33: 8343 | R33: 9204 | S33: 9604 | T33: 9313 | U33: 8984 | V33: 9744 | W33: 10496 | X33: 0.00063115721 | Y33: 0.017578982 | Z33: 0.014553295 | AA33: 0.023695046
A34: 260203 | B34: ZWS | C34: United States | D34: Pollution & Treatment Controls | E34: Dec'25 | F34: 2.2 | G34: 232.3 | H34: 239.6 | I34: 284.2 | J34: 417.7 | K34: 340.3 | L34: 372.1 | M34: 403.2 | N34: 398.4 | O34: 356.8 | P34: 373.8 | Q34: 412 | R34: 410 | S34: 370.7 | T34: 388.8 | U34: 444.5 | V34: 455.4 | W34: 407.2 | X34: 0.0095754868 | Y34: 0.020550111 | Z34: 0.028128872 | AA34: 0.021995902
A35: 260203 | B35: AMGN | C35: United States | D35: Drug Manufacturers - General | E35: Dec'25 | F35: 2.2 | G35: 6846 | H35: 6238 | I35: 6594 | J35: 6652 | K35: 6839 | L35: 6105 | M35: 6986 | N35: 6903 | O35: 8196 | P35: 7447 | Q35: 8388 | R35: 8503 | S35: 9086 | T35: 8149 | U35: 9179 | V35: 9557 | W35: 9866 | X35: 0.021002872 | Y35: 0.023178808 | Z35: 0.030185869 | AA35: 0.021684134
A36: 260203 | B36: SWKS | C36: United States | D36: Semiconductors | E36: Dec'25 | F36: 1.9 | G36: 1311 | H36: 1510 | I36: 1336 | J36: 1233 | K36: 1407 | L36: 1329 | M36: 1153 | N36: 1071 | O36: 1219 | P36: 1202 | Q36: 1046 | R36: 905.5 | S36: 1025 | T36: 1069 | U36: 953.2 | V36: 965 | W36: 1100 | X36: -0.031829604 | Y36: -0.022939068 | Z36: 0.015053002 | AA36: 0.018692986
... A54: 260203 | B54: MLI | C54: United States | D54: Metal Fabrication | E54: Dec'25 | F54: 0.9 | G54: 956.36 | H54: 1010 | I54: 1150 | J54: 944.83 | K54: 877.58 | L54: 971.19 | M54: 896.98 | N54: 819.79 | O54: 732.38 | P54: 849.65 | Q54: 997.75 | R54: 997.83 | S54: 923.54 | T54: 1000 | U54: 1138 | V54: 1078 | W54: 962.39 | X54: 0.039893652 | Y54: 0.035786095 | Z54: 0.01974937 | AA54: 0.0093851008
A55: 260203 | B55: VLTO | C55: United States | D55: Pollution & Treatment Controls | E55: Dec'25 | F55: 0.9 | H55: 1172 | I55: 1231 | J55: 1219 | K55: 1248 | L55: 1225 | M55: 1253 | N55: 1255 | O55: 1288 | P55: 1246 | Q55: 1288 | R55: 1314 | S55: 1345 | T55: 1332 | U55: 1371 | V55: 1404 | W55: 1396 | X55: 0.016560755 | Y55: 0.015722675 | Z55: 0.016784782 | AA55: 0.0093543654
A56: 260203 | B56: POWL | C56: United States | D56: Electrical Equipment & Parts | E56: Mar'26 | F56: 0.9 | G56: 106.57 | H56: 127.85 | I56: 135.48 | J56: 162.68 | K56: 126.86 | L56: 171.44 | M56: 192.37 | N56: 208.64 | O56: 194.02 | P56: 255.11 | Q56: 288.17 | R56: 275.06 | S56: 241.43 | T56: 278.63 | U56: 286.27 | V56: 297.98 | W56: 251.18 | X56: 0.022193495 | Y56: -0.0017539163 | Z56: 0.021194944 | AA56: 0.0088290426
A57: 260203 | B57: CRVL | C57: United States | D57: Insurance Brokers | E57: Sep'26 | F57: 0.8 | G57: 164.51 | H57: 171.36 | I57: 176.31 | J57: 177.43 | K57: 179.39 | L57: 185.44 | M57: 190.25 | N57: 195.52 | O57: 202.3 | P57: 207.23 | Q57: 211.72 | R57: 224.38 | S57: 227.97 | T57: 231.51 | U57: 234.71 | V57: 239.64 | W57: 235.63 | X57: 0.027866407 | Y57: 0.025670515 | Z57: 0.016612779 | AA57: 0.0082027778
A58: 260203 | B58: FUBO | C58: United States | D58: Broadcasting | E58: Dec'25 | F58: 0.8 | P58: 1051 | Q58: 1076 | R58: 1058 | S58: 1058 | T58: 1116 | U58: 1125 | V58: 1091 | W58: 1091 | X58: 0.01531935 | Y58: 0.011374188 | Z58: 0.0075740188 | AA58: 0.0075170843
A59: 260203 | B59: IT | C59: United States | D59: Information Technology Services | E59: Dec'25 | F59: 0.6 | G59: 1306 | H59: 1263 | I59: 1377 | J59: 1332 | K59: 1505 | L59: 1409 | M59: 1503 | N59: 1409 | O59: 1586 | P59: 1473 | Q59: 1595 | R59: 1484 | S59: 1715 | T59: 1534 | U59: 1686 | V59: 1524 | W59: 1753 | X59: 0.0097335248 | Y59: 0.014380531 | Z59: 0.0062315002 | AA59: 0.0058832637
...

Sheet Operating Income
B1: 1 | C1: 2 | D1: 3 | E1: 4 | F1: 5 | G1: 6 | H1: 7 | I1: 8 | J1: 9 | K1: 10 | L1: 11 | M1: 12 | N1: 13 | O1: 14 | P1: 15 | Q1: 16 | R1: 17 | S1: 18 | T1: 19 | U1: 20 | V1: 21 | W1: 22
B2: Ticker | C2: Country | D2: Industry | E2: Latest_Date | F2: Growth_Rate | G2: 4Q21 | H2: 1Q22 | I2: 2Q22 | J2: 3Q22 | K2: 4Q22 | L2: 1Q23 | M2: 2Q23 | N2: 3Q23 | O2: 4Q23 | P2: 1Q24 | Q2: 2Q24 | R2: 3Q24 | S2: 4Q24 | T2: 1Q25 | U2: 2Q25 | V2: 3Q25 | W2: 4Q25 | X2: 1Q25 | Y2: 2Q25 | Z2: 3Q25 | AA2: 4Q25
A3: 260203 | B3: KREF | C3: United States | D3: REIT - Mortgage | E3: Dec'25 | F3: 1180.3 | G3: 35.67 | H3: 35.41 | I3: 25 | J3: -42.92 | K3: 18.86 | L3: -25.09 | M3: -19.95 | N3: 27 | O3: -12.91 | P3: -3.39 | Q3: 25.6 | R3: -7.24 | S3: 19.6 | T3: -5.75 | U3: -30.57 | V3: 12.77 | W3: -27.02 | X3: -0.068267284 | Y3: -1.7438684 | Z3: -0.8351419 | AA3: 11.802532
A4: 260203 | B4: INNV | C4: United States | D4: Medical Care Facilities | E4: Jun'26 | F4: 239.2 | G4: 2.95 | H4: -6.27 | I4: -12.35 | J4: -16.6 | K4: -13.68 | L4: -8.17 | M4: -10.94 | N4: -10.72 | O4: -1.79 | P4: -5.79 | Q4: -4.88 | R4: -4.9 | S4: -4.06 | T4: -10.16 | U4: 13.07 | V4: 8.39 | W4: 13.26 | X4: 0.22261844 | Y4: -0.74791667 | Z4: -2.1966942 | AA4: 2.3922652
A5: 260203 | B5: IAC | C5: United States | D5: Internet Content & Information | E5: Dec'25 | F5: 63.8 | G5: -4.52 | H5: -117.74 | I5: -106.37 | J5: -97.26 | K5: 0 | L5: -65.5 | M5: -51.8 | N5: -15.39 | O5: -105.06 | P5: -63.37 | Q5: -21.54 | R5: 8.15 | S5: 51.24 | T5: 35.67 | U5: 0.68 | V5: -20.4 | W5: 94.08 | X5: -3.8808777 | Y5: 0.30223069 | Z5: -0.29820347 | AA5: 0.63759488
A6: 260203 | B6: ATS | C6: United States | D6: Specialty Industrial Machinery | E6: Jun'26 | F6: 60.8 | G6: 43.65 | H6: 53.69 | I6: 66.61 | J6: 67.15 | K6: 58.72 | L6: 67.17 | M6: 69.13 | N6: 79.15 | O6: 84.22 | P6: 96.46 | Q6: 88.05 | R6: 69.89 | S6: 40.94 | T6: 39.54 | U6: -84.45 | V6: 60.58 | W6: 75.34 | X6: -0.19272703 | Y6: -0.72351313 | Z6: -0.1412318 | AA6: 0.60766649
A7: 260203 | B7: HTLD | C7: United States | D7: Trucking | E7: Dec'25 | F7: 59.2 | G7: 16.41 | H7: 18.14 | I7: 23.34 | J7: 27.91 | K7: 22.07 | L7: 16.1 | M7: 8.21 | N7: -8.51 | O7: -14.51 | P7: -14.29 | Q7: -0.86 | R7: -7.62 | S7: -4.98 | T7: -16.68 | U7: -15.2 | V7: -13.94 | W7: -35.04 | X7: 0.086126126 | Y7: 0.47577969 | Z7: 0.14208633 | AA7: 0.59173228
A8: 260203 | B8: PRU | C8: United States | D8: Insurance - Life | E8: Dec'25 | F8: 57.7 | G8: 2448 | H8: -657 | I8: -1061 | J8: -126 | K8: -1435 | L8: 1847 | M8: 621 | N8: -1058 | O8: 2069 | P8: 1390 | Q8: 1415 | R8: 553 | S8: -148 | T8: 920 | U8: 740 | V8: 1773 | W8: 1747 | X8: -0.14641745 | Y8: -0.24635036 | Z8: 0.59079903 | AA8: 0.57686454
A9: 260203 | B9: MPC | C9: United States | D9: Oil & Gas Refining & Marketing | E9: Dec'25 | F9: 28.4 | G9: 1610 | H9: 1613 | I9: 8110 | J9: 5462 | K9: 0 | L9: 3948 | M9: 3118 | N9: 4448 | O9: 2130 | P9: 1571 | Q9: 2161 | R9: 1140 | S9: 886 | T9: 452 | U9: 1973 | V9: 1733 | W9: 2321 | X9: -0.19433831 | Y9: -0.040525975 | Z9: 0.13322849 | AA9: 0.28449643
A10: 260203 | B10: AMD | C10: United States | D10: Semiconductors | E10: Dec'25 | F10: 22.899506 | G10: 1174 | H10: 951 | I10: 526 | J10: -64 | K10: -149 | L10: -145 | M10: -20 | N10: 224 | O10: 342 | P10: 36 | Q10: 269 | R10: 724 | S10: 1057 | T10: 806 | U10: -98 | V10: 1270 | W10: 1752 | X10: 0.36912752 | Y10: -0.1285014 | Z10: 0.21936521 | AA10: 0.22899506
A11: 260203 | B11: MSGE | C11: United States | D11: Leisure | E11: Jun'26 | F11: 19.8 | G11: 59.98 | H11: 21.19 | I11: -5.27 | J11: -11.31 | K11: 116.62 | L11: 27.42 | M11: -25.42 | N11: -20.48 | O11: 137.25 | P11: 18.31 | Q11: -6.9 | R11: -19.38 | S11: 138.11 | T11: 36.25 | U11: -23.19 | V11: -15.41 | W11: 164.94 | X11: 0.13785154 | Y11: -0.1100081 | Z11: 0.030123682 | AA11: 0.19762817
A12: 260203 | B12: SIMO | C12: United States | D12: Semiconductors | E12: Dec'25 | F12: 17.7 | G12: 68.87 | H12: 66.46 | I12: 67.85 | J12: 55.07 | K12: 24.93 | L12: 5.52 | M12: 5.04 | N12: 15.69 | O12: 14.94 | P12: 17.95 | Q12: 32.04 | R12: 24.46 | S12: 17.69 | T12: 9.77 | U12: 22.33 | V12: 29.23 | W12: 31.71 | X12: -0.088777947 | Y12: -0.11565031 | Z12: 0.064242424 | AA12: 0.17742344
A13: 260203 | B13: CPRI | C13: United States | D13: Luxury Goods | E13: Sep'26 | F13: 17.2 | G13: 343 | H13: 172 | I13: 233 | J13: 263 | K13: 237 | L13: 89 | M13: 78 | N13: 124 | O13: 141 | P13: 41 | Q13: 17 | R13: 25 | S13: 69 | T13: -39 | U13: 17 | V13: 11 | W13: 79 | X13: -0.52631579 | Y13: 0 | Z13: -0.19444444 | AA13: 0.17241379
A14: 260203 | B14: VRNS | C14: United States | D14: Software - Infrastructure | E14: Dec'25 | F14: 15.3 | G14: -17.83 | H14: -48.09 | I14: -37.57 | J14: -25.58 | K14: -9.99 | L14: -43.12 | M14: -39.72 | N14: -29.15 | O14: -5.24 | P14: -47.63 | Q14: -28.83 | R14: -23.64 | S14: -10.9 | T14: -43.16 | U14: -36.55 | V14: -35.93 | W14: -30.26 | X14: -0.04027027 | Y14: 0.072467849 | Z14: 0.10757112 | AA14: 0.1529951
... A55: 260203 | B55: J | C55: United States | D55: Engineering & Construction | E55: Mar'26 | F55: 0.5 | G55: 256.02 | H55: 266.2 | I55: 245.75 | J55: 252.13 | K55: 264.46 | L55: 299.52 | M55: 299.9 | N55: -184.71 | O55: 182.92 | P55: 149.36 | Q55: 219.4 | R55: 0 | S55: 227.9 | T55: 194.86 | U55: 264.61 | V55: 331.76 | W55: 232.56 | X55: 0.076257835 | Y55: 0.070403015 | Z55: 0.48265126 | AA55: 0.0045725275
A56: 260203 | B56: VLTO | C56: United States | D56: Pollution & Treatment Controls | E56: Dec'25 | F56: 0.4 | H56: 231 | I56: 311 | J56: 285 | K56: 295 | L56: 292 | M56: 295 | N56: 273 | O56: 299 | P56: 293 | Q56: 299 | R56: 308 | S56: 311 | T56: 322 | U56: 313 | V56: 326 | W56: 316 | X56: 0.023947151 | Y56: 0.011290323 | Z56: 0.014354067 | AA56: 0.0039308176
A57: 260203 | B57: JJSF | C57: United States | D57: Packaged Foods | E57: Mar'26 | F57: 0.2 | G57: 14.85 | H57: 4.09 | I57: 21.26 | J57: 25.72 | K57: 9.33 | L57: 10.19 | M57: 48.29 | N57: 43.38 | O57: 11.88 | P57: 17.9 | Q57: 50.12 | R57: 44.84 | S57: 5.74 | T57: 5.72 | U57: 51.48 | V57: 33.7 | W57: 5.95 | X57: -0.10269815 | Y57: 0.012779553 | Z57: -0.10335869 | AA57: 0.0021730132
A58: 260203 | B58: CMG | C58: United States | D58: Restaurants | E58: Dec'25 | F58: 0.1 | G58: 163 | H58: 194.53 | I58: 342.28 | J58: 342.62 | K58: 302.12 | L58: 375.97 | M58: 448.05 | N58: 402.19 | O58: 369.98 | P58: 446.77 | Q58: 591.82 | R58: 488.43 | S58: 426.36 | T58: 497.3 | U58: 564.52 | V58: 484.58 | W58: 428.78 | X58: 0.025867983 | Y58: -0.013623366 | Z58: -0.0019477793 | AA58: 0.0012267078
A59: 260203 | B59: PNR | C59: United States | D59: Specialty Industrial Machinery | E59: Dec'25 | F59: 0 | G59: 158.6 | H59: 153.2 | I59: 196 | J59: 175.5 | K59: 197.8 | L59: 195.2 | M59: 215.3 | N59: 182.1 | O59: 171.6 | P59: 203.2 | Q59: 265.1 | R59: 229.3 | S59: 204.8 | T59: 227.1 | U59: 286.9 | V59: 245.1 | W59: 205 | X59: 0.026484929 | Y59: 0.023534492 | Z59: 0.016664909 | AA59: 0.0002074904
A60: 260203 | B60: VOYA | C60: United States | D60: Financial Conglomerates | E60: Dec'25 | F60: -0.1 | G60: 20 | H60: 171 | I60: 198 | J60: 114 | K60: 232 | L60: 191 | M60: 369 | N60: 248 | O60: 252 | P60: 344 | Q60: 374 | R60: 185 | S60: 198 | T60: 240 | U60: 251 | V60: 367 | W60: 197 | X60: -0.094459582 | Y60: -0.12337011 | Z60: 0.20823799 | AA60: -0.0009469697
A61: 260203 | B61: MZTI | C61: United States | D61: Packaged Foods | E61: Jun'26 | F61: -0.3 | G61: 45.06 | H61: 13.81 | I61: 44.24 | J61: 49.3 | K61: 51.33 | L61: 29.41 | M61: 36.44 | N61: 56.78 | O61: 65.94 | P61: 50.07 | Q61: 43.87 | R61: 55.86 | S61: 77.47 | T61: 51.59 | U61: 44.09 | V61: 60.4 | W61: 76.85 | X61: 0.0066880803 | Y61: 0.00096158049 | Z61: 0.019824462 | AA61: -0.0026546778
A62: 260203 | B62: WTW | C62: United States | D62: Insurance Brokers | E62: Dec'25 | F62: -0.5 | G62: 0 | H62: 276 | I62: 300 | J62: 277 | K62: 958 | L62: 375 | M62: 270 | N62: 318 | O62: 965 | P62: 445 | Q62: 333 | R62: 380 | S62: 1045 | T62: 357 | U62: 383 | V62: 432 | W62: 1035 | X62: -0.039945529 | Y62: 0.023640662 | Z62: 0.024018476 | AA62: -0.0045105999
A63: 260203 | B63: HRB | C63: United States | D63: Personal Services | E63: Jun'26 | F63: -0.7 | G63: -277.3 | H63: 885.37 | I63: 311.6 | J63: -209.11 | K63: -283.2 | L63: 864.5 | M63: 376.51 | N63: -206.33 | O63: -267.43 | P63: 928.2 | Q63: 350.83 | R63: -228.33 | S63: -293.29 | T63: 978.31 | U63: 371.28 | V63: -207.03 | W63: -298.88 | X63: 0.066159676 | Y63: 0.02532445 | Z63: 0.02572557 | AA63: -0.0065821235
A64: 260203 | B64: ATI | C64: United States | D64: Metal Fabrication | E64: Dec'25 | F64: -1 | G64: 58.1 | H64: 88.4 | I64: 96.4 | J64: 104.1 | K64: 266.2 | L64: 110.2 | M64: 121.2 | N64: 122.4 | O64: 62.7 | P64: 114.6 | Q64: 142.1 | R64: 140.8 | S64: 154.6 | T64: 150.9 | U64: 164.3 | V64: 170.1 | W64: 148 | X64: 0.065748959 | Y64: 0.037729436 | Z64: 0.047985588 | AA64: -0.010314112
A65: 260203 | B65: GWW | C65: United States | D65: Industrial Distribution | E65: Dec'25 | F65: -1.2 | G65: 588 | H65: 534 | I65: 534 | J65: 603 | K65: 546 | L65: 680 | M65: 661 | N65: 667 | O65: 601 | P65: 669 | Q65: 649 | R65: 686 | S65: 668 | T65: 672 | U65: 678 | V65: 707 | W65: 634 | X65: 0.0011227545 | Y65: 0.010841121 | Z65: 0.0077662722 | AA65: -0.012477064
A66: 260203 | B66: ADM | C66: United States | D66: Farm Products | E66: Dec'25 | F66: -1.4 | G66: 880 | H66: 1074 | I66: 1292 | J66: 1000 | K66: 805 | L66: 1203 | M66: 1047 | N66: 999 | O66: 751 | P66: 708 | Q66: 489 | R66: 460 | S66: 340 | T66: 248 | U66: 459 | V66: 397 | W66: 320 | X66: -0.23034552 | Y66: -0.019518543 | Z66: -0.04180491 | AA66: -0.013850416
A67: 260203 | B67: FUBO | C67: United States | D67: Broadcasting | E67: Dec'25 | F67: -1.5 | P67: -38.78 | Q67: -43.98 | R67: -40.75 | S67: -40.75 | T67: -39.75 | U67: -40.91 | V67: -38.39 | W67: -38.39 | X67: 0.0059052721 | Y67: -0.018580161 | Z67: -0.014553527 | AA67: -0.014768461
A68: 260203 | B68: INGR | C68: United States | D68: Packaged Foods | E68: Dec'25 | F68: -1.9 | G68: 113 | H68: 213 | I68: 215 | J68: 186 | K68: 150 | L68: 291 | M68: 249 | N68: 222 | O68: 200 | P68: 216 | Q68: 263 | R68: 277 | S68: 250 | T68: 283 | U68: 274 | V68: 251 | W68: 230 | X68: 0.066600398 | Y68: 0.010251631 | Z68: -0.02398524 | AA68: -0.018903592
A69: 260203 | B69: SKY | C69: United States | D69: Residential Construction | E69: Sep'26 | F69: -3.8 | G69: 91.41 | H69: 116 | I69: 157.05 | J69: 190.19 | K69: 102.27 | L69: 68.77 | M69: 59.23 | N69: 52.04 | O69: 56.18 | P69: 7.76 | Q69: 63.3 | R69: 66.68 | S69: 72.81 | T69: 42.87 | U69: 81.42 | V69: 74.82 | W69: 62.47 | X69: 0.16675374 | Y69: 0.073760482 | Z69: 0.030859049 | AA69: -0.03802589
A70: 260203 | B70: BV | C70: United States | D70: Specialty Business Services | E70: Mar'26 | F70: -4 | G70: -3.6 | H70: 17.3 | I70: 48.2 | J70: 46.1 | K70: -1.9 | L70: -2.6 | M70: 51.2 | N70: 78.1 | O70: -6.2 | P70: 18.3 | Q70: 66 | R70: 62.5 | S70: -0.6 | T70: 39.4 | U70: 61.8 | V70: 60.1 | W70: -7.1 | X70: 0.14432285 | Y70: -0.025104603 | Z70: -0.014714899 | AA70: -0.04044804
A71: 260203 | B71: CBT | C71: United States | D71: Specialty Chemicals | E71: Mar'26 | F71: -4.1 | G71: 119 | H71: 144 | I71: 170 | J71: 125 | K71: 108 | L71: 130 | M71: 151 | N71: 135 | O71: 136 | P71: 157 | Q71: 172 | R71: 163 | S71: 155 | T71: 163 | U71: 167 | V71: 146 | W71: 129 | X71: 0.0092735703 | Y71: -0.0076569678 | Z71: -0.026234568 | AA71: -0.041204437
A72: 260203 | B72: AAT | C72: United States | D72: REIT - Diversified | E72: Dec'25 | F72: -6.3 | G72: 25.72 | H72: 28.34 | I72: 28.32 | J72: 31 | K72: 27.07 | L72: 29.72 | M72: 31.49 | N72: 31.14 | O72: 29.4 | P72: 30.55 | Q72: 30.79 | R72: 37.81 | S72: 30.05 | T72: 27.5 | U72: 25.98 | V72: 24.77 | W72: 23.22 | X72: -0.023606811 | Y72: -0.038129211 | Z72: -0.10746662 | AA72: -0.063065559
A73: 260203 | B73: COLM | C73: United States | D73: Apparel Manufacturing | E73: Dec'25 | F73: -8 | G73: 212.57 | H73: 83.67 | I73: 8.77 | J73: 145.26 | K73: 191.8 | L73: 56.43 | M73: 6.23 | N73: 134.55 | O73: 138.07 | P73: 44.68 | Q73: -23.8 | R73: 112.54 | S73: 137.32 | T73: 46.51 | U73: -23.59 | V73: 96.39 | W73: 116.74 | X73: 0.0067592524 | Y73: 0.00077044429 | Z73: -0.05920522 | AA73: -0.080193274
A74: 260203 | B74: INTA | C74: United States | D74: Software - Application | E74: Jun'26 | F74: -9 | G74: -23.91 | H74: -28.7 | I74: -21.62 | J74: -17.2 | K74: -20.01 | L74: -18.89 | M74: -11.97 | N74: -15.4 | O74: -11.08 | P74: -7.45 | Q74: 0.34 | R74: -8.17 | S74: -10.19 | T74: -5.7 | U74: -3.74 | V74: -13.95 | W74: -7.18 | X74: -0.068708284 | Y74: 0.17200675 | Z74: 0.20791367 | AA74: -0.089636689
A75: 260203 | B75: RES | C75: United States | D75: Oil & Gas Equipment & Services | E75: Dec'25 | F75: -9.9 | G75: 16.58 | H75: 20.08 | I75: 58.62 | J75: 90.63 | K75: 112.73 | L75: 105.1 | M75: 80.27 | N75: 20.93 | O75: 47.6 | P75: 31.14 | Q75: 32.13 | R75: 17.41 | S75: 8.66 | T75: 10.86 | U75: 19.89 | V75: 23.7 | W75: 2.4 | X75: -0.22699799 | Y75: -0.17723719 | Z75: 0.11070046 | AA75: -0.099191887
A76: 260203 | B76: BRBR | C76: United States | D76: Packaged Foods | E76: Mar'26 | F76: -10.3 | G76: 52.6 | H76: 43.5 | I76: 68.4 | J76: 62.4 | K76: 75.2 | L76: 58 | M76: 76 | N76: 85.2 | O76: 90.4 | P76: 91 | Q76: 111.6 | R76: 112.1 | S76: 115.3 | T76: 95.1 | U76: 44.8 | V76: 102.2 | W76: 78.5 | X76: 0.0095348837 | Y76: -0.15388159 | Z76: -0.026953444 | AA76: -0.10296586
A77: 260203 | B77: SWKS | C77: United States | D77: Semiconductors | E77: Dec'25 | F77: -13.4 | G77: 376.6 | H77: 448.3 | I77: 372 | J77: 327.9 | K77: 409.5 | L77: 367.4 | M77: 296.4 | N77: 235.1 | O77: 254.3 | P77: 274.5 | Q77: 188.9 | R77: 132 | S77: 191.9 | T77: 182.7 | U77: 104.4 | V77: 112.1 | W77: 112.6 | X77: -0.11660104 | Y77: -0.12149533 | Z77: -0.032569558 | AA77: -0.13415666
A78: 260203 | B78: MDLZ | C78: United States | D78: Confectioners | E78: Dec'25 | F78: -14.2 | G78: 1111 | H78: 1344 | I78: 1003 | J78: 1037 | K78: 1219 | L78: 1619 | M78: 1492 | N78: 1521 | O78: 1339 | P78: 2838 | Q78: 930 | R78: 1026 | S78: 1651 | T78: 723 | U78: 1168 | V78: 1056 | W78: 1000 | X78: -0.32816137 | Y78: 0.054965358 | Z78: 0.0065674256 | AA78: -0.1415833
A79: 260203 | B79: AMGN | C79: United States | D79: Drug Manufacturers - General | E79: Dec'25 | F79: -14.9 | G79: 2355 | H79: 2490 | I79: 2176 | J79: 2654 | K79: 2138 | L79: 2069 | M79: 2661 | N79: 1874 | O79: 3197 | P79: 1752 | Q79: 2707 | R79: 2708 | S79: 4707 | T79: 2341 | U79: 3004 | V79: 3264 | W79: 2720 | X79: 0.049604177 | Y79: 0.023830538 | Z79: 0.043573668 | AA79: -0.14921898
... A93: 260203 | B93: MRCY | C93: United States | D93: Aerospace & Defense | E93: Jun'26 | F93: -826.5 | G93: 6.08 | H93: 19.03 | I93: 36.54 | J93: -3.19 | K93: -4.54 | L93: 6.34 | M93: -4.87 | N93: -29.69 | O93: -53.7 | P93: -35.61 | Q93: -0.88 | R93: -10.98 | S93: -12.2 | T93: -12.1 | U93: 24.87 | V93: -1.25 | W93: -6.58 | X93: -0.39400034 | Y93: -0.71211283 | Z93: -0.93467819 | AA93: -8.2647059
...

Sheet 빨간줄
B2: (단위: mil $)
B4: XOM | C4: 6 | D4: 7 | E4: 8 | F4: 9 | G4: 10 | H4: 11 | I4: 12 | J4: 13 | K4: 14 | L4: 15 | M4: 16 | N4: 17 | O4: 18 | P4: 19 | Q4: 20 | R4: 21 | S4: 22
C6: 4Q21 | D6: 1Q22 | E6: 2Q22 | F6: 3Q22 | G6: 4Q22 | H6: 1Q23 | I6: 2Q23 | J6: 3Q23 | K6: 4Q23 | L6: 1Q24 | M6: 2Q24 | N6: 3Q24 | O6: 4Q24 | P6: 1Q25 | Q6: 2Q25 | R6: 3Q25 | S6: 4Q25 | T6: 1Q26 | U6: 2Q26 | V6: 3Q26 | W6: 4Q26
B7: Revenue | C7: =VLOOKUP($B$4,Revenue!$B:$W,C4,FALSE) -> 82885 | D7: =VLOOKUP($B$4,Revenue!$B:$W,D4,FALSE) -> 87962 | E7: =VLOOKUP($B$4,Revenue!$B:$W,E4,FALSE) -> 111993 | F7: =VLOOKUP($B$4,Revenue!$B:$W,F4,FALSE) -> 107438 | G7: =VLOOKUP($B$4,Revenue!$B:$W,G4,FALSE) -> 93790 | H7: =VLOOKUP($B$4,Revenue!$B:$W,H4,FALSE) -> 84183 | I7: =VLOOKUP($B$4,Revenue!$B:$W,I4,FALSE) -> 80256 | J7: =VLOOKUP($B$4,Revenue!$B:$W,J4,FALSE) -> 88570 | ... S7: =VLOOKUP($B$4,Revenue!$B:$W,S4,FALSE) -> 80039
B8: OP | C8: =VLOOKUP($B$4,'Operating Income'!$B:$W,C4,FALSE) -> 11128 | D8: =VLOOKUP($B$4,'Operating Income'!$B:$W,D4,FALSE) -> 9181 | E8: =VLOOKUP($B$4,'Operating Income'!$B:$W,E4,FALSE) -> 21439 | F8: =VLOOKUP($B$4,'Operating Income'!$B:$W,F4,FALSE) -> 21696 | G8: =VLOOKUP($B$4,'Operating Income'!$B:$W,G4,FALSE) -> 13738 | H8: =VLOOKUP($B$4,'Operating Income'!$B:$W,H4,FALSE) -> 14581 | I8: =VLOOKUP($B$4,'Operating Income'!$B:$W,I4,FALSE) -> 9247 | J8: =VLOOKUP($B$4,'Operating Income'!$B:$W,J4,FALSE) -> 11678 | ... S8: =VLOOKUP($B$4,'Operating Income'!$B:$W,S4,FALSE) -> 7780
B9: Trailing 4Q OP avg. | C9: =AVERAGE(C8:C8) -> 11128 | D9: =AVERAGE(C8:D8) -> 10154.5 | E9: =AVERAGE(C8:E8) -> 13916 | F9: =AVERAGE(C8:F8) -> 15861 | G9: =AVERAGE(D8:G8) -> 16513.5 | H9: =AVERAGE(E8:H8) -> 17863.5 | I9: =AVERAGE(F8:I8) -> 14815.5 | J9: =AVERAGE(G8:J8) -> 12311 | K9: =AVERAGE(H8:K8) -> 11761.75 | L9: =AVERAGE(I8:L8) -> 10596 | M9: =AVERAGE(J8:M8) -> 10999.75 | ... S9: =AVERAGE(P8:S8) -> 8887
B10: Trailing 4Q OP sum. | C10: =SUM(C8:C8) -> 11128 | D10: =SUM(C8:D8) -> 20309 | E10: =SUM(C8:E8) -> 41748 | F10: =SUM(C8:F8) -> 63444 | G10: =SUM(D8:G8) -> 66054 | H10: =SUM(E8:H8) -> 71454 | I10: =SUM(F8:I8) -> 59262 | J10: =SUM(G8:J8) -> 49244 | K10: =SUM(H8:K8) -> 47047 | L10: =SUM(I8:L8) -> 42384 | M10: =SUM(J8:M8) -> 43999 | ... S10: =SUM(P8:S8) -> 35548
B11: Trailing OP Delta | D11: =D9/C9-1 -> -0.087482027 | E11: =E9/D9-1 -> 0.3704269 | F11: =F9/E9-1 -> 0.13976717 | G11: =G9/F9-1 -> 0.041138642 | H11: =H9/G9-1 -> 0.081751294 | I11: =I9/H9-1 -> -0.17062726 | J11: =J9/I9-1 -> -0.16904593 | K11: =K9/J9-1 -> -0.044614572 | ... S11: =S9/R9-1 -> -0.015781605
B12: opm | C12: =IFERROR(C8/C7,"-") -> 0.13425831 | D12: =IFERROR(D8/D7,"-") -> 0.10437462 | E12: =IFERROR(E8/E7,"-") -> 0.19143161 | F12: =IFERROR(F8/F7,"-") -> 0.20193972 | G12: =IFERROR(G8/G7,"-") -> 0.14647617 | H12: =IFERROR(H8/H7,"-") -> 0.17320599 | I12: =IFERROR(I8/I7,"-") -> 0.1152188 | J12: =IFERROR(J8/J7,"-") -> 0.13185051 | ... S12: =IFERROR(S8/S7,"-") -> 0.097202614
B13: op yoy | C13: =C8/#REF!-1 -> #REF! | D13: =D8/#REF!-1 -> #REF! | E13: =E8/#REF!-1 -> #REF! | F13: =F8/#REF!-1 -> #REF! | G13: =G8/C8-1 -> 0.23454349 | H13: =H8/D8-1 -> 0.58817122 | I13: =I8/E8-1 -> -0.56868324 | J13: =J8/F8-1 -> -0.4617441 | K13: =K8/G8-1 -> -0.15992139 | L13: =L8/H8-1 -> -0.31979974 | M13: =M8/I8-1 -> 0.17465124 | N13: =N8/J8-1 -> -0.057287207 | ... S13: =S8/O8-1 -> -0.068263473
B14: rv yoy | G14: =G7/C7-1 -> 0.13156783 | H14: =H9/D9-1 -> 0.75917081 | I14: =I9/E9-1 -> 0.064637827 | J14: =J9/F9-1 -> -0.22381943 | K14: =K9/G9-1 -> -0.28774942 | L14: =L9/H9-1 -> -0.40683517 | M14: =M9/I9-1 -> -0.25755121 | N14: =N9/J9-1 -> -0.12009585 | O14: =O9/K9-1 -> -0.14683189 | ... S14: =S9/O9-1 -> -0.11437754
