Workbook

Sheet 해외 실적 기업 리스트
B2: 260129 실적 기업 정보
B4: Ticker | C4: Company | D4: Date | E4: Time | F4: Quarter Ending | G4: Market Cap (bil$)
B5: AAPL | C5: Apple Inc. | D5: 46051 | E5: After Hours | F5: 46381 | G5: 3755761
B6: V | C6: Visa Inc. | D6: 46051 | E6: After Hours | F6: 46381 | G6: 627788
B7: MA | C7: Mastercard Incorporated | D7: 46051 | E7: Pre Market | F7: 46381 | G7: 484460
B8: ROG | C8: Roche Holding AG | D8: 46051 | F8: 46381 | G8: 370914
B9: CAT | C9: Caterpillar Inc. | D9: 46051 | F9: 46381 | G9: 302731
B10: SAP | C10: SAP SE | D10: 46051 | E10: Pre Market | F10: 46381 | G10: 272488
B11: TMO | C11: Thermo Fisher Scientific Inc. | D11: 46051 | F11: 46381 | G11: 235186
B12: KLAC | C12: KLA Corporation | D12: 46051 | F12: 46381 | G12: 198768
B13: 6501 | C13: Hitachi, Ltd. | D13: 46051 | F13: 46381 | G13: 153613
B14: HON | C14: Honeywell International Inc. | D14: 46051 | E14: Pre Market | F14: 46381 | G14: 140602
B15: ABBN | C15: ABB Ltd | D15: 46051 | F15: 46381 | G15: 139029
B16: LMT | C16: Lockheed Martin Corporation | D16: 46051 | E16: Pre Market | F16: 46381 | G16: 136714
B17: SYK | C17: Stryker Corporation | D17: 46051 | E17: After Hours | F17: 46381 | G17: 135776
B18: BX | C18: Blackstone Inc. | D18: 46051 | E18: Pre Market | F18: 46381 | G18: 117785
B19: PH | C19: Parker-Hannifin Corporation | D19: 46051 | E19: Pre Market | F19: 46381 | G19: 117100
B20: SAN | C20: Sanofi | D20: 46051 | E20: Pre Market | F20: 46381 | G20: 113339
B21: CMCSA | C21: Comcast Corporation | D21: 46051 | E21: Pre Market | F21: 46381 | G21: 106766
B22: MO | C22: Altria Group, Inc. | D22: 46051 | F22: 46381 | G22: 103927
B23: 6861 | C23: Keyence Corporation | D23: 46051 | F23: 46381 | G23: 92593
B24: 4519 | C24: Chugai Pharmaceutical Co., Ltd. | D24: 46051 | F24: 46381 | G24: 92445
B25: MRSH | C25: Marsh & McLennan Companies, Inc. | D25: 46051 | F25: 46381 | G25: 89732
B26: SHW | C26: The Sherwin-Williams Company | D26: 46051 | F26: 46381 | G26: 85899
B27: TT | C27: Trane Technologies plc | D27: 46051 | E27: Pre Market | F27: 46381 | G27: 85640
B28: INGA | C28: ING Groep N.V. | D28: 46051 | F28: 46381 | G28: 82691
B29: A005380 | C29: Hyundai Motor Company | D29: 46051 | F29: 46381 | G29: 81607
B30: WDC | C30: Western Digital Corporation | D30: 46051 | E30: After Hours | F30: 46381 | G30: 80822
B31: RCL | C31: Royal Caribbean Cruises Ltd. | D31: 46051 | E31: Pre Market | F31: 46381 | G31: 78026
B32: DBK | C32: Deutsche Bank Aktiengesellschaft | D32: 46051 | F32: 46381 | G32: 74123
B33: NDA FI | C33: Nordea Bank Abp | D33: 46051 | F33: 46381 | G33: 67136
B34: LHX | C34: L3Harris Technologies, Inc. | D34: 46051 | E34: Pre Market | F34: 46381 | G34: 66353
B35: AJG | C35: Arthur J. Gallagher & Co. | D35: 46051 | E35: After Hours | F35: 46381 | G35: 65026
B36: NSC | C36: Norfolk Southern Corporation | D36: 46051 | E36: Pre Market | F36: 46381 | G36: 64491
B37: VLO | C37: Valero Energy Corporation | D37: 46051 | E37: Pre Market | F37: 46381 | G37: 57064
B38: NDAQ | C38: Nasdaq, Inc. | D38: 46051 | E38: Pre Market | F38: 46381 | G38: 55986
B39: 4502 | C39: Takeda Pharmaceutical Company Limited | D39: 46051 | E39: Pre Market | F39: 46381 | G39: 51863
B40: 6701 | C40: NEC Corporation | D40: 46051 | F40: 46381 | G40: 49922
B41: 6702 | C41: Fujitsu Limited | D41: 46051 | F41: 46381 | G41: 49365
B42: AMP | C42: Ameriprise Financial, Inc. | D42: 46051 | F42: 46381 | G42: 46137
...

Sheet Revenue
B1: 1 | C1: 2 | D1: 3 | E1: 4 | F1: 5 | G1: 6 | H1: 7 | I1: 8 | J1: 9 | K1: 10 | L1: 11 | M1: 12 | N1: 13 | O1: 14 | P1: 15 | Q1: 16 | R1: 17 | S1: 18 | T1: 19 | U1: 20 | V1: 21 | W1: 22
B2: Ticker | C2: Country | D2: Industry | E2: Latest_Date | F2: Growth_Rate | G2: 4Q21 | H2: 1Q22 | I2: 2Q22 | J2: 3Q22 | K2: 4Q22 | L2: 1Q23 | M2: 2Q23 | N2: 3Q23 | O2: 4Q23 | P2: 1Q24 | Q2: 2Q24 | R2: 3Q24 | S2: 4Q24 | T2: 1Q25 | U2: 2Q25 | V2: 3Q25 | W2: 4Q25 | X2: 1Q25 | Y2: 2Q25 | Z2: 3Q25 | AA2: 4Q25
B3: FISI | C3: United States | D3: Banks - Regional | E3: Dec '25 Dec 31, 2025 | F3: 99.862943 | G3: 53.73 | H3: 48.56 | I3: 52.39 | J3: 51.41 | K3: 47.97 | L3: 48.53 | M3: 50.57 | N3: 51.2 | O3: 49.98 | P3: 56.44 | Q3: 63.17 | R3: 47.02 | S3: -55.86 | T3: 54.31 | U3: 57.18 | V3: 61.11 | W3: 60.72 | X3: =SUM(Q3:T3)/SUM(P3:S3)-1 -> -0.019229033 | Y3: =SUM(R3:U3)/SUM(Q3:T3)-1 -> -0.05513623 | Z3: =SUM(S3:V3)/SUM(R3:U3)-1 -> 0.13726254 | AA3: =SUM(T3:W3)/SUM(S3:V3)-1 -> 0.99862943
B4: IVR | C4: United States | D4: REIT - Mortgage | E4: Dec '25 Dec 31, 2025 | F4: 65.753804 | G4: -57.46 | H4: -221.12 | I4: -102.4 | J4: -95.57 | K4: 41.5 | L4: 26.53 | M4: 9.38 | N4: -63.78 | O4: 32.06 | P4: 33.82 | Q4: -8.32 | R4: 45.33 | S4: 8.52 | T4: 24.3 | U4: -18.46 | V4: 57.94 | W4: 56.06 | X4: =SUM(Q4:T4)/SUM(P4:S4)-1 -> -0.1199748 | Y4: =SUM(R4:U4)/SUM(Q4:T4)-1 -> -0.1452098 | Z4: =SUM(S4:V4)/SUM(R4:U4)-1 -> 0.21125817 | AA4: =SUM(T4:W4)/SUM(S4:V4)-1 -> 0.65753804
B5: WDC | C5: United States | D5: Computer Hardware | E5: Jan '26 Jan 2, 2026 | F5: 39.095503 | G5: 4833 | H5: 4381 | I5: 4528 | J5: 3736 | K5: 3107 | L5: 2803 | M5: 2672 | N5: 2750 | O5: 0 | P5: 1752 | Q5: 0 | R5: 2212 | S5: 0 | T5: 2294 | U5: 2605 | V5: 2818 | W5: 3017 | X5: =SUM(Q5:T5)/SUM(P5:S5)-1 -> 0.13673058 | Y5: =SUM(R5:U5)/SUM(Q5:T5)-1 -> 0.57811806 | Z5: =SUM(S5:V5)/SUM(R5:U5)-1 -> 0.085220082 | AA5: =SUM(T5:W5)/SUM(S5:V5)-1 -> 0.39095503
B6: PFSI | C6: United States | D6: Mortgage Finance | E6: Dec '25 Dec 31, 2025 | F6: 24.722392 | G6: 848.95 | H6: 444.05 | I6: 398.6 | J6: 380.35 | K6: 405.49 | L6: 539.17 | M6: 499.51 | N6: 602.23 | O6: 364.77 | P6: 333.84 | Q6: 507.25 | R6: 1040 | S6: -79.81 | T6: 862.08 | U6: 690.76 | V6: 1026 | W6: 538.01 | X6: =SUM(Q6:T6)/SUM(P6:S6)-1 -> 0.29325813 | Y6: =SUM(R6:U6)/SUM(Q6:T6)-1 -> 0.078775885 | Z6: =SUM(S6:V6)/SUM(R6:U6)-1 -> -0.0055709641 | AA6: =SUM(T6:W6)/SUM(S6:V6)-1 -> 0.24722392
B7: SNDK | C7: United States | D7: Computer Hardware | E7: Jan '26 Jan 2, 2026 | F7: 14.768638 | G7: 1746 | H7: 1735 | I7: 1332 | J7: 1237 | K7: 1452 | N7: 1533 | O7: 1665 | P7: 1705 | Q7: 1760 | R7: 1883 | S7: 1876 | T7: 1695 | U7: 1901 | V7: 2308 | W7: 3025 | X7: =SUM(Q7:T7)/SUM(P7:S7)-1 -> -0.0013842746 | Y7: =SUM(R7:U7)/SUM(Q7:T7)-1 -> 0.019545329 | Z7: =SUM(S7:V7)/SUM(R7:U7)-1 -> 0.057783821 | AA7: =SUM(T7:W7)/SUM(S7:V7)-1 -> 0.14768638
B8: CNX | C8: United States | D8: Oil & Gas E&P | E8: Dec '25 Dec 31, 2025 | F8: 14.671467 | G8: 908.93 | H8: 812.5 | I8: 1072 | J8: 1179 | K8: 860.84 | L8: 513.7 | M8: 295.89 | N8: 302.46 | O8: 350.62 | P8: 376.78 | Q8: 307.12 | R8: 334.72 | S8: 327.24 | T8: 610.55 | U8: 541.91 | V8: 450.85 | W8: 610.48 | X8: =SUM(Q8:T8)/SUM(P8:S8)-1 -> 0.17369563 | Y8: =SUM(R8:U8)/SUM(Q8:T8)-1 -> 0.14863607 | Z8: =SUM(S8:V8)/SUM(R8:U8)-1 -> 0.064003924 | AA8: =SUM(T8:W8)/SUM(S8:V8)-1 -> 0.14671467
B9: PMT | C9: United States | D9: REIT - Mortgage | E9: Dec '25 Dec 31, 2025 | F9: 13.97301 | G9: 221.21 | H9: -221.88 | I9: -112.28 | J9: 84.09 | K9: 104.41 | L9: 227.81 | M9: 178.45 | N9: 2.5 | O9: 317.11 | P9: 102.41 | Q9: 121.75 | R9: 265.78 | S9: 14.66 | T9: 189.06 | U9: 145.33 | V9: 215.61 | W9: 93.56 | X9: =SUM(Q9:T9)/SUM(P9:S9)-1 -> 0.17172017 | Y9: =SUM(R9:U9)/SUM(Q9:T9)-1 -> 0.039881607 | Z9: =SUM(S9:V9)/SUM(R9:U9)-1 -> -0.081599792 | AA9: =SUM(T9:W9)/SUM(S9:V9)-1 -> 0.1397301
B10: BX | C10: United States | D10: Asset Management | E10: Dec '25 Dec 31, 2025 | F10: 11.109374 | G10: 5655 | H10: 4987 | I10: 404.08 | J10: 778.23 | K10: 1847 | L10: 1292 | M10: 2738 | N10: 2367 | O10: 1287 | P10: 3535 | Q10: 2668 | R10: 3648 | S10: 2811 | T10: 3245 | U10: 3801 | V10: 2934 | W10: 4232 | X10: =SUM(Q10:T10)/SUM(P10:S10)-1 -> -0.022903175 | Y10: =SUM(R10:U10)/SUM(Q10:T10)-1 -> 0.091577756 | Z10: =SUM(S10:V10)/SUM(R10:U10)-1 -> -0.052869308 | AA10: =SUM(T10:W10)/SUM(S10:V10)-1 -> 0.11109374
B11: 6135 | C11: Japan | D11: N/A | E11: Sep '25 Sep 30, 2025 | F11: 3.2198364 | G11: 38401 | H11: 47532 | I11: 63719 | J11: 46481 | K11: 56558 | L11: 62459 | M11: 62487 | N11: 53850 | O11: 54665 | P11: 54477 | Q11: 62368 | R11: 51868 | S11: 56369 | T11: 60557 | U11: 65422 | V11: 55397 | W11: 64024
B12: MXL | C12: United States | D12: Semiconductors | E12: Dec '25 Dec 31, 2025 | F12: 10.456575 | G12: 247.89 | H12: 263.93 | I12: 280.01 | J12: 285.73 | K12: 290.59 | L12: 248.44 | M12: 183.94 | N12: 135.53 | O12: 125.35 | P12: 95.27 | Q12: 91.99 | R12: 81.1 | S12: 92.17 | T12: 95.93 | U12: 108.81 | V12: 126.46 | W12: 136.44 | X12: =SUM(Q12:T12)/SUM(P12:S12)-1 -> 0.0018306382 | Y12: =SUM(R12:U12)/SUM(Q12:T12)-1 -> 0.046568288 | Z12: =SUM(S12:V12)/SUM(R12:U12)-1 -> 0.11999683 | AA12: =SUM(T12:W12)/SUM(S12:V12)-1 -> 0.10456575
B13: 6995 | C13: Japan | D13: N/A | E13: Sep '25 Sep 30, 2025 | F13: 1.6376556 | G13: 107972 | H13: 126906 | I13: 129273 | J13: 124844 | K13: 142083 | L13: 141654 | M13: 144543 | N13: 148652 | O13: 158816 | P13: 167461 | Q13: 148629 | R13: 151966 | S13: 152006 | T13: 155520 | U13: 158168 | V13: 152690 | W13: 162133
B14: LPLA | C14: United States | D14: Capital Markets | E14: Dec '25 Dec 31, 2025 | F14: 9.3846864 | G14: 2067 | H14: 2038 | I14: 2010 | J14: 2130 | K14: 2296 | L14: 2379 | M14: 2424 | N14: 2474 | O14: 2589 | P14: 2773 | Q14: 2867 | R14: 3041 | S14: 3404 | T14: 3584 | U14: 3729 | V14: 4446 | W14: 4827 | X14: =SUM(Q14:T14)/SUM(P14:S14)-1 -> 0.067107985 | Y14: =SUM(R14:U14)/SUM(Q14:T14)-1 -> 0.066842432 | Z14: =SUM(S14:V14)/SUM(R14:U14)-1 -> 0.1021224 | AA14: =SUM(T14:W14)/SUM(S14:V14)-1 -> 0.093846864
B15: 2782 | C15: Japan | D15: N/A | E15: Sep '25 Sep 30, 2025 | F15: -24.572468 | G15: 50333 | H15: 52506 | I15: 51951 | J15: 56241 | K15: 51661 | L15: 53848 | M15: 53280 | N15: 166469 | O15: 166469 | P15: 56733 | Q15: 58115 | R15: 57784 | S15: 178047 | T15: 178047 | U15: 60214 | V15: 60498 | W15: 60884
B16: AJG | C16: United States | D16: Insurance Brokers | E16: Dec '25 Dec 31, 2025 | F16: 9.057791 | G16: 1904 | H16: 2385 | I16: 1982 | J16: 1976 | K16: 1927 | L16: 2607 | M16: 2326 | N16: 2352 | O16: 2274 | P16: 3125 | Q16: 2637 | R16: 2631 | S16: 2534 | T16: 3441 | U16: 2945 | V16: 3158 | W16: 3628 | X16: =SUM(Q16:T16)/SUM(P16:S16)-1 -> 0.028919191 | Y16: =SUM(R16:U16)/SUM(Q16:T16)-1 -> 0.027394823 | Z16: =SUM(S16:V16)/SUM(R16:U16)-1 -> 0.045623756 | AA16: =SUM(T16:W16)/SUM(S16:V16)-1 -> 0.09057791
B17: IP | C17: United States | D17: Packaging & Containers | E17: Dec '25 Dec 31, 2025 | F17: 8.5373885 | G17: 5086 | H17: 5237 | I17: 5389 | J17: 5402 | K17: 5133 | L17: 5020 | M17: 4682 | N17: 4613 | O17: 4601 | P17: 4619 | Q17: 0 | R17: 3979 | S17: 4580 | T17: 5901 | U17: 0 | V17: 6222 | W17: 6006 | X17: =SUM(Q17:T17)/SUM(P17:S17)-1 -> 0.097283351 | Y17: =SUM(R17:U17)/SUM(Q17:T17)-1 -> 0 | Z17: =SUM(S17:V17)/SUM(R17:U17)-1 -> 0.15511757 | AA17: =SUM(T17:W17)/SUM(S17:V17)-1 -> 0.085373885
B18: VLY | C18: United States | D18: Banks - Regional | E18: Dec '25 Dec 31, 2025 | F18: 8.2156332 | G18: 339.71 | H18: 350.49 | I18: 429.5 | J18: 505.06 | K18: 508.16 | L18: 468.93 | M18: 471.47 | N18: 457.77 | O18: 424.84 | P18: 404.2 | Q18: 365.04 | R18: 382.96 | S18: 365.9 | T18: 406.42 | U18: 448.08 | V18: 483.79 | W18: 505.91 | X18: =SUM(Q18:T18)/SUM(P18:S18)-1 -> 0.0014623543 | Y18: =SUM(R18:U18)/SUM(Q18:T18)-1 -> 0.05462008 | Z18: =SUM(S18:V18)/SUM(R18:U18)-1 -> 0.062886688 | AA18: =SUM(T18:W18)/SUM(S18:V18)-1 -> 0.082156332
B19: APTUS | C19: India | D19: N/A | E19: Sep '25 Sep 30, 2025 | F19: 5.5457814 | G19: 1405 | H19: 1677 | I19: 1500 | J19: 1850 | K19: 2011 | L19: 2099 | M19: 2172 | N19: 2276 | O19: 3336 | P19: 2562 | Q19: 2729 | R19: 2811 | S19: 2981 | T19: 3089 | U19: 3412 | V19: 3591 | W19: 3706
B20: EPR | C20: United States | D20: REIT - Specialty | E20: Sep '25 Sep 30, 2025 | F20: 0.81803671 | G20: 139.19 | H20: 151.66 | I20: 156.77 | J20: 161.84 | K20: 161.85 | L20: 174.9 | M20: 169.41 | N20: 172.08 | O20: 189.72 | P20: 167.04 | Q20: 163.61 | R20: 171.9 | S20: 179.4 | T20: 173.57 | U20: 172.39 | V20: 176.32 | W20: 185.14
B21: GMDCLTD | C21: India | D21: N/A | E21: Sep '25 Sep 30, 2025 | F21: -2.2739917 | G21: 4519 | H21: 7246 | I21: 10573 | J21: 11554 | K21: 5389 | L21: 8554 | M21: 9482 | N21: 7656 | O21: 3827 | P21: 5643 | Q21: 8019 | R21: 8181 | S21: 5930 | T21: 6534 | U21: 8970 | V21: 7326 | W21: 5276
B22: SBCF | C22: United States | D22: Banks - Regional | E22: Dec '25 Dec 31, 2025 | F22: 8.0549816 | G22: 94.94 | H22: 85.34 | I22: 97.79 | J22: 99.71 | K22: 123.23 | L22: 119.88 | M22: 149.3 | N22: 134.41 | O22: 124.17 | P22: 124.21 | Q22: 121.69 | R22: 124.07 | S22: 129.17 | T22: 134.45 | U22: 144.01 | V22: 148.92 | W22: 174 | X22: =SUM(Q22:T22)/SUM(P22:S22)-1 -> 0.020515286 | Y22: =SUM(R22:U22)/SUM(Q22:T22)-1 -> 0.043817975 | Z22: =SUM(S22:V22)/SUM(R22:U22)-1 -> 0.046736882 | AA22: =SUM(T22:W22)/SUM(S22:V22)-1 -> 0.080549816
B23: FFWM | C23: United States | D23: Banks - Regional | E23: Dec '25 Dec 31, 2025 | F23: 6.7978197 | G23: 71.91 | H23: 90.71 | I23: 95.03 | J23: 99.88 | K23: 80.77 | L23: 70.04 | M23: 60.18 | N23: 65.79 | O23: 56.14 | P23: 50.49 | Q23: 58.29 | R23: -56.74 | S23: 44.03 | T23: 67.98 | U23: 49.05 | V23: -1.45 | W23: 54.88 | X23: =SUM(Q23:T23)/SUM(P23:S23)-1 -> 0.18205475 | Y23: =SUM(R23:U23)/SUM(Q23:T23)-1 -> -0.081366678 | Z23: =SUM(S23:V23)/SUM(R23:U23)-1 -> 0.53000383 | AA23: =SUM(T23:W23)/SUM(S23:V23)-1 -> 0.067978197
B24: ALGM | C24: United States | D24: Semiconductors | E24: Dec '25 Dec 26, 2025 | F24: 6.5120055 | G24: 186.63 | H24: 200.29 | I24: 217.75 | J24: 237.67 | K24: 248.79 | L24: 269.45 | M24: 278.29 | N24: 275.51 | O24: 254.98 | P24: 240.58 | Q24: 166.92 | R24: 187.39 | S24: 177.87 | T24: 192.82 | U24: 203.41 | V24: 214.29 | W24: 229.21 | X24: =SUM(Q24:T24)/SUM(P24:S24)-1 -> -0.061804441 | Y24: =SUM(R24:U24)/SUM(Q24:T24)-1 -> 0.050331034 | Z24: =SUM(S24:V24)/SUM(R24:U24)-1 -> 0.03532548 | AA24: =SUM(T24:W24)/SUM(S24:V24)-1 -> 0.065120055
B25: TAL | C25: United States | D25: Education & Training Services | E25: Nov '25 Nov 30, 2025 | F25: 6.171034 | G25: 1021 | H25: 541.15 | I25: 224.05 | J25: 294.06 | K25: 232.68 | L25: 268.99 | M25: 275.44 | N25: 411.93 | O25: 373.51 | P25: 429.56 | Q25: 414.19 | R25: 619.36 | S25: 606.45 | T25: 610.24 | U25: 575 | V25: 861.35 | W25: 770.17 | X25: =SUM(Q25:T25)/SUM(P25:S25)-1 -> 0.087303581 | Y25: =SUM(R25:U25)/SUM(Q25:T25)-1 -> 0.071463488 | Z25: =SUM(S25:V25)/SUM(R25:U25)-1 -> 0.10036706 | AA25: =SUM(T25:W25)/SUM(S25:V25)-1 -> 0.06171034
B26: AX | C26: United States | D26: Banks - Regional | E26: Dec '25 Dec 31, 2025 | F26: 5.3584793 | G26: 172.36 | H26: 173.81 | I26: 186.51 | J26: 198.93 | K26: 225.24 | L26: 225.73 | M26: 229.46 | N26: 238.66 | O26: 246.84 | P26: 288.77 | Q26: 284.92 | R26: 306.66 | S26: 295.65 | T26: 294.34 | U26: 306.45 | V26: 306.14 | W26: 360.09 | X26: =SUM(Q26:T26)/SUM(P26:S26)-1 -> 0.0047363946 | Y26: =SUM(R26:U26)/SUM(Q26:T26)-1 -> 0.018221519 | Z26: =SUM(S26:V26)/SUM(R26:U26)-1 -> -0.00043221677 | AA26: =SUM(T26:W26)/SUM(S26:V26)-1 -> 0.053584793
B27: APPF | C27: United States | D27: Software - Application | E27: Dec '25 Dec 31, 2025 | F27: 4.9134383 | G27: 95.6 | H27: 105.3 | I27: 117.45 | J27: 125.08 | K27: 124.06 | L27: 136.1 | M27: 147.08 | N27: 165.44 | O27: 171.83 | P27: 187.43 | Q27: 197.38 | R27: 205.73 | S27: 203.66 | T27: 217.7 | U27: 235.58 | V27: 249.35 | W27: 248.19 | X27: =SUM(Q27:T27)/SUM(P27:S27)-1 -> 0.038113825 | Y27: =SUM(R27:U27)/SUM(Q27:T27)-1 -> 0.046332796 | Z27: =SUM(S27:V27)/SUM(R27:U27)-1 -> 0.050563947 | AA27: =SUM(T27:W27)/SUM(S27:V27)-1 -> 0.049134383
B28: AAPL | C28: United States | D28: Consumer Electronics | E28: Dec '25 Dec 27, 2025 | F28: 4.6751137 | G28: 123945 | H28: 97278 | I28: 82959 | J28: 90146 | K28: 117154 | L28: 94836 | M28: 81797 | N28: 89498 | O28: 119575 | P28: 90753 | Q28: 85777 | R28: 94930 | S28: 124300 | T28: 95359 | U28: 94036 | V28: 102466 | W28: 143756 | X28: =SUM(Q28:T28)/SUM(P28:S28)-1 -> 0.011638367 | Y28: =SUM(R28:U28)/SUM(Q28:T28)-1 -> 0.020628625 | Z28: =SUM(S28:V28)/SUM(R28:U28)-1 -> 0.018442337 | AA28: =SUM(T28:W28)/SUM(S28:V28)-1 -> 0.046751137
B29: VIRT | C29: United States | D29: Capital Markets | E29: Dec '25 Dec 31, 2025 | F29: 4.5555102 | G29: 618.89 | H29: 609.81 | I29: 529.5 | J29: 472.57 | K29: 395.94 | L29: 496.02 | M29: 365.64 | N29: 469.41 | O29: 352.44 | P29: 490.19 | Q29: 520.18 | R29: 547.11 | S29: 660.31 | T29: 675.97 | U29: 734.14 | V29: 623.68 | W29: 783.04 | X29: =SUM(Q29:T29)/SUM(P29:S29)-1 -> 0.083768075 | Y29: =SUM(R29:U29)/SUM(Q29:T29)-1 -> 0.089017586 | Z29: =SUM(S29:V29)/SUM(R29:U29)-1 -> 0.029252769 | AA29: =SUM(T29:W29)/SUM(S29:V29)-1 -> 0.045555102
B30: CAT | C30: United States | D30: Farm & Heavy Construction Machinery | E30: Dec '25 Dec 31, 2025 | F30: 4.5120688 | G30: 13798 | H30: 13589 | I30: 14247 | J30: 14994 | K30: 16597 | L30: 15862 | M30: 17318 | N30: 16810 | O30: 17070 | P30: 15799 | Q30: 16689 | R30: 16106 | S30: 16215 | T30: 14249 | U30: 16569 | V30: 17638 | W30: 19133 | X30: =SUM(Q30:T30)/SUM(P30:S30)-1 -> -0.023916431 | Y30: =SUM(R30:U30)/SUM(Q30:T30)-1 -> -0.0018969633 | Z30: =SUM(S30:V30)/SUM(R30:U30)-1 -> 0.024263926 | AA30: =SUM(T30:W30)/SUM(S30:V30)-1 -> 0.045120688
B31: MA | C31: United States | D31: Credit Services | E31: Dec '25 Dec 31, 2025 | F31: 4.1844062 | G31: 5216 | H31: 5167 | I31: 5497 | J31: 5756 | K31: 5817 | L31: 5748 | M31: 6269 | N31: 6533 | O31: 6548 | P31: 6348 | Q31: 6961 | R31: 7369 | S31: 7489 | T31: 7250 | U31: 8133 | V31: 8602 | W31: 8806 | X31: =SUM(Q31:T31)/SUM(P31:S31)-1 -> 0.03202329 | Y31: =SUM(R31:U31)/SUM(Q31:T31)-1 -> 0.040317864 | Z31: =SUM(S31:V31)/SUM(R31:U31)-1 -> 0.040772461 | AA31: =SUM(T31:W31)/SUM(S31:V31)-1 -> 0.041844062
B32: CSW | C32: United States | D32: Specialty Industrial Machinery | E32: Dec '25 Dec 31, 2025 | F32: 4.077529 | G32: 136.29 | H32: 173.3 | I32: 199.93 | J32: 191.19 | K32: 171.09 | L32: 195.69 | M32: 203.36 | N32: 203.65 | O32: 174.97 | P32: 210.86 | Q32: 226.18 | R32: 227.93 | S32: 193.65 | T32: 230.55 | U32: 263.65 | V32: 276.95 | W32: 232.99 | X32: =SUM(Q32:T32)/SUM(P32:S32)-1 -> 0.022932147 | Y32: =SUM(R32:U32)/SUM(Q32:T32)-1 -> 0.042661475 | Z32: =SUM(S32:V32)/SUM(R32:U32)-1 -> 0.05352814 | AA32: =SUM(T32:W32)/SUM(S32:V32)-1 -> 0.04077529
B33: SXI | C33: United States | D33: Specialty Industrial Machinery | E33: Dec '25 Dec 31, 2025 | F33: 3.7643208 | G33: 185.71 | H33: 189.28 | I33: 184.74 | J33: 180.6 | K33: 187.79 | L33: 184.33 | M33: 188.33 | N33: 184.77 | O33: 178.4 | P33: 177.27 | Q33: 180.19 | R33: 170.46 | S33: 189.81 | T33: 207.78 | U33: 222.05 | V33: 217.43 | W33: 221.32 | X33: =SUM(Q33:T33)/SUM(P33:S33)-1 -> 0.042509021 | Y33: =SUM(R33:U33)/SUM(Q33:T33)-1 -> 0.055944617 | Z33: =SUM(S33:V33)/SUM(R33:U33)-1 -> 0.059448171 | AA33: =SUM(T33:W33)/SUM(S33:V33)-1 -> 0.037643208
... B35: SRCE | C35: United States | D35: Banks - Regional | E35: Dec '25 Dec 31, 2025 | F35: 3.6874754 | G35: 85.01 | H35: 80.53 | I35: 83.79 | J35: 87.77 | K35: 89.39 | L35: 89.84 | M35: 91.24 | N35: 92.83 | O35: 89.5 | P35: 86.59 | Q35: 97.59 | R35: 96.21 | S35: 95.14 | T35: 100.78 | U35: 100.56 | V35: 109.76 | W35: 110.12 | X35: =SUM(Q35:T35)/SUM(P35:S35)-1 -> 0.037786595 | Y35: =SUM(R35:U35)/SUM(Q35:T35)-1 -> 0.007620856 | Z35: =SUM(S35:V35)/SUM(R35:U35)-1 -> 0.03450559 | AA35: =SUM(T35:W35)/SUM(S35:V35)-1 -> 0.036874754
B36: INOXWIND | C36: India | D36: N/A | E36: Sep '25 Sep 30, 2025 | F36: 10.334882 | G36: 1658 | H36: 1520 | I36: 1374 | J36: 2106 | K36: 1072 | L36: 2262 | M36: 0 | N36: 3487 | O36: 3706 | P36: 5035 | Q36: 5308 | R36: 6388 | S36: 7322 | T36: 9113 | U36: 12748 | V36: 8263 | W36: 11192
B37: MO | C37: United States | D37: Tobacco | E37: Dec '25 Dec 31, 2025 | F37: 3.6695428 | G37: 5086 | H37: 4819 | I37: 5374 | J37: 5412 | K37: 5083 | L37: 4763 | M37: 5438 | N37: 5277 | O37: 5024 | P37: 4717 | Q37: 5277 | R37: 5344 | S37: 5106 | T37: 4519 | U37: 5290 | V37: 5251 | W37: 5846 | X37: =SUM(Q37:T37)/SUM(P37:S37)-1 -> -0.0096849932 | Y37: =SUM(R37:U37)/SUM(Q37:T37)-1 -> 0.00064210214 | Z37: =SUM(S37:V37)/SUM(R37:U37)-1 -> -0.0045905523 | AA37: =SUM(T37:W37)/SUM(S37:V37)-1 -> 0.036695428
B38: HMN | C38: United States | D38: Insurance - Property & Casualty | E38: Sep '25 Sep 30, 2025 | F38: 1.6007761 | G38: 329.6 | H38: 331.4 | I38: 346.7 | J38: 345.9 | K38: 342.6 | L38: 346.4 | M38: 353.9 | N38: 356.4 | O38: 378.7 | P38: 402.9 | Q38: 386 | R38: 388.1 | S38: 412.1 | T38: 409 | U38: 416.4 | V38: 411.7 | W38: 438.5
B39: V | C39: United States | D39: Credit Services | E39: Dec '25 Dec 31, 2025 | F39: 3.4775 | G39: 7059 | H39: 7189 | I39: 7275 | J39: 7787 | K39: 7936 | L39: 7985 | M39: 8123 | N39: 8609 | O39: 8634 | P39: 8775 | Q39: 8900 | R39: 9617 | S39: 9510 | T39: 9594 | U39: 10172 | V39: 10724 | W39: 10901 | X39: =SUM(Q39:T39)/SUM(P39:S39)-1 -> 0.022254225 | Y39: =SUM(R39:U39)/SUM(Q39:T39)-1 -> 0.033810903 | Z39: =SUM(S39:V39)/SUM(R39:U39)-1 -> 0.028462705 | AA39: =SUM(T39:W39)/SUM(S39:V39)-1 -> 0.034775
B40: BC | C40: United States | D40: Recreational Vehicles | E40: Dec '25 Dec 31, 2025 | F40: 3.4529321 | G40: 1431 | H40: 1696 | I40: 1836 | J40: 1698 | K40: 1583 | L40: 1744 | M40: 1702 | N40: 1594 | O40: 1362 | P40: 1365 | Q40: 1444 | R40: 1273 | S40: 1155 | T40: 1222 | U40: 1447 | V40: 1360 | W40: 1334 | X40: =SUM(Q40:T40)/SUM(P40:S40)-1 -> -0.027305709 | Y40: =SUM(R40:U40)/SUM(Q40:T40)-1 -> 0.00058892815 | Z40: =SUM(S40:V40)/SUM(R40:U40)-1 -> 0.017068864 | AA40: =SUM(T40:W40)/SUM(S40:V40)-1 -> 0.034529321
B41: FHI | C41: United States | D41: Asset Management | E41: Dec '25 Dec 31, 2025 | F41: 3.3371401 | G41: 321.65 | H41: 324.76 | I41: 366.01 | J41: 381.14 | K41: 373.9 | L41: 382.19 | M41: 433.23 | N41: 402.66 | O41: 391.5 | P41: 396.37 | Q41: 402.58 | R41: 408.46 | S41: 424.68 | T41: 423.54 | U41: 424.84 | V41: 469.45 | W41: 482.83 | X41: =SUM(Q41:T41)/SUM(P41:S41)-1 -> 0.016647366 | Y41: =SUM(R41:U41)/SUM(Q41:T41)-1 -> 0.013415619 | Z41: =SUM(S41:V41)/SUM(R41:U41)-1 -> 0.036270755 | AA41: =SUM(T41:W41)/SUM(S41:V41)-1 -> 0.033371401
...

Sheet Operating Income
B1: 1 | C1: 2 | D1: 3 | E1: 4 | F1: 5 | G1: 6 | H1: 7 | I1: 8 | J1: 9 | K1: 10 | L1: 11 | M1: 12 | N1: 13 | O1: 14 | P1: 15 | Q1: 16 | R1: 17 | S1: 18 | T1: 19 | U1: 20 | V1: 21 | W1: 22
B2: Ticker | C2: Country | D2: Industry | E2: Latest_Date | F2: Growth_Rate | G2: 4Q21 | H2: 1Q22 | I2: 2Q22 | J2: 3Q22 | K2: 4Q22 | L2: 1Q23 | M2: 2Q23 | N2: 3Q23 | O2: 4Q23 | P2: 1Q24 | Q2: 2Q24 | R2: 3Q24 | S2: 4Q24 | T2: 1Q25 | U2: 2Q25 | V2: 3Q25 | W2: 4Q25 | X2: 1Q25 | Y2: 2Q25 | Z2: 3Q25 | AA2: 4Q25
B3: SNDK | C3: United States | D3: Computer Hardware | E3: Jan '26 Jan 2, 2026 | F3: 230.56995 | N3: -546 | O3: -198 | P3: 79 | Q3: 185 | R3: 313 | S3: 185 | T3: -42 | U3: 51 | V3: 192 | W3: 1075 | X3: =SUM(Q3:T3)/SUM(P3:S3)-1 -> -0.15879265 | Y3: =SUM(R3:U3)/SUM(Q3:T3)-1 -> -0.20904836 | Z3: =SUM(S3:V3)/SUM(R3:U3)-1 -> -0.23865878 | AA3: =SUM(T3:W3)/SUM(S3:V3)-1 -> 2.3056995
B4: TAL | C4: United States | D4: Education & Training Services | E4: Nov '25 Nov 30, 2025 | F4: 143.57143 | G4: -62.18 | H4: 33.26 | I4: -28.32 | J4: 14.89 | K4: -32.88 | L4: -44.42 | M4: -57.77 | N4: 31.79 | O4: -32.19 | P4: -11.06 | Q4: -17.33 | R4: 47.62 | S4: -17.43 | T4: -16.02 | U4: 14.35 | V4: 96.1 | W4: 93.12 | X4: =SUM(Q4:T4)/SUM(P4:S4)-1 -> -2.7555556 | Y4: =SUM(R4:U4)/SUM(Q4:T4)-1 -> -10.025316 | Z4: =SUM(S4:V4)/SUM(R4:U4)-1 -> 1.6998597 | AA4: =SUM(T4:W4)/SUM(S4:V4)-1 -> 1.4357143
B5: CNX | C5: United States | D5: Oil & Gas E&P | E5: Dec '25 Dec 31, 2025 | F5: 106.10558 | G5: 939.41 | H5: -1236 | I5: 90.52 | J5: -207.27 | K5: 1293 | L5: 955.26 | M5: 567.73 | N5: 50.32 | O5: 664.58 | P5: 65.45 | Q5: 20.67 | R5: 104.8 | S5: -189.17 | T5: -236.88 | U5: 616.3 | V5: 241.65 | W5: 269.1 | X5: =SUM(Q5:T5)/SUM(P5:S5)-1 -> -172.76 | Y5: =SUM(R5:U5)/SUM(Q5:T5)-1 -> -1.9816022 | Z5: =SUM(S5:V5)/SUM(R5:U5)-1 -> 0.46381969 | AA5: =SUM(T5:W5)/SUM(S5:V5)-1 -> 1.0610558
B6: IVR | C6: United States | D6: REIT - Mortgage | E6: Dec '25 Dec 31, 2025 | F6: 89.218984 | G6: -64.65 | H6: -228.42 | I6: -109.54 | J6: -101.43 | K6: 36.46 | L6: 21.46 | M6: 4.25 | N6: -68.56 | O6: 27.31 | P6: 29.16 | Q6: -13.2 | R6: 40.64 | S6: 3.74 | T6: 19.64 | U6: -23.33 | V6: 53.47 | W6: 51.49 | X6: =SUM(Q6:T6)/SUM(P6:S6)-1 -> -0.15777262 | Y6: =SUM(R6:U6)/SUM(Q6:T6)-1 -> -0.19933097 | Z6: =SUM(S6:V6)/SUM(R6:U6)-1 -> 0.31531089 | AA6: =SUM(T6:W6)/SUM(S6:V6)-1 -> 0.89218984
B7: WDC | C7: United States | D7: Computer Hardware | E7: Jan '26 Jan 2, 2026 | F7: 47.159647 | G7: 729 | H7: 524 | I7: 611 | J7: 182 | K7: -245 | L7: -432 | M7: -574 | N7: -539 | O7: 0 | P7: 100 | Q7: 0 | R7: 340 | S7: 0 | T7: 559 | U7: 688 | V7: 795 | W7: 963 | X7: =SUM(Q7:T7)/SUM(P7:S7)-1 -> 1.0431818 | Y7: =SUM(R7:U7)/SUM(Q7:T7)-1 -> 0.76529477 | Z7: =SUM(S7:V7)/SUM(R7:U7)-1 -> 0.28670447 | AA7: =SUM(T7:W7)/SUM(S7:V7)-1 -> 0.47159647
B8: VLO | C8: United States | D8: Oil & Gas Refining & Marketing | E8: Dec '25 Dec 31, 2025 | F8: 35.295841 | G8: 1601 | H8: 1400 | I8: 6237 | J8: 3796 | K8: 4383 | L8: 4067 | M8: 2785 | N8: 3529 | O8: 1575 | P8: 1703 | Q8: 1245 | R8: 527 | S8: 370 | T8: 250 | U8: 1117 | V8: 1677 | W8: 1575 | X8: =SUM(Q8:T8)/SUM(P8:S8)-1 -> -0.37789337 | Y8: =SUM(R8:U8)/SUM(Q8:T8)-1 -> -0.053511706 | Z8: =SUM(S8:V8)/SUM(R8:U8)-1 -> 0.50795053 | AA8: =SUM(T8:W8)/SUM(S8:V8)-1 -> 0.35295841
B9: VLY | C9: United States | D9: Banks - Regional | E9: Dec '25 Dec 31, 2025 | F9: 21.700506 | G9: 157.31 | H9: 156.04 | I9: 132.97 | J9: 246.52 | K9: 245.14 | L9: 203.72 | M9: 190.82 | N9: 194.83 | O9: 88.97 | P9: 129.45 | Q9: 93.33 | R9: 126.67 | S9: 89.06 | T9: 139.12 | U9: 173.09 | V9: 209.96 | W9: 221.7 | X9: =SUM(Q9:T9)/SUM(P9:S9)-1 -> 0.022051949 | Y9: =SUM(R9:U9)/SUM(Q9:T9)-1 -> 0.17796421 | Z9: =SUM(S9:V9)/SUM(R9:U9)-1 -> 0.15776414 | AA9: =SUM(T9:W9)/SUM(S9:V9)-1 -> 0.21700506
B10: KEX | C10: United States | D10: Marine Shipping | E10: Dec '25 Dec 31, 2025 | F10: 17.982016 | G10: 33.21 | H10: 28.25 | I10: 47.29 | J10: 62.03 | K10: 59.54 | L10: 60.42 | M10: 88.03 | N10: 93.2 | O10: 93.24 | P10: 103.8 | Q10: 122.68 | R10: 127.91 | S10: 52.65 | T10: 110.22 | U10: 134.46 | V10: 130.82 | W10: 129.64 | X10: =SUM(Q10:T10)/SUM(P10:S10)-1 -> 0.015772406 | Y10: =SUM(R10:U10)/SUM(Q10:T10)-1 -> 0.028491269 | Z10: =SUM(S10:V10)/SUM(R10:U10)-1 -> 0.0068431944 | AA10: =SUM(T10:W10)/SUM(S10:V10)-1 -> 0.17982016
B11: 6135 | C11: Japan | D11: N/A | E11: Sep '25 Sep 30, 2025 | F11: 8.9775029 | G11: 1919 | H11: 2356 | I11: 6106 | J11: 1643 | K11: 3761 | L11: 6207 | M11: 5883 | N11: 4267 | O11: 3510 | P11: 4380 | Q11: 4216 | R11: 2960 | S11: 4616 | T11: 5656 | U11: 5285 | V11: 3201 | W11: 6300
B12: LMT | C12: United States | D12: Aerospace & Defense | E12: Dec '25 Dec 31, 2025 | F12: 17.90892 | G12: 2498 | H12: 2099 | I12: 654 | J12: 2247 | K12: 2499 | L12: 2161 | M12: 2241 | N12: 2151 | O12: 2490 | P12: 2030 | Q12: 2240 | R12: 2151 | S12: 703 | T12: 2279 | U12: 705 | V12: 2176 | W12: 1753 | X12: =SUM(Q12:T12)/SUM(P12:S12)-1 -> 0.034952274 | Y12: =SUM(R12:U12)/SUM(Q12:T12)-1 -> -0.20819205 | Z12: =SUM(S12:V12)/SUM(R12:U12)-1 -> 0.0042822885 | AA12: =SUM(T12:W12)/SUM(S12:V12)-1 -> 0.1790892
B13: 6995 | C13: Japan | D13: N/A | E13: Sep '25 Sep 30, 2025 | F13: 2.3013305 | G13: 581 | H13: 4345 | I13: -2039 | J13: -772 | K13: 4692 | L13: 3422 | M13: 9315 | N13: 8783 | O13: 11464 | P13: 12967 | Q13: -4392 | R13: 7124 | S13: 11418 | T13: 9078 | U13: 7821 | V13: 7836 | W13: 12250
B14: APPF | C14: United States | D14: Software - Application | E14: Dec '25 Dec 31, 2025 | F14: 14.977444 | G14: -7.34 | H14: -14.67 | I14: -10.53 | J14: -7.82 | K14: -17.72 | L14: -26.53 | M14: -2.58 | N14: -0.07 | O14: 43.14 | P14: 34.09 | Q14: 36.03 | R14: 42.57 | S14: 23.66 | T14: 33.78 | U14: 40.51 | V14: 35.05 | W14: 43.58 | X14: =SUM(Q14:T14)/SUM(P14:S14)-1 -> -0.0022735607 | Y14: =SUM(R14:U14)/SUM(Q14:T14)-1 -> 0.032931491 | Z14: =SUM(S14:V14)/SUM(R14:U14)-1 -> -0.053515514 | AA14: =SUM(T14:W14)/SUM(S14:V14)-1 -> 0.14977444
B15: 2782 | C15: Japan | D15: N/A | E15: Sep '25 Sep 30, 2025 | F15: -25.546717 | G15: 4299 | H15: 4374 | I15: 3679 | J15: 4822 | K15: 2571 | L15: 3146 | M15: 3035 | N15: 11258 | O15: 11258 | P15: 3863 | Q15: 3968 | R15: 3680 | S15: 13166 | T15: 13166 | U15: 4595 | V15: 4146 | W15: 4206
B16: BFH | C16: United States | D16: Credit Services | E16: Dec '25 Dec 31, 2025 | F16: 13.703704 | G16: 0 | H16: 302 | I16: 16 | J16: 189 | K16: -208 | L16: 638 | M16: 86 | N16: 225 | O16: 18 | P16: 188 | Q16: 180 | R16: 40 | S16: -27 | T16: 197 | U16: 174 | V16: 196 | W16: 47 | X16: =SUM(Q16:T16)/SUM(P16:S16)-1 -> 0.023622047 | Y16: =SUM(R16:U16)/SUM(Q16:T16)-1 -> -0.015384615 | Z16: =SUM(S16:V16)/SUM(R16:U16)-1 -> 0.40625 | AA16: =SUM(T16:W16)/SUM(S16:V16)-1 -> 0.13703704
B17: VIRT | C17: United States | D17: Capital Markets | E17: Dec '25 Dec 31, 2025 | F17: 13.336436 | G17: 250.76 | H17: 242.52 | I17: 172.22 | J17: 101.62 | K17: 51.49 | L17: 137.21 | M17: 34.49 | N17: 139.02 | O17: 21.87 | P17: 139.62 | Q17: 155.48 | R17: 150.47 | S17: 220.86 | T17: 226.93 | U17: 284.22 | V17: 192 | W17: 344.09 | X17: =SUM(Q17:T17)/SUM(P17:S17)-1 -> 0.13101151 | Y17: =SUM(R17:U17)/SUM(Q17:T17)-1 -> 0.1708016 | Z17: =SUM(S17:V17)/SUM(R17:U17)-1 -> 0.047060557 | AA17: =SUM(T17:W17)/SUM(S17:V17)-1 -> 0.13336436
B18: BX | C18: United States | D18: Asset Management | E18: Dec '25 Dec 31, 2025 | F18: 13.013368 | G18: 3213 | H18: 2857 | I18: -270.39 | J18: -102.63 | K18: 876.81 | L18: 206.65 | M18: 1371 | N18: 1103 | O18: 454.33 | P18: 1853 | Q18: 1144 | R18: 1863 | S18: 1427 | T18: 1469 | U18: 2004 | V18: 1309 | W18: 2235 | X18: =SUM(Q18:T18)/SUM(P18:S18)-1 -> -0.061078416 | Y18: =SUM(R18:U18)/SUM(Q18:T18)-1 -> 0.14568863 | Z18: =SUM(S18:V18)/SUM(R18:U18)-1 -> -0.081916309 | AA18: =SUM(T18:W18)/SUM(S18:V18)-1 -> 0.13013368
B19: APTUS | C19: India | D19: N/A | E19: Sep '25 Sep 30, 2025 | F19: 5.5475296 | G19: 1094 | H19: 1312 | I19: 1437 | J19: 1523 | K19: 1566 | L19: 1684 | M19: 1706 | N19: 1834 | O19: 1896 | P19: 2051 | Q19: 2147 | R19: 2216 | S19: 2367 | T19: 2455 | U19: 2706 | V19: 2855 | W19: 2943
B20: EPR | C20: United States | D20: REIT - Specialty | E20: Sep '25 Sep 30, 2025 | F20: 2.0532877 | G20: 77.85 | H20: 59.94 | I20: 81.77 | J20: 86.31 | K20: 83.65 | L20: 98.61 | M20: 90.55 | N20: 89.99 | O20: 106.11 | P20: 83.74 | Q20: 78.6 | R20: 89.15 | S20: 94.43 | T20: 89.88 | U20: 89.49 | V20: 94.39 | W20: 101.99
B21: GMDCLTD | C21: India | D21: N/A | E21: Sep '25 Sep 30, 2025 | F21: -11.517512 | G21: 65.12 | H21: 1801 | I21: 4289 | J21: 4192 | K21: 1523 | L21: 3151 | M21: 3719 | N21: 2273 | O21: 345.33 | P21: 1013 | Q21: 2227 | R21: 1901 | S21: 1204 | T21: 658.6 | U21: 2981 | V21: 1472 | W21: 476.6
B22: SIGI | C22: United States | D22: Insurance - Property & Casualty | E22: Dec '25 Dec 31, 2025 | F22: 8.5367718 | G22: 131.09 | H22: 77.06 | I22: 57.16 | J22: 59.82 | K22: 115.01 | L22: 121.93 | M22: 81.42 | N22: 119.7 | O22: 164.77 | P22: 109.75 | Q22: -72.9 | R22: 123.74 | S22: 159.05 | T22: 148.46 | U22: 122.16 | V22: 158.96 | W22: 209.3 | X22: =SUM(Q22:T22)/SUM(P22:S22)-1 -> 0.12110499 | Y22: =SUM(R22:U22)/SUM(Q22:T22)-1 -> 0.54432817 | Z22: =SUM(S22:V22)/SUM(R22:U22)-1 -> 0.063641785 | AA22: =SUM(T22:W22)/SUM(S22:V22)-1 -> 0.085367718
B23: SXI | C23: United States | D23: Specialty Industrial Machinery | E23: Dec '25 Dec 31, 2025 | F23: 8.2875038 | G23: 25.24 | H23: 26.08 | I23: 26.06 | J23: 27.16 | K23: 28.49 | L23: 28.67 | M23: 28.05 | N23: 29.05 | O23: 28.39 | P23: 26.53 | Q23: 28.33 | R23: 27.03 | S23: 25.78 | T23: 30.38 | U23: 38.7 | V23: 36.06 | W23: 36.63 | X23: =SUM(Q23:T23)/SUM(P23:S23)-1 -> 0.035757407 | Y23: =SUM(R23:U23)/SUM(Q23:T23)-1 -> 0.092987805 | Z23: =SUM(S23:V23)/SUM(R23:U23)-1 -> 0.07408319 | AA23: =SUM(T23:W23)/SUM(S23:V23)-1 -> 0.082875038
B24: HIG | C24: United States | D24: Insurance - Diversified | E24: Dec '25 Dec 31, 2025 | F24: 7.1058315 | G24: 954 | H24: 590 | I24: 593 | J24: 483 | K24: 802 | L24: 709 | M24: 729 | N24: 867 | O24: 1014 | P24: 966 | Q24: 967 | R24: 1008 | S24: 1134 | T24: 832 | U24: 1296 | V24: 1368 | W24: 1463 | X24: =SUM(Q24:T24)/SUM(P24:S24)-1 -> -0.032883436 | Y24: =SUM(R24:U24)/SUM(Q24:T24)-1 -> 0.08348135 | Z24: =SUM(S24:V24)/SUM(R24:U24)-1 -> 0.084309133 | AA24: =SUM(T24:W24)/SUM(S24:V24)-1 -> 0.071058315
B25: SRCE | C25: United States | D25: Banks - Regional | E25: Dec '25 Dec 31, 2025 | F25: 7.0728768 | G25: 36.27 | H25: 35.19 | I25: 38.13 | J25: 42.44 | K25: 41.02 | L25: 40.42 | M25: 42.07 | N25: 42.67 | O25: 36.52 | P25: 37.89 | Q25: 47.72 | R25: 45.38 | S25: 40.06 | T25: 47.7 | U25: 48.13 | V25: 54.98 | W25: 53.56 | X25: =SUM(Q25:T25)/SUM(P25:S25)-1 -> 0.057351652 | Y25: =SUM(R25:U25)/SUM(Q25:T25)-1 -> 0.0022669468 | Z25: =SUM(S25:V25)/SUM(R25:U25)-1 -> 0.052959673 | AA25: =SUM(T25:W25)/SUM(S25:V25)-1 -> 0.070728768
B26: JBSS | C26: United States | D26: Packaged Foods | E26: Dec '25 Dec 25, 2025 | F26: 6.9604297 | G26: 17.32 | H26: 16.4 | I26: 23.52 | J26: 21.66 | K26: 23.81 | L26: 21.1 | M26: 20.94 | N26: 23.87 | O26: 24.77 | P26: 17.68 | Q26: 14.8 | R26: 16.24 | S26: 18.66 | T26: 27.2 | U26: 19.32 | V26: 26.05 | W26: 25.01 | X26: =SUM(Q26:T26)/SUM(P26:S26)-1 -> 0.14128822 | Y26: =SUM(R26:U26)/SUM(Q26:T26)-1 -> 0.058777633 | Z26: =SUM(S26:V26)/SUM(R26:U26)-1 -> 0.12048637 | AA26: =SUM(T26:W26)/SUM(S26:V26)-1 -> 0.069604297
B27: RCL | C27: United States | D27: Travel Services | E27: Dec '25 Dec 31, 2025 | F27: 6.7462039 | G27: -987.85 | H27: -859.21 | I27: -217.74 | J27: 303 | K27: 18.98 | L27: 272 | M27: 776 | N27: 1265 | O27: 591 | P27: 750 | Q27: 1108 | R27: 1636 | S27: 625 | T27: 949 | U27: 1333 | V27: 1703 | W27: 936 | X27: =SUM(Q27:T27)/SUM(P27:S27)-1 -> 0.048312697 | Y27: =SUM(R27:U27)/SUM(Q27:T27)-1 -> 0.052107457 | Z27: =SUM(S27:V27)/SUM(R27:U27)-1 -> 0.014747964 | AA27: =SUM(T27:W27)/SUM(S27:V27)-1 -> 0.067462039
B28: BC | C28: United States | D28: Recreational Vehicles | E28: Dec '25 Dec 31, 2025 | F28: 6.2075984 | G28: 137 | H28: 239.3 | I28: 278.7 | J28: 261.9 | K28: 195.2 | L28: 245.6 | M28: 208.3 | N28: 212.4 | O28: 125.4 | P28: 127.7 | Q28: 166.2 | R28: 110.6 | S28: 33.8 | T28: 58.1 | U28: 111.3 | V28: 91.6 | W28: 52.1 | X28: =SUM(Q28:T28)/SUM(P28:S28)-1 -> -0.15879535 | Y28: =SUM(R28:U28)/SUM(Q28:T28)-1 -> -0.14890155 | Z28: =SUM(S28:V28)/SUM(R28:U28)-1 -> -0.06054812 | AA28: =SUM(T28:W28)/SUM(S28:V28)-1 -> 0.062075984
B29: AAPL | C29: United States | D29: Consumer Electronics | E29: Dec '25 Dec 27, 2025 | F29: 6.0278091 | G29: 41488 | H29: 29979 | I29: 23076 | J29: 24894 | K29: 36016 | L29: 28318 | M29: 22998 | N29: 26969 | O29: 40373 | P29: 27900 | Q29: 25352 | R29: 29591 | S29: 42832 | T29: 29589 | U29: 28202 | V29: 32427 | W29: 50852 | X29: =SUM(Q29:T29)/SUM(P29:S29)-1 -> 0.013439427 | Y29: =SUM(R29:U29)/SUM(Q29:T29)-1 -> 0.02237681 | Z29: =SUM(S29:V29)/SUM(R29:U29)-1 -> 0.021779532 | AA29: =SUM(T29:W29)/SUM(S29:V29)-1 -> 0.060278091
B30: MA | C30: United States | D30: Credit Services | E30: Dec '25 Dec 31, 2025 | F30: 4.6722417 | G30: 2837 | H30: 2984 | I30: 3184 | J30: 3320 | K30: 3136 | L30: 3347 | M30: 3676 | N30: 3844 | O30: 3680 | P30: 3730 | Q30: 4134 | R30: 4370 | S30: 4218 | T30: 4300 | U30: 4873 | V30: 5144 | W30: 5084 | X30: =SUM(Q30:T30)/SUM(P30:S30)-1 -> 0.034646244 | Y30: =SUM(R30:U30)/SUM(Q30:T30)-1 -> 0.043414405 | Z30: =SUM(S30:V30)/SUM(R30:U30)-1 -> 0.043578627 | AA30: =SUM(T30:W30)/SUM(S30:V30)-1 -> 0.046722417
B31: RMD | C31: United States | D31: Medical Instruments & Supplies | E31: Dec '25 Dec 31, 2025 | F31: 4.5596137 | G31: 248.71 | H31: 234.27 | I31: 257.26 | J31: 275.74 | K31: 288.61 | L31: 300.67 | M31: 286.24 | N31: 289 | O31: 339.32 | P31: 374.58 | Q31: 381.22 | R31: 387.31 | S31: 417.24 | T31: 426.27 | U31: 456.57 | V31: 462.35 | W31: 497.6 | X31: =SUM(Q31:T31)/SUM(P31:S31)-1 -> 0.033127183 | Y31: =SUM(R31:U31)/SUM(Q31:T31)-1 -> 0.046742016 | Z31: =SUM(S31:V31)/SUM(R31:U31)-1 -> 0.044471047 | AA31: =SUM(T31:W31)/SUM(S31:V31)-1 -> 0.045596137
B32: NDAQ | C32: United States | D32: Financial Data & Stock Exchanges | E32: Dec '25 Dec 31, 2025 | F32: 4.2839143 | G32: 403 | H32: 428 | I32: 432 | J32: 421 | K32: 414 | L32: 441 | M32: 450 | N32: 461 | O32: 483 | P32: 455 | Q32: 501 | R32: 489 | S32: 560 | T32: 591 | U32: 611 | V32: 619 | W32: 662 | X32: =SUM(Q32:T32)/SUM(P32:S32)-1 -> 0.067830424 | Y32: =SUM(R32:U32)/SUM(Q32:T32)-1 -> 0.051377861 | Z32: =SUM(S32:V32)/SUM(R32:U32)-1 -> 0.05775211 | AA32: =SUM(T32:W32)/SUM(S32:V32)-1 -> 0.042839143
B33: HTH | C33: United States | D33: Financial Conglomerates | E33: Dec '25 Dec 31, 2025 | F33: 4.2293366 | G33: 85.51 | H33: 29.95 | I33: 47.45 | J33: 42.5 | K33: 36.22 | L33: 31.4 | M33: 27.11 | N33: 52.52 | O33: 38.09 | P33: 38.09 | Q33: 29.56 | R33: 42.44 | S33: 44.17 | T33: 57.65 | U33: 49.47 | V33: 60.8 | W33: 53.14 | X33: =SUM(Q33:T33)/SUM(P33:S33)-1 -> 0.12679891 | Y33: =SUM(R33:U33)/SUM(Q33:T33)-1 -> 0.11454378 | Z33: =SUM(S33:V33)/SUM(R33:U33)-1 -> 0.094771073 | AA33: =SUM(T33:W33)/SUM(S33:V33)-1 -> 0.042293366
... B35: FMBH | C35: United States | D35: Banks - Regional | E35: Dec '25 Dec 31, 2025 | F35: 4.1184843 | G35: 22 | H35: 21.27 | I35: 22.96 | J35: 23.36 | K35: 23.7 | L35: 24.91 | M35: 21.35 | N35: 20.49 | O35: 21.65 | P35: 26.94 | Q35: 26.71 | R35: 25.37 | S35: 25.37 | T35: 28.15 | U35: 30.13 | V35: 28.77 | W35: 30 | X35: =SUM(Q35:T35)/SUM(P35:S35)-1 -> 0.011591149 | Y35: =SUM(R35:U35)/SUM(Q35:T35)-1 -> 0.032386364 | Z35: =SUM(S35:V35)/SUM(R35:U35)-1 -> 0.031186938 | AA35: =SUM(T35:W35)/SUM(S35:V35)-1 -> 0.041184843
B36: INOXWIND | C36: India | D36: N/A | E36: Sep '25 Sep 30, 2025 | F36: 7.8421822 | G36: -215.2 | H36: -558.9 | I36: -2940 | J36: -530 | K36: -494.9 | L36: -2105 | M36: 0 | N36: 25.6 | O36: 220.8 | P36: 647.2 | Q36: 629.26 | R36: 944.8 | S36: 1286 | T36: 1605 | U36: 1918 | V36: 1350 | W36: 1769
B37: SAP | C37: United States | D37: Software - Application | E37: Dec '25 Dec 31, 2025 | F37: 4.0963133 | G37: 1558 | H37: 1557 | I37: 1285 | J37: 1651 | K37: 1889 | L37: 1154 | M37: 1453 | N37: 1763 | O37: 2136 | P37: 1534 | Q37: 1940 | R37: 2252 | S37: 2419 | T37: 2455 | U37: 2569 | V37: 2566 | W37: 2829 | X37: =SUM(Q37:T37)/SUM(P37:S37)-1 -> 0.11307551 | Y37: =SUM(R37:U37)/SUM(Q37:T37)-1 -> 0.069380101 | Z37: =SUM(S37:V37)/SUM(R37:U37)-1 -> 0.032387829 | AA37: =SUM(T37:W37)/SUM(S37:V37)-1 -> 0.040963133
B38: HMN | C38: United States | D38: Insurance - Property & Casualty | E38: Sep '25 Sep 30, 2025 | F38: 13.82928 | G38: 22.4 | H38: 53.1 | I38: 28.9 | J38: -1.7 | K38: 28.7 | L38: -15.2 | M38: 14.8 | N38: -8.7 | O38: 21.1 | P38: 55.8 | Q38: 41.7 | R38: 13.3 | S38: 51.4 | T38: 56.8 | U38: 56.4 | V38: 45.1 | W38: 80.4
B39: DECK | C39: United States | D39: Footwear & Accessories | E39: Dec '25 Dec 31, 2025 | F39: 3.8066758 | G39: 296.74 | H39: 81.28 | I39: 57.33 | J39: 126 | K39: 362.66 | L39: 108.74 | M39: 70.74 | N39: 224.62 | O39: 487.9 | P39: 153.44 | Q39: 132.81 | R39: 305.09 | S39: 567.27 | T39: 178.22 | U39: 165.29 | V39: 326.52 | W39: 614.37 | X39: =SUM(Q39:T39)/SUM(P39:S39)-1 -> 0.021387697 | Y39: =SUM(R39:U39)/SUM(Q39:T39)-1 -> 0.027446573 | Z39: =SUM(S39:V39)/SUM(R39:U39)-1 -> 0.01762524 | AA39: =SUM(T39:W39)/SUM(S39:V39)-1 -> 0.038066758
B40: V | C40: United States | D40: Credit Services | E40: Dec '25 Dec 31, 2025 | F40: 3.4131603 | G40: 4924 | H40: 4862 | I40: 4865 | J40: 5090 | K40: 5431 | L40: 5336 | M40: 5481 | N40: 5679 | O40: 5963 | P40: 5841 | Q40: 5833 | R40: 6359 | S40: 6530 | T40: 6435 | U40: 6792 | V40: 7051 | W40: 7445 | X40: =SUM(Q40:T40)/SUM(P40:S40)-1 -> 0.024182714 | Y40: =SUM(R40:U40)/SUM(Q40:T40)-1 -> 0.038120603 | Z40: =SUM(S40:V40)/SUM(R40:U40)-1 -> 0.026497166 | AA40: =SUM(T40:W40)/SUM(S40:V40)-1 -> 0.034131603
B41: LPLA | C41: United States | D41: Capital Markets | E41: Dec '25 Dec 31, 2025 | F41: 3.285609 | G41: 150.86 | H41: 186.68 | I41: 221.22 | J41: 314.23 | K41: 425.72 | L41: 447.6 | M41: 392.92 | N41: 323.67 | O41: 341.95 | P41: 383.79 | Q41: 366.9 | R41: 363.65 | S41: 340.51 | T41: 453.95 | U41: 440.41 | V41: 501.49 | W41: 397.56 | X41: =SUM(Q41:T41)/SUM(P41:S41)-1 -> 0.048224903 | Y41: =SUM(R41:U41)/SUM(Q41:T41)-1 -> 0.048202963 | Z41: =SUM(S41:V41)/SUM(R41:U41)-1 -> 0.086229763 | AA41: =SUM(T41:W41)/SUM(S41:V41)-1 -> 0.03285609
...

Sheet 빨간줄
B2: (단위: mil $)
Y3: SNDK
B4: 6702 | C4: 6 | D4: 7 | E4: 8 | F4: 9 | G4: 10 | H4: 11 | I4: 12 | J4: 13 | K4: 14 | L4: 15 | M4: 16 | N4: 17 | O4: 18 | P4: 19 | Q4: 20 | R4: 21 | S4: 22 | Y4: TAL
Y5: CNX
C6: 4Q21 | D6: 1Q22 | E6: 2Q22 | F6: 3Q22 | G6: 4Q22 | H6: 1Q23 | I6: 2Q23 | J6: 3Q23 | K6: 4Q23 | L6: 1Q24 | M6: 2Q24 | N6: 3Q24 | O6: 4Q24 | P6: 1Q25 | Q6: 2Q25 | R6: 3Q25 | S6: 4Q25 | T6: 1Q26 | U6: 2Q26 | V6: 3Q26 | W6: 4Q26 | Y6: IVR
B7: Revenue | C7: =VLOOKUP($B$4,Revenue!$B:$W,C4,FALSE) -> 880526 | D7: =VLOOKUP($B$4,Revenue!$B:$W,D4,FALSE) -> 1043302 | E7: =VLOOKUP($B$4,Revenue!$B:$W,E4,FALSE) -> 818862 | F7: =VLOOKUP($B$4,Revenue!$B:$W,F4,FALSE) -> 886449 | G7: =VLOOKUP($B$4,Revenue!$B:$W,G4,FALSE) -> 931424 | H7: =VLOOKUP($B$4,Revenue!$B:$W,H4,FALSE) -> 1077032 | I7: =VLOOKUP($B$4,Revenue!$B:$W,I4,FALSE) -> 799640 | J7: =VLOOKUP($B$4,Revenue!$B:$W,J4,FALSE) -> 912257 | ... S7: =VLOOKUP($B$4,Revenue!$B:$W,S4,FALSE) -> 884642 | Y7: WDC
B8: OP | C8: =VLOOKUP($B$4,'Operating Income'!$B:$W,C4,FALSE) -> 65185 | D8: =VLOOKUP($B$4,'Operating Income'!$B:$W,D4,FALSE) -> 113339 | E8: =VLOOKUP($B$4,'Operating Income'!$B:$W,E4,FALSE) -> 25602 | F8: =VLOOKUP($B$4,'Operating Income'!$B:$W,F4,FALSE) -> 75367 | G8: =VLOOKUP($B$4,'Operating Income'!$B:$W,G4,FALSE) -> 72316 | H8: =VLOOKUP($B$4,'Operating Income'!$B:$W,H4,FALSE) -> 105062 | I8: =VLOOKUP($B$4,'Operating Income'!$B:$W,I4,FALSE) -> -1665 | J8: =VLOOKUP($B$4,'Operating Income'!$B:$W,J4,FALSE) -> 46445 | ... S8: =VLOOKUP($B$4,'Operating Income'!$B:$W,S4,FALSE) -> 105656 | Y8: VLO
B9: Trailing 4Q OP avg. | C9: =AVERAGE(C8:C8) -> 65185 | D9: =AVERAGE(C8:D8) -> 89262 | E9: =AVERAGE(C8:E8) -> 68042 | F9: =AVERAGE(C8:F8) -> 69873.25 | G9: =AVERAGE(D8:G8) -> 71656 | H9: =AVERAGE(E8:H8) -> 69586.75 | I9: =AVERAGE(F8:I8) -> 62770 | J9: =AVERAGE(G8:J8) -> 55539.5 | K9: =AVERAGE(H8:K8) -> 38287.75 | L9: =AVERAGE(I8:L8) -> 63843.75 | M9: =AVERAGE(J8:M8) -> 69606.75 | ... S9: =AVERAGE(P8:S8) -> 52750.25 | Y9: VLY
B10: Trailing 4Q OP sum. | C10: =SUM(C8:C8) -> 65185 | D10: =SUM(C8:D8) -> 178524 | E10: =SUM(C8:E8) -> 204126 | F10: =SUM(C8:F8) -> 279493 | G10: =SUM(D8:G8) -> 286624 | H10: =SUM(E8:H8) -> 278347 | I10: =SUM(F8:I8) -> 251080 | J10: =SUM(G8:J8) -> 222158 | K10: =SUM(H8:K8) -> 153151 | L10: =SUM(I8:L8) -> 255375 | M10: =SUM(J8:M8) -> 278427 | ... S10: =SUM(P8:S8) -> 211001 | Y10: KEX
B11: Trailing OP Delta | D11: =D9/C9-1 -> 0.36936412 | E11: =E9/D9-1 -> -0.23772714 | F11: =F9/E9-1 -> 0.026913524 | G11: =G9/F9-1 -> 0.025514056 | H11: =IFERROR(H9/G9-1,0) -> -0.028877554 | I11: =IFERROR(I9/H9-1,0) -> -0.097960459 | J11: =IFERROR(J9/I9-1,0) -> -0.11519038 | K11: =K9/J9-1 -> -0.31062127 | L11: =L9/K9-1 -> 0.66747197 | M11: =M9/L9-1 -> 0.090267254 | N11: =N9/M9-1 -> -0.041077194 | O11: =O9/N9-1 -> 0.245571 | P11: =P9/O9-1 -> -0.62331344 | Q11: =Q9/P9-1 -> 0.096584151 | R11: =R9/Q9-1 -> 0.26826481 | S11: =S9/R9-1 -> 0.21112508 | Y11: LMT
B12: opm | C12: =IFERROR(C8/C7,"-") -> 0.074029614 | D12: =IFERROR(D8/D7,"-") -> 0.10863489 | E12: =IFERROR(E8/E7,"-") -> 0.031265341 | F12: =IFERROR(F8/F7,"-") -> 0.085021248 | G12: =IFERROR(G8/G7,"-") -> 0.077640258 | H12: =IFERROR(H8/H7,"-") -> 0.097547705 | I12: =IFERROR(I8/I7,"-") -> -0.002082187 | J12: =IFERROR(J8/J7,"-") -> 0.050912188 | ... S12: =IFERROR(S8/S7,"-") -> 0.11943362 | Y12: APPF
B13: op yoy | C13: =C8/#REF!-1 -> #REF! | D13: =D8/#REF!-1 -> #REF! | E13: =E8/#REF!-1 -> #REF! | F13: =F8/#REF!-1 -> #REF! | G13: =G8/C8-1 -> 0.10939633 | H13: =IFERROR(H8/D8-1,0) -> -0.073028702 | I13: =IFERROR(I8/E8-1,0) -> -1.065034 | J13: =IFERROR(J8/F8-1,0) -> -0.38374886 | K13: =IFERROR(K8/G8-1,0) -> -0.95424249 | L13: =IFERROR(L8/H8-1,0) -> 0.97298738 | M13: =IFERROR(M8/I8-1,0) -> -13.845045 | N13: =N8/J8-1 -> -0.24624825 | O13: =O8/K8-1 -> 19.814143 | P13: =P8/L8-1 -> -1 | Q13: =Q8/M8-1 -> 0.56571749 | R13: =R8/N8-1 -> 1.0526451 | S13: =S8/O8-1 -> 0.53404768 | Y13: BFH
B14: rv yoy | G14: =G7/C7-1 -> 0.057804085 | H14: =H7/D7-1 -> 0.032330044 | I14: =I7/E7-1 -> -0.023474041 | J14: =J7/F7-1 -> 0.029113914 | K14: =K7/G7-1 -> -0.00064310132 | L14: =L7/H7-1 -> 0.033708376 | M14: =M7/I7-1 -> 0.038004602 | N14: =N7/J7-1 -> -0.049997972 | ... S14: =S7/O7-1 -> -0.043377929 | Y14: VIRT
Y15: BX
