Workbook

Sheet 실적 기업 정보
B2: 260128 실적 기업 정보
B4: Ticker | C4: Company | D4: Date | E4: Time | F4: Quarter Ending | G4: Market Cap (mil$)
B5: MSFT | C5: Microsoft Corporation | D5: 46050 | E5: After Hours | F5: 46381 | G5: 3417853190000
B6: META | C6: Meta Platforms, Inc. | D6: 46050 | E6: After Hours | F6: 46381 | G6: 1563357240000
B7: TSLA | C7: Tesla, Inc. | D7: 46050 | F7: 46381 | G7: 1455045890000
B8: ASML | C8: ASML Holding N.V. | D8: 46050 | E8: Pre Market | F8: 46381 | G8: 522992700000
B9: A000660 | C9: SK hynix Inc. | D9: 46050 | F9: 46381 | G9: 354526930000
B10: LRCX | C10: Lam Research Corporation | D10: 46050 | E10: After Hours | F10: 46381 | G10: 273739180000
B11: IBM | C11: International Business Machines Corporation | D11: 46050 | E11: After Hours | F11: 46381 | G11: 273353960000
B12: APH | C12: Amphenol Corporation | D12: 46050 | E12: Pre Market | F12: 46381 | G12: 184820140000
B13: GEV | C13: GE Vernova Inc. | D13: 46050 | E13: Pre Market | F13: 46381 | G13: 178469170000
B14: T | C14: AT&T Inc. | D14: 46050 | E14: Pre Market | F14: 46381 | G14: 167240110000
B15: DHR | C15: Danaher Corporation | D15: 46050 | E15: Pre Market | F15: 46381 | G15: 165999210000
B16: NOW | C16: ServiceNow, Inc. | D16: 46050 | E16: After Hours | F16: 46381 | G16: 138089320000
B17: PGR | C17: The Progressive Corporation | D17: 46050 | F17: 46351 | G17: 120815420000
B18: SBUX | C18: Starbucks Corporation | D18: 46050 | E18: Pre Market | F18: 46381 | G18: 111003700000
B19: 6857 | C19: Advantest Corporation | D19: 46050 | F19: 46381 | G19: 109823180000
B20: ADP | C20: Automatic Data Processing, Inc. | D20: 46050 | E20: Pre Market | F20: 46381 | G20: 104295200000
B21: GD | C21: General Dynamics Corporation | D21: 46050 | E21: Pre Market | F21: 46381 | G21: 97979740000
B22: WM | C22: Waste Management, Inc. | D22: 46050 | E22: After Hours | F22: 46381 | G22: 92349210000
B23: ELV | C23: Elevance Health, Inc. | D23: 46050 | E23: Pre Market | F23: 46381 | G23: 82463920000
B24: GLW | C24: Corning Incorporated | D24: 46050 | E24: Pre Market | F24: 46381 | G24: 79991720000
B25: VOLV B | C25: AB Volvo (publ) | D25: 46050 | F25: 46381 | G25: 71617480000
B26: NDA FI | C26: Nordea Bank Abp | D26: 46050 | F26: 46381 | G26: 67136190000
B27: CP | C27: Canadian Pacific Kansas City Limited | D27: 46050 | E27: After Hours | F27: 46381 | G27: 65616280000
B28: URI | C28: United Rentals, Inc. | D28: 46050 | E28: After Hours | F28: 46381 | G28: 58478010000
B29: 500510 | C29: Larsen & Toubro Limited | D29: 46050 | F29: 46381 | G29: 56215870000
B30: MARUTI | C30: Maruti Suzuki India Limited | D30: 46050 | F30: 46381 | G30: 53078970000
B31: LONN | C31: Lonza Group AG | D31: 46050 | F31: 46381 | G31: 49897270000
B32: MSCI | C32: MSCI Inc. | D32: 46050 | E32: Pre Market | F32: 46381 | G32: 44314290000
B33: LVS | C33: Las Vegas Sands Corp. | D33: 46050 | E33: After Hours | F33: 46381 | G33: 39856880000
B34: FICO | C34: Fair Isaac Corporation | D34: 46050 | E34: After Hours | F34: 46381 | G34: 37244980000
B35: TEVA | C35: Teva Pharmaceutical Industries Limited | D35: 46050 | E35: Pre Market | F35: 46381 | G35: 36437690000
B36: CLS | C36: Celestica Inc. | D36: 46050 | F36: 46381 | G36: 36111000000
B37: OTIS | C37: Otis Worldwide Corporation | D37: 46050 | E37: Pre Market | F37: 46381 | G37: 35136780000
B38: RJF | C38: Raymond James Financial, Inc. | D38: 46050 | E38: After Hours | F38: 46381 | G38: 33876710000
B39: 500049 | C39: Bharat Electronics Limited | D39: 46050 | F39: 46381 | G39: 33041420000
B40: GIB.A | C40: CGI Inc. | D40: 46050 | E40: Pre Market | F40: 46381 | G40: 20241470000
B41: SBILIFE | C41: SBI Life Insurance Company Limited | D41: 46050 | F41: 46381 | G41: 20158800000
B42: A012330 | C42: Hyundai Mobis Co.,Ltd | D42: 46050 | F42: 46381 | G42: 18872010000
...

Sheet Revenue
B1: 1 | C1: 2 | D1: 3 | E1: 4 | F1: 5 | G1: 6 | H1: 7 | I1: 8 | J1: 9 | K1: 10 | L1: 11 | M1: 12 | N1: 13 | O1: 14 | P1: 15 | Q1: 16 | R1: 17 | S1: 18 | T1: 19 | U1: 20 | V1: 21 | W1: 22
B2: Ticker | C2: Country | D2: Industry | E2: Latest_Date | F2: Growth_Rate | G2: 4Q21 | H2: 1Q22 | I2: 2Q22 | J2: 3Q22 | K2: 4Q22 | L2: 1Q23 | M2: 2Q23 | N2: 3Q23 | O2: 4Q23 | P2: 1Q24 | Q2: 2Q24 | R2: 3Q24 | S2: 4Q24 | T2: 1Q25 | U2: 2Q25 | V2: 3Q25 | W2: 4Q25 | X2: 1Q25 | Y2: 2Q25 | Z2: 3Q25 | AA2: 4Q25
A3: 260130 | B3: TMP | C3: United States | D3: Banks - Regional | E3: Dec'25 | F3: 37.3 | G3: 73.05 | H3: 77.12 | I3: 76.35 | J3: 77.75 | K3: 74.25 | L3: 75.47 | M3: 62.26 | N3: 8.24 | O3: 69.45 | P3: 71.96 | Q3: 70.56 | R3: 74.4 | S3: 75.7 | T3: 76.41 | U3: 79.86 | V3: 84.95 | W3: 193.85 | X3: 0.015207436 | Y3: 0.031305753 | Z3: 0.034435487 | AA3: 0.37280702
A4: 260130 | B4: JHG | C4: United States | D4: Asset Management | E4: Dec'25 | F4: 16.3 | G4: 697.2 | H4: 620 | I4: 555.5 | J4: 512.9 | K4: 515.2 | L4: 495.8 | M4: 516.5 | N4: 521 | O4: 568.5 | P4: 551.7 | Q4: 588.4 | R4: 624.8 | S4: 708.3 | T4: 621.4 | U4: 633.2 | V4: 700.4 | W4: 1142 | X4: 0.028182112 | Y4: 0.017617681 | Z4: 0.029215133 | AA4: 0.16284309
A5: 260130 | B5: MCHB | C5: United States | D5: Banks - Regional | E5: Dec'25 | F5: 13.4 | P5: -68.66 | Q5: 157.95 | R5: 141.14 | S5: 151.18 | T5: 147.19 | U5: 149.4 | V5: 119.03 | W5: 227.05 | X5: 0.56562983 | Y5: -0.014310581 | Z5: -0.037543937 | AA5: 0.13385674
A6: 260130 | B6: LPG | C6: United States | D6: Oil & Gas Midstream | E6: Jun'26 | F6: 11.9 | G6: 61.99 | H6: 68.16 | I6: 83.57 | J6: 76.41 | K6: 75.78 | L6: 102.53 | M6: 132.53 | N6: 110.81 | O6: 144.33 | P6: 162.33 | Q6: 141.36 | R6: 112.82 | S6: 82.31 | T6: 80.46 | U6: 74.08 | V6: 83.84 | W6: 120.63 | X6: -0.16412734 | Y6: -0.16136227 | Z6: -0.082878142 | AA6: 0.11949234
A7: 260130 | B7: SOFI | C7: United States | D7: Credit Services | E7: Dec'25 | F7: 8.7 | G7: 280.92 | H7: 317.38 | I7: 352.42 | J7: 407.66 | K7: 441.73 | L7: 463.75 | M7: 485.4 | N7: 515.38 | O7: 603.31 | P7: 637.81 | Q7: 586.98 | R7: 691.11 | S7: 734.13 | T7: 766.08 | U7: 844.91 | V7: 952.4 | W7: 1020 | X7: 0.048403226 | Y7: 0.092837347 | Z7: 0.08605738 | AA7: 0.086692423
A8: 260130 | B8: WT | C8: United States | D8: Asset Management | E8: Dec'25 | F8: 8 | G8: 79.18 | H8: 78.37 | I8: 77.25 | J8: 72.41 | K8: 73.31 | L8: 82.04 | M8: 85.72 | N8: 90.42 | O8: 90.84 | P8: 96.84 | Q8: 107.03 | R8: 113.17 | S8: 110.7 | T8: 108.08 | U8: 112.62 | V8: 125.62 | W8: 147.43 | X8: 0.026277645 | Y8: 0.012734065 | Z8: 0.028004589 | AA8: 0.080368474
A9: 260130 | B9: OPY | C9: United States | D9: Capital Markets | E9: Dec'25 | F9: 6.8 | G9: 362.84 | H9: 263.52 | I9: 233.61 | J9: 287.09 | K9: 302.9 | L9: 308.54 | M9: 288.73 | N9: 292.92 | O9: 289.97 | P9: 332.59 | Q9: 308.63 | R9: 349.25 | S9: 354.04 | T9: 346.43 | U9: 350.65 | V9: 401.94 | W9: 452.49 | X9: 0.010293713 | Y9: 0.03093459 | Z9: 0.03762577 | AA9: 0.067753568
A10: 260130 | B10: TOWN | C10: United States | D10: Banks - Regional | E10: Dec'25 | F10: 5.8 | G10: 161.53 | H10: 166.86 | I10: 166.92 | J10: 175.31 | K10: 168.04 | L10: 172.47 | M10: 178.01 | N10: 171.86 | O10: 153.1 | P10: 167.98 | Q10: 175.15 | R10: 175.62 | S10: 175.55 | T10: 189.62 | U10: 201.03 | V10: 200.39 | W10: 220.11 | X10: 0.031168083 | Y10: 0.036148281 | Z10: 0.03339085 | AA10: 0.058127552
A11: 260130 | B11: SAIL | C11: United States | D11: Software - Infrastructure | E11: Sep'26 | F11: 4.8 | P11: 202.71 | Q11: 187.66 | R11: 198.58 | S11: 235.26 | T11: 240.12 | U11: 230.47 | V11: 264.36 | W11: 281.94 | X11: 0.045388918 | Y11: 0.049685476 | Z11: 0.072730891 | AA11: 0.048113295
A12: 260130 | B12: GNTX | C12: United States | D12: Auto Parts | E12: Dec'25 | F12: 4.2 | G12: 419.84 | H12: 468.25 | I12: 463.42 | J12: 493.64 | K12: 493.65 | L12: 550.76 | M12: 583.47 | N12: 575.85 | O12: 589.13 | P12: 590.23 | Q12: 572.93 | R12: 608.53 | S12: 541.64 | T12: 576.77 | U12: 657.86 | V12: 655.24 | W12: 644.4 | X12: -0.0058184522 | Y12: 0.036928174 | Z12: 0.019586548 | AA12: 0.042261804
A13: 260130 | B13: FLG | C13: United States | D13: Banks - Regional | E13: Dec'25 | F13: 4.1 | G13: 334 | H13: 348 | I13: 368 | J13: 341 | K13: 294 | L13: 482 | M13: 1012 | N13: 980 | O13: 326 | P13: 439 | Q13: 281 | R13: 381 | S13: 480 | T13: 411 | U13: 432 | V13: 481 | W13: 554 | X13: -0.01771031 | Y13: 0.097231165 | Z13: 0.058685446 | AA13: 0.041019956
A14: 260130 | B14: IESC | C14: United States | D14: Engineering & Construction | E14: Mar'26 | F14: 3.6 | G14: 480.51 | H14: 501.59 | I14: 567.3 | J14: 617.41 | K14: 574.87 | L14: 568.88 | M14: 584.45 | N14: 649.02 | O14: 634.44 | P14: 705.73 | Q14: 768.42 | R14: 775.77 | S14: 749.55 | T14: 833.96 | U14: 890.16 | V14: 897.8 | W14: 870.96 | X14: 0.042750886 | Y14: 0.03892317 | Z14: 0.037554163 | AA14: 0.036010998
A15: 260130 | B15: FHB | C15: United States | D15: Banks - Regional | E15: Dec'25 | F15: 3.6 | G15: 178.9 | H15: 181 | I15: 188.28 | J15: 205.41 | K15: 216.99 | L15: 207.47 | M15: 202.29 | N15: 195.75 | O15: 204.81 | P15: 199.5 | Q15: 202.82 | R15: 202.6 | S15: 188.88 | T15: 200.5 | U15: 213.04 | V15: 221.89 | W15: 218.15 | X15: 0.0012597632 | Y15: 0.012858581 | Z15: 0.023962138 | AA15: 0.035508486
A16: 260130 | B16: RRBI | C16: United States | D16: Banks - Regional | E16: Dec'25 | F16: 3.3 | G16: 24.3 | H16: 22.98 | I16: 25.76 | J16: 27.36 | K16: 27.54 | L16: 27.25 | M16: 27.22 | N16: 26.12 | O16: 26.23 | P16: 25.85 | Q16: 26.59 | R16: 27.58 | S16: 28.38 | T16: 29.43 | U16: 30.09 | V16: 31.26 | W16: 32.31 | X16: 0.03302583 | Y16: 0.031255581 | Z16: 0.03186699 | AA16: 0.032980866
A17: 260130 | B17: AXP | C17: United States | D17: Credit Services | E17: Dec'25 | F17: 2.6 | G17: 12092 | H17: 11768 | I17: 12985 | J17: 12778 | K17: 13149 | L17: 13226 | M17: 13856 | N17: 14148 | O17: 14362 | P17: 14532 | Q17: 15065 | R17: 15280 | S17: 15887 | T17: 15817 | U17: 16451 | V17: 17139 | W17: 17566 | X17: 0.02114739 | Y17: 0.022337185 | Z17: 0.029305588 | AA17: 0.025714461
A18: 260130 | B18: BDL | C18: United States | D18: Restaurants | E18: Dec'25 | F18: 2.1 | G18: 33.6 | H18: 37.37 | I18: 40.27 | J18: 40.63 | K18: 39.69 | L18: 41.83 | M18: 43.76 | N18: 45.32 | O18: 43.33 | P18: 45.09 | Q18: 48.07 | R18: 49.05 | S18: 45.97 | T18: 50.22 | U18: 53.63 | V18: 52.1 | W18: 50.2 | X18: 0.027261133 | Y18: 0.028762092 | Z18: 0.015336652 | AA18: 0.020948891
A19: 260130 | B19: ALV | C19: United States | D19: Auto Parts | E19: Dec'25 | F19: 1.9 | G19: 2119 | H19: 2124 | I19: 2081 | J19: 2302 | K19: 2335 | L19: 2493 | M19: 2635 | N19: 2596 | O19: 2751 | P19: 2615 | Q19: 2605 | R19: 2555 | S19: 2616 | T19: 2578 | U19: 2714 | V19: 2706 | W19: 2817 | X19: -0.0035607737 | Y19: 0.010527332 | Z19: 0.014431807 | AA19: 0.018937253
A20: 260130 | B20: APD | C20: United States | D20: Specialty Chemicals | E20: Mar'26 | F20: 1.4 | G20: 2994 | H20: 2945 | I20: 3189 | J20: 0 | K20: 3175 | L20: 3200 | M20: 3034 | N20: 0 | O20: 2997 | P20: 2930 | Q20: 2986 | R20: 0 | S20: 2932 | T20: 2916 | U20: 3023 | V20: 3167 | W20: 3103 | X20: -0.0015822785 | Y20: 0.0041883631 | Z20: 0.35700597 | AA20: 0.014205017
A21: 260130 | B21: CL | C21: United States | D21: Household & Personal Products | E21: Dec'25 | F21: 1.4 | G21: 4403 | H21: 4399 | I21: 4484 | J21: 4455 | K21: 4629 | L21: 4770 | M21: 4822 | N21: 4915 | O21: 4950 | P21: 5065 | Q21: 5058 | R21: 5033 | S21: 4945 | T21: 4911 | U21: 5110 | V21: 5131 | W21: 5230 | X21: -0.0076613104 | Y21: 0.0026069083 | Z21: 0.004900245 | AA21: 0.014181221
A22: 260130 | B22: BEPC | C22: United States | D22: Utilities - Renewable | E22: Dec'25 | F22: 1.3 | G22: 917 | H22: 993 | I22: 1003 | J22: 905 | K22: 970 | L22: 1079 | M22: 940 | N22: 1029 | O22: 919 | P22: 1149 | Q22: 965 | R22: 1041 | S22: 891 | T22: 930 | U22: 929 | V22: 931 | W22: 938 | X22: -0.054127533 | Y22: -0.0094068461 | Z22: -0.029016091 | AA22: 0.012768269
A23: 260130 | B23: CHD | C23: United States | D23: Household & Personal Products | E23: Dec'25 | F23: 1 | G23: 1369 | H23: 1297 | I23: 1325 | J23: 1317 | K23: 1436 | L23: 1430 | M23: 1454 | N23: 1456 | O23: 1528 | P23: 1503 | Q23: 1511 | R23: 1511 | S23: 1582 | T23: 1467 | U23: 1506 | V23: 1586 | W23: 1644 | X23: -0.0058948747 | Y23: -0.00082358755 | Z23: 0.012363996 | AA23: 0.010096076
... A33: 260130 | B33: IMO | C33: United States | D33: Oil & Gas Integrated | E33: Dec'25 | F33: -2.9 | G33: 12295 | H33: 12657 | I33: 17285 | J33: 15071 | K33: 14400 | L33: 12057 | M33: 11764 | N33: 13873 | O33: 13202 | P33: 12249 | Q33: 13348 | R33: 13215 | S33: 12702 | T33: 12466 | U33: 11208 | V33: 11994 | W33: 11280 | X33: 0.0042124471 | Y33: -0.041367845 | Z33: -0.024621403 | AA33: -0.029398387
A34: 260130 | B34: 8550 | C34: Japan | D34: The Tochigi Bank, Ltd. | E34: Sep'26 | F34: 33.4 | G34: 9261 | H34: 9547 | I34: 11915 | J34: 10457 | K34: 11143 | L34: 8064 | M34: 9243 | N34: 10474 | O34: 10896 | P34: 8660 | Q34: 10606 | R34: 7289 | S34: 11295 | T34: -26917 | U34: 9687 | V34: 11199 | W34: 13055 | X34: -0.93994716 | Y34: -0.40431148 | Z34: 2.88774 | AA34: 0.3343465
A35: 260130 | B35: 6777 | C35: Japan | D35: santec Holdings Corporation | E35: Sep'26 | F35: 12.7 | G35: 2188 | H35: 3070 | I35: 3188 | J35: 3487 | K35: 3914 | L35: 4657 | M35: 3583 | N35: 4064 | O35: 4327 | P35: 6893 | Q35: 6306 | R35: 5691 | S35: 5316 | T35: 6713 | U35: 6186 | V35: 6592 | W35: 8470 | X35: -0.0074361728 | Y35: -0.0049945892 | Z35: 0.037689283 | AA35: 0.12714153
A36: 260130 | B36: 6331 | C36: Japan | D36: Mitsubishi Kakoki Kaisha, Ltd. | E36: Sep'26 | F36: 12.3 | G36: 10538 | H36: 13501 | I36: 8957 | J36: 12243 | K36: 10175 | L36: 13215 | M36: 9243 | N36: 12902 | O36: 12075 | P36: 13554 | Q36: 11944 | R36: 14679 | S36: 14690 | T36: 17889 | U36: 15813 | V36: 20310 | W36: 23150 | X36: 0.079009241 | Y36: 0.065352522 | Z36: 0.089280335 | AA36: 0.12314052
A37: 260130 | B37: 8345 | C37: Japan | D37: The Bank of Iwate, Ltd. | E37: Sep'26 | F37: 11.3 | G37: 10189 | H37: 8142 | I37: 11594 | J37: 11452 | K37: 13951 | L37: 2403 | M37: 10474 | N37: 10609 | O37: 10051 | P37: 9375 | Q37: 11508 | R37: 10888 | S37: 12165 | T37: 9396 | U37: 12494 | V37: 14761 | W37: 17685 | X37: 0.00047796795 | Y37: 0.022431012 | Z37: 0.086175823 | AA37: 0.11307768
A38: 260130 | B38: 6946 | C38: Japan | D38: Nippon Avionics Co., Ltd. | E38: Sep'26 | F38: 10.4 | G38: 4532 | H38: 5050 | I38: 3263 | J38: 4599 | K38: 4762 | L38: 5130 | M38: 3605 | N38: 5064 | O38: 4584 | P38: 4802 | Q38: 4087 | R38: 5019 | S38: 4564 | T38: 6452 | U38: 5037 | V38: 7666 | W38: 7023 | X38: 0.089324383 | Y38: 0.047212007 | Z38: 0.12561693 | AA38: 0.10367216
A39: 260130 | B39: 8316 | C39: Japan | D39: Sumitomo Mitsui Financial Group, Inc. | E39: Sep'26 | F39: 8.3 | G39: 942800 | H39: 82233 | I39: 994279 | J39: 1039205 | K39: 1013583 | L39: 479754 | M39: 1040727 | N39: 1129858 | O39: 1210013 | P39: 122089 | Q39: 1286487 | R39: 1534002 | S39: 1296678 | T39: -842478 | U39: 1358238 | V39: 1611881 | W39: 1579788 | X39: -0.22753214 | Y39: 0.021910783 | Z39: 0.023272194 | AA39: 0.082676293
A40: 260130 | B40: 9719 | C40: Japan | D40: SCSK Corporation | E40: Sep'26 | F40: 8.2 | G40: 102729 | H40: 111396 | I40: 104417 | J40: 108682 | K40: 109924 | L40: 122888 | M40: 113371 | N40: 117824 | O40: 120167 | P40: 128944 | Q40: 122543 | R40: 128980 | S40: 133317 | T40: 211225 | U40: 177474 | V40: 193805 | W40: 191813 | X40: 0.16014707 | Y40: 0.092156057 | Z40: 0.099578185 | AA40: 0.081718754
A41: 260130 | B41: 2127 | C41: Japan | D41: Nihon M&A Center Holdings Inc. | E41: Sep'26 | F41: 8.1 | G41: 10853 | H41: 6128 | I41: 9068 | J41: 11031 | K41: 9777 | L41: 11439 | M41: 8246 | N41: 10925 | O41: 11976 | P41: 12989 | Q41: 7638 | R41: 10953 | S41: 11252 | T41: 14234 | U41: 9018 | V41: 13569 | W41: 15151 | X41: 0.029067053 | Y41: 0.031308846 | Z41: 0.057548892 | AA41: 0.081105818
A42: 260130 | B42: 8803 | C42: Japan | D42: Heiwa Real Estate Co., Ltd. | E42: Sep'26 | F42: 6.1 | G42: 7105 | H42: 9432 | I42: 17385 | J42: 7569 | K42: 7179 | L42: 12389 | M42: 15028 | N42: 13163 | O42: 7524 | P42: 8718 | Q42: 10579 | R42: 8182 | S42: 8186 | T42: 15128 | U42: 13123 | V42: 8697 | W42: 10952 | X42: 0.17972802 | Y42: 0.060463458 | Z42: 0.011542168 | AA42: 0.061284176
A43: 260130 | B43: 6961 | C43: Japan | D43: Enplas Corporation | E43: Sep'26 | F43: 6 | G43: 7755 | H43: 9021 | I43: 10115 | J43: 10982 | K43: 11173 | L43: 9970 | M43: 9715 | N43: 9485 | O43: 8754 | P43: 9851 | Q43: 10601 | R43: 9099 | S43: 9105 | T43: 9264 | U43: 8999 | V43: 11902 | W43: 11473 | X43: -0.015185224 | Y43: -0.042081484 | Z43: 0.076864014 | AA43: 0.060300484
A44: 260130 | B44: 6196 | C44: Japan | D44: Strike Company,Limited | E44: Mar'26 | F44: 5.8 | G44: 2355 | H44: 2861 | I44: 1916 | J44: 3595 | K44: 1969 | L44: 4113 | M44: 3050 | N44: 4694 | O44: 3676 | P44: 5554 | Q44: 4042 | R44: 4866 | S44: 3665 | T44: 5286 | U44: 5490 | V44: 5873 | W44: 4842 | X44: -0.014784575 | Y44: 0.081079568 | Z44: 0.052157249 | AA44: 0.057940337
A45: 260130 | B45: 8308 | C45: Japan | D45: Resona Holdings, Inc. | E45: Sep'26 | F45: 5.7 | G45: 173983 | H45: 178409 | I45: 194300 | J45: 217183 | K45: 195938 | L45: 193615 | M45: 178656 | N45: 210154 | O45: 187334 | P45: 236919 | Q45: 219748 | R45: 243077 | S45: 230960 | T45: 259613 | U45: 248800 | V45: 251222 | W45: 286985 | X45: 0.024383692 | Y45: 0.030472059 | Z45: 0.0082904982 | AA45: 0.056556918
A46: 260130 | B46: 8341 | C46: Japan | D46: The 77 Bank, Ltd. | E46: Sep'26 | F46: 5.5 | G46: 27470 | H46: 26921 | I46: 30911 | J46: 27118 | K46: 30476 | L46: 31502 | M46: 36678 | N46: 35841 | O46: 32103 | P46: 40464 | Q46: 43379 | R46: 38316 | S46: 40171 | T46: 42126 | U46: 40982 | V46: 44774 | W46: 49467 | X46: 0.010238403 | Y46: -0.014616567 | Z46: 0.039964108 | AA46: 0.055315882
A47: 260130 | B47: 6526 | C47: Japan | D47: Socionext Inc. | E47: Sep'26 | F47: 5 | I47: 39934 | J47: 42833 | K47: 56074 | L47: 53926 | M47: 61447 | N47: 55541 | O47: 52650 | P47: 51608 | Q47: 52783 | R47: 46398 | S47: 46083 | T47: 43271 | U47: 34553 | V47: 52656 | W47: 54931 | X47: -0.042347312 | Y47: -0.096692922 | Z47: 0.036745838 | AA47: 0.050112424
A48: 260130 | B48: 2121 | C48: Japan | D48: MIXI, Inc. | E48: Sep'26 | F48: 4.9 | G48: 29502 | H48: 37010 | I48: 31022 | J48: 34712 | K48: 39068 | L48: 42065 | M48: 29207 | N48: 34761 | O48: 41241 | P48: 41659 | Q48: 30087 | R48: 38733 | S48: 41532 | T48: 44495 | U48: 31323 | V48: 36105 | W48: 48997 | X48: 0.018656545 | Y48: 0.0079820726 | Z48: -0.016837196 | AA48: 0.048646183
A49: 260130 | B49: 7327 | C49: Japan | D49: Daishi Hokuetsu Financial Group, Inc. | E49: Sep'26 | F49: 4.7 | G49: 30022 | H49: 30809 | I49: 37378 | J49: 33124 | K49: 30140 | L49: 28562 | M49: 38919 | N49: 34477 | O49: 31639 | P49: 31389 | Q49: 41750 | R49: 31320 | S49: 38855 | T49: 35784 | U49: 45728 | V49: 71647 | W49: 47817 | X49: 0.030666927 | Y49: 0.026931331 | Z49: 0.26585667 | AA49: 0.04667368
...

Sheet Operating Income
B1: 1 | C1: 2 | D1: 3 | E1: 4 | F1: 5 | G1: 6 | H1: 7 | I1: 8 | J1: 9 | K1: 10 | L1: 11 | M1: 12 | N1: 13 | O1: 14 | P1: 15 | Q1: 16 | R1: 17 | S1: 18 | T1: 19 | U1: 20 | V1: 21 | W1: 22
B2: Ticker | C2: Country | D2: Industry | E2: Latest_Date | F2: Growth_Rate | G2: 4Q21 | H2: 1Q22 | I2: 2Q22 | J2: 3Q22 | K2: 4Q22 | L2: 1Q23 | M2: 2Q23 | N2: 3Q23 | O2: 4Q23 | P2: 1Q24 | Q2: 2Q24 | R2: 3Q24 | S2: 4Q24 | T2: 1Q25 | U2: 2Q25 | V2: 3Q25 | W2: 4Q25 | X2: 1Q25 | Y2: 2Q25 | Z2: 3Q25 | AA2: 4Q25
A3: 260129 | B3: SNDK | C3: United States | D3: Computer Hardware | E3: Jan '26 Jan 2, 2026 | F3: 230.56995 | N3: -546 | O3: -198 | P3: 79 | Q3: 185 | R3: 313 | S3: 185 | T3: -42 | U3: 51 | V3: 192 | W3: 1075 | X3: -0.15879265 | Y3: -0.20904836 | Z3: -0.23865878 | AA3: 2.3056995
A4: 260129 | B4: TAL | C4: United States | D4: Education & Training Services | E4: Nov '25 Nov 30, 2025 | F4: 143.57143 | G4: -62.18 | H4: 33.26 | I4: -28.32 | J4: 14.89 | K4: -32.88 | L4: -44.42 | M4: -57.77 | N4: 31.79 | O4: -32.19 | P4: -11.06 | Q4: -17.33 | R4: 47.62 | S4: -17.43 | T4: -16.02 | U4: 14.35 | V4: 96.1 | W4: 93.12 | X4: -2.7555556 | Y4: -10.025316 | Z4: 1.6998597 | AA4: 1.4357143
A5: 260129 | B5: CNX | C5: United States | D5: Oil & Gas E&P | E5: Dec '25 Dec 31, 2025 | F5: 106.10558 | G5: 939.41 | H5: -1236 | I5: 90.52 | J5: -207.27 | K5: 1293 | L5: 955.26 | M5: 567.73 | N5: 50.32 | O5: 664.58 | P5: 65.45 | Q5: 20.67 | R5: 104.8 | S5: -189.17 | T5: -236.88 | U5: 616.3 | V5: 241.65 | W5: 269.1 | X5: -172.76 | Y5: -1.9816022 | Z5: 0.46381969 | AA5: 1.0610558
A6: 260129 | B6: IVR | C6: United States | D6: REIT - Mortgage | E6: Dec '25 Dec 31, 2025 | F6: 89.218984 | G6: -64.65 | H6: -228.42 | I6: -109.54 | J6: -101.43 | K6: 36.46 | L6: 21.46 | M6: 4.25 | N6: -68.56 | O6: 27.31 | P6: 29.16 | Q6: -13.2 | R6: 40.64 | S6: 3.74 | T6: 19.64 | U6: -23.33 | V6: 53.47 | W6: 51.49 | X6: -0.15777262 | Y6: -0.19933097 | Z6: 0.31531089 | AA6: 0.89218984
A7: 260129 | B7: WDC | C7: United States | D7: Computer Hardware | E7: Jan '26 Jan 2, 2026 | F7: 47.159647 | G7: 729 | H7: 524 | I7: 611 | J7: 182 | K7: -245 | L7: -432 | M7: -574 | N7: -539 | O7: 0 | P7: 100 | Q7: 0 | R7: 340 | S7: 0 | T7: 559 | U7: 688 | V7: 795 | W7: 963 | X7: 1.0431818 | Y7: 0.76529477 | Z7: 0.28670447 | AA7: 0.47159647
A8: 260129 | B8: VLO | C8: United States | D8: Oil & Gas Refining & Marketing | E8: Dec '25 Dec 31, 2025 | F8: 35.295841 | G8: 1601 | H8: 1400 | I8: 6237 | J8: 3796 | K8: 4383 | L8: 4067 | M8: 2785 | N8: 3529 | O8: 1575 | P8: 1703 | Q8: 1245 | R8: 527 | S8: 370 | T8: 250 | U8: 1117 | V8: 1677 | W8: 1575 | X8: -0.37789337 | Y8: -0.053511706 | Z8: 0.50795053 | AA8: 0.35295841
A9: 260129 | B9: VLY | C9: United States | D9: Banks - Regional | E9: Dec '25 Dec 31, 2025 | F9: 21.700506 | G9: 157.31 | H9: 156.04 | I9: 132.97 | J9: 246.52 | K9: 245.14 | L9: 203.72 | M9: 190.82 | N9: 194.83 | O9: 88.97 | P9: 129.45 | Q9: 93.33 | R9: 126.67 | S9: 89.06 | T9: 139.12 | U9: 173.09 | V9: 209.96 | W9: 221.7 | X9: 0.022051949 | Y9: 0.17796421 | Z9: 0.15776414 | AA9: 0.21700506
A10: 260129 | B10: KEX | C10: United States | D10: Marine Shipping | E10: Dec '25 Dec 31, 2025 | F10: 17.982016 | G10: 33.21 | H10: 28.25 | I10: 47.29 | J10: 62.03 | K10: 59.54 | L10: 60.42 | M10: 88.03 | N10: 93.2 | O10: 93.24 | P10: 103.8 | Q10: 122.68 | R10: 127.91 | S10: 52.65 | T10: 110.22 | U10: 134.46 | V10: 130.82 | W10: 129.64 | X10: 0.015772406 | Y10: 0.028491269 | Z10: 0.0068431944 | AA10: 0.17982016
A11: 260129 | B11: LMT | C11: United States | D11: Aerospace & Defense | E11: Dec '25 Dec 31, 2025 | F11: 17.90892 | G11: 2498 | H11: 2099 | I11: 654 | J11: 2247 | K11: 2499 | L11: 2161 | M11: 2241 | N11: 2151 | O11: 2490 | P11: 2030 | Q11: 2240 | R11: 2151 | S11: 703 | T11: 2279 | U11: 705 | V11: 2176 | W11: 1753 | X11: 0.034952274 | Y11: -0.20819205 | Z11: 0.0042822885 | AA11: 0.1790892
A12: 260129 | B12: APPF | C12: United States | D12: Software - Application | E12: Dec '25 Dec 31, 2025 | F12: 14.977444 | G12: -7.34 | H12: -14.67 | I12: -10.53 | J12: -7.82 | K12: -17.72 | L12: -26.53 | M12: -2.58 | N12: -0.07 | O12: 43.14 | P12: 34.09 | Q12: 36.03 | R12: 42.57 | S12: 23.66 | T12: 33.78 | U12: 40.51 | V12: 35.05 | W12: 43.58 | X12: -0.0022735607 | Y12: 0.032931491 | Z12: -0.053515514 | AA12: 0.14977444
A13: 260129 | B13: BFH | C13: United States | D13: Credit Services | E13: Dec '25 Dec 31, 2025 | F13: 13.703704 | G13: 0 | H13: 302 | I13: 16 | J13: 189 | K13: -208 | L13: 638 | M13: 86 | N13: 225 | O13: 18 | P13: 188 | Q13: 180 | R13: 40 | S13: -27 | T13: 197 | U13: 174 | V13: 196 | W13: 47 | X13: 0.023622047 | Y13: -0.015384615 | Z13: 0.40625 | AA13: 0.13703704
A14: 260129 | B14: VIRT | C14: United States | D14: Capital Markets | E14: Dec '25 Dec 31, 2025 | F14: 13.336436 | G14: 250.76 | H14: 242.52 | I14: 172.22 | J14: 101.62 | K14: 51.49 | L14: 137.21 | M14: 34.49 | N14: 139.02 | O14: 21.87 | P14: 139.62 | Q14: 155.48 | R14: 150.47 | S14: 220.86 | T14: 226.93 | U14: 284.22 | V14: 192 | W14: 344.09 | X14: 0.13101151 | Y14: 0.1708016 | Z14: 0.047060557 | AA14: 0.13336436
A15: 260129 | B15: BX | C15: United States | D15: Asset Management | E15: Dec '25 Dec 31, 2025 | F15: 13.013368 | G15: 3213 | H15: 2857 | I15: -270.39 | J15: -102.63 | K15: 876.81 | L15: 206.65 | M15: 1371 | N15: 1103 | O15: 454.33 | P15: 1853 | Q15: 1144 | R15: 1863 | S15: 1427 | T15: 1469 | U15: 2004 | V15: 1309 | W15: 2235 | X15: -0.061078416 | Y15: 0.14568863 | Z15: -0.081916309 | AA15: 0.13013368
... A92: 260129 | B92: INDT | C92: Sweden | D92: Indutrade AB (publ) | E92: Dec '25 Dec 31, 2025 | F92: -2.9765013 | G92: 802 | H92: 830 | I92: 908 | J92: 912 | K92: 877 | L92: 1077 | M92: 1061 | N92: 1031 | O92: 974 | P92: 860 | Q92: 1087 | R92: 1015 | S92: 1032 | T92: 874 | U92: 950 | V92: 974 | W92: 918 | X92: 0.0035052579 | Y92: -0.034181637 | Z92: -0.010591578 | AA92: -0.029765013
A93: 260129 | B93: 6952 | C93: Japan | D93: Casio Computer Co.,Ltd. | E93: Dec '25 Dec 31, 2025 | F93: 58.140925 | G93: 8009 | H93: 1969 | I93: 4835 | J93: 5244 | K93: 6411 | L93: 1674 | M93: 4327 | N93: 3850 | O93: 3643 | P93: 2388 | Q93: 4529 | R93: 5812 | S93: 888 | T93: 3007 | U93: 3730 | V93: 5758 | W93: 8669 | X93: 0.045457884 | Y93: -0.056125316 | Z93: -0.0040187542 | AA93: 0.58140925
A94: 260129 | B94: 6702 | C94: Japan | D94: Fujitsu Limited | E94: Dec '25 Dec 31, 2025 | F94: 21.112508 | G94: 65185 | H94: 113339 | I94: 25602 | J94: 75367 | K94: 72316 | L94: 105062 | M94: -1665 | N94: 46445 | O94: 3309 | P94: 207286 | Q94: 21387 | R94: 35008 | S94: 68874 | T94: 0 | U94: 33486 | V94: 71859 | W94: 105656 | X94: -0.62331344 | Y94: 0.096584151 | Z94: 0.26826481 | AA94: 0.21112508
A95: 260129 | B95: 4519 | C95: Japan | D95: Chugai Pharmaceutical Co., Ltd. | E95: Dec '25 Dec 31, 2025 | F95: 8.2434516 | G95: 139062 | H95: 187007 | I95: 99939 | J95: 96887 | K95: 149475 | L95: 98296 | M95: 112614 | N95: 106686 | O95: 121576 | P95: 99873 | Q95: 158321 | R95: 160406 | S95: 123401 | T95: 136650 | U95: 136691 | V95: 156485 | W95: 169006 | X95: 0.067854118 | Y95: -0.037371842 | Z95: -0.0070376273 | AA95: 0.082434516
A96: 260129 | B96: 7380 | C96: Japan | D96: Juroku Financial Group,Inc. | E96: Dec '25 Dec 31, 2025 | F96: 6.0038191 | G96: 7798 | H96: 3765 | I96: 8429 | J96: 7078 | K96: 5716 | L96: 5772 | M96: 7490 | N96: 6522 | O96: 6921 | P96: 6867 | Q96: 8834 | R96: 6915 | S96: 7689 | T96: 7185 | U96: 8874 | V96: 7149 | W96: 9544 | X96: 0.010493318 | Y96: 0.0013062078 | Z96: 0.0076313472 | AA96: 0.060038191
A97: 260129 | B97: 7205 | C97: Japan | D97: Hino Motors, Ltd. | E97: Dec '25 Dec 31, 2025 | F97: 5.2065988 | G97: 18021 | H97: -16022 | I97: 4317 | J97: 12299 | K97: 9020 | L97: -8229 | M97: 1135 | N97: 5632 | O97: -2098 | P97: -12772 | Q97: 6384 | R97: 17713 | S97: 20972 | T97: 12422 | U97: 16946 | V97: 21127 | W97: 24693 | X97: 0.78007245 | Y97: 0.18371571 | Z97: 0.050166782 | AA97: 0.052065988
A98: 260129 | B98: 4373 | C98: Japan | D98: Simplex Holdings, Inc. | E98: Dec '25 Dec 31, 2025 | F98: 4.7802237 | G98: 1602 | H98: 1140 | I98: 1340 | J98: 2010 | K98: 2017 | L98: 1971 | M98: 1707 | N98: 2292 | O98: 2386 | P98: 2516 | Q98: 1625 | R98: 2292 | S98: 3090 | T98: 3892 | U98: 3213 | V98: 3842 | W98: 3761 | X98: 0.14449228 | Y98: 0.14570144 | Z98: 0.12412909 | AA98: 0.047802237
A99: 260129 | B99: 9044 | C99: Japan | D99: Nankai Electric Railway Co., Ltd. | E99: Dec '25 Dec 31, 2025 | F99: 4.0385474 | G99: 6065 | H99: 2328 | I99: 4798 | J99: 4649 | K99: 6442 | L99: 5135 | M99: 6828 | N99: 7411 | O99: 12522 | P99: 4060 | Q99: 9877 | R99: 8380 | S99: 10950 | T99: 5449 | U99: 11296 | V99: 10388 | W99: 12488 | X99: 0.041753089 | Y99: 0.040945291 | Z99: 0.055661816 | AA99: 0.040385474
A100: 260129 | B100: 6754 | C100: Japan | D100: Anritsu Corporation | E100: Dec '25 Dec 31, 2025 | F100: 3.9750816 | G100: 3459 | H100: 5891 | I100: 3019 | J100: 2397 | K100: 2586 | L100: 3701 | M100: -57 | N100: 2994 | O100: 2227 | P100: 4337 | Q100: 624 | R100: 2954 | S100: 2842 | T100: 5607 | U100: 1341 | V100: 3694 | W100: 3378 | X100: 0.11806266 | Y100: 0.059615864 | Z100: 0.058066541 | AA100: 0.039750816
A101: 260129 | B101: 1944 | C101: Japan | D101: Kinden Corporation | E101: Dec '25 Dec 31, 2025 | F101: 2.7990649 | G101: 8303 | H101: 17228 | I101: 354 | J101: 6246 | K101: 6968 | L101: 23863 | M101: 869 | N101: 8267 | O101: 11485 | P101: 22057 | Q101: 1964 | R101: 10913 | S101: 17831 | T101: 30272 | U101: 7245 | V101: 24643 | W101: 20070 | X101: 0.15569033 | Y101: 0.086602165 | Z101: 0.20721088 | AA101: 0.027990649
A102: 260129 | B102: 6504 | C102: Japan | D102: Fuji Electric Co., Ltd. | E102: Dec '25 Dec 31, 2025 | F102: 2.3697199 | G102: 16368 | H102: 41580 | I102: 9873 | J102: 16847 | K102: 15716 | L102: 45979 | M102: 14664 | N102: 20331 | O102: 22663 | P102: 48012 | Q102: 17254 | R102: 23083 | S102: 28095 | T102: 49115 | U102: 17777 | V102: 24352 | W102: 30923 | X102: 0.0094723644 | Y102: 0.0044492841 | Z102: 0.010747861 | AA102: 0.023697199
A103: 260129 | B103: 4307 | C103: Japan | D103: Nomura Research Institute, Ltd. | E103: Dec '25 Dec 31, 2025 | F103: 2.3444311 | G103: 27290 | H103: 21453 | I103: 27992 | J103: 27139 | K103: 28403 | L103: 26044 | M103: 26880 | N103: 31696 | O103: 32043 | P103: 28318 | Q103: 32491 | R103: 32815 | S103: 36288 | T103: 32235 | U103: 36962 | V103: 41331 | W103: 39730 | X103: 0.030151179 | Y103: 0.033408305 | Z103: 0.061576283 | AA103: 0.023444311
A104: 260129 | B104: 4290 | C104: Japan | D104: Prestige International Inc. | E104: Dec '25 Dec 31, 2025 | F104: 2.0774315 | G104: 1860 | H104: 1918 | I104: 1886 | J104: 1953 | K104: 2202 | L104: 1788 | M104: 1890 | N104: 1968 | O104: 1996 | P104: 2067 | Q104: 1730 | R104: 2000 | S104: 2249 | T104: 1967 | U104: 1935 | V104: 2321 | W104: 2425 | X104: -0.012428536 | Y104: 0.025799144 | Z104: 0.039381671 | AA104: 0.020774315
... A124: 260129 | B124: 3593 | C124: Japan | D124: Hogy Medical Co.,Ltd. | E124: Dec '25 Dec 31, 2025 | F124: -17.130406 | G124: 1814 | H124: 1334 | I124: 1858 | J124: 1328 | K124: 1878 | L124: 1571 | M124: 1303 | N124: 1073 | O124: 1111 | P124: 682 | Q124: 1337 | R124: 586 | S124: 1322 | T124: 383 | U124: 951 | V124: 327 | W124: 811 | X124: -0.076139547 | Y124: -0.10639471 | Z124: -0.079888957 | AA124: -0.17130406
A125: 260129 | B125: PRESTIGE | C125: India | D125: Prestige Estates Projects Limited | E125: Dec '25 Dec 31, 2025 | F125: 8.1999766 | G125: 2907 | H125: 2742 | I125: 3149 | J125: 2060 | K125: 4044 | L125: 5173 | M125: 3612 | N125: 4184 | O125: 3718 | P125: 6526 | Q125: 6058 | R125: 7127 | S125: 4288 | T125: 3432 | U125: 6776 | V125: 11187 | W125: 6394 | X125: -0.12892204 | Y125: 0.03434585 | Z125: 0.18776303 | AA125: 0.081999766
A126: 260129 | B126: CANBK | C126: India | D126: Canara Bank | E126: Dec '25 Dec 31, 2025 | F126: 5.5355681 | G126: 24224 | H126: 29307 | I126: 30960 | J126: 34870 | K126: 40209 | L126: 43595 | M126: 51142 | N126: 52495 | O126: 50969 | P126: -596.52 | Q126: 55431 | R126: 56389 | S126: 56092 | T126: 9007 | U126: 65378 | V126: 63812 | W126: 66847 | X126: 0.057397678 | Y126: 0.056223469 | Z126: 0.039723652 | AA126: 0.055355681
A127: 260129 | B127: CONCOR | C127: India | D127: Container Corporation of India Limited | E127: Dec '25 Dec 31, 2025 | F127: 5.3415698 | G127: 3212 | H127: 3205 | I127: 3415 | J127: 3670 | K127: 2905 | L127: 3591 | M127: 2537 | N127: 3934 | O127: 3586 | P127: 3497 | Q127: 2722 | R127: 4157 | S127: 3795 | T127: 2970 | U127: 2711 | V127: 4284 | W127: 4530 | X127: -0.037188625 | Y127: -0.00080621519 | Z127: 0.0093156312 | AA127: 0.053415698
A128: 260129 | B128: VOLTAS | C128: India | D128: Voltas Limited | E128: Dec '25 Dec 31, 2025 | F128: 3.4432981 | G128: 1459 | H128: 2771 | I128: 1685 | J128: 911.4 | K128: 653.2 | L128: 2343 | M128: 1741 | N128: 585.9 | O128: 155.8 | P128: 2061 | Q128: 4104 | R128: 1458 | S128: 1795 | T128: 3695 | U128: 1601 | V128: 459.9 | W128: 2055 | X128: 0.17349756 | Y128: -0.22647485 | Z128: -0.1167505 | AA128: 0.034432981
A129: 260129 | B129: JSWHL | C129: India | D129: JSW Holdings Limited | E129: Dec '25 Dec 31, 2025 | F129: 1.9810574 | G129: 149.09 | H129: 181.65 | I129: 175.48 | J129: 3354 | K129: 247.37 | L129: 232.17 | M129: 231.96 | N129: 861.33 | O129: 245.84 | P129: 235.77 | Q129: 240.34 | R129: 1585 | S129: 259.48 | T129: 255.96 | U129: 263.46 | V129: 799.55 | W129: 290.75 | X129: 0.0087003736 | Y129: 0.0098770495 | Z129: -0.33226871 | AA129: 0.019810574
A130: 260129 | B130: COROMANDEL | C130: India | D130: Coromandel International Limited | E130: Dec '25 Dec 31, 2025 | F130: 0.075412073 | G130: 5020 | H130: 4022 | I130: 6408 | J130: 10112 | K130: 7335 | L130: 5250 | M130: 6611 | N130: 10048 | O130: 2943 | P130: 2557 | Q130: 4405 | R130: 9058 | S130: 6510 | T130: 4274 | U130: 6615 | V130: 10448 | W130: 6531 | X130: 0.076209498 | Y130: 0.091145296 | Z130: 0.052538081 | AA130: 0.00075412073
A131: 260129 | B131: EQUITASBNK | C131: India | D131: Equitas Small Finance Bank Limited | E131: Dec '25 Dec 31, 2025 | F131: -2.0977879 | G131: 2247 | H131: 3926 | I131: 2682 | J131: 2423 | K131: 2791 | L131: 4247 | M131: 3121 | N131: 3302 | O131: 3603 | P131: 4139 | Q131: 3404 | R131: 3497 | S131: 3329 | T131: 3368 | U131: 3148 | V131: 2406 | W131: 3072 | X131: -0.053657179 | Y131: -0.018826298 | Z131: -0.081771848 | AA131: -0.020977879
A132: 260129 | B132: ADANIPOWER | C132: India | D132: Adani Power Limited | E132: Dec '25 Dec 31, 2025 | F132: -4.6059661 | G132: 9864 | H132: 45900 | I132: 49037 | J132: 1148 | K132: 6321 | L132: 12776 | M132: 25796 | N132: 41669 | O132: 36431 | P132: 39329 | Q132: 51987 | R132: 42170 | S132: 38529 | T132: 38789 | U132: 45967 | V132: 39569 | W132: 31028 | X132: -0.0031392611 | Y132: -0.035107158 | Z132: -0.015720286 | AA132: -0.046059661
A133: 260129 | B133: CARBORUNIV | C133: India | D133: Carborundum Universal Limited | E133: Dec '25 Dec 31, 2025 | F133: -7.5148037 | G133: 1297 | H133: 803.88 | I133: 846.4 | J133: 1185 | K133: 1237 | L133: 1409 | M133: 1237 | N133: 1217 | O133: 1443 | P133: 1607 | Q133: 1422 | R133: 1430 | S133: 1244 | T133: 975.13 | U133: 623.6 | V133: 941.8 | W133: 959.6 | X133: -0.11079607 | Y133: -0.15744025 | Z133: -0.1142595 | AA133: -0.075148037
A134: 260129 | B134: PAYTM | C134: India | D134: One97 Communications Limited | E134: Dec '25 Dec 31, 2025 | F134: -170.50931 | G134: -8488 | H134: -8163 | I134: -7311 | J134: -6421 | K134: -4547 | L134: -2872 | M134: -4518 | N134: -4111 | O134: -3604 | P134: -3028 | Q134: -9706 | R134: -5819 | S134: -3877 | T134: 887 | U134: -702 | V134: 40 | W134: 2350 | X134: -0.17454302 | Y134: -0.4863084 | Z134: -0.61602355 | AA134: -1.7050931
A135: 260128 | B135: BBT | C135: United States | D135: Banks - Regional | E135: Dec '25 Dec 31, 2025 | F135: 731.76638 | G135: 38.5 | H135: 33.05 | I135: 33.7 | J135: 37.07 | K135: 36.14 | L135: 8.67 | M135: 27.82 | N135: 28.87 | O135: 28.56 | P135: 19.48 | Q135: 21.65 | R135: 26.75 | S135: 23.82 | T135: 25.48 | U135: 29.59 | V135: -71.87 | W135: 75.19 | X135: =SUM(Q135:T135)/SUM(P135:S135)-1 -> 0.065430752 | Y135: =SUM(R135:U135)/SUM(Q135:T135)-1 -> 0.081269191 | Z135: =SUM(S135:V135)/SUM(R135:U135)-1 -> -0.9335479 | AA135: =SUM(T135:W135)/SUM(S135:V135)-1 -> 7.3176638
...

Sheet 빨간줄
B2: (단위: mil $)
B4: SNDK | C4: 6 | D4: 7 | E4: 8 | F4: 9 | G4: 10 | H4: 11 | I4: 12 | J4: 13 | K4: 14 | L4: 15 | M4: 16 | N4: 17 | O4: 18 | P4: 19 | Q4: 20 | R4: 21 | S4: 22
C6: 4Q21 | D6: 1Q22 | E6: 2Q22 | F6: 3Q22 | G6: 4Q22 | H6: 1Q23 | I6: 2Q23 | J6: 3Q23 | K6: 4Q23 | L6: 1Q24 | M6: 2Q24 | N6: 3Q24 | O6: 4Q24 | P6: 1Q25 | Q6: 2Q25 | R6: 3Q25 | S6: 4Q25 | T6: 1Q26 | U6: 2Q26 | V6: 3Q26 | W6: 4Q26
B7: Revenue | C7: =VLOOKUP($B$4,Revenue!$B:$W,C4,FALSE) -> 1746 | D7: =VLOOKUP($B$4,Revenue!$B:$W,D4,FALSE) -> 1735 | E7: =VLOOKUP($B$4,Revenue!$B:$W,E4,FALSE) -> 1332 | F7: =VLOOKUP($B$4,Revenue!$B:$W,F4,FALSE) -> 1237 | G7: =VLOOKUP($B$4,Revenue!$B:$W,G4,FALSE) -> 1452 | H7: =VLOOKUP($B$4,Revenue!$B:$W,H4,FALSE) -> 0 | I7: =VLOOKUP($B$4,Revenue!$B:$W,I4,FALSE) -> 0 | J7: =VLOOKUP($B$4,Revenue!$B:$W,J4,FALSE) -> 1533 | ... S7: =VLOOKUP($B$4,Revenue!$B:$W,S4,FALSE) -> 3025
B8: OP | C8: =VLOOKUP($B$4,'Operating Income'!$B:$W,C4,FALSE) -> 0 | D8: =VLOOKUP($B$4,'Operating Income'!$B:$W,D4,FALSE) -> 0 | E8: =VLOOKUP($B$4,'Operating Income'!$B:$W,E4,FALSE) -> 0 | F8: =VLOOKUP($B$4,'Operating Income'!$B:$W,F4,FALSE) -> 0 | G8: =VLOOKUP($B$4,'Operating Income'!$B:$W,G4,FALSE) -> 0 | H8: =VLOOKUP($B$4,'Operating Income'!$B:$W,H4,FALSE) -> 0 | I8: =VLOOKUP($B$4,'Operating Income'!$B:$W,I4,FALSE) -> 0 | J8: =VLOOKUP($B$4,'Operating Income'!$B:$W,J4,FALSE) -> -546 | ... S8: =VLOOKUP($B$4,'Operating Income'!$B:$W,S4,FALSE) -> 1075
B9: Trailing 4Q OP avg. | C9: =AVERAGE(C8:C8) -> 0 | D9: =AVERAGE(C8:D8) -> 0 | E9: =AVERAGE(C8:E8) -> 0 | F9: =AVERAGE(C8:F8) -> 0 | G9: =AVERAGE(D8:G8) -> 0 | H9: =AVERAGE(E8:H8) -> 0 | I9: =AVERAGE(F8:I8) -> 0 | J9: =AVERAGE(G8:J8) -> -136.5 | K9: =AVERAGE(H8:K8) -> -186 | L9: =AVERAGE(I8:L8) -> -166.25 | M9: =AVERAGE(J8:M8) -> -120 | ... S9: =AVERAGE(P8:S8) -> 319
B10: Trailing 4Q OP sum. | C10: =SUM(C8:C8) -> 0 | D10: =SUM(C8:D8) -> 0 | E10: =SUM(C8:E8) -> 0 | F10: =SUM(C8:F8) -> 0 | G10: =SUM(D8:G8) -> 0 | H10: =SUM(E8:H8) -> 0 | I10: =SUM(F8:I8) -> 0 | J10: =SUM(G8:J8) -> -546 | K10: =SUM(H8:K8) -> -744 | L10: =SUM(I8:L8) -> -665 | M10: =SUM(J8:M8) -> -480 | ... S10: =SUM(P8:S8) -> 1276
B11: Trailing OP Delta | D11: =D9/C9-1 -> #DIV/0! | E11: =E9/D9-1 -> #DIV/0! | F11: =F9/E9-1 -> #DIV/0! | G11: =G9/F9-1 -> #DIV/0! | H11: =H9/G9-1 -> #DIV/0! | I11: =I9/H9-1 -> #DIV/0! | J11: =J9/I9-1 -> #DIV/0! | K11: =K9/J9-1 -> 0.36263736 | ... S11: =S9/R9-1 -> 2.3056995
B12: opm | C12: =IFERROR(C8/C7,"-") -> 0 | D12: =IFERROR(D8/D7,"-") -> 0 | E12: =IFERROR(E8/E7,"-") -> 0 | F12: =IFERROR(F8/F7,"-") -> 0 | G12: =IFERROR(G8/G7,"-") -> 0 | H12: =IFERROR(H8/H7,"-") -> - | I12: =IFERROR(I8/I7,"-") -> - | J12: =IFERROR(J8/J7,"-") -> -0.35616438 | ... S12: =IFERROR(S8/S7,"-") -> 0.3553719
B13: op yoy | C13: =C8/#REF!-1 -> #REF! | D13: =D8/#REF!-1 -> #REF! | E13: =E8/#REF!-1 -> #REF! | F13: =F8/#REF!-1 -> #REF! | G13: =G8/C8-1 -> #DIV/0! | H13: =H8/D8-1 -> #DIV/0! | I13: =I8/E8-1 -> #DIV/0! | J13: =J8/F8-1 -> #DIV/0! | K13: =K8/G8-1 -> #DIV/0! | L13: =L8/H8-1 -> #DIV/0! | M13: =M8/I8-1 -> #DIV/0! | N13: =N8/J8-1 -> -1.5732601 | ... S13: =S8/O8-1 -> 4.8108108
B14: rv yoy | G14: =G7/C7-1 -> -0.16838488 | H14: =H9/D9-1 -> #DIV/0! | I14: =I9/E9-1 -> #DIV/0! | J14: =J9/F9-1 -> #DIV/0! | K14: =K9/G9-1 -> #DIV/0! | L14: =L9/H9-1 -> #DIV/0! | M14: =M9/I9-1 -> #DIV/0! | N14: =N9/J9-1 -> -1.6941392 | O14: =O9/K9-1 -> -2.0241935 | ... S14: =S9/O9-1 -> 0.67454068
