Workbook

Sheet 기업리스트
B2: 실적 기업 정보
B3: Ticker | C3: Company | D3: Date | E3: Time | F3: Quarter Ending | G3: Market Cap (mil$)
B4: 7203 | C4: Toyota Motor Corporation | D4: 06-Feb-26 | F4: Dec-25 | G4: 296741
B5: PM | C5: Philip Morris International Inc. | D5: 06-Feb-26 | F5: Dec-25 | G5: 279323
B6: 8035 | C6: Tokyo Electron Limited | D6: 06-Feb-26 | F6: Dec-25 | G6: 123043
B7: SBIN | C7: State Bank of India | D7: 07-Feb-26 | F7: Dec-25 | G7: 108265
B8: GLE | C8: Société Générale Société anonyme | D8: 06-Feb-26 | F8: Dec-25 | G8: 66078.41
B9: 9433 | C9: KDDI Corporation | D9: 06-Feb-26 | F9: Dec-25 | G9: 64477.07
B10: KNEBV | C10: KONE Oyj | D10: 06-Feb-26 | F10: Dec-25 | G10: 37852.53
B11: UI | C11: Ubiquiti Inc. | D11: 06-Feb-26 | F11: Dec-25 | G11: 33298.41
B12: 8801 | C12: Mitsui Fudosan Co., Ltd. | D12: 06-Feb-26 | F12: Dec-25 | G12: 32377.91
B13: KOG | C13: Kongsberg Gruppen ASA | D13: 06-Feb-26 | F13: Dec-25 | G13: 28974.04
B14: CBOE | C14: Cboe Global Markets, Inc. | D14: 06-Feb-26 | E14: Pre Market | F14: Dec-25 | G14: 28625.51
B15: ORSTED | C15: Ørsted A/S | D15: 06-Feb-26 | F15: Dec-25 | G15: 27792.17
B16: 8830 | C16: Sumitomo Realty & Development Co., Ltd. | D16: 06-Feb-26 | F16: Dec-25 | G16: 24956.84
B17: BIIB | C17: Biogen Inc. | D17: 06-Feb-26 | E17: Pre Market | F17: Dec-25 | G17: 24120.79
B18: AER | C18: AerCap Holdings N.V. | D18: 06-Feb-26 | E18: Pre Market | F18: Dec-25 | G18: 23730.02
B19: CG | C19: The Carlyle Group Inc. | D19: 06-Feb-26 | E19: Pre Market | F19: Dec-25 | G19: 23650.14
B20: CNC | C20: Centene Corporation | D20: 06-Feb-26 | E20: Pre Market | F20: Dec-25 | G20: 22486.95
B21: COLO B | C21: Coloplast A/S | D21: 06-Feb-26 | F21: Dec-25 | G21: 20204.97
B22: TEL | C22: Telenor ASA | D22: 06-Feb-26 | F22: Dec-25 | G22: 19382.34
B23: SAB | C23: Banco de Sabadell, S.A. | D23: 06-Feb-26 | F23: Dec-25 | G23: 18784.41
B24: INDU A | C24: AB Industrivärden (publ) | D24: 06-Feb-26 | F24: Dec-25 | G24: 17630.69
B25: EMSN | C25: EMS-CHEMIE HOLDING AG | D25: 06-Feb-26 | F25: Dec-25 | G25: 16840.92
B26: NVT | C26: nVent Electric plc | D26: 06-Feb-26 | E26: Pre Market | F26: Dec-25 | G26: 15740.65
B27: C38U | C27: CapitaLand Integrated Commercial Trust | D27: 06-Feb-26 | F27: Dec-25 | G27: 13873.21
B28: A316140 | C28: Woori Financial Group Inc. | D28: 06-Feb-26 | F28: Dec-25 | G28: 13607.32
B29: FBK | C29: FinecoBank Banca Fineco S.p.A. | D29: 06-Feb-26 | F29: Dec-25 | G29: 13184.99
B30: SIEMENS | C30: Siemens Limited | D30: 06-Feb-26 | F30: Dec-25 | G30: 12692.15
B31: PAA | C31: Plains All American Pipeline, L.P. | D31: 06-Feb-26 | E31: Pre Market | F31: Dec-25 | G31: 11611.56
B32: ROIV | C32: Roivant Sciences Ltd. | D32: 06-Feb-26 | E32: Pre Market | F32: Dec-25 | G32: 11042.2
B33: SHREECEM | C33: Shree Cement Limited | D33: 06-Feb-26 | F33: Dec-25 | G33: 11037.99
B34: SKA B | C34: Skanska AB (publ) | D34: 06-Feb-26 | F34: Dec-25 | G34: 10800.61
B35: FRHC | C35: Freedom Holding Corp. | D35: 06-Feb-26 | F35: Dec-25 | G35: 10457.28
B36: KOMB | C36: Komercní banka, a.s. | D36: 06-Feb-26 | F36: Dec-25 | G36: 9511.89
B37: ISCTR | C37: Türkiye Is Bankasi A.S. | D37: 06-Feb-26 | F37: Dec-25 | G37: 9125.62
B38: TUPRS | C38: Türkiye Petrol Rafinerileri A.S. | D38: 06-Feb-26 | F38: Dec-25 | G38: 8556.1
B39: AN | C39: AutoNation, Inc. | D39: 06-Feb-26 | E39: Pre Market | F39: Dec-25 | G39: 8460.48
B40: BALD B | C40: Fastighets AB Balder (publ) | D40: 06-Feb-26 | F40: Dec-25 | G40: 8405.36
B41: 9684 | C41: Square Enix Holdings Co., Ltd. | D41: 06-Feb-26 | F41: Dec-25 | G41: 8036.29
...

Sheet Revenue
B2: Ticker | C2: Country | D2: Industry | E2: Latest_Date | F2: Growth_Rate | G2: 4Q21 | H2: 1Q22 | I2: 2Q22 | J2: 3Q22 | K2: 4Q22 | L2: 1Q23 | M2: 2Q23 | N2: 3Q23 | O2: 4Q23 | P2: 1Q24 | Q2: 2Q24 | R2: 3Q24 | S2: 4Q24 | T2: 1Q25 | U2: 2Q25 | V2: 3Q25 | W2: 4Q25 | X2: 1Q25 | Y2: 2Q25 | Z2: 3Q25 | AA2: 4Q25
B3: CG | C3: United States | D3: Asset Management | E3: Dec'25 | F3: 25.7 | G3: 1917 | H3: 1511 | I3: 981.5 | J3: 1008 | K3: 616.5 | L3: 735.6 | M3: 329.3 | N3: 582.7 | O3: 773.4 | P3: 533 | Q3: 887.2 | R3: 2443 | S3: 876.8 | T3: 831.8 | U3: 1374 | V3: 125.6 | W3: 1700 | X3: 0.063037975 | Y3: 0.096610304 | Z3: -0.41939337 | AA3: 0.25659248
B4: WTM | C4: United States | D4: Insurance - Property & Casualty | E4: Dec'25 | F4: 15.9 | G4: 261 | H4: 260.4 | I4: 76.7 | J4: 383.2 | K4: 437.6 | L4: 531.9 | M4: 378.4 | N4: 519.6 | O4: 736.8 | P4: 647.3 | Q4: 395.4 | R4: 953.6 | S4: 358 | T4: 577.8 | U4: 689.2 | V4: 864.2 | W4: 754.5 | X4: -0.029520452 | Y4: 0.12858894 | Z4: -0.034669976 | AA4: 0.15928812
B5: FBK | C5: United States | D5: Banks - Regional | E5: Dec'25 | F5: 11.7 | G5: 153.74 | H5: 133.82 | I5: 123.07 | J5: 122.61 | K5: 128.42 | L5: 126.52 | M5: 126.43 | N5: 106.15 | O5: 116.12 | P5: 106.67 | Q5: 126 | R5: 87.61 | S5: 123.29 | T5: 128.38 | U5: 71.53 | V5: 139.46 | W5: 177.37 | X5: 0.048943797 | Y5: -0.11706929 | Z5: 0.12621406 | AA5: 0.11688929
B6: PIPR | C6: United States | D6: Capital Markets | E6: Dec'25 | F6: 10.6 | G6: 648.24 | H6: 350.65 | I6: 352.19 | J6: 331.75 | K6: 391.05 | L6: 297.91 | M6: 288.73 | N6: 289.49 | O6: 471.85 | P6: 343.06 | Q6: 339.18 | R6: 359.57 | S6: 484.11 | T6: 357.27 | U6: 396.78 | V6: 479.28 | W6: 666.05 | X6: 0.0093124148 | Y6: 0.03739944 | Z6: 0.07492505 | AA6: 0.10593674
B7: NVT | C7: United States | D7: Electrical Equipment & Parts | E7: Dec'25 | F7: 8.8 | G7: 669 | H7: 694.7 | I7: 727.5 | J7: 745.2 | K7: 741.6 | L7: 740.6 | M7: 0 | N7: 715 | O7: 690.5 | P7: 732.1 | Q7: 739.8 | R7: 782 | S7: 752.2 | T7: 809.3 | U7: 963.1 | V7: 1054 | W7: 1067 | X7: 0.025681115 | Y7: 0.072422405 | Z7: 0.082259723 | AA7: 0.087967362
B8: UI | C8: United States | D8: Communication Equipment | E8: Jun'26 | F8: 7.8 | G8: 431.57 | H8: 358.07 | I8: 443.15 | J8: 498.08 | K8: 493.57 | L8: 457.77 | M8: 491.09 | N8: 463.08 | O8: 464.95 | P8: 493 | Q8: 507.46 | R8: 550.34 | S8: 599.88 | T8: 664.17 | U8: 759.15 | V8: 733.77 | W8: 814.87 | X8: 0.079588781 | Y8: 0.10840063 | Z8: 0.071275364 | AA8: 0.077980537
B9: CNC | C9: United States | D9: Healthcare Plans | E9: Dec'25 | F9: 5.1 | G9: 30534 | H9: 34284 | I9: 34010 | J9: 33928 | K9: 33777 | L9: 35226 | M9: 35180 | N9: 35181 | O9: 35806 | P9: 36782 | Q9: 36433 | R9: 37331 | S9: 36620 | T9: 43252 | U9: 42457 | V9: 45348 | W9: 45096 | X9: 0.043963959 | Y9: 0.03920956 | Z9: 0.050212953 | AA9: 0.050549569
B10: TEL | C10: United States | D10: Electronic Components | E10: Mar'26 | F10: 4.8 | G10: 3818 | H10: 4007 | I10: 4097 | J10: 4359 | K10: 3841 | L10: 4160 | M10: 3998 | N10: 4035 | O10: 3831 | P10: 3967 | Q10: 3979 | R10: 4068 | S10: 3836 | T10: 4143 | U10: 4534 | V10: 4749 | W10: 4669 | X10: 0.011104101 | Y10: 0.034631224 | Z10: 0.041071105 | AA10: 0.048256285
B11: GHM | C11: United States | D11: Specialty Industrial Machinery | E11: Sep'26 | F11: 4.2 | G11: 28.77 | H11: 39.74 | I11: 36.08 | J11: 38.14 | K11: 39.87 | L11: 43.03 | M11: 47.57 | N11: 45.08 | O11: 43.82 | P11: 49.07 | Q11: 49.95 | R11: 53.56 | S11: 47.04 | T11: 59.35 | U11: 55.49 | V11: 66.03 | W11: 56.7 | X11: 0.051497846 | Y11: 0.026393521 | Z11: 0.057881545 | AA11: 0.042385152
B12: APAM | C12: United States | D12: Asset Management | E12: Dec'25 | F12: 3.3 | G12: 315.04 | H12: 281.6 | I12: 251.39 | J12: 234.31 | K12: 225.99 | L12: 234.51 | M12: 242.9 | N12: 248.72 | O12: 249 | P12: 264.35 | Q12: 270.82 | R12: 279.58 | S12: 297.05 | T12: 277.15 | U12: 282.75 | V12: 301.29 | W12: 335.5 | X12: 0.011512862 | Y12: 0.010608216 | Z12: 0.019102003 | AA12: 0.033196919
B13: PRLB | C13: United States | D13: Metal Fabrication | E13: Dec'25 | F13: 2.8 | G13: 123.58 | H13: 124.17 | I13: 126.9 | J13: 121.72 | K13: 115.61 | L13: 125.86 | M13: 122.27 | N13: 130.71 | O13: 125.05 | P13: 127.89 | Q13: 125.63 | R13: 125.62 | S13: 121.75 | T13: 126.21 | U13: 135.06 | V13: 135.37 | W13: 136.49 | X13: -0.0033540298 | Y13: 0.018889846 | Z13: 0.019168764 | AA13: 0.02843419
B14: CBOE | C14: United States | D14: Financial Data & Stock Exchanges | E14: Dec'25 | F14: 2.1 | G14: 866.4 | H14: 974.5 | I14: 985.8 | J14: 993.5 | K14: 1005 | L14: 988.2 | M14: 907.8 | N14: 908.8 | O14: 968.7 | P14: 957.2 | Q14: 974 | R14: 1056 | S14: 1108 | T14: 1195 | U14: 1174 | V14: 1142 | W14: 1204 | X14: 0.058067982 | Y14: 0.046157397 | Z14: 0.018971983 | AA14: 0.020783719
... B28: PAGP | C28: United States | D28: Oil & Gas Midstream | E28: Dec'25 | F28: -4 | G28: 12989 | H28: 13694 | I28: 16359 | J28: 14336 | K28: 12952 | L28: 12341 | M28: 11602 | N28: 12071 | O28: 12698 | P28: 11639 | Q28: 0 | R28: 12456 | S28: 12402 | T28: 11477 | U28: 10642 | V28: 11578 | W28: 10564 | X28: -0.004438721 | Y28: 0.29288565 | Z28: -0.018689997 | AA28: -0.039870713
B29: GLE | C29: United States | D29: Information Technology Services | E29: H2 2025 | F29: -12 | N29: 16.31 | O29: 9.3 | P29: 36.8 | Q29: 17.82 | R29: 30.86 | S29: 13.82 | T29: 22.57 | U29: 26.88 | V29: 19.13 | W29: 3.95 | X29: -0.14330312 | Y29: 0.10650053 | Z29: -0.12461489 | AA29: -0.11978155
B30: ROIV | C30: United States | D30: Biotechnology | E30: Sep'26 | F30: -34.5 | G30: 24.34 | H30: 9.22 | I30: 4.32 | J30: 12.53 | K30: 17.05 | L30: 0 | M30: 4.48 | N30: 3.65 | O30: 15.56 | P30: 9.02 | Q30: 7.99 | R30: 4.48 | S30: 9.02 | T30: 7.57 | U30: 2.17 | V30: 1.57 | W30: 2 | X30: -0.047525402 | Y30: -0.20027529 | Z30: -0.12521515 | AA30: -0.34530251
B31: DUNI | C31: Sweden | D31: =VLOOKUP(B31,기업리스트!B:G,2,FALSE) -> Duni AB (publ) | E31: Dec'25 | F31: -1.2 | G31: 1552 | H31: 1443 | I31: 1724 | J31: 1834 | K31: 1974 | L31: 1877 | M31: 1936 | N31: 1935 | O31: 1971 | P31: 1736 | Q31: 1875 | R31: 1910 | S31: 2057 | T31: 1863 | U31: 1884 | V31: 1972 | W31: 1965 | X31: 0.016759039 | Y31: 0.0011680727 | Z31: 0.0080373347 | AA31: -0.011831276
B32: HOFI | C32: Sweden | D32: =VLOOKUP(B32,기업리스트!B:G,2,FALSE) -> Hoist Finance AB (publ) | E32: Dec'25 | F32: -2.7 | G32: 0 | H32: 631 | I32: 728 | J32: 593 | K32: 649 | L32: 758 | M32: 848 | N32: 881 | O32: 925 | P32: 962 | Q32: 1031 | R32: 1083 | S32: 1145 | T32: 995 | U32: 1016 | V32: 1015 | W32: 1031 | X32: 0.0078180526 | Y32: -0.0035260931 | Z32: -0.016041519 | AA32: -0.027331575
B33: 6366 | C33: Japan | D33: =VLOOKUP(B33,기업리스트!B:G,2,FALSE) -> Chiyoda Corporation | E33: Sep'26 | F33: 20.5 | G33: 69717 | H33: 94017 | I33: 75741 | J33: 108571 | K33: 124169 | L33: 121682 | M33: 129392 | N33: 142303 | O33: 125768 | P33: 108518 | Q33: 117019 | R33: 120323 | S33: 108711 | T33: 110916 | U33: 90457 | V33: 104272 | W33: 193462 | X33: 0.0052753035 | Y33: -0.058126481 | Z33: -0.037292609 | AA33: 0.20453668
B34: 6804 | C34: Japan | D34: =VLOOKUP(B34,기업리스트!B:G,2,FALSE) -> Hosiden Corporation | E34: Sep'26 | F34: 17.5 | G34: 58906 | H34: 51914 | I34: 71230 | J34: 49436 | K34: 85326 | L34: 71252 | M34: 56273 | N34: 68636 | O34: 52557 | P34: 41444 | Q34: 57876 | R34: 58297 | S34: 63591 | T34: 67807 | U34: 116340 | V34: 129086 | W34: 129592 | X34: 0.11917743 | Y34: 0.23615044 | Z34: 0.23131014 | AA34: 0.17515073
B35: 8424 | C35: Japan | D35: =VLOOKUP(B35,기업리스트!B:G,2,FALSE) -> Fuyo General Lease Co., Ltd. | E35: Sep'26 | F35: 14.1 | G35: 177644 | H35: 194777 | I35: 217415 | J35: 138648 | K35: 177702 | L35: 154890 | M35: 157183 | N35: 193210 | O35: 170196 | P35: 187949 | Q35: 161347 | R35: 170637 | S35: 149777 | T35: 196634 | U35: 172457 | V35: 171063 | W35: 246916 | X35: 0.0129683 | Y35: 0.01637689 | Z35: 0.00061783453 | AA35: 0.14079524
B36: 7826 | C36: Japan | D36: =VLOOKUP(B36,기업리스트!B:G,2,FALSE) -> Furuya Metal Co., Ltd. | E36: Jun'26 | F36: 11.7 | G36: 9255 | H36: 10652 | I36: 13567 | J36: 13201 | K36: 11069 | L36: 12443 | M36: 11402 | N36: 10128 | O36: 10996 | P36: 12235 | Q36: 14168 | R36: 13899 | S36: 12923 | T36: 13986 | U36: 16571 | V36: 23201 | W36: 20699 | X36: 0.032898074 | Y36: 0.043709983 | Z36: 0.16211506 | AA36: 0.11661493
B37: 1968 | C37: Japan | D37: =VLOOKUP(B37,기업리스트!B:G,2,FALSE) -> Taihei Dengyo Kaisha, Ltd. | E37: Sep'26 | F37: 7.2 | G37: 29723 | H37: 37197 | I37: 28977 | J37: 30153 | K37: 31885 | L37: 34759 | M37: 26902 | N37: 31179 | O37: 33978 | P37: 37304 | Q37: 30080 | R37: 30281 | S37: 30525 | T37: 34784 | U37: 29572 | V37: 33981 | W37: 39749 | X37: -0.01965832 | Y37: -0.0040423331 | Z37: 0.029561688 | AA37: 0.07158045
B38: 8418 | C38: Japan | D38: =VLOOKUP(B38,기업리스트!B:G,2,FALSE) -> Yamaguchi Financial Group, Inc. | E38: Sep'26 | F38: 6.9 | G38: 36089 | H38: 9117 | I38: 35627 | J38: 32380 | K38: 33129 | L38: 30009 | M38: 36964 | N38: 33551 | O38: 40916 | P38: 35222 | Q38: 48951 | R38: 40623 | S38: 46409 | T38: 39859 | U38: 43042 | V38: 41926 | W38: 58223 | X38: 0.027084489 | Y38: -0.033604031 | Z38: 0.0076677279 | AA38: 0.068992502
B39: 7322 | C39: Japan | D39: =VLOOKUP(B39,기업리스트!B:G,2,FALSE) -> San ju San Financial Group,Inc. | E39: Sep'26 | F39: 6.6 | G39: 17158 | H39: 14952 | I39: 18299 | J39: 15714 | K39: 15744 | L39: 14962 | M39: 17888 | N39: 16022 | O39: 16397 | P39: 16369 | Q39: 17954 | R39: 16814 | S39: 18091 | T39: 16691 | U39: 19653 | V39: 19692 | W39: 22986 | X39: 0.0046512972 | Y39: 0.024428469 | Z39: 0.040393549 | AA39: 0.066035318
B40: 8919 | C40: Japan | D40: =VLOOKUP(B40,기업리스트!B:G,2,FALSE) -> KATITAS CO., Ltd. | E40: Sep'26 | F40: 5.3 | G40: 26633 | H40: 25077 | I40: 28351 | J40: 30809 | K40: 29549 | L40: 32632 | M40: 31613 | N40: 30441 | O40: 31615 | P40: 33049 | Q40: 31195 | R40: 32815 | S40: 32629 | T40: 32898 | U40: 35063 | V40: 37352 | W40: 39999 | X40: -0.0011643329 | Y40: 0.029860194 | Z40: 0.03400922 | AA40: 0.053428252
B41: 1951 | C41: Japan | D41: =VLOOKUP(B41,기업리스트!B:G,2,FALSE) -> EXEO Group, Inc. | E41: Sep'26 | F41: 4.7 | G41: 134371 | H41: 199530 | I41: 120883 | J41: 144302 | K41: 152141 | L41: 210281 | M41: 124382 | N41: 140792 | O41: 138213 | P41: 210708 | Q41: 125415 | R41: 148056 | S41: 165799 | T41: 231552 | U41: 138599 | V41: 182709 | W41: 199687 | X41: 0.032068778 | Y41: 0.0196535 | Z41: 0.050661836 | AA41: 0.047154492
B42: 1965 | C42: Japan | D42: =VLOOKUP(B42,기업리스트!B:G,2,FALSE) -> Techno Ryowa Ltd. | E42: Sep'26 | F42: 4.5 | G42: 14506 | H42: 17018 | I42: 12960 | J42: 13350 | K42: 16133 | L42: 18587 | M42: 14513 | N42: 17158 | O42: 19198 | P42: 22819 | Q42: 16184 | R42: 18839 | S42: 22047 | T42: 27120 | U42: 20479 | V42: 23140 | W42: 26265 | X42: 0.053837199 | Y42: 0.05101556 | Z42: 0.048607109 | AA42: 0.045459444
B43: 7184 | C43: Japan | D43: =VLOOKUP(B43,기업리스트!B:G,2,FALSE) -> The First Bank Of Toyama, Ltd. | E43: Sep'26 | F43: 4.4 | G43: 7612 | H43: 4857 | I43: 10584 | J43: 6417 | K43: 7709 | L43: 7810 | M43: 10892 | N43: 6135 | O43: 9789 | P43: 7665 | Q43: 19024 | R43: 9621 | S43: 11947 | T43: 5891 | U43: 12795 | V43: 8814 | W43: 13671 | X43: -0.036761506 | Y43: -0.13400598 | Z43: -0.020047697 | AA43: 0.043704211
B44: 3107 | C44: Japan | D44: =VLOOKUP(B44,기업리스트!B:G,2,FALSE) -> Daiwabo Holdings Co., Ltd. | E44: Sep'26 | F44: 4.2 | G44: 188400 | H44: 224770 | I44: 185445 | J44: 223801 | K44: 228364 | L44: 266308 | M44: 209337 | N44: 236580 | O44: 229354 | P44: 292489 | Q44: 227844 | R44: 289539 | S44: 291418 | T44: 328016 | U44: 290601 | V44: 366229 | W44: 344401 | X44: 0.032259441 | Y44: 0.055204136 | Z44: 0.063931029 | AA44: 0.041514138
... B112: 6448 | C112: Japan | D112: =VLOOKUP(B112,기업리스트!B:G,2,FALSE) -> Brother Industries, Ltd. | E112: Sep'26 | F112: -26.1 | G112: 184457 | H112: 175964 | I112: 199734 | J112: 196931 | K112: 216807 | L112: 201795 | M112: 200407 | N112: 199225 | O112: 213133 | P112: 210164 | Q112: 214718 | R112: 212510 | S112: 231531 | T112: 217799 | U112: 213070 | V112: 224707 | W112: 0 | X112: 0.0087867394 | Y112: -0.001880081 | Z112: 0.013940862 | AA112: -0.26099557
B113: KALYANKJIL | C113: India | D113: =VLOOKUP(B113,기업리스트!B:G,2,FALSE) -> Kalyan Jewellers India Limited | E113: Sep'26 | F113: 10.7 | G113: 34354 | H113: 28571 | I113: 33326 | J113: 34729 | K113: 38841 | L113: 33818 | M113: 43757 | N113: 44145 | O113: 52231 | P113: 45022 | Q113: 55355 | R113: 60655 | S113: 72869 | T113: 61572 | U113: 72685 | V113: 78560 | W113: 103434 | X113: 0.070756431 | Y113: 0.069195172 | Z113: 0.066864341 | AA113: 0.10698809
B114: GRINFRA | C114: India | D114: =VLOOKUP(B114,기업리스트!B:G,2,FALSE) -> G R Infraprojects Limited | E114: Sep'26 | F114: 8.1 | G114: 19797 | H114: 23318 | I114: 26922 | J114: 21364 | K114: 21919 | L114: 24611 | M114: 24782 | N114: 18828 | O114: 21340 | P114: 24851 | Q114: 20303 | R114: 13943 | S114: 16945 | T114: 22785 | U114: 19878 | V114: 16021 | W114: 23083 | X114: -0.027169196 | Y114: -0.0057451065 | Z114: 0.028252505 | AA114: 0.081159344
B115: INDIASHLTR | C115: India | D115: =VLOOKUP(B115,기업리스트!B:G,2,FALSE) -> India Shelter Finance Corporation Limited | E115: Sep'26 | F115: 6.5 | G115: 671.03 | H115: 1246 | I115: 766.38 | J115: 916.64 | K115: 977.71 | L115: 1197 | M115: 1157 | N115: 1337 | O115: 1402 | P115: 1640 | Q115: 1774 | R115: 1910 | S115: 2035 | T115: 2237 | U115: 2446 | V115: 2501 | W115: 2636 | X115: 0.081125153 | Y115: 0.084464555 | Z115: 0.068497914 | AA115: 0.065191452
B116: INOXINDIA | C116: India | D116: =VLOOKUP(B116,기업리스트!B:G,2,FALSE) -> INOX India Limited | E116: Jun'26 | F116: 3.8 | J116: 2434 | K116: 2434 | L116: 2438 | M116: 2353 | N116: 3085 | O116: 2577 | P116: 2904 | Q116: 2783 | R116: 2964 | S116: 3066 | T116: 3336 | U116: 3694 | V116: 3396 | W116: 3582 | X116: 0.036869506 | Y116: 0.074985596 | Z116: 0.033078101 | AA116: 0.038244886
B117: EMBASSY | C117: India | D117: =VLOOKUP(B117,기업리스트!B:G,2,FALSE) -> Embassy Office Parks REIT | E117: Sep'26 | F117: 3.8 | G117: 7696 | H117: 7805 | I117: 8599 | J117: 8959 | K117: 9062 | L117: 8999 | M117: 9676 | N117: 9218 | O117: 9876 | P117: 9888 | Q117: 9825 | R117: 10545 | S117: 10449 | T117: 10993 | U117: 10808 | V117: 11556 | W117: 12104 | X117: 0.027145208 | Y117: 0.023509997 | Z117: 0.023624255 | AA117: 0.037780213
B118: LEMONTREE | C118: India | D118: =VLOOKUP(B118,기업리스트!B:G,2,FALSE) -> Lemon Tree Hotels Limited | E118: Sep'26 | F118: 3.7 | G118: 1437 | H118: 1200 | I118: 1920 | J118: 1967 | K118: 2335 | L118: 2533 | M118: 2223 | N118: 2272 | O118: 2887 | P118: 3346 | Q118: 2680 | R118: 2844 | S118: 3552 | T118: 3805 | U118: 3158 | V118: 3063 | W118: 4061 | X118: 0.036950572 | Y118: 0.03710892 | Z118: 0.016393443 | AA118: 0.037487112
B119: SIEMENS | C119: India | D119: =VLOOKUP(B119,기업리스트!B:G,2,FALSE) -> Siemens Limited | E119: Sep'26 | F119: 2.7 | G119: 35504 | H119: 39547 | I119: 42583 | J119: 46571 | K119: 40151 | L119: 48578 | M119: 48732 | N119: 58077 | O119: 48252 | P119: 57499 | Q119: 52035 | R119: 64611 | S119: 33601 | T119: 42590 | U119: 43468 | V119: 51712 | W119: 38307 | X119: -0.071765521 | Y119: -0.044426122 | Z119: -0.070000543 | AA119: 0.027460889
B120: SONATSOFTW | C120: India | D120: =VLOOKUP(B120,기업리스트!B:G,2,FALSE) -> Sonata Software Limited | E120: Sep'26 | F120: 2.4 | G120: 18580 | H120: 14636 | I120: 17789 | J120: 14960 | K120: 22608 | L120: 19135 | M120: 20155 | N120: 19126 | O120: 24934 | P120: 21916 | Q120: 25274 | R120: 21698 | S120: 28428 | T120: 26172 | U120: 29652 | V120: 21193 | W120: 30920 | X120: 0.043733816 | Y120: 0.04310243 | Z120: -0.0047663992 | AA120: 0.023633174
B121: SAPPHIRE | C121: India | D121: =VLOOKUP(B121,기업리스트!B:G,2,FALSE) -> Sapphire Foods India Limited | E121: Sep'26 | F121: 1.9 | G121: 5075 | H121: 4968 | I121: 5463 | J121: 5628 | K121: 5961 | L121: 5604 | M121: 6544 | N121: 6426 | O121: 6656 | P121: 6317 | Q121: 7183 | R121: 6957 | S121: 7565 | T121: 7113 | U121: 7768 | V121: 7424 | W121: 8138 | X121: 0.028406252 | Y121: 0.020299813 | Z121: 0.015882733 | AA121: 0.019183127
...

Sheet Operating Income
B2: Ticker | C2: Country | D2: Industry | E2: Latest_Date | F2: Growth_Rate | G2: 4Q21 | H2: 1Q22 | I2: 2Q22 | J2: 3Q22 | K2: 4Q22 | L2: 1Q23 | M2: 2Q23 | N2: 3Q23 | O2: 4Q23 | P2: 1Q24 | Q2: 2Q24 | R2: 3Q24 | S2: 4Q24 | T2: 1Q25 | U2: 2Q25 | V2: 3Q25 | W2: 4Q25 | X2: 1Q25 | Y2: 2Q25 | Z2: 3Q25 | AA2: 4Q25
B3: NB | C3: United States | D3: Other Industrial Metals & Mining | E3: Mar'26 | F3: 88.8 | G3: -1.26 | H3: -3.03 | I3: -1.39 | J3: -2.13 | K3: -2.08 | L3: -2.2 | M3: -29.19 | N3: -3.94 | O3: -3.44 | P3: -2.92 | Q3: -5.11 | R3: -2.29 | S3: -1.4 | T3: -2.9 | U3: -2.6 | V3: -5.06 | W3: -12.02 | X3: -0.0017064846 | Y3: -0.21452991 | Z3: 0.30141458 | AA3: 0.88795987
B4: WTM | C4: United States | D4: Insurance - Property & Casualty | E4: Dec'25 | F4: 57 | G4: 36.7 | H4: -5.8 | I4: -222.4 | J4: -17.8 | K4: 154.2 | L4: 211.7 | M4: 33.8 | N4: 53.8 | O4: 377.5 | P4: 247.8 | Q4: -6.6 | R4: 404.9 | S4: -92.8 | T4: 99.9 | U4: 223.5 | V4: 234.8 | W4: 172.6 | X4: -0.26730526 | Y4: 0.56758757 | Z4: -0.26766326 | AA4: 0.57026214
B5: CG | C5: United States | D5: Asset Management | E5: Dec'25 | F5: 38.3 | G5: 890 | H5: 740.2 | I5: 323.4 | J5: 404.2 | K5: 143.2 | L5: 156.1 | M5: -85.6 | N5: 161.6 | O5: -839.7 | P5: 127.9 | Q5: 223.6 | R5: 786.2 | S5: 231.7 | T5: 164.9 | U5: 393.7 | V5: -37.4 | W5: 519.9 | X5: 0.027019132 | Y5: 0.1209471 | Z5: -0.52242309 | AA5: 0.38278656
B6: PAA | C6: United States | D6: Oil & Gas Midstream | E6: Dec'25 | F6: 32.3 | G6: 616 | H6: 336 | I6: 407 | J6: 626 | K6: 192 | L6: 319 | M6: 381 | N6: 241 | O6: 427 | P6: 357 | Q6: 0 | R6: 316 | S6: 22 | T6: 342 | U6: 281 | V6: 392 | W6: 357 | X6: -0.021582734 | Y6: 0.41323529 | Z6: 0.079084287 | AA6: 0.32304725
B7: PIPR | C7: United States | D7: Capital Markets | E7: Dec'25 | F7: 20.1 | G7: 169.72 | H7: 36.88 | I7: 38.77 | J7: 25.37 | K7: 44.79 | L7: 25.81 | M7: 18.28 | N7: -3.45 | O7: 160.6 | P7: 60.67 | Q7: 39.56 | R7: 67.5 | S7: 128.65 | T7: 38.32 | U7: 60.8 | V7: 116.4 | W7: 197.83 | X7: -0.075409947 | Y7: 0.077509762 | Z7: 0.16561114 | AA7: 0.20100532
B8: FBK | C8: United States | D8: Banks - Regional | E8: Dec'25 | F8: 16.6 | G8: 62.84 | H8: 44.55 | I8: 26.07 | J8: 40.76 | K8: 48.19 | L8: 46.08 | M8: 45.14 | N8: 23.15 | O8: 35.92 | P8: 34.25 | Q8: 50.91 | R8: 11.39 | S8: 50.12 | T8: 48.83 | U8: -9.74 | V8: 29.6 | W8: 69.82 | X8: 0.099406832 | Y8: -0.37612403 | Z8: 0.18101392 | AA8: 0.16581096
B9: PRLB | C9: United States | D9: Metal Fabrication | E9: Dec'25 | F9: 16.2 | G9: -0.2 | H9: 7.89 | I9: 10.4 | J9: 7.25 | K9: 1.41 | L9: 3.82 | M9: 5.71 | N9: 10.44 | O9: 8.42 | P9: 6.83 | Q9: 6 | R9: 8.58 | S9: 4.09 | T9: 4.49 | U9: 5.12 | V9: 8.85 | W9: 7.74 | X9: -0.091764706 | Y9: -0.037996546 | Z9: 0.012118492 | AA9: 0.16186253
B10: UI | C10: United States | D10: Communication Equipment | E10: Jun'26 | F10: 12.3 | G10: 125.39 | H10: 62.61 | I10: 112.57 | J10: 122.01 | K10: 145.15 | L10: 133.53 | M10: 143.88 | N10: 128.3 | O10: 121.1 | P10: 111.22 | Q10: 138.37 | R10: 169.21 | S10: 178.81 | T10: 226.86 | U10: 261.4 | V10: 261.72 | W10: 292.9 | X10: 0.19350412 | Y10: 0.17249211 | Z10: 0.11062084 | AA10: 0.12283724
B11: PAGP | C11: United States | D11: Oil & Gas Midstream | E11: Dec'25 | F11: 9.2 | G11: 596 | H11: 249 | I11: 405 | J11: 624 | K11: 275 | L11: 317 | M11: 378 | N11: 239 | O11: 415 | P11: 356 | Q11: 0 | R11: 195 | S11: 246 | T11: 341 | U11: 279 | V11: 391 | W11: 362 | X11: -0.018820577 | Y11: 0.35677749 | Z11: 0.18473139 | AA11: 0.092283214
B12: CBOE | C12: United States | D12: Financial Data & Stock Exchanges | E12: Dec'25 | F12: 9.2 | G12: 221.6 | H12: 241.7 | I12: 237 | J12: 239.2 | K12: 247.3 | L12: 254.3 | M12: 245.5 | N12: 272 | O12: 279.1 | P12: 283 | Q12: 294.7 | R12: 306.5 | S12: 300.7 | T12: 354.1 | U12: 356.2 | V12: 375 | W12: 428.8 | X12: 0.060005064 | Y12: 0.048964968 | Z12: 0.05199241 | AA12: 0.092424242
B13: NVT | C13: United States | D13: Electrical Equipment & Parts | E13: Dec'25 | F13: 8.6 | G13: 102.8 | H13: 92.4 | I13: 107.5 | J13: 121 | K13: 186.7 | L13: 128.1 | M13: 0 | N13: 138.7 | O13: 100.6 | P13: 133.1 | Q13: 146.3 | R13: 136 | S13: 114.2 | T13: 130.9 | U13: 159.8 | V13: 169 | W13: 163.8 | X13: -0.0041540785 | Y13: 0.02559727 | Z13: 0.061009429 | AA13: 0.086426207
B14: TEL | C14: United States | D14: Electronic Components | E14: Mar'26 | F14: 7.1 | G14: 709 | H14: 742 | I14: 766 | J14: 766 | K14: 617 | L14: 658 | M14: 689 | N14: 717 | O14: 722 | P14: 724 | Q14: 751 | R14: 737 | S14: 738 | T14: 802 | U14: 891 | V14: 939 | W14: 976 | X14: 0.026440678 | Y14: 0.046235139 | Z14: 0.063762626 | AA14: 0.070623145
... B31: RXO | C31: United States | D31: Trucking | E31: Dec'25 | F31: -163.6 | G31: 56 | H31: 54 | I31: 79 | J31: 44 | K31: 43 | L31: 19 | M31: 19 | N31: 11 | O31: 18 | P31: 0 | Q31: 9 | R31: 12 | S31: 9 | T31: -10 | U31: 10 | V31: 2 | W31: -9 | X31: -0.33333333 | Y31: 0.05 | Z31: -0.47619048 | AA31: -1.6363636
B32: GLE | C32: United States | D32: Information Technology Services | E32: H2 2025 | F32: -266.3 | N32: 6.51 | O32: 1.71 | P32: 7.92 | Q32: 1.55 | R32: 2.01 | S32: 1.14 | T32: 0.76 | U32: 2.11 | V32: -1.46 | W32: -5.65 | X32: -0.56735341 | Y32: 0.1025641 | Z32: -0.57641196 | AA32: -2.6627451
B33: DUNI | C33: Sweden | D33: =VLOOKUP(B33,기업리스트!B:G,2,FALSE) -> Duni AB (publ) | E33: Dec'25 | F33: -6.1 | G33: 86 | H33: 36 | I33: 76 | J33: 136 | K33: 96 | L33: 117 | M33: 153 | N33: 209 | O33: 168 | P33: 123 | Q33: 115 | R33: 135 | S33: 171 | T33: 89 | U33: 102 | V33: 150 | W33: 140 | X33: -0.0625 | Y33: -0.025490196 | Z33: 0.030181087 | AA33: -0.060546875
B34: HOFI | C34: Sweden | D34: =VLOOKUP(B34,기업리스트!B:G,2,FALSE) -> Hoist Finance AB (publ) | E34: Dec'25 | F34: -6.4 | G34: 0 | H34: 146 | I34: 207 | J34: 73 | K34: -20 | L34: 137 | M34: 111 | N34: 222 | O34: 238 | P34: 273 | Q34: 213 | R34: 363 | S34: 318 | T34: 305 | U34: 294 | V34: 326 | W34: 238 | X34: 0.027420737 | Y34: 0.067556297 | Z34: -0.02890625 | AA34: -0.064360418
B35: 6366 | C35: Japan | D35: =VLOOKUP(B35,기업리스트!B:G,2,FALSE) -> Chiyoda Corporation | E35: Sep'26 | F35: 212.8 | G35: 1980 | H35: 2268 | I35: 3771 | J35: 2340 | K35: 7507 | L35: 4499 | M35: 5100 | N35: 5698 | O35: 7021 | P35: -32825 | Q35: 6414 | R35: 7317 | S35: 6084 | T35: 4607 | U35: 5111 | V35: 10505 | W35: 62078 | X35: -2.8771714 | Y35: -0.053353534 | Z35: 0.13789524 | AA35: 2.1284829
B36: 5021 | C36: Japan | D36: =VLOOKUP(B36,기업리스트!B:G,2,FALSE) -> Cosmo Energy Holdings Co., Ltd. | E36: Jun'26 | F36: 61.5 | G36: 45191 | H36: 52718 | I36: 89187 | J36: 123880 | K36: 49011 | L36: -19986 | M36: 10877 | N36: 7065 | O36: 68848 | P36: 25748 | Q36: 47540 | R36: 45019 | S36: -3805 | T36: 46880 | U36: 40157 | V36: 7988 | W36: 52267 | X36: 0.18455573 | Y36: -0.054433254 | Z36: -0.28873849 | AA36: 0.61468976
B37: 6976 | C37: Japan | D37: =VLOOKUP(B37,기업리스트!B:G,2,FALSE) -> Taiyo Yuden Co., Ltd. | E37: Sep'26 | F37: 57.1 | G37: 17627 | H37: 15901 | I37: 13138 | J37: 16469 | K37: 6447 | L37: -4125 | M37: -597 | N37: 2691 | O37: 4866 | P37: 1983 | Q37: 2567 | R37: 4861 | S37: 748 | T37: 1988 | U37: 3053 | V37: 5778 | W37: 7356 | X37: 0.00049217443 | Y37: 0.047815821 | Z37: 0.086103286 | AA37: 0.57128037
B38: 6804 | C38: Japan | D38: =VLOOKUP(B38,기업리스트!B:G,2,FALSE) -> Hosiden Corporation | E38: Sep'26 | F38: 41.7 | G38: 3218 | H38: 1918 | I38: 6745 | J38: 3403 | K38: 3029 | L38: 2573 | M38: 2597 | N38: 3870 | O38: 4761 | P38: 1698 | Q38: 4393 | R38: 3577 | S38: 2937 | T38: 2667 | U38: 2392 | V38: 5707 | W38: 8650 | X38: 0.076874256 | Y38: -0.14741417 | Z38: 0.18404908 | AA38: 0.416916
B39: 5214 | C39: Japan | D39: =VLOOKUP(B39,기업리스트!B:G,2,FALSE) -> Nippon Electric Glass Co., Ltd. | E39: Dec'25 | F39: 30.9 | G39: 7673 | H39: 10516 | I39: 8642 | J39: 4097 | K39: 2076 | L39: -1941 | M39: -4456 | N39: -1209 | O39: -4189 | P39: 766 | Q39: 1788 | R39: 1569 | S39: 1354 | T39: 7898 | U39: 8771 | V39: 7649 | W39: 9298 | X39: 1.3021727 | Y39: 0.55381077 | Z39: 0.31033075 | AA39: 0.30944219
B40: 6652 | C40: Japan | D40: =VLOOKUP(B40,기업리스트!B:G,2,FALSE) -> IDEC Corporation | E40: Sep'26 | F40: 21.6 | G40: 2341 | H40: 2477 | I40: 3154 | J40: 4407 | K40: 3870 | L40: 2631 | M40: 1666 | N40: 2382 | O40: 603 | P40: 1625 | Q40: 273 | R40: 1277 | S40: 752 | T40: 1351 | U40: 326 | V40: 2286 | W40: 1769 | X40: -0.069773364 | Y40: 0.014508623 | Z40: 0.2722612 | AA40: 0.21569459
B41: 4751 | C41: Japan | D41: =VLOOKUP(B41,기업리스트!B:G,2,FALSE) -> CyberAgent, Inc. | E41: Mar'26 | F41: 21.1 | G41: 19804 | H41: 25723 | I41: 9286 | J41: 12740 | K41: -1779 | L41: 18172 | M41: 865 | N41: 4925 | O41: 5865 | P41: 20638 | Q41: 8524 | R41: 3697 | S41: 8302 | T41: 20669 | U41: 19828 | V41: 22705 | W41: 23395 | X41: 0.00075314011 | Y41: 0.27442222 | Z41: 0.36208473 | AA41: 0.2110791
B42: 1968 | C42: Japan | D42: =VLOOKUP(B42,기업리스트!B:G,2,FALSE) -> Taihei Dengyo Kaisha, Ltd. | E42: Sep'26 | F42: 19.5 | G42: 430 | H42: 3397 | I42: 2997 | J42: 3442 | K42: 4793 | L42: 3113 | M42: 768 | N42: 2443 | O42: 2784 | P42: 4055 | Q42: 2441 | R42: 3621 | S42: 3688 | T42: 3354 | U42: 1534 | V42: 3288 | W42: 6004 | X42: -0.050778703 | Y42: -0.069215507 | Z42: -0.027301796 | AA42: 0.19521241
B43: 7322 | C43: Japan | D43: =VLOOKUP(B43,기업리스트!B:G,2,FALSE) -> San ju San Financial Group,Inc. | E43: Sep'26 | F43: 18.8 | G43: 2154 | H43: -461 | I43: 3993 | J43: 1602 | K43: 2959 | L43: 430 | M43: 3247 | N43: 2221 | O43: 2877 | P43: 2101 | Q43: 3635 | R43: 3316 | S43: 2749 | T43: 2072 | U43: 3745 | V43: 3879 | W43: 5085 | X43: -0.0024574189 | Y43: 0.0093442066 | Z43: 0.047382596 | AA43: 0.18770591
B44: 8522 | C44: Japan | D44: =VLOOKUP(B44,기업리스트!B:G,2,FALSE) -> The Bank of Nagoya, Ltd. | E44: Sep'26 | F44: 16.1 | G44: 5661 | H44: 1496 | I44: 3524 | J44: 2941 | K44: 3282 | L44: 1734 | M44: 4110 | N44: 2183 | O44: 5025 | P44: 3195 | Q44: 5849 | R44: 4326 | S44: 6668 | T44: 3858 | U44: 7568 | V44: 5476 | W44: 10458 | X44: 0.033087134 | Y44: 0.083039467 | Z44: 0.051293488 | AA44: 0.16079762
B45: 9684 | C45: Japan | D45: =VLOOKUP(B45,기업리스트!B:G,2,FALSE) -> Square Enix Holdings Co., Ltd. | E45: Sep'26 | F45: 14.8 | G45: 20993 | H45: 9122 | I45: 14432 | J45: 11613 | K45: 15271 | L45: 3017 | M45: 3098 | N45: 14240 | O45: 17582 | P45: -2361 | Q45: 10846 | R45: 10331 | S45: 12205 | T45: 7199 | U45: 9019 | V45: 18260 | W45: 19109 | X45: 0.30817833 | Y45: -0.045021069 | Z45: 0.20459824 | AA45: 0.1478911
B46: 1720 | C46: Japan | D46: =VLOOKUP(B46,기업리스트!B:G,2,FALSE) -> Tokyu Construction Co., Ltd. | E46: Sep'26 | F46: 14.3 | G46: 2170 | H46: -1096 | I46: -517 | J46: 684 | K46: 1549 | L46: 3392 | M46: 230 | N46: 1814 | O46: 571 | P46: 5541 | Q46: -954 | R46: 950 | S46: 3183 | T46: 5662 | U46: 2170 | V46: 2977 | W46: 5183 | X46: 0.013876147 | Y46: 0.35335369 | Z46: 0.16941078 | AA46: 0.14293882
... B114: 4521 | C114: Japan | D114: =VLOOKUP(B114,기업리스트!B:G,2,FALSE) -> Kaken Pharmaceutical Co., Ltd. | E114: Sep'26 | F114: -331 | G114: 4853 | H114: 3175 | I114: 4057 | J114: 4152 | K114: 4186 | L114: -4395 | M114: 3294 | N114: 2220 | O114: 3360 | P114: 640 | Q114: 2751 | R114: 16829 | S114: 5844 | T114: -4388 | U114: 16 | V114: 187 | W114: 352 | X114: -0.19290976 | Y114: -0.13001521 | Z114: -0.90934922 | AA114: -3.310428
B115: KALYANKJIL | C115: India | D115: =VLOOKUP(B115,기업리스트!B:G,2,FALSE) -> Kalyan Jewellers India Limited | E115: Sep'26 | F115: 20.1 | G115: 2404 | H115: 1804 | I115: 2052 | J115: 2058 | K115: 2649 | L115: 2081 | M115: 2589 | N115: 2467 | O115: 3001 | P115: 2072 | Q115: 3006 | R115: 2423 | S115: 3499 | T115: 2955 | U115: 4103 | V115: 3938 | W115: 6416 | X115: 0.080272727 | Y115: 0.092316755 | Z115: 0.11671803 | AA115: 0.20124181
B116: SONATSOFTW | C116: India | D116: =VLOOKUP(B116,기업리스트!B:G,2,FALSE) -> Sonata Software Limited | E116: Sep'26 | F116: 9.6 | G116: 1190 | H116: 1577 | I116: 1287 | J116: 1410 | K116: 1426 | L116: 1376 | M116: 1471 | N116: 1640 | O116: 1740 | P116: 1654 | Q116: 1429 | R116: 1443 | S116: 1313 | T116: 1509 | U116: 1336 | V116: 1464 | W116: 1851 | X116: -0.024833019 | Y116: -0.016332982 | Z116: 0.0037493305 | AA116: 0.095695482
B117: GRINFRA | C117: India | D117: =VLOOKUP(B117,기업리스트!B:G,2,FALSE) -> G R Infraprojects Limited | E117: Sep'26 | F117: 7.1 | G117: 2837 | H117: 4538 | I117: 6236 | J117: 5393 | K117: 5336 | L117: 6181 | M117: 5471 | N117: 4053 | O117: 4466 | P117: 4857 | Q117: 3049 | R117: 2900 | S117: 3087 | T117: 5618 | U117: 3458 | V117: 3361 | W117: 4191 | X117: 0.054775786 | Y117: 0.027910468 | Z117: 0.030604793 | AA117: 0.071115692
B118: EMBASSY | C118: India | D118: =VLOOKUP(B118,기업리스트!B:G,2,FALSE) -> Embassy Office Parks REIT | E118: Sep'26 | F118: 6.8 | G118: 4133 | H118: 4040 | I118: 4348 | J118: 4047 | K118: 4134 | L118: 3063 | M118: 5048 | N118: 4661 | O118: 5084 | P118: 5025 | Q118: 4862 | R118: 5285 | S118: 4949 | T118: 5410 | U118: 5524 | V118: 6035 | W118: 6431 | X118: 0.019134238 | Y118: 0.032283234 | Z118: 0.035430839 | AA118: 0.067615658
B119: INDIASHLTR | C119: India | D119: =VLOOKUP(B119,기업리스트!B:G,2,FALSE) -> India Shelter Finance Corporation Limited | E119: Sep'26 | F119: 6.2 | G119: 519.99 | H119: 641.53 | I119: 340.17 | J119: 471.08 | K119: 519.65 | L119: 681.12 | M119: 609.83 | N119: 773.75 | O119: 811.59 | P119: 996.68 | Q119: 1081 | R119: 1172 | S119: 1244 | T119: 1395 | U119: 1552 | V119: 1581 | W119: 1599 | X119: 0.088640046 | Y119: 0.09627964 | Z119: 0.076263285 | AA119: 0.061503812
B120: INOXINDIA | C120: India | D120: =VLOOKUP(B120,기업리스트!B:G,2,FALSE) -> INOX India Limited | E120: Jun'26 | F120: 4.7 | J120: 530.11 | K120: 530.11 | L120: 485.7 | M120: 383.77 | N120: 678.91 | O120: 547.37 | P120: 614.6 | Q120: 505.1 | R120: 645.98 | S120: 579.88 | T120: 628.12 | U120: 749.66 | V120: 685.68 | W120: 702.91 | X120: 0.0057640819 | Y120: 0.10366753 | Z120: 0.015247884 | AA120: 0.046543388
B121: LEMONTREE | C121: India | D121: =VLOOKUP(B121,기업리스트!B:G,2,FALSE) -> Lemon Tree Hotels Limited | E121: Sep'26 | F121: 4.1 | G121: 378.68 | H121: 2.82 | I121: 630.89 | J121: 685.99 | K121: 1035 | L121: 1182 | M121: 840.52 | N121: 821.87 | O121: 1086 | P121: 1424 | Q121: 808.5 | R121: 964.4 | S121: 1498 | T121: 1729 | U121: 1079 | V121: 981.25 | W121: 1716 | X121: 0.06496411 | Y121: 0.054101082 | Z121: 0.0031971008 | AA121: 0.041231264
B122: SHREECEM | C122: India | D122: =VLOOKUP(B122,기업리스트!B:G,2,FALSE) -> Shree Cement Limited | E122: Sep'26 | F122: 4 | G122: 5599 | H122: 6199 | I122: 4512 | J122: 1471 | K122: 2841 | L122: 4200 | M122: 6055 | N122: 4743 | O122: 8201 | P122: 7187 | Q122: 2229 | R122: -1024 | S122: 1657 | T122: 6360 | U122: 6788 | V122: 3061 | W122: 2375 | X122: -0.082296746 | Y122: 0.49436131 | Z122: 0.29642261 | AA122: 0.040188067
B123: SIEMENS | C123: India | D123: =VLOOKUP(B123,기업리스트!B:G,2,FALSE) -> Siemens Limited | E123: Sep'26 | F123: 1.8 | G123: 2840 | H123: 4048 | I123: 3335 | J123: 5666 | K123: 5231 | L123: 5427 | M123: 4790 | N123: 6021 | O123: 5176 | P123: 7982 | Q123: 6060 | R123: 8612 | S123: 3202 | T123: 3989 | U123: 4503 | V123: 5455 | W123: 3505 | X123: -0.15443224 | Y123: -0.07121621 | Z123: -0.15547129 | AA123: 0.017668669
B124: CROMPTON | C124: India | D124: =VLOOKUP(B124,기업리스트!B:G,2,FALSE) -> Crompton Greaves Consumer Electricals Limited | E124: Sep'26 | F124: 0.2 | G124: 1914 | H124: 2143 | I124: 1924 | J124: 1648 | K124: 1227 | L124: 1747 | M124: 1566 | N124: 1424 | O124: 1173 | P124: 1686 | Q124: 1952 | R124: 1653 | S124: 1501 | T124: 2248 | U124: 1522 | V124: 1143 | W124: 1517 | X124: 0.082744405 | Y124: -0.05847158 | Z124: -0.073656846 | AA124: 0.0024945432
...

Sheet 빨간줄
B2: (단위: mil $)
B4: 7287 | C4: 6 | D4: 7 | E4: 8 | F4: 9 | G4: 10 | H4: 11 | I4: 12 | J4: 13 | K4: 14 | L4: 15 | M4: 16 | N4: 17 | O4: 18 | P4: 19 | Q4: 20 | R4: 21 | S4: 22 | Z4: WTM | AA4: 6366 | AB4: Chiyoda Corporation
Z5: CG | AA5: 5021 | AB5: Cosmo Energy Holdings Co., Ltd.
C6: 4Q21 | D6: 1Q22 | E6: 2Q22 | F6: 3Q22 | G6: 4Q22 | H6: 1Q23 | I6: 2Q23 | J6: 3Q23 | K6: 4Q23 | L6: 1Q24 | M6: 2Q24 | N6: 3Q24 | O6: 4Q24 | P6: 1Q25 | Q6: 2Q25 | R6: 3Q25 | S6: 4Q25 | T6: 1Q26 | U6: 2Q26 | V6: 3Q26 | W6: 4Q26 | Z6: PAA | AA6: 6976 | AB6: Taiyo Yuden Co., Ltd.
B7: Revenue | C7: =VLOOKUP($B$4,Revenue!$B:$W,C4,FALSE) -> 55708 | D7: =VLOOKUP($B$4,Revenue!$B:$W,D4,FALSE) -> 62912 | E7: =VLOOKUP($B$4,Revenue!$B:$W,E4,FALSE) -> 56212 | F7: =VLOOKUP($B$4,Revenue!$B:$W,F4,FALSE) -> 71742 | G7: =VLOOKUP($B$4,Revenue!$B:$W,G4,FALSE) -> 71570 | H7: =VLOOKUP($B$4,Revenue!$B:$W,H4,FALSE) -> 76251 | I7: =VLOOKUP($B$4,Revenue!$B:$W,I4,FALSE) -> 74397 | J7: =VLOOKUP($B$4,Revenue!$B:$W,J4,FALSE) -> 75794 | ... S7: =VLOOKUP($B$4,Revenue!$B:$W,S4,FALSE) -> 78120 | Z7: PIPR | AA7: 6804 | AB7: Hosiden Corporation
B8: OP | C8: =VLOOKUP($B$4,'Operating Income'!$B:$W,C4,FALSE) -> -1954 | D8: =VLOOKUP($B$4,'Operating Income'!$B:$W,D4,FALSE) -> 2675 | E8: =VLOOKUP($B$4,'Operating Income'!$B:$W,E4,FALSE) -> -3297 | F8: =VLOOKUP($B$4,'Operating Income'!$B:$W,F4,FALSE) -> 3047 | G8: =VLOOKUP($B$4,'Operating Income'!$B:$W,G4,FALSE) -> 1804 | H8: =VLOOKUP($B$4,'Operating Income'!$B:$W,H4,FALSE) -> 1254 | I8: =VLOOKUP($B$4,'Operating Income'!$B:$W,I4,FALSE) -> 2307 | J8: =VLOOKUP($B$4,'Operating Income'!$B:$W,J4,FALSE) -> 2486 | ... S8: =VLOOKUP($B$4,'Operating Income'!$B:$W,S4,FALSE) -> 3318 | Z8: FBK | AA8: 5214 | AB8: Nippon Electric Glass Co., Ltd.
B9: Trailing 4Q OP avg. | C9: =AVERAGE(C8:C8) -> -1954 | D9: =AVERAGE(C8:D8) -> 360.5 | E9: =AVERAGE(C8:E8) -> -858.66667 | F9: =AVERAGE(C8:F8) -> 117.75 | G9: =AVERAGE(D8:G8) -> 1057.25 | H9: =AVERAGE(E8:H8) -> 702 | I9: =AVERAGE(F8:I8) -> 2103 | J9: =AVERAGE(G8:J8) -> 1962.75 | K9: =AVERAGE(H8:K8) -> 1974 | L9: =AVERAGE(I8:L8) -> 2560 | M9: =AVERAGE(J8:M8) -> 2528.75 | ... S9: =AVERAGE(P8:S8) -> 3073 | Z9: PRLB | AA9: 6652 | AB9: IDEC Corporation
B10: Trailing 4Q OP sum. | C10: =SUM(C8:C8) -> -1954 | D10: =SUM(C8:D8) -> 721 | E10: =SUM(C8:E8) -> -2576 | F10: =SUM(C8:F8) -> 471 | G10: =SUM(D8:G8) -> 4229 | H10: =SUM(E8:H8) -> 2808 | I10: =SUM(F8:I8) -> 8412 | J10: =SUM(G8:J8) -> 7851 | K10: =SUM(H8:K8) -> 7896 | L10: =SUM(I8:L8) -> 10240 | M10: =SUM(J8:M8) -> 10115 | ... S10: =SUM(P8:S8) -> 12292 | Z10: UI | AA10: 4751 | AB10: CyberAgent, Inc.
B11: Trailing OP Delta | D11: =D9/C9-1 -> -1.1844933 | E11: =E9/D9-1 -> -3.381877 | F11: =F9/E9-1 -> -1.1371312 | G11: =G9/F9-1 -> 7.9787686 | H11: =H9/G9-1 -> -0.33601324 | I11: =I9/H9-1 -> 1.9957265 | J11: =J9/I9-1 -> -0.066690442 | K11: =K9/J9-1 -> 0.0057317539 | ... S11: =S9/R9-1 -> 0.10212499 | AA11: 1968 | AB11: Taihei Dengyo Kaisha, Ltd.
B12: opm | C12: =IFERROR(C8/C7,"-") -> -0.035075752 | D12: =IFERROR(D8/D7,"-") -> 0.04251971 | E12: =IFERROR(E8/E7,"-") -> -0.058652957 | F12: =IFERROR(F8/F7,"-") -> 0.042471634 | G12: =IFERROR(G8/G7,"-") -> 0.025206092 | H12: =IFERROR(H8/H7,"-") -> 0.016445686 | I12: =IFERROR(I8/I7,"-") -> 0.031009315 | J12: =IFERROR(J8/J7,"-") -> 0.03279943 | ... S12: =IFERROR(S8/S7,"-") -> 0.042473118 | AA12: 7322 | AB12: San ju San Financial Group,Inc.
B13: op yoy | C13: =C8/#REF!-1 -> #REF! | D13: =D8/#REF!-1 -> #REF! | E13: =E8/#REF!-1 -> #REF! | F13: =F8/#REF!-1 -> #REF! | G13: =G8/C8-1 -> -1.9232344 | H13: =H8/D8-1 -> -0.53121495 | I13: =I8/E8-1 -> -1.699727 | J13: =J8/F8-1 -> -0.18411552 | K13: =K8/G8-1 -> 0.024944568 | L13: =L8/H8-1 -> 1.8692185 | M13: =M8/I8-1 -> -0.054182922 | N13: =N8/J8-1 -> -0.49115044 | ... S13: =S8/O8-1 -> 0.52271684 | AA13: 8522 | AB13: The Bank of Nagoya, Ltd.
B14: rv yoy | G14: =G7/C7-1 -> 0.28473469 | H14: =H7/D7-1 -> 0.21202632 | I14: =I7/E7-1 -> 0.32350744 | J14: =J7/F7-1 -> 0.056480165 | K14: =K7/G7-1 -> 0.11015789 | L14: =L7/H7-1 -> 0.084693971 | M14: =M7/I7-1 -> 0.026694625 | N14: =N7/J7-1 -> 0.0035622873 | ... S14: =S7/O7-1 -> 0.036720502 | AA14: 9684 | AB14: Square Enix Holdings Co., Ltd.
AA15: 1720 | AB15: Tokyu Construction Co., Ltd.
AA16: 1965 | AB16: Techno Ryowa Ltd.
AA17: 8424 | AB17: Fuyo General Lease Co., Ltd.
AA18: 6406 | AB18: Fujitec Co., Ltd.
AA19: 6332 | AB19: Tsukishima Holdings Co., Ltd.
AA20: 1515 | AB20: Nittetsu Mining Co., Ltd.
AA21: 2004 | AB21: Showa Sangyo Co., Ltd.
AA22: 8359 | AB22: Hachijuni Nagano Bank, Ltd.
AA23: 7287 | AB23: Nippon Seiki Co., Ltd.
