Workbook

Sheet 기업 정보
B2: 지난주 실적 기업 정보
B4: Ticker | C4: Company | D4: Date | E4: Time | F4: Quarter Ending | G4: Market Cap (mil$)
B5: JNJ | C5: Johnson & Johnson | D5: 46043 | E5: Pre Market | F5: 45992 | G5: 526816470000
B6: NFLX | C6: Netflix, Inc. | D6: 46042 | E6: After Hours | F6: 45992 | G6: 402115560000
B7: PG | C7: The Procter & Gamble Company | D7: 46044 | F7: 45992 | G7: 337728100000
B8: INTC | C8: Intel Corporation | D8: 46044 | F8: 45992 | G8: 225132700000
B9: ABT | C9: Abbott Laboratories | D9: 46044 | F9: 45992 | G9: 186785560000
B10: ISRG | C10: Intuitive Surgical, Inc. | D10: 46044 | F10: 45992 | G10: 185752400000
B11: SCHW | C11: The Charles Schwab Corporation | D11: 46043 | E11: Pre Market | F11: 45992 | G11: 181567400000
B12: COF | C12: Capital One Financial Corporation | D12: 46044 | F12: 45992 | G12: 135834230000
B13: PLD | C13: Prologis, Inc. | D13: 46043 | E13: Pre Market | F13: 45992 | G13: 118105440000
B14: FCX | C14: Freeport-McMoRan Inc. | D14: 46044 | F14: 45992 | G14: 86744570000
B15: MMM | C15: 3M Company | D15: 46042 | E15: Pre Market | F15: 45992 | G15: 86265810000
B16: USB | C16: U.S. Bancorp | D16: 46042 | E16: Pre Market | F16: 45992 | G16: 86224460000
B17: SLB | C17: SLB N.V. | D17: 46045 | F17: 45992 | G17: 73495540000
B18: CSX | C18: CSX Corporation | D18: 46044 | F18: 45992 | G18: 68224340000
B19: KMI | C19: Kinder Morgan, Inc. | D19: 46043 | E19: After Hours | F19: 45992 | G19: 65786160000
B20: TEL | C20: TE Connectivity plc | D20: 46043 | E20: Pre Market | F20: 45992 | G20: 65682330000
B21: TFC | C21: Truist Financial Corporation | D21: 46043 | E21: Pre Market | F21: 45992 | G21: 62580640000
B22: TRV | C22: The Travelers Companies, Inc. | D22: 46043 | E22: Pre Market | F22: 45992 | G22: 60404100000
B23: FAST | C23: Fastenal Company | D23: 46042 | E23: Pre Market | F23: 45992 | G23: 50388240000
B24: EQT | C24: EQT AB (publ) | D24: 46044 | F24: 45992 | G24: 47934030000
B25: SAND | C25: Sandvik AB (publ) | D25: 46043 | F25: 45992 | G25: 44480180000
B26: DHI | C26: D.R. Horton, Inc. | D26: 46042 | E26: Pre Market | F26: 45992 | G26: 43603260000
B27: SWED A | C27: Swedbank AB (publ) | D27: 46043 | F27: 45992 | G27: 42398140000
B28: ULTRACEMCO | C28: UltraTech Cement Limited | D28: 46046 | F28: 45992 | G28: 40129660000
B29: UAL | C29: United Airlines Holdings, Inc. | D29: 46042 | E29: After Hours | F29: 45992 | G29: 36741020000
B30: IBKR | C30: Interactive Brokers Group, Inc. | D30: 46042 | E30: After Hours | F30: 45992 | G30: 32671910000
B31: FITB | C31: Fifth Third Bancorp | D31: 46042 | E31: Pre Market | F31: 45992 | G31: 32497200000
B32: ERIC B | C32: Telefonaktiebolaget LM Ericsson (publ) | D32: 46045 | F32: 45992 | G32: 31602580000
B33: ETERNAL | C33: Eternal Limited | D33: 46042 | F33: 45992 | G33: 28767160000
B34: HBAN | C34: Huntington Bancshares Incorporated | D34: 46044 | F34: 45992 | G34: 28253480000
B35: NTRS | C35: Northern Trust Corporation | D35: 46044 | F35: 45992 | G35: 27529820000
B36: TDY | C36: Teledyne Technologies Incorporated | D36: 46043 | E36: Pre Market | F36: 45992 | G36: 27312330000
B37: FCNC.A | C37: First Citizens BancShares, Inc. | D37: 46045 | F37: 45992 | G37: 26585810000
B38: CFG | C38: Citizens Financial Group, Inc. | D38: 46043 | E38: Pre Market | F38: 45992 | G38: 26121350000
B39: USB | C39: U.S. Bancorp. | D39: 46042 | F39: 45992 | G39: 22204210000
B40: HAL | C40: Halliburton Company | D40: 46043 | E40: Pre Market | F40: 45992 | G40: 20726760000
B41: KEY | C41: KeyCorp | D41: 46042 | E41: Pre Market | F41: 45992 | G41: 20428090000
B42: DLF | C42: DLF Limited | D42: 46044 | F42: 45992 | G42: 20331290000
...

Sheet 영업이익 DATA
C1: 3 | E1: 6 | F1: 5 | G1: 6 | H1: 7 | I1: 8 | J1: 9 | K1: 10 | L1: 11 | M1: 12 | N1: 13 | O1: 14 | P1: 15 | Q1: 16 | R1: 17 | S1: 18 | T1: 19 | U1: 20 | V1: 21
B2: Ticker | C2: Latest_Date | D2: 최근 분기 빨간줄 | E2: Recent_Avg | F2: 4Q21 | G2: 1Q22 | H2: 2Q22 | I2: 3Q22 | J2: 4Q22 | K2: 1Q23 | L2: 2Q23 | M2: 3Q23 | N2: 4Q23 | O2: 1Q24 | P2: 2Q24 | Q2: 3Q24 | R2: 4Q24 | S2: 1Q25 | T2: 2Q25 | U2: 3Q25 | V2: 4Q25 | W2: Highlight_Quarters | Y2: * 최근에 실적 안나온 기업은 제외
B3: JNJ | C3: Sep '25 Sep 28, 2025 | D3: 9.3066629 | E3: 5860.75 | F3: 5706 | G3: 1331 | H3: 5748 | I3: 6087 | J3: 5299 | K3: 2821 | L3: 5667 | M3: 5813 | N3: 5534 | O3: 4193 | P3: 5909 | Q3: 6276 | R3: 5037 | S3: 3582 | T3: 6182 | U3: 6646 | V3: 7033 | W3: set()
B4: TCI | C4: ('Q3 2025', "Sep '25 Sep 30, 2025") | D4: 0.21413276 | E4: -1.17 | F4: -0.93 | G4: -1.16 | H4: 0.58 | I4: -1.21 | J4: 461.32 | K4: -1.89 | L4: -1.89 | M4: -3.49 | N4: -1.69 | O4: -1.87 | P4: -0.9 | Q4: -0.97 | R4: -1.39 | S4: -1.81 | T4: -0.64 | U4: -0.83 | V4: -1.4 | W4: set()
B5: NWFL | C5: ('Q4 2025', "Dec '25 Dec 31, 2025") | D5: 265.17205 | E5: 8.755 | F5: 8.03 | G5: 8.98 | H5: 8.61 | I5: 10.21 | J5: 8.58 | K5: 7.27 | L5: 8.24 | M5: 5.19 | N5: 0.45 | O5: 5.61 | P5: 5.34 | Q5: 4.85 | R5: -16.06 | S5: 7.29 | T5: 7.83 | U5: 10.53 | V5: 9.37 | W5: set()
B6: ASB | C6: ('Q4 2025', "Dec '25 Dec 31, 2025") | D6: 143.57062 | E6: 144.48 | F6: 92.05 | G6: 92.91 | H6: 110.19 | I6: 122.44 | J6: 134.09 | K6: 130.7 | L6: 110.69 | M6: 102.67 | N6: -138.01 | O6: 101.19 | P6: 102.88 | Q6: 108.14 | R6: -177.75 | S6: 121.1 | T6: 139.63 | U6: 154.29 | V6: 162.9 | W6: {'4Q23', '2Q23', '1Q24', '3Q23'}
B7: KEY | C7: ('Q4 2025', "Dec '25 Dec 31, 2025") | D7: 85.358005 | E7: 576 | F7: 768 | G7: 537 | H7: 662 | I7: 664 | J7: 470 | K7: 392 | L7: 344 | M7: 367 | N7: 57 | O7: 278 | P7: 335 | Q7: -506 | R7: -413 | S7: 515 | T7: 539 | U7: 602 | V7: 648 | W7: {'3Q25', '4Q25', '4Q22'}
B8: MCBS | C8: ('Q3 2025', "Sep '25 Sep 30, 2025") | D8: 1.3219807 | E8: 22.61 | F8: 22.03 | G8: 24.05 | H8: 26.03 | I8: 21.75 | J8: 23.9 | K8: 19.53 | L8: 21.57 | M8: 18.61 | N8: 15.65 | O8: 16.14 | P8: 20.43 | Q8: 23.37 | R8: 22.66 | S8: 20.85 | T8: 22.08 | U8: 23.67 | V8: 23.84 | W8: set()
B9: DCOM | C9: ('Q4 2025', "Dec '25 Dec 31, 2025") | D9: 70.657379 | E9: 39.2 | F9: 51.17 | G9: 48.02 | H9: 53.75 | I9: 54.91 | J9: 55.23 | K9: 50.93 | L9: 37.55 | M9: 23.08 | N9: 25.33 | O9: 24.28 | P9: 26.03 | Q9: 18.22 | R9: -17.09 | S9: 28.71 | T9: 40.17 | U9: 40.09 | V9: 47.83 | W9: set()
B10: LOB | C10: ('Q4 2025', "Dec '25 Dec 31, 2025") | D10: 51.715712 | E10: 35.7025 | F10: 47.78 | G10: 42.9 | H10: 122.32 | I10: 44.39 | J10: 0.72 | K10: 3.61 | L10: 18.97 | M10: 42.76 | N10: 17.48 | O10: 22.11 | P10: 36.06 | Q10: 17.84 | R10: 13.23 | S10: 13.13 | T10: 31.2 | U10: 36.57 | V10: 61.91 | W10: {'3Q25', '4Q25', '4Q22', '2Q24'}
B11: MOFG | C11: ('Q3 2025', "Sep '25 Sep 30, 2025") | D11: -197.23053 | E11: 18.695 | F11: 20.82 | G11: 18.98 | H11: 17.34 | I11: 16.71 | J11: 23.06 | K11: 19.49 | L11: 1.78 | M11: 9.19 | N11: 11.34 | O11: 2.52 | P11: 4.23 | Q11: 20.87 | R11: -130.2 | S11: 21.11 | T11: 19.6 | U11: 12.58 | V11: 21.49 | W11: {'3Q25', '3Q24'}
B12: ALLY | C12: ('Q4 2025', "Dec '25 Dec 31, 2025") | D12: 35.788114 | E12: 262.75 | F12: 899 | G12: 846 | H12: 634 | I12: 417 | J12: 445 | K12: 388 | L12: 403 | M12: 228 | N12: 84 | O12: 183 | P12: 279 | Q12: 265 | R12: 109 | S12: -284 | T12: 436 | U12: 513 | V12: 386 | W12: set()
B13: CASS | C13: ('Q4 2025', "Dec '25 Dec 31, 2025") | D13: 31.991373 | E13: 13.77 | F13: 8.9 | G13: 10.5 | H13: 10.92 | I13: 11.67 | J13: 13.3 | K13: 12.22 | L13: 12.56 | M13: 13.8 | N13: 15.04 | O13: 14.08 | P13: 10.88 | Q13: 15.48 | R13: 2.53 | S13: 12.99 | T13: 10.44 | U13: 15.77 | V13: 15.88 | W13: {'4Q22'}
B14: EQBK | C14: ('Q4 2025', "Dec '25 Dec 31, 2025") | D14: 29.886755 | E14: 6.595 | F14: 10.45 | G14: 19.26 | H14: 16.94 | I14: 18.81 | J14: 15.26 | K14: 14.85 | L14: 12.95 | M14: 14.27 | N14: -39.66 | O14: 17.76 | P14: 16.3 | Q14: 23.84 | R14: 20.39 | S14: 18.85 | T14: 18.37 | U14: -37.3 | V14: 26.46 | W14: {'3Q25', '2Q23', '1Q25', '4Q23', '4Q25', '3Q23'}
... B165: AMTB | C165: ('Q4 2025', "Dec '25 Dec 31, 2025") | D165: -19.584245 | E165: 16.5375 | F165: 84.48 | G165: 18.13 | H165: 10.59 | I165: 22.43 | J165: 27.45 | K165: 25.24 | L165: 8.92 | M165: 28.08 | N165: -20.91 | O165: 13.46 | P165: 6.32 | Q165: -61.89 | R165: 18.02 | S165: 15.43 | T165: 29.8 | U165: 19.01 | V165: 1.91 | W165: set()

Sheet 빨간줄
B2: (단위: mil $)
B4: JNJ | C4: 5 | D4: 6 | E4: 7 | F4: 8 | G4: 9 | H4: 10 | I4: 11 | J4: 12 | K4: 13 | L4: 14 | M4: 15 | N4: 16 | O4: 17 | P4: 18 | Q4: 19 | R4: 20 | S4: 21
C6: 4Q21 | D6: 1Q22 | E6: 2Q22 | F6: 3Q22 | G6: 4Q22 | H6: 1Q23 | I6: 2Q23 | J6: 3Q23 | K6: 4Q23 | L6: 1Q24 | M6: 2Q24 | N6: 3Q24 | O6: 4Q24 | P6: 1Q25 | Q6: 2Q25 | R6: 3Q25 | S6: 4Q25 | T6: 1Q26 | U6: 2Q26 | V6: 3Q26 | W6: 4Q26
B7: Revenue
B8: OP | C8: =VLOOKUP($B$4,'영업이익 DATA'!$B$1:$V$165,C4,FALSE) -> 5706 | D8: =VLOOKUP($B$4,'영업이익 DATA'!$B$1:$V$165,D4,FALSE) -> 1331 | E8: =VLOOKUP($B$4,'영업이익 DATA'!$B$1:$V$165,E4,FALSE) -> 5748 | F8: =VLOOKUP($B$4,'영업이익 DATA'!$B$1:$V$165,F4,FALSE) -> 6087 | G8: =VLOOKUP($B$4,'영업이익 DATA'!$B$1:$V$165,G4,FALSE) -> 5299 | H8: =VLOOKUP($B$4,'영업이익 DATA'!$B$1:$V$165,H4,FALSE) -> 2821 | I8: =VLOOKUP($B$4,'영업이익 DATA'!$B$1:$V$165,I4,FALSE) -> 5667 | J8: =VLOOKUP($B$4,'영업이익 DATA'!$B$1:$V$165,J4,FALSE) -> 5813 | ... S8: =VLOOKUP($B$4,'영업이익 DATA'!$B$1:$V$165,S4,FALSE) -> 7033
B9: Trailing 4Q OP avg. | C9: =AVERAGE(C8:C8) -> 5706 | D9: =AVERAGE(C8:D8) -> 3518.5 | E9: =AVERAGE(C8:E8) -> 4261.6667 | F9: =AVERAGE(C8:F8) -> 4718 | G9: =AVERAGE(D8:G8) -> 4616.25 | H9: =AVERAGE(E8:H8) -> 4988.75 | I9: =AVERAGE(F8:I8) -> 4968.5 | J9: =AVERAGE(G8:J8) -> 4900 | K9: =AVERAGE(H8:K8) -> 4958.75 | L9: =AVERAGE(I8:L8) -> 5301.75 | M9: =AVERAGE(J8:M8) -> 5362.25 | ... S9: =AVERAGE(P8:S8) -> 5860.75
B10: Trailing 4Q OP sum. | C10: =SUM(C8:C8) -> 5706 | D10: =SUM(C8:D8) -> 7037 | E10: =SUM(C8:E8) -> 12785 | F10: =SUM(C8:F8) -> 18872 | G10: =SUM(D8:G8) -> 18465 | H10: =SUM(E8:H8) -> 19955 | I10: =SUM(F8:I8) -> 19874 | J10: =SUM(G8:J8) -> 19600 | K10: =SUM(H8:K8) -> 19835 | L10: =SUM(I8:L8) -> 21207 | M10: =SUM(J8:M8) -> 21449 | ... S10: =SUM(P8:S8) -> 23443
B11: Trailing OP Delta | D11: =D9/C9-1 -> -0.38336838 | E11: =E9/D9-1 -> 0.2112169 | F11: =F9/E9-1 -> 0.10707861 | G11: =G9/F9-1 -> -0.021566342 | H11: =H9/G9-1 -> 0.080693203 | I11: =I9/H9-1 -> -0.004059133 | J11: =J9/I9-1 -> -0.013786857 | K11: =K9/J9-1 -> 0.011989796 | ... S11: =S9/R9-1 -> 0.093066629
B12: opm | C12: =IFERROR(C8/C7,"-") -> - | D12: =IFERROR(D8/D7,"-") -> - | E12: =IFERROR(E8/E7,"-") -> - | F12: =IFERROR(F8/F7,"-") -> - | G12: =IFERROR(G8/G7,"-") -> - | H12: =IFERROR(H8/H7,"-") -> - | I12: =IFERROR(I8/I7,"-") -> - | J12: =IFERROR(J8/J7,"-") -> - | ... S12: =IFERROR(S8/S7,"-") -> -
B13: op yoy | C13: =C8/#REF!-1 -> #REF! | D13: =D8/#REF!-1 -> #REF! | E13: =E8/#REF!-1 -> #REF! | F13: =F8/#REF!-1 -> #REF! | G13: =G8/C8-1 -> -0.071328426 | H13: =H8/D8-1 -> 1.1194591 | I13: =I8/E8-1 -> -0.014091858 | J13: =J8/F8-1 -> -0.045013964 | K13: =K8/G8-1 -> 0.04434799 | L13: =L8/H8-1 -> 0.48635236 | M13: =M8/I8-1 -> 0.04270337 | N13: =N8/J8-1 -> 0.079649062 | ... S13: =S8/O8-1 -> 0.39626762
