Workbook

Sheet 실적 기업 정보
B2: 실적 기업 정보
B4: Ticker | C4: Company | D4: Date | E4: Time | F4: Quarter Ending | G4: Market Cap (mil$)
B5: GOOGL | C5: Alphabet Inc. | D5: 04-Feb-26 | E5: After Hours | F5: Dec-25 | G5: 4081510
B6: MSFT | C6: Microsoft Corporation | D6: 46050 | E6: After Hours | F6: 46381 | G6: 3417853.2
B7: AMZN | C7: Amazon.com, Inc. | D7: 05-Feb-26 | E7: After Hours | F7: Dec-25 | G7: 2558170
B8: META | C8: Meta Platforms, Inc. | D8: 46050 | E8: After Hours | F8: 46381 | G8: 1563357.2
B9: TSLA | C9: Tesla, Inc. | D9: 46050 | F9: 46381 | G9: 1455045.9
B10: WMT | C10: Walmart Inc. | D10: 19-Feb-26 | E10: Pre Market | F10: Jan-26 | G10: 1067130
B11: LLY | C11: Eli Lilly and Company | D11: 04-Feb-26 | E11: Pre Market | F11: Dec-25 | G11: 928644
B12: XOM | C12: Exxon Mobil Corporation | D12: 30-Jan-26 | E12: Pre Market | F12: 25-Dec | G12: 590910.6
B13: ASML | C13: ASML Holding N.V. | D13: 46050 | E13: Pre Market | F13: 46381 | G13: 522992.7
B14: ABBV | C14: AbbVie Inc. | D14: 04-Feb-26 | E14: Pre Market | F14: Dec-25 | G14: 394144
B15: AMD | C15: Advanced Micro Devices, Inc. | D15: 03-Feb-26 | E15: After Hours | F15: Dec-25 | G15: 385406
B16: A000660 | C16: SK hynix Inc. | D16: 46050 | F16: 46381 | G16: 354526.93
B17: CVX | C17: Chevron Corporation | D17: 30-Jan-26 | E17: Pre Market | F17: 25-Dec | G17: 350262
B18: PLTR | C18: Palantir Technologies Inc. | D18: 02-Feb-26 | E18: After Hours | F18: Dec-25 | G18: 349387.93
B19: BABA | C19: Alibaba Group Holding Limited | D19: 19-Feb-26 | F19: Dec-25 | G19: 348128
B20: KO | C20: The Coca-Cola Company | D20: 10-Feb-26 | F20: Dec-25 | G20: 339956
B21: CSCO | C21: Cisco Systems, Inc. | D21: 11-Feb-26 | E21: After Hours | F21: Jan-26 | G21: 335132
B22: AZN | C22: AstraZeneca PLC | D22: 10-Feb-26 | E22: Pre Market | F22: Dec-25 | G22: 297912
B23: 7203 | C23: Toyota Motor Corporation | D23: 06-Feb-26 | F23: Dec-25 | G23: 296741
B24: HSBA | C24: HSBC Holdings plc | D24: 18-Feb-26 | F24: Dec-25 | G24: 290025
B25: NOVN | C25: Novartis AG | D25: 04-Feb-26 | E25: Pre Market | F25: Dec-25 | G25: 284517
B26: PM | C26: Philip Morris International Inc. | D26: 06-Feb-26 | F26: Dec-25 | G26: 279323
B27: LRCX | C27: Lam Research Corporation | D27: 46050 | E27: After Hours | F27: 46381 | G27: 273739.18
B28: MRK | C28: Merck & Co., Inc. | D28: 03-Feb-26 | F28: Dec-25 | G28: 273693
B29: IBM | C29: International Business Machines Corporation | D29: 46050 | E29: After Hours | F29: 46381 | G29: 273353.96
B30: NOVO B | C30: Novo Nordisk A/S | D30: 04-Feb-26 | E30: Pre Market | F30: Dec-25 | G30: 261350
B31: AMAT | C31: Applied Materials, Inc. | D31: 12-Feb-26 | E31: After Hours | F31: Jan-26 | G31: 255983
B32: RMS | C32: Hermès International Société en commandite par actions | D32: 12-Feb-26 | F32: Dec-25 | G32: 254688
B33: OR | C33: L'Oréal S.A. | D33: 12-Feb-26 | F33: Dec-25 | G33: 248655
B34: AXP | C34: American Express Company | D34: 30-Jan-26 | E34: Pre Market | F34: 25-Dec | G34: 241588.62
B35: MCD | C35: McDonald's Corporation | D35: 11-Feb-26 | E35: Pre Market | F35: Dec-25 | G35: 232988
B36: SIE | C36: Siemens Aktiengesellschaft | D36: 12-Feb-26 | F36: Dec-25 | G36: 229885
B37: TMUS | C37: T-Mobile US, Inc. | D37: 11-Feb-26 | E37: Pre Market | F37: Dec-25 | G37: 220782
B38: SHEL | C38: Shell plc | D38: 05-Feb-26 | F38: Dec-25 | G38: 218501
B39: LIN | C39: Linde plc | D39: 05-Feb-26 | E39: Pre Market | F39: Dec-25 | G39: 213382
B40: PEP | C40: PepsiCo, Inc. | D40: 03-Feb-26 | F40: Dec-25 | G40: 212497
B41: 8306 | C41: Mitsubishi UFJ Financial Group, Inc. | D41: 04-Feb-26 | F41: Dec-25 | G41: 206552
B42: DIS | C42: The Walt Disney Company | D42: 02-Feb-26 | F42: Dec-25 | G42: 201380.58
...

Sheet Revenue
B1: 1 | C1: 2 | D1: 3 | E1: 4 | F1: 5 | G1: 6 | H1: 7 | I1: 8 | J1: 9 | K1: 10 | L1: 11 | M1: 12 | N1: 13 | O1: 14 | P1: 15 | Q1: 16 | R1: 17 | S1: 18 | T1: 19 | U1: 20 | V1: 21 | W1: 22
B2: Ticker | C2: Country | D2: Industry | E2: Latest_Date | F2: Growth_Rate | G2: 4Q21 | H2: 1Q22 | I2: 2Q22 | J2: 3Q22 | K2: 4Q22 | L2: 1Q23 | M2: 2Q23 | N2: 3Q23 | O2: 4Q23 | P2: 1Q24 | Q2: 2Q24 | R2: 3Q24 | S2: 4Q24 | T2: 1Q25 | U2: 2Q25 | V2: 3Q25 | W2: 4Q25 | X2: 1Q25 | Y2: 2Q25 | Z2: 3Q25 | AA2: 4Q25
A3: 260220 | B3: ASB | C3: United States | D3: Banks - Regional | E3: Dec'25 | F3: 30.6 | G3: 270.3 | H3: 266.21 | I3: 291.61 | J3: 318.23 | K3: 330.65 | L3: 318.11 | M3: 301.36 | N3: 298.88 | O3: 101.38 | P3: 298.84 | Q3: 298.74 | R3: 308.74 | S3: 46.53 | T3: 331.72 | U3: 348.98 | V3: 370.49 | W3: 382.37 | X3: 0.034507005 | Y3: 0.050967303 | Z3: 0.059605973 | AA3: 0.30594323
A4: 260220 | B4: HBM | C4: United States | D4: Copper | E4: Dec'25 | F4: 7.2 | G4: 425.17 | H4: 378.62 | I4: 415.45 | J4: 346.17 | K4: 321.2 | L4: 295.22 | M4: 312.17 | N4: 480.46 | O4: 602.16 | P4: 525 | Q4: 425.5 | R4: 485.8 | S4: 584.9 | T4: 594.9 | U4: 536.4 | V4: 346.8 | W4: 732.9 | X4: 0.034583416 | Y4: 0.053034288 | Z4: -0.063124432 | AA4: 0.071740184
A5: 260220 | B5: RCL | C5: United States | D5: Travel Services | E5: Dec'25 | F5: 2.9 | G5: 982.25 | H5: 1059 | I5: 2184 | J5: 2993 | K5: 2603 | L5: 2886 | M5: 3523 | N5: 4160 | O5: 3331 | P5: 3728 | Q5: 4110 | R5: 4886 | S5: 3760 | T5: 3999 | U5: 4538 | V5: 5139 | W5: 4259 | X5: 0.016440184 | Y5: 0.025544614 | Z5: 0.014723855 | AA5: 0.028618949
A6: 260220 | B6: BCPC | C6: United States | D6: Specialty Chemicals | E6: Dec'25 | F6: 2.3 | G6: 213.13 | H6: 228.87 | I6: 236.69 | J6: 244.27 | K6: 232.53 | L6: 232.54 | M6: 231.25 | N6: 229.95 | O6: 228.7 | P6: 239.66 | Q6: 234.08 | R6: 239.94 | S6: 240 | T6: 250.52 | U6: 255.47 | V6: 267.56 | W6: 263.62 | X6: 0.011387467 | Y6: 0.022176374 | Z6: 0.028014159 | AA6: 0.023304228
A7: 260220 | B7: OIS | C7: United States | D7: Oil & Gas Equipment & Services | E7: Dec'25 | F7: 2.1 | G7: 161.32 | H7: 164.04 | I7: 181.83 | J7: 189.39 | K7: 202.43 | L7: 196.2 | M7: 183.53 | N7: 194.29 | O7: 208.27 | P7: 167.26 | Q7: 186.38 | R7: 174.35 | S7: 164.6 | T7: 159.94 | U7: 165.41 | V7: 165.18 | W7: 178.46 | X7: -0.010569024 | Y7: -0.030601077 | Z7: -0.013804004 | AA7: 0.021156106
A8: 260220 | B8: BN | C8: United States | D8: Asset Management | E8: Dec'25 | F8: 0.9 | G8: 22420 | H8: 22725 | I8: 23820 | J8: 24351 | K8: 24486 | L8: 23726 | M8: 24069 | N8: 25250 | O8: 24947 | P8: 23593 | Q8: 23875 | R8: 20807 | S8: 20460 | T8: 18463 | U8: 18550 | V8: 19460 | W8: 21184 | X8: -0.057812588 | Y8: -0.063692363 | Z8: -0.01720746 | AA8: 0.009410786
A9: 260220 | B9: AAL | C9: United States | D9: Airlines | E9: Dec'25 | F9: 0.6 | G9: 9427 | H9: 8899 | I9: 13422 | J9: 13462 | K9: 13188 | L9: 12189 | M9: 14055 | N9: 13482 | O9: 13062 | P9: 12570 | Q9: 14334 | R9: 13647 | S9: 13660 | T9: 12551 | U9: 14392 | V9: 13691 | W9: 13999 | X9: -0.00035048237 | Y9: 0.0010702687 | Z9: 0.00081105991 | AA9: 0.0062437838
A10: 260220 | B10: LAMR | C10: United States | D10: REIT - Specialty | E10: Dec'25 | F10: 0.6 | G10: 496.82 | H10: 452.13 | I10: 518.21 | J10: 528.94 | K10: 537.17 | L10: 471.51 | M10: 541.59 | N10: 543.31 | O10: 558.28 | P10: 497.59 | Q10: 565.26 | R10: 566.78 | S10: 582.57 | T10: 505.81 | U10: 579.14 | V10: 585.54 | W10: 595.93 | X10: 0.0037157581 | Y10: 0.0062510696 | Z10: 0.0083963658 | AA10: 0.0059297134
A11: 260220 | B11: RSG | C11: United States | D11: Waste Management | E11: Dec'25 | F11: 0.5 | G11: 2953 | H11: 2970 | I11: 3414 | J11: 3598 | K11: 3530 | L11: 3581 | M11: 3726 | N11: 3826 | O11: 3832 | P11: 3862 | Q11: 4048 | R11: 4076 | S11: 4046 | T11: 4009 | U11: 4235 | V11: 4212 | W11: 4135 | X11: 0.0091691617 | Y11: 0.011558193 | Z11: 0.0083099108 | AA11: 0.0053932857
A12: 260220 | B12: EA | C12: United States | D12: Electronic Gaming & Multimedia | E12: Sep'26 | F12: 0.2 | G12: 1789 | H12: 1825 | I12: 1767 | J12: 1904 | K12: 1881 | L12: 1874 | M12: 1924 | N12: 1914 | O12: 1945 | P12: 1779 | Q12: 1660 | R12: 2025 | S12: 1883 | T12: 1895 | U12: 1671 | V12: 1839 | W12: 1901 | X12: 0.015788757 | Y12: 0.0014739381 | Z12: -0.024886272 | AA12: 0.0024698134
A13: 260220 | B13: CCOI | C13: United States | D13: Telecom Services | E13: Dec'25 | F13: -1.2 | G13: 142.91 | H13: 145.48 | I13: 145.05 | J13: 145.9 | K13: 147.88 | L13: 149.39 | M13: 228.81 | N13: 260.83 | O13: 251.7 | P13: 245.67 | Q13: 241.24 | R13: 237.4 | S13: 231.39 | T13: 226.85 | U13: 226.25 | V13: 222.75 | W13: 220.72 | X13: -0.019692372 | Y13: -0.015999915 | Z13: -0.015891267 | AA13: -0.011760945
A14: 260220 | B14: WU | C14: United States | D14: Credit Services | E14: Dec'25 | F14: -1.2 | G14: 1285 | H14: 1156 | I14: 1138 | J14: 1090 | K14: 1092 | L14: 1037 | M14: 1170 | N14: 1098 | O14: 1052 | P14: 1049 | Q14: 1066 | R14: 1036 | S14: 1058 | T14: 983.6 | U14: 1026 | V14: 1033 | W14: 1008 | X14: -0.015538133 | Y14: -0.0096534415 | Z14: -0.00073106541 | AA14: -0.012193338
... A17: 260220 | B17: AD | C17: United States | D17: Telecom Services | E17: Dec'25 | F17: -47.7 | G17: 1069 | H17: 1010 | I17: 1027 | J17: 1083 | K17: 1049 | L17: 986 | M17: 957 | N17: 963 | O17: 1000 | P17: 950 | Q17: 0 | R17: 25.74 | S17: 971 | T17: 891 | U17: 0 | V17: 47.12 | W17: 60.33 | X17: -0.030307077 | Y17: 0 | Z17: 0.011325712 | AA17: -0.47701035
A18: 260220 | B18: 8987 | C18: Japan | D18: Japan Excellent, Inc. | E18: H2 2025 | F18: -4.5024388 | G18: 10666 | I18: 11065 | K18: 10672 | M18: 13763 | O18: 10799 | Q18: 11460 | S18: 12752 | U18: 11235 | W18: 11672 | X18: -0.093762723 | Y18: 0.087739791 | Z18: -0.0092929126 | AA18: -0.045024388
A19: 260220 | B19: 2350 | C19: Hong Kong | D19: Saudi Kayan Petrochemical Company | E19: H1 2026 | F19: 15.090926 | G19: 261.8 | I19: 369.71 | K19: 406.14 | M19: 346.41 | O19: 360.06 | Q19: 268.01 | S19: 220.28 | U19: 409.9 | W19: 315.38 | X19: -0.11097428 | Y19: -0.22255481 | Z19: 0.29058551 | AA19: 0.15090926
A20: 260219 | B20: INSM | C20: United States | D20: Biotechnology | E20: Dec'25 | F20: 35.7 | G20: 56.12 | H20: 53.11 | I20: 65.22 | J20: 67.73 | K20: 59.3 | L20: 65.21 | M20: 77.23 | N20: 79.07 | O20: 83.69 | P20: 75.5 | Q20: 90.34 | R20: 93.43 | S20: 104.44 | T20: 92.82 | U20: 107.42 | V20: 142.34 | W20: 263.84 | X20: 0.047620357 | Y20: 0.044825867 | Z20: 0.12285549 | AA20: 0.3565836
A21: 260219 | B21: SII | C21: United States | D21: Asset Management | E21: Dec'25 | F21: 31.8 | G21: 47.29 | H21: 42.46 | I21: 30.55 | J21: 36.01 | K21: 36.16 | L21: 39.92 | M21: 36.28 | N21: 34.47 | O21: 40.69 | P21: 41.54 | Q21: 47.99 | R21: 46.51 | S21: 42.62 | T21: 43.36 | U21: 65.17 | V21: 65.11 | W21: 111.43 | X21: 0.010186947 | Y21: 0.095190603 | Z21: 0.094100981 | AA21: 0.31818182
A22: 260219 | B22: AG | C22: United States | D22: Silver | E22: Dec'25 | F22: 30.2 | G22: 204.88 | H22: 156.84 | I22: 159.44 | J22: 159.75 | K22: 148.19 | L22: 156.95 | M22: 146.69 | N22: 133.21 | O22: 136.95 | P22: 106.01 | Q22: 136.17 | R22: 146.09 | S22: 172.34 | T22: 243.94 | U22: 264.23 | V22: 285.06 | W22: 463.92 | X22: 0.24603557 | Y22: 0.18332522 | Z22: 0.16812243 | AA22: 0.30197707
A23: 260219 | B23: MDGL | C23: United States | D23: Biotechnology | E23: Dec'25 | F23: 29.4 | G23: 0 | H23: 0 | I23: 0 | J23: 0 | K23: 0 | L23: 0 | M23: 0 | N23: 0 | O23: 0 | P23: 0 | Q23: 14.64 | R23: 62.18 | S23: 103.32 | T23: 137.25 | U23: 212.8 | V23: 287.27 | W23: 321.08 | X23: 0.76190741 | Y23: 0.62434229 | Z23: 0.43660169 | AA23: 0.29401599
A24: 260219 | B24: CG | C24: United States | D24: Asset Management | E24: Dec'25 | F24: 25.7 | G24: 1917 | H24: 1511 | I24: 981.5 | J24: 1008 | K24: 616.5 | L24: 735.6 | M24: 329.3 | N24: 582.7 | O24: 773.4 | P24: 533 | Q24: 887.2 | R24: 2443 | S24: 876.8 | T24: 831.8 | U24: 1374 | V24: 125.6 | W24: 1700 | X24: 0.063037975 | Y24: 0.096610304 | Z24: -0.41939337 | AA24: 0.25659248
A25: 260219 | B25: CHH | C25: United States | D25: Lodging | E25: Dec'25 | F25: 21.5 | G25: 140.18 | H25: 131.09 | I25: 178.59 | J25: 194.16 | K25: 172.66 | L25: 162.18 | M25: 213.12 | N25: 207.92 | O25: 176.79 | P25: 202.96 | Q25: 258.89 | R25: 256.14 | S25: 188.97 | T25: 209.44 | U25: 259.09 | V25: 277.91 | W25: 390.15 | X25: 0.0071447473 | Y25: 0.00021895253 | Z25: 0.023827766 | AA25: 0.21507147
A26: 260219 | B26: LMND | C26: United States | D26: Insurance - Property & Casualty | E26: Dec'25 | F26: 12 | G26: 41 | H26: 44.3 | I26: 50 | J26: 74 | K26: 88.4 | L26: 95.2 | M26: 104.6 | N26: 115.2 | O26: 114.8 | P26: 119.1 | Q26: 122 | R26: 136.6 | S26: 148.8 | T26: 151.2 | U26: 164.1 | V26: 194.3 | W26: 228.1 | X26: 0.060968661 | Y26: 0.075366989 | Z26: 0.096054603 | AA26: 0.1204435
A27: 260219 | B27: FIX | C27: United States | D27: Engineering & Construction | E27: Dec'25 | F27: 9.3 | G27: 856.08 | H27: 885.22 | I27: 1018 | J27: 1120 | K27: 1117 | L27: 1175 | M27: 1296 | N27: 1378 | O27: 1358 | P27: 1537 | Q27: 1810 | R27: 1812 | S27: 1868 | T27: 1831 | U27: 2173 | V27: 2451 | W27: 2646 | X27: 0.041838622 | Y27: 0.04958339 | Z27: 0.083159813 | AA27: 0.09347591
A28: 260219 | B28: GH | C28: United States | D28: Diagnostics & Research | E28: Dec'25 | F28: 8.8 | G28: 108.11 | H28: 96.1 | I28: 109.14 | J28: 117.4 | K28: 126.89 | L28: 128.71 | M28: 137.15 | N28: 143.03 | O28: 155.05 | P28: 168.49 | Q28: 177.24 | R28: 191.48 | S28: 201.81 | T28: 203.47 | U28: 232.09 | V28: 265.2 | W28: 281.27 | X28: 0.047332954 | Y28: 0.070865633 | Z28: 0.088942511 | AA28: 0.088037493
A29: 260219 | B29: LAUR | C29: United States | D29: Education & Training Services | E29: Dec'25 | F29: 7.5 | G29: 296.73 | H29: 209.56 | I29: 385.38 | J29: 301 | K29: 346.33 | L29: 251.26 | M29: 462.07 | N29: 361.53 | O29: 409.43 | P29: 275.37 | Q29: 499.25 | R29: 368.63 | S29: 423.39 | T29: 236.16 | U29: 524.16 | V29: 400.22 | W29: 541.4 | X29: -0.025028086 | Y29: 0.01630844 | Z29: 0.020349923 | AA29: 0.074504555
A30: 260219 | B30: PRU | C30: United States | D30: Insurance - Life | E30: Dec'25 | F30: 6.7 | G30: 16424 | H30: 11855 | I30: 11392 | J30: 20201 | K30: 11135 | L30: 17045 | M30: 13498 | N30: 8352 | O30: 15084 | P30: 23509 | Q30: 14883 | R30: 19490 | S30: 12314 | T30: 13470 | U30: 13726 | V30: 17879 | W30: 16158 | X30: -0.14301385 | Y30: -0.019233007 | Z30: -0.027305085 | AA30: 0.066981477
A31: 260219 | B31: TALK | C31: United States | D31: Health Information Services | E31: Dec'25 | F31: 6.7 | G31: 29.17 | H31: 30.15 | I31: 29.84 | J31: 29.33 | K31: 30.24 | L31: 33.34 | M31: 35.65 | N31: 38.65 | O31: 42.42 | P31: 45.42 | Q31: 46.06 | R31: 47.4 | S31: 48.72 | T31: 52.18 | U31: 54.31 | V31: 59.38 | W31: 63 | X31: 0.036034115 | Y31: 0.042447006 | Z31: 0.059128375 | AA31: 0.066545505
A32: 260219 | B32: IRTC | C32: United States | D32: Medical Devices | E32: Dec'25 | F32: 6.3 | G32: 81.8 | H32: 92.38 | I32: 102.05 | J32: 103.88 | K32: 112.62 | L32: 111.44 | M32: 124.13 | N32: 124.6 | O32: 132.51 | P32: 131.93 | Q32: 148.05 | R32: 147.54 | S32: 164.33 | T32: 158.68 | U32: 186.69 | V32: 192.88 | W32: 208.89 | X32: 0.045197263 | Y32: 0.062463628 | Z32: 0.068985454 | AA32: 0.063423382
A33: 260219 | B33: HG | C33: United States | D33: Insurance - Reinsurance | E33: Dec'25 | F33: 6 | H33: 246.31 | I33: 493.69 | J33: 225.04 | K33: 261.85 | L33: 324.43 | M33: 360.58 | N33: 394.83 | O33: 497.39 | P33: 660.77 | Q33: 589.72 | R33: 518.82 | S33: 563.84 | T33: 771.31 | U33: 745.28 | V33: 665.03 | W33: 729.89 | X33: 0.047378008 | Y33: 0.063657829 | Z33: 0.056250842 | AA33: 0.060481668
A34: 260219 | B34: NEM | C34: United States | D34: Gold | E34: Dec'25 | F34: 5.4 | G34: 3390 | H34: 3023 | I34: 3058 | J34: 2634 | K34: 3200 | L34: 2679 | M34: 2683 | N34: 2493 | O34: 3957 | P34: 4023 | Q34: 4402 | R34: 4605 | S34: 5652 | T34: 5010 | U34: 5317 | V34: 5524 | W34: 6818 | X34: 0.052831603 | Y34: 0.046519904 | Z34: 0.044646327 | AA34: 0.054224992
A35: 260219 | B35: APPN | C35: United States | D35: Software - Infrastructure | E35: Dec'25 | F35: 5.2 | G35: 104.99 | H35: 114.27 | I35: 110.06 | J35: 117.88 | K35: 125.79 | L35: 135.24 | M35: 127.72 | N35: 137.09 | O35: 145.32 | P35: 149.84 | Q35: 146.45 | R35: 154.05 | S35: 166.69 | T35: 166.43 | U35: 170.64 | V35: 187 | W35: 202.87 | X35: 0.026886861 | Y35: 0.038177457 | Z35: 0.050090452 | AA35: 0.052377092
A36: 260219 | B36: PWR | C36: United States | D36: Engineering & Construction | E36: Dec'25 | F36: 4.7 | G36: 3924 | H36: 3966 | I36: 4232 | J36: 4460 | K36: 4417 | L36: 4429 | M36: 5049 | N36: 5621 | O36: 5784 | P36: 5032 | Q36: 5594 | R36: 6493 | S36: 6553 | T36: 6233 | U36: 6773 | V36: 7631 | W36: 7842 | X36: 0.050735046 | Y36: 0.047400796 | Z36: 0.043681867 | AA36: 0.047407135
A37: 260219 | B37: WK | C37: United States | D37: Software - Application | E37: Dec'25 | F37: 4.6 | G37: 120.78 | H37: 129.67 | I37: 131.55 | J37: 132.85 | K37: 143.8 | L37: 150.19 | M37: 155.02 | N37: 158.18 | O37: 166.65 | P37: 175.67 | Q37: 177.5 | R37: 185.62 | S37: 199.89 | T37: 206.28 | U37: 215.19 | V37: 224.17 | W37: 238.94 | X37: 0.041438783 | Y37: 0.048993228 | Z37: 0.047770701 | AA37: 0.04618405
A38: 260219 | B38: PRDO | C38: United States | D38: Education & Training Services | E38: Dec'25 | F38: 4.3 | G38: 159.86 | H38: 182.96 | I38: 167.68 | J38: 168.42 | K38: 176.15 | L38: 195.6 | M38: 186.56 | N38: 179.92 | O38: 147.92 | P38: 168.26 | Q38: 166.74 | R38: 169.83 | S38: 176.43 | T38: 213 | U38: 209.58 | V38: 211.87 | W38: 211.64 | X38: 0.06567243 | Y38: 0.059008264 | Z38: 0.054679777 | AA38: 0.043421961
A39: 260219 | B39: WEAV | C39: United States | D39: Health Information Services | E39: Dec'25 | F39: 4 | G39: 31.84 | H39: 33.27 | I39: 34.93 | J39: 36.23 | K39: 37.69 | L39: 39.57 | M39: 41.67 | N39: 43.54 | O39: 45.69 | P39: 47.17 | Q39: 50.59 | R39: 52.39 | S39: 54.17 | T39: 55.81 | U39: 58.47 | V39: 61.34 | W39: 63.4 | X39: 0.042286609 | Y39: 0.037002254 | Z39: 0.040527078 | AA39: 0.040167109
A40: 260219 | B40: LZ | C40: United States | D40: Specialty Business Services | E40: Dec'25 | F40: 3.9 | G40: 142.14 | H40: 155.43 | I40: 162.65 | J40: 155.28 | K40: 146.63 | L40: 165.94 | M40: 168.85 | N40: 167.27 | O40: 158.66 | P40: 174.21 | Q40: 177.36 | R40: 168.6 | S40: 161.71 | T40: 183.11 | U40: 192.51 | V40: 190.16 | W40: 190.27 | X40: 0.01305215 | Y40: 0.021931729 | Z40: 0.030541272 | AA40: 0.039258272
A41: 260219 | B41: SVV | C41: United States | D41: Specialty Retail | E41: Dec'25 | F41: 3.9 | G41: 344.83 | H41: 327.47 | I41: 364.67 | J41: 378.29 | K41: 366.8 | L41: 345.68 | M41: 379.1 | N41: 392.7 | O41: 382.77 | P41: 354.17 | Q41: 386.66 | R41: 394.8 | S41: 401.99 | T41: 370.15 | U41: 417.21 | V41: 426.94 | W41: 464.67 | X41: 0.010392685 | Y41: 0.019664006 | Z41: 0.020288483 | AA41: 0.038780169
A42: 260219 | B42: AIR | C42: United States | D42: Aerospace & Defense | E42: Jun'26 | F42: 3.8 | G42: 436.6 | H42: 452.2 | I42: 476.1 | J42: 446.3 | K42: 469.8 | L42: 521.1 | M42: 553.3 | N42: 549.7 | O42: 545.4 | P42: 567.3 | Q42: 656.5 | R42: 661.7 | S42: 686.1 | T42: 678.2 | U42: 754.5 | V42: 739.6 | W42: 795.3 | X42: 0.043124903 | Y42: 0.036533085 | Z42: 0.028016544 | AA42: 0.038203191
...

Sheet Operating Income
B1: 1 | C1: 2 | D1: 3 | E1: 4 | F1: 5 | G1: 6 | H1: 7 | I1: 8 | J1: 9 | K1: 10 | L1: 11 | M1: 12 | N1: 13 | O1: 14 | P1: 15 | Q1: 16 | R1: 17 | S1: 18 | T1: 19 | U1: 20 | V1: 21 | W1: 22
B2: Ticker | C2: Country | D2: Industry | E2: Latest_Date | F2: Growth_Rate | G2: 4Q21 | H2: 1Q22 | I2: 2Q22 | J2: 3Q22 | K2: 4Q22 | L2: 1Q23 | M2: 2Q23 | N2: 3Q23 | O2: 4Q23 | P2: 1Q24 | Q2: 2Q24 | R2: 3Q24 | S2: 4Q24 | T2: 1Q25 | U2: 2Q25 | V2: 3Q25 | W2: 4Q25 | X2: 1Q25 | Y2: 2Q25 | Z2: 3Q25 | AA2: 4Q25
A3: 260220 | B3: TDS | C3: United States | D3: Telecom Services | E3: Dec'25 | F3: 355.8 | G3: 32 | H3: 96 | I3: 73 | J3: -7 | K3: -11 | L3: 40 | M3: 38 | N3: 54 | O3: 26 | P3: 73 | Q3: 0 | R3: -24.6 | S3: -13 | T3: 37 | U3: 0 | V3: -18.05 | W3: 8.17 | X3: -1.0169492 | Y3: 0 | Z3: -10.916667 | AA3: 3.5579832
A4: 260220 | B4: ASB | C4: United States | D4: Banks - Regional | E4: Dec'25 | F4: 143.6 | G4: 92.05 | H4: 92.91 | I4: 110.19 | J4: 122.44 | K4: 134.09 | L4: 130.7 | M4: 110.69 | N4: 102.67 | O4: -138.01 | P4: 101.19 | Q4: 102.88 | R4: 108.14 | S4: -177.75 | T4: 121.1 | U4: 139.63 | V4: 154.29 | W4: 162.9 | X4: 0.14807378 | Y4: 0.23806439 | Z4: 0.24147133 | AA4: 1.4357062
A5: 260220 | B5: AD | C5: United States | D5: Telecom Services | E5: Dec'25 | F5: 52.8 | G5: 12 | H5: 72 | I5: 49 | J5: -14 | K5: -17 | L5: 36 | M5: 37 | N5: 58 | O5: 23 | P5: 56 | Q5: 0 | R5: -25.94 | S5: -6 | T5: 42 | U5: 0 | V5: -6.25 | W5: 9.72 | X5: -0.58187864 | Y5: 0 | Z5: 1.9572565 | AA5: 0.52840336
A6: 260220 | B6: LAMR | C6: United States | D6: REIT - Specialty | E6: Dec'25 | F6: 29 | G6: 151.99 | H6: 120.64 | I6: 165.49 | J6: 182.49 | K6: 97.98 | L6: 116.29 | M6: 175.56 | N6: 187.95 | O6: 193.85 | P6: 121.85 | Q6: 183.41 | R6: 186.72 | S6: 39.09 | T6: 121.83 | U6: 193.33 | V6: 186.93 | W6: 196.24 | X6: -3.7659819e-05 | Y6: 0.018679974 | Z6: 0.00038819158 | AA6: 0.29038398
A7: 260220 | B7: HBM | C7: United States | D7: Copper | E7: Dec'25 | F7: 13.7 | G7: 26.48 | H7: 128.14 | I7: 137.93 | J7: 17.83 | K7: 21.06 | L7: 52.48 | M7: 5.13 | N7: 114.94 | O7: 130.06 | P7: 121.8 | Q7: 44.4 | R7: 105.2 | S7: 149.7 | T7: 186.4 | U7: 150.7 | V7: 11.5 | W7: 218.1 | X7: 0.15340774 | Y7: 0.21885938 | Z7: -0.15827703 | AA7: 0.13726671
A8: 260220 | B8: AI | C8: United States | D8: Software - Infrastructure | E8: Jun'26 | F8: 9.8 | G8: -55.68 | H8: -47.41 | I8: -56.52 | J8: -73.21 | K8: -71.97 | L8: -72.04 | M8: -73.28 | N8: -74.09 | O8: -79.4 | P8: -82.55 | Q8: -82.31 | R8: -72.59 | S8: -75.29 | T8: -87.59 | U8: -88.97 | V8: -124.82 | W8: -112.11 | X8: 0.016115623 | Y8: 0.020957895 | Z8: 0.16098508 | AA8: 0.097751347
A9: 260220 | B9: RCL | C9: United States | D9: Travel Services | E9: Dec'25 | F9: 6.6 | G9: -987.85 | H9: -859.21 | I9: -217.74 | J9: 303 | K9: 18.98 | L9: 272 | M9: 776 | N9: 1265 | O9: 591 | P9: 750 | Q9: 1108 | R9: 1636 | S9: 633 | T9: 949 | U9: 1333 | V9: 1703 | W9: 936 | X9: 0.048219045 | Y9: 0.052011096 | Z9: 0.014722039 | AA9: 0.065612819
A10: 260220 | B10: BCPC | C10: United States | D10: Specialty Chemicals | E10: Dec'25 | F10: 2.6 | G10: 33.82 | H10: 38.34 | I10: 40.45 | J10: 33.63 | K10: 35.6 | L10: 34.97 | M10: 48.98 | N10: 45.23 | O10: 28.25 | P10: 42.12 | Q10: 45.8 | R10: 48.51 | S10: 48.04 | T10: 51.5 | U10: 51.44 | V10: 54.58 | W10: 53.34 | X10: 0.050848376 | Y10: 0.029094661 | Z10: 0.03042759 | AA10: 0.025783226
A11: 260220 | B11: BN | C11: United States | D11: Asset Management | E11: Dec'25 | F11: 0.7 | G11: 4020 | H11: 3997 | I11: 3953 | J11: 4553 | K11: 4246 | L11: 3892 | M11: 4140 | N11: 4146 | O11: 4336 | P11: 4530 | Q11: 4704 | R11: 5443 | S11: 6046 | T11: 4995 | U11: 4615 | V11: 4810 | W11: 6186 | X11: 0.022438836 | Y11: -0.0042004908 | Z11: -0.030001422 | AA11: 0.0068406137
A12: 260220 | B12: RSG | C12: United States | D12: Waste Management | E12: Dec'25 | F12: 0.1 | G12: 510.7 | H12: 571.4 | I12: 649.6 | J12: 674.6 | K12: 593 | L12: 657.2 | M12: 733.3 | N12: 738.8 | O12: 719.7 | P12: 739 | Q12: 818 | R12: 863 | S12: 804 | T12: 806 | U12: 870 | V12: 839 | W12: 806 | X12: 0.020781638 | Y12: 0.015800668 | Z12: -0.0071791804 | AA12: 0.00060259114
A13: 260220 | B13: WU | C13: United States | D13: Credit Services | E13: Dec'25 | F13: -0.1 | G13: 316 | H13: 256.2 | I13: 264.2 | J13: 231.2 | K13: 172.8 | L13: 211.8 | M13: 250.9 | N13: 215 | O13: 169.3 | P13: 206.1 | Q13: 200.1 | R13: 164.9 | S13: 197 | T13: 177.4 | U13: 192.7 | V13: 201.9 | W13: 196.2 | X13: -0.037364926 | Y13: -0.010008115 | Z13: 0.050546448 | AA13: -0.0010403121
A14: 260220 | B14: CCOI | C14: United States | D14: Telecom Services | E14: Dec'25 | F14: -17.3 | G14: 28.8 | H14: 28.41 | I14: 29.48 | J14: 30.77 | K14: 27.55 | L14: 24.71 | M14: -33.87 | N14: -50.21 | O14: -51.48 | P14: -50.35 | Q14: -38.11 | R14: -57.83 | S14: -33.23 | T14: -40.29 | U14: -31.46 | V14: -20.58 | W14: -11.48 | X14: -0.056038324 | Y14: -0.039242299 | Z14: -0.2287943 | AA14: -0.17322396
... A17: 260220 | B17: OIS | C17: United States | D17: Oil & Gas Equipment & Services | E17: Dec'25 | F17: -41.8 | G17: -9.06 | H17: -4.34 | I17: -1.09 | J17: -1.04 | K17: 0.42 | L17: 5.88 | M17: 3.27 | N17: 7.84 | O17: 4.61 | P17: 1.33 | Q17: 5.51 | R17: 7.17 | S17: -7.88 | T17: 6.87 | U17: 8.94 | V17: 8.31 | W17: -14.67 | X17: 0.90375204 | Y17: 0.29391602 | Z17: 0.075496689 | AA17: -0.41810345
A18: 260220 | B18: 8987 | C18: Japan | D18: Japan Excellent, Inc. | E18: H2 2025 | F18: -8.0237474 | G18: 4486 | I18: 4711 | K18: 4105 | M18: 7121 | O18: 4608 | Q18: 4836 | S18: 6098 | U18: 5019 | W18: 5206 | X18: -0.19481627 | Y18: 0.15777213 | Z18: 0.016736784 | AA18: -0.080237474
A19: 260220 | B19: 2350 | C19: Hong Kong | D19: Saudi Kayan Petrochemical Company | E19: H1 2026 | F19: -44.034091 | G19: 23.15 | I19: 41.52 | K19: 40.77 | M19: 16.02 | O19: 2.59 | Q19: -16.58 | S19: -17.61 | U19: 10.57 | W19: -14.51 | X19: -1.7517464 | Y19: 1.4438885 | Z19: -0.79409184 | AA19: -0.44034091
A20: 260219 | B20: ALIT | C20: United States | D20: Software - Application | E20: Dec'25 | F20: 325 | G20: 40 | H20: -2 | I20: -9 | J20: -27 | K20: 18 | L20: -40 | M20: -11 | N20: -30 | O20: -23 | P20: -40 | Q20: -34 | R20: -30 | S20: -1 | T20: -8 | U20: 9 | V20: 20 | W20: 64 | X20: -0.3047619 | Y20: -0.5890411 | Z20: -1.6666667 | AA20: 3.25
A21: 260219 | B21: TALK | C21: United States | D21: Health Information Services | E21: Dec'25 | F21: 189 | G21: -28.58 | H21: -21.21 | I21: -21.07 | J21: -19.55 | K21: -15.2 | L21: -9.04 | M21: -6.41 | N21: -5.18 | O21: -2.58 | P21: -1.68 | Q21: -3.49 | R21: 0.1 | S21: 1.77 | T21: -1.09 | U21: -1.79 | V21: 2.2 | W21: 3.83 | X21: -0.17878788 | Y21: -0.62730627 | Z21: -2.0792079 | AA21: 1.8899083
A22: 260219 | B22: AG | C22: United States | D22: Silver | E22: Dec'25 | F22: 105.6 | G22: 27.08 | H22: -4.71 | I22: -4.69 | J22: -13.74 | K22: -28.47 | L22: -115.47 | M22: -11.89 | N22: -9.25 | O22: -193.17 | P22: -22.8 | Q22: -5.59 | R22: 7.59 | S22: 35.95 | T22: 37.87 | U22: 24.93 | V22: 76.87 | W22: 221.36 | X22: 4.0046205 | Y22: 0.40253231 | Z22: 0.6514952 | AA22: 1.0557454
A23: 260219 | B23: LNT | C23: United States | D23: Utilities - Regulated Electric | E23: Dec'25 | F23: 95.6 | G23: 123 | H23: 248 | I23: 212 | J23: 309 | K23: 132 | L23: 222 | M23: 217 | N23: 482 | O23: -342 | P23: 222 | Q23: 190 | R23: 313 | S23: -305 | T23: 257 | U23: 223 | V23: 349 | W23: 196 | X23: 0.083333333 | Y23: 0.072527473 | Z23: 0.073770492 | AA23: 0.95610687
A24: 260219 | B24: PRU | C24: United States | D24: Insurance - Life | E24: Dec'25 | F24: 66.3 | G24: 2448 | H24: -657 | I24: -1061 | J24: -126 | K24: -1435 | L24: 1847 | M24: 621 | N24: -1058 | O24: 2069 | P24: 1390 | Q24: 1415 | R24: 553 | S24: -357 | T24: 920 | U24: 740 | V24: 1773 | W24: 1682 | X24: -0.15661446 | Y24: -0.26669301 | Z24: 0.65732759 | AA24: 0.66287386
A25: 260219 | B25: CG | C25: United States | D25: Asset Management | E25: Dec'25 | F25: 38.3 | G25: 890 | H25: 740.2 | I25: 323.4 | J25: 404.2 | K25: 143.2 | L25: 156.1 | M25: -85.6 | N25: 161.6 | O25: -839.7 | P25: 127.9 | Q25: 223.6 | R25: 786.2 | S25: 231.7 | T25: 164.9 | U25: 393.7 | V25: -37.4 | W25: 519.9 | X25: 0.027019132 | Y25: 0.1209471 | Z25: -0.52242309 | AA25: 0.38278656
A26: 260219 | B26: OPEN | C26: United States | D26: Real Estate Services | E26: Dec'25 | F26: 36.5 | G26: -102 | H26: 118 | I26: 32 | J26: -809 | K26: -192 | L26: -122 | M26: -57 | N26: -77 | O26: -106 | P26: -84 | Q26: -72 | R26: -66 | S26: -81 | T26: -53 | U26: -4 | V26: -65 | W26: -155 | X26: -0.10231023 | Y26: -0.25 | Z26: -0.0049019608 | AA26: 0.36453202
A27: 260219 | B27: SII | C27: United States | D27: Asset Management | E27: Dec'25 | F27: 36.3 | G27: 13.75 | H27: 11.04 | I27: 6.25 | J27: 9.05 | K27: 17.07 | L27: 13.21 | M27: 11.49 | N27: 11.27 | O27: 10.88 | P27: 16.32 | Q27: 19.06 | R27: 20.36 | S27: 14.4 | T27: 16.64 | U27: 22.41 | V27: 16.86 | W27: 39.95 | X27: 0.004562304 | Y27: 0.047544706 | Z27: -0.047419049 | AA27: 0.3633907
A28: 260219 | B28: AIR | C28: United States | D28: Aerospace & Defense | E28: Jun'26 | F28: 34.4 | G28: 28.1 | H28: 31.4 | I28: 34.1 | J28: 31.8 | K28: 33.1 | L28: 35.7 | M28: 37.1 | N28: 37.4 | O28: 39.1 | P28: 45.4 | Q28: 53.8 | R28: 42.6 | S28: -3.6 | T28: 64.7 | U28: 84 | V28: 61.9 | W28: 67.7 | X28: 0.13965268 | Y28: 0.19174603 | Z28: 0.10282365 | AA28: 0.34444444
A29: 260219 | B29: RNG | C29: United States | D29: Software - Application | E29: Dec'25 | F29: 29.6 | G29: -103.26 | H29: -103.54 | I29: -106.34 | J29: -74 | K29: -348.96 | L29: -49.66 | M29: -41.46 | N29: -49.73 | O29: -38.48 | P29: -6.32 | Q29: -4.16 | R29: 8.14 | S29: 12.11 | T29: 17.43 | U29: 39.78 | V29: 33.27 | W29: 42.44 | X29: 2.430911 | Y29: 1.3108592 | Z29: 0.32442551 | AA29: 0.29564285
A30: 260219 | B30: CNA | C30: United States | D30: Insurance - Property & Casualty | E30: Dec'25 | F30: 25.9 | G30: 358 | H30: 383 | I30: 255 | J30: -23 | K30: 311 | L30: 399 | M30: 392 | N30: 360 | O30: 494 | P30: 462 | Q30: 436 | R30: 393 | S30: 53 | T30: 381 | U30: 411 | V30: 549 | W30: 414 | X30: -0.060267857 | Y30: -0.019794141 | Z30: 0.12600969 | AA30: 0.258967
A31: 260219 | B31: FIX | C31: United States | D31: Engineering & Construction | E31: Dec'25 | F31: 18 | G31: 48.81 | H31: 35.37 | I31: 56.27 | J31: 81.03 | K31: 79.6 | L31: 63.07 | M31: 91.49 | N31: 134.56 | O31: 118.96 | P31: 134.64 | Q31: 184.06 | R31: 201.54 | S31: 226.1 | T31: 208.54 | U31: 299.43 | V31: 378.29 | W31: 426.35 | X31: 0.099016534 | Y31: 0.14065395 | Z31: 0.18891418 | AA31: 0.18002265
A32: 260219 | B32: NEM | C32: United States | D32: Gold | E32: Dec'25 | F32: 17.8 | G32: -645 | H32: 834 | I32: 562 | J32: 306 | K32: -97 | L32: 513 | M32: 407 | N32: 275 | O32: -487 | P32: 958 | Q32: 1344 | R32: 1298 | S32: 2310 | T32: 2016 | U32: 2417 | V32: 2588 | W32: 3974 | X32: 0.17901861 | Y32: 0.15398967 | Z32: 0.16042781 | AA32: 0.1783303
A33: 260219 | B33: HG | C33: United States | D33: Insurance - Reinsurance | E33: Dec'25 | F33: 16.5 | H33: -73.68 | I33: 249.93 | J33: -148.19 | K33: -21.21 | L33: 62.15 | M33: 52.77 | N33: 58.89 | O33: 109.03 | P33: 285.76 | Q33: 210.69 | R33: 75.39 | S33: 75.57 | T33: 192.6 | U33: 279.7 | V33: 182.61 | W33: 196.17 | X33: -0.14389645 | Y33: 0.1245106 | Z33: 0.17203093 | AA33: 0.16509692
A34: 260219 | B34: LAUR | C34: United States | D34: Education & Training Services | E34: Dec'25 | F34: 14.7 | G34: 32.2 | H34: 10.03 | I34: 126.94 | J34: 56.32 | K34: 78.02 | L34: 15.63 | M34: 156.11 | N34: 58.71 | O34: 111.45 | P34: 11.13 | Q34: 166.6 | R34: 72.04 | S34: 124.22 | T34: -13.19 | U34: 193.34 | V34: 71.47 | W34: 179.5 | X34: -0.065028477 | Y34: 0.076472102 | Z34: -0.0015143062 | AA34: 0.14708387
A35: 260219 | B35: SEM | C35: United States | D35: Medical Care Facilities | E35: Dec'25 | F35: 14.6 | G35: 67.68 | H35: 103.99 | I35: 105.84 | J35: 83.03 | K35: 86.63 | L35: 151.46 | M35: 159.2 | N35: 129.96 | O35: 0 | P35: 118.47 | Q35: 73.86 | R35: 54.9 | S35: 21.09 | T35: 112.75 | U35: 86.53 | V35: 72.96 | W35: 63.94 | X35: -0.021317829 | Y35: 0.048248286 | Z35: 0.065608312 | AA35: 0.14608121
A36: 260219 | B36: RIO | C36: United States | D36: Other Industrial Metals & Mining | E36: H2 2025 | F36: 11.665641 | G36: 12268 | I36: 11498 | K36: 6597 | M36: 7862 | O36: 7005 | Q36: 7718 | S36: 6272 | U36: 6732 | W36: 7789 | X36: -0.0096858815 | Y36: -0.049786049 | Z36: -0.070478914 | AA36: 0.11665641
A37: 260219 | B37: PRAX | C37: United States | D37: Biotechnology | E37: Dec'25 | F37: 11.3 | G37: -58.66 | H37: -68.85 | I37: -59.39 | J37: -44.29 | K37: -40.45 | L37: -38.09 | M37: -34.96 | N37: -25.52 | O37: -27.81 | P37: -41.89 | Q37: -37.49 | R37: -56.84 | S37: -63.96 | T37: -74.73 | U37: -76.07 | V37: -78.36 | W37: -97.04 | X37: 0.16405235 | Y37: 0.16556519 | Z37: 0.079234168 | AA37: 0.1128548
A38: 260219 | B38: FIVN | C38: United States | D38: Software - Infrastructure | E38: Dec'25 | F38: 9.4 | G38: 1.98 | H38: -27.28 | I38: -20.86 | J38: -20.93 | K38: -3.09 | L38: -28.4 | M38: -24.44 | N38: -25.74 | O38: -11.82 | P38: -20.7 | Q38: -19.37 | R38: -15.42 | S38: 16.48 | T38: -5.43 | U38: 8.31 | V38: 16.14 | W38: 19.8 | X38: -0.39143809 | Y38: -1.1659646 | Z38: 8.0101523 | AA38: 0.093521127
A39: 260219 | B39: CARG | C39: United States | D39: Auto & Truck Dealerships | E39: Dec'25 | F39: 7.4 | G39: 44.57 | H39: 26.66 | I39: 23.54 | J39: 28.66 | K39: 29.79 | L39: 14.06 | M39: 17.74 | N39: 23.1 | O39: -22.27 | P39: 26.28 | Q39: 34.07 | R39: 44.21 | S39: 53.28 | T39: 45.76 | U39: 57.4 | V39: 58.48 | W39: 69.13 | X39: 0.12341612 | Y39: 0.13157004 | Z39: 0.071118864 | AA39: 0.073748371
A40: 260219 | B40: VICR | C40: United States | D40: Electronic Components | E40: Dec'25 | F40: 7.4 | G40: 8.9 | H40: 4.78 | I40: 11.3 | J40: 9.5 | K40: 8.12 | L40: 10.44 | M40: 17.86 | N40: 15.7 | O40: 7.35 | P40: 1.09 | Q40: 2.51 | R40: 5.39 | S40: 9.65 | T40: 0.18 | U40: 50.83 | V40: 21.26 | W40: 15.69 | X40: -0.048819742 | Y40: 2.7253243 | Z40: 0.24027252 | AA40: 0.073730469
A41: 260219 | B41: TRGP | C41: United States | D41: Oil & Gas Midstream | E41: Dec'25 | F41: 7 | G41: 373 | H41: 295.8 | I41: 451.9 | J41: 430 | K41: 551.4 | L41: 836.7 | M41: 649.1 | N41: 505.1 | O41: 635.3 | P41: 639.4 | Q41: 627.2 | R41: 728.2 | S41: 700.5 | T41: 543.3 | U41: 1034 | V41: 836.9 | W41: 917.4 | X41: -0.035654658 | Y41: 0.1565097 | Z41: 0.036161011 | AA41: 0.069637525
A42: 260219 | B42: CVE | C42: United States | D42: Oil & Gas Integrated | E42: Dec'25 | F42: 6.5 | G42: 1691 | H42: 1880 | I42: 3552 | J42: 2073 | K42: 1401 | L42: 749 | M42: 1019 | N42: 2622 | O42: 951 | P42: 1588 | Q42: 1423 | R42: 998 | S42: 994 | T42: 1211 | U42: 724 | V42: 1452 | W42: 1277 | X42: -0.075354787 | Y42: -0.15110246 | Z42: 0.11560988 | AA42: 0.064597124
...

Sheet 빨간줄
B2: (단위: mil $)
B4: AAPL | C4: 6 | D4: 7 | E4: 8 | F4: 9 | G4: 10 | H4: 11 | I4: 12 | J4: 13 | K4: 14 | L4: 15 | M4: 16 | N4: 17 | O4: 18 | P4: 19 | Q4: 20 | R4: 21 | S4: 22
C6: 4Q21 | D6: 1Q22 | E6: 2Q22 | F6: 3Q22 | G6: 4Q22 | H6: 1Q23 | I6: 2Q23 | J6: 3Q23 | K6: 4Q23 | L6: 1Q24 | M6: 2Q24 | N6: 3Q24 | O6: 4Q24 | P6: 1Q25 | Q6: 2Q25 | R6: 3Q25 | S6: 4Q25 | T6: 1Q26 | U6: 2Q26 | V6: 3Q26 | W6: 4Q26
B7: Revenue | C7: =VLOOKUP($B$4,Revenue!$B:$W,C4,FALSE) -> 123945 | D7: =VLOOKUP($B$4,Revenue!$B:$W,D4,FALSE) -> 97278 | E7: =VLOOKUP($B$4,Revenue!$B:$W,E4,FALSE) -> 82959 | F7: =VLOOKUP($B$4,Revenue!$B:$W,F4,FALSE) -> 90146 | G7: =VLOOKUP($B$4,Revenue!$B:$W,G4,FALSE) -> 117154 | H7: =VLOOKUP($B$4,Revenue!$B:$W,H4,FALSE) -> 94836 | I7: =VLOOKUP($B$4,Revenue!$B:$W,I4,FALSE) -> 81797 | J7: =VLOOKUP($B$4,Revenue!$B:$W,J4,FALSE) -> 89498 | ... S7: =VLOOKUP($B$4,Revenue!$B:$W,S4,FALSE) -> 143756
B8: OP | C8: =VLOOKUP($B$4,'Operating Income'!$B:$W,C4,FALSE) -> 41488 | D8: =VLOOKUP($B$4,'Operating Income'!$B:$W,D4,FALSE) -> 29979 | E8: =VLOOKUP($B$4,'Operating Income'!$B:$W,E4,FALSE) -> 23076 | F8: =VLOOKUP($B$4,'Operating Income'!$B:$W,F4,FALSE) -> 24894 | G8: =VLOOKUP($B$4,'Operating Income'!$B:$W,G4,FALSE) -> 36016 | H8: =VLOOKUP($B$4,'Operating Income'!$B:$W,H4,FALSE) -> 28318 | I8: =VLOOKUP($B$4,'Operating Income'!$B:$W,I4,FALSE) -> 22998 | J8: =VLOOKUP($B$4,'Operating Income'!$B:$W,J4,FALSE) -> 26969 | ... S8: =VLOOKUP($B$4,'Operating Income'!$B:$W,S4,FALSE) -> 50852
B9: Trailing 4Q OP avg. | C9: =AVERAGE(C8:C8) -> 41488 | D9: =AVERAGE(C8:D8) -> 35733.5 | E9: =AVERAGE(C8:E8) -> 31514.333 | F9: =AVERAGE(C8:F8) -> 29859.25 | G9: =AVERAGE(D8:G8) -> 28491.25 | H9: =AVERAGE(E8:H8) -> 28076 | I9: =AVERAGE(F8:I8) -> 28056.5 | J9: =AVERAGE(G8:J8) -> 28575.25 | K9: =AVERAGE(H8:K8) -> 29664.5 | L9: =AVERAGE(I8:L8) -> 29560 | M9: =AVERAGE(J8:M8) -> 30148.5 | ... S9: =AVERAGE(P8:S8) -> 35267.5
B10: Trailing 4Q OP sum. | C10: =SUM(C8:C8) -> 41488 | D10: =SUM(C8:D8) -> 71467 | E10: =SUM(C8:E8) -> 94543 | F10: =SUM(C8:F8) -> 119437 | G10: =SUM(D8:G8) -> 113965 | H10: =SUM(E8:H8) -> 112304 | I10: =SUM(F8:I8) -> 112226 | J10: =SUM(G8:J8) -> 114301 | K10: =SUM(H8:K8) -> 118658 | L10: =SUM(I8:L8) -> 118240 | M10: =SUM(J8:M8) -> 120594 | ... S10: =SUM(P8:S8) -> 141070
B11: Trailing OP Delta | D11: =D9/C9-1 -> -0.13870276 | E11: =E9/D9-1 -> -0.11807314 | F11: =F9/E9-1 -> -0.052518431 | G11: =G9/F9-1 -> -0.045814948 | H11: =H9/G9-1 -> -0.01457465 | I11: =I9/H9-1 -> -0.00069454338 | J11: =J9/I9-1 -> 0.018489477 | K11: =K9/J9-1 -> 0.038118652 | ... S11: =S9/R9-1 -> 0.060278091
B12: opm | C12: =IFERROR(C8/C7,"-") -> 0.33472911 | D12: =IFERROR(D8/D7,"-") -> 0.30817862 | E12: =IFERROR(E8/E7,"-") -> 0.2781615 | F12: =IFERROR(F8/F7,"-") -> 0.27615202 | G12: =IFERROR(G8/G7,"-") -> 0.30742442 | H12: =IFERROR(H8/H7,"-") -> 0.29859969 | I12: =IFERROR(I8/I7,"-") -> 0.28115946 | J12: =IFERROR(J8/J7,"-") -> 0.30133634 | ... S12: =IFERROR(S8/S7,"-") -> 0.35373828
B13: op yoy | C13: =C8/#REF!-1 -> #REF! | D13: =D8/#REF!-1 -> #REF! | E13: =E8/#REF!-1 -> #REF! | F13: =F8/#REF!-1 -> #REF! | G13: =G8/C8-1 -> -0.13189356 | H13: =H8/D8-1 -> -0.05540545 | I13: =I8/E8-1 -> -0.0033801352 | J13: =J8/F8-1 -> 0.083353418 | K13: =K8/G8-1 -> 0.12097401 | L13: =L8/H8-1 -> -0.014760929 | M13: =M8/I8-1 -> 0.10235673 | N13: =N8/J8-1 -> 0.097222737 | ... S13: =S8/O8-1 -> 0.18724318
B14: rv yoy | G14: =G7/C7-1 -> -0.054790431 | H14: =H7/D7-1 -> -0.025103312 | I14: =I7/E7-1 -> -0.014006919 | J14: =J7/F7-1 -> -0.0071883389 | K14: =K7/G7-1 -> 0.020665107 | L14: =L7/H7-1 -> -0.043053271 | M14: =M7/I7-1 -> 0.048657041 | N14: =N7/J7-1 -> 0.060694094 | ... S14: =S7/O7-1 -> 0.15652454
